<mujocoinclude model="MoBL Arms Index Model">

    <body name="thorax" pos="0 0 0" quat="0.7071067811865475 0.7071067811865475 0.0 0.0">
      <light mode="trackcom" directional="false" pos="0 0 4.0" dir="0 0 -1" />
      <geom name="thorax" type="mesh" mesh="thorax" />
      <site name="PECM1-P3" pos="  -7e-05  0.00821  0.10454" />
      <site name="PECM2-P4" pos="0.0268488 -0.0340669 0.0842987" />
      <site name="PECM2-P5" pos="0.0240518 -0.0390701 0.0197262" />
      <site name="PECM2-P3" pos=" 0.02083 -0.02005  0.11555" />
      <site name="PECM3-P4" pos="0.0456021 -0.073111 0.0776104" />
      <site name="PECM3-P5" pos="0.0497193 -0.101228 0.0328943" />
      <site name="PECM3-P3" pos=" 0.02984 -0.0544459   0.1151" />
      <site name="LAT1-P4" pos="-0.102739 -0.0878861 0.0288031" />
      <site name="LAT1-P5" pos="-0.0831956 -0.101836 0.00766115" />
      <site name="LAT2-P4" pos="-0.0954777 -0.146865 0.0249986" />
      <site name="LAT2-P5" pos="-0.0624184 -0.163455 0.00707918" />
      <site name="LAT3-P4" pos="-0.096911 -0.168398 0.0480516" />
      <site name="LAT3-P5" pos="-0.0618191 -0.215919 0.0078783" />
      <joint name="r_z" type="hinge" pos="0 0 0" axis="       0        0        1" limited="true" range="-6.28319  6.28319" ref="0" armature="0" damping="0" stiffness="0" />
      <body name="clavicle" pos="0.00549397 0.00601948 0.0221192" quat="1.0 0.0 0.0 0.0">
        <geom name="clavicle" type="mesh" mesh="clavicle" />
        <inertial pos="-0.00963811 0.00553505 0.0470509" mass="0.135503355694502" fullinertia="0.000158982 0.000167286 2.91109e-05 -1.24386e-05 -4.58355e-05 3.51991e-05" />
        <site name="DELT1-P4" pos="-0.0121606 0.00960684 0.0696713" />
        <site name="DELT2-P2" pos="0.0191703 0.0244002 0.162891" />
        <site name="PECM1-P4" pos="0.00278824 -0.000112919 0.0444121" />
        <joint name="sternoclavicular_r2" type="hinge" pos="0 0 0" axis="  0.0153 0.989299  -0.1451" limited="false" range="-99999.9  99999.9" ref="0" />
        <joint name="sternoclavicular_r3" type="hinge" pos="0 0 0" axis="-0.994473        0 -0.104997" limited="false" range="-99999.9  99999.9" ref="0" />
        <body name="clavphant" pos="-0.0124472 0.017433 0.117727" quat="1.0 0.0 0.0 0.0">
          <inertial pos="       0        0        0" mass="8.68611254451936e-05" fullinertia="0.655355 0.655355 0.655355        0        0        0" />
          <joint name="unrotscap_r3" type="hinge" pos="0 0 0" axis="-0.994473        0 -0.104997" limited="false" range="-99999.9  99999.9" ref="0" />
          <joint name="unrotscap_r2" type="hinge" pos="0 0 0" axis="  0.0153 0.989299  -0.1451" limited="false" range="-99999.9  99999.9" ref="0" />
          <body name="scapula" pos="       0        0        0" quat="1.0 0.0 0.0 0.0">
            <geom name="scapula" type="mesh" mesh="scapula" />
            <inertial pos="-0.0475078 -0.0304292 -0.0379878" mass="0.611467578683985" fullinertia="0.00081454 0.00075392 0.000894625 0.000294516 0.000268184 0.000158006" />
            <site name="DELT1-P3" pos="0.0377585 -0.0282472 0.000859925" />
            <site name="DELT2-P3" pos="4.34306e-005 0.00255372 0.0193961" />
            <site name="DELT2-P4" pos="-0.00936363 -0.000295328 0.00538539" />
            <site name="DELT3-P1" pos="-0.0484077 0.00105971 -0.0218195" />
            <site name="DELT3-P2" pos="-0.0629483 -0.0285339 0.01071" />
            <site name="SUPSP-P2" pos="-0.01666 0.00110314 -0.01104" />
            <site name="SUPSP-P3" pos="-0.0382189 -0.0131334 -0.0508572" />
            <site name="INFSP-P2" pos="-0.0641209 -0.0475652 -0.0415283" />
            <site name="SUBSC-P2" pos="-0.0159043 -0.0453676 -0.0213418" />
            <site name="SUBSC-P3" pos="-0.0629396 -0.0342493 -0.0562426" />
            <site name="TMIN-P2" pos="-0.0822835 -0.0694107 -0.0411461" />
            <site name="TMIN-P3" pos="-0.0837602 -0.0705399 -0.046019" />
            <site name="TMAJ-P2" pos="-0.0891543 -0.089632 -0.0506314" />
            <site name="TMAJ-P3" pos="-0.0911086 -0.0946352 -0.0618191" />
            <site name="LAT1-P2" pos="-0.08052 -0.06821 -0.02908" />
            <site name="LAT1-P3" pos="-0.10925 -0.07239 -0.07422" />
            <site name="LAT2-P2" pos="-0.08345 -0.08695 -0.02453" />
            <site name="LAT2-P3" pos="-0.11524 -0.10749 -0.08863" />
            <site name="LAT3-P2" pos="-0.08438 -0.11598 -0.02995" />
            <site name="LAT3-P3" pos="-0.11279 -0.13833 -0.08911" />
            <site name="CORB-P1" pos="0.0108576 -0.0358476 -0.0230356" />
            <site name="CORB-P2" pos="0.00419539 -0.060438 -0.0135764" />
            <site name="TRIlong-P1" pos="-0.0396521 -0.0353785 -0.0119608" />
            <site name="BIClong-P1" pos="-0.0271267 -0.0204384 -0.0113354" />
            <site name="BIClong-P2" pos="-0.0181887 -0.0113701 -0.0040043" />
            <site name="BICshort-P1" pos="0.011014 -0.0341451 -0.022801" />
            <site name="BICshort-P2" pos="0.000807808 -0.0582317 -0.013837" />
            <joint name="acromioclavicular_r2" type="hinge" pos="0 0 0" axis="0.157095 0.947269 -0.279291" limited="false" range="-99999.9  99999.9" ref="0" />
            <joint name="acromioclavicular_r3" type="hinge" pos="0 0 0" axis="-0.754084 0.297594 0.585487" limited="false" range="-99999.9  99999.9" ref="0" />
            <joint name="acromioclavicular_r1" type="hinge" pos="0 0 0" axis="  0.6377   0.1186   0.7611" limited="false" range="-99999.9  99999.9" ref="0" />
            <body name="scapphant" pos="-0.00829524 -0.0295328 0.0078175" quat="1.0 0.0 0.0 0.0">
              <inertial pos="       0        0        0" mass="8.68611254451936e-05" fullinertia="0.655355 0.655355 0.655355        0        0        0" />
              <joint name="unrothum_r1" type="hinge" pos="0 0 0" axis="  0.6377   0.1186   0.7611" limited="false" range="-99999.9  99999.9" ref="0" />
              <joint name="unrothum_r3" type="hinge" pos="0 0 0" axis="-0.754084 0.297594 0.585487" limited="false" range="-99999.9  99999.9" ref="0" />
              <joint name="unrothum_r2" type="hinge" pos="0 0 0" axis="0.157095 0.947269 -0.279291" limited="false" range="-99999.9  99999.9" ref="0" />
              <body name="humphant" pos="       0        0        0" quat="1.0 0.0 0.0 0.0">
                <inertial pos="       0        0        0" mass="8.68611254451936e-05" fullinertia="0.655355 0.655355 0.655355        0        0        0" />
                <joint name="elv_angle" type="hinge" pos="0 0 0" axis="  0.0048 0.999089   0.0424" limited="true" range=" -1.5708  2.26893" ref="0" user="1" />
                <body name="humphant1" pos="       0        0        0" quat="1.0 0.0 0.0 0.0">
                  <inertial pos="       0        0        0" mass="8.68611254451936e-05" fullinertia="0.655355 0.655355 0.655355        0        0        0" />
                  <joint name="shoulder_elv" type="hinge" pos="0 0 0" axis="-0.998261   0.0023 0.058898" limited="true" range="       0  3.14159" ref="0" user="1" />
                  <joint name="shoulder1_r2" type="hinge" pos="0 0 0" axis="  0.0048 0.999089   0.0424" limited="false" range="-99999.9  99999.9" ref="0" />
                  <body name="humerus" pos="       0        0        0" quat="1.0 0.0 0.0 0.0">
                    <geom name="humerus" type="mesh" mesh="humerus" />
                    <inertial pos="0.0156906 -0.121728 -0.0110713" mass="1.73511178355555" fullinertia="0.0080462 0.00167203 0.00824363 -0.000227677 -0.00015237 0.000805627" />
                    <site name="DELT1-P1" pos="0.00778276 -0.103217 0.00508138" />
                    <site name="DELT1-P2" pos="0.0140976 -0.0958339 0.00357868" />
                    <site name="DELT2-P1" pos="0.0040043 -0.118227 0.00486422" />
                    <site name="DELT3-P3" pos="0.00178934 -0.0660318 0.00907699" />
                    <site name="SUPSP-P1" pos="0.00222364 0.00923334 0.0225231" />
                    <site name="INFSP-P1" pos="-0.00770458 0.00420408 0.0212636" />
                    <site name="SUBSC-P1" pos="0.0121866 0.00729633 -0.0115612" />
                    <site name="TMIN-P1" pos="-0.000955472 -0.0109792 0.0187273" />
                    <site name="TMAJ-P1" pos="0.00866874 -0.04707 -0.00493371" />
                    <site name="PECM1-P1" pos="0.0101541 -0.0364035 0.00677517" />
                    <site name="PECM1-P2" pos="  0.0191  -0.0301  0.00143" />
                    <site name="PECM2-P1" pos="0.0110661 -0.0372547 0.0068186" />
                    <site name="PECM2-P2" pos=" 0.01748 -0.03533  0.00033" />
                    <site name="PECM3-P1" pos="0.0110227 -0.0380017 0.00651458" />
                    <site name="PECM3-P2" pos="0.0159185 -0.045833 -0.00378312" />
                    <site name="LAT1-P1" pos="0.00912042 -0.0296631 -0.00567203" />
                    <site name="LAT2-P1" pos="0.00840816 -0.0353612 -0.00530721" />
                    <site name="LAT3-P1" pos="0.0104928 -0.0340669 -0.00361342" />
                    <site name="CORB-P3" pos="0.00645378 -0.130709 -0.00679254" />
                    <site name="TRIlong-P2" pos="-0.0235741 -0.0993778 -0.00576758" />
                    <site name="TRIlong-P3" pos="-0.0276566 -0.196628 -0.010571" />
                    <site name="TRIlong-P4" pos="-0.0151399 -0.232414 -0.0104928" />
                    <site name="TRIlat-P1" pos="-0.00520298 -0.109845 0.00371766" />
                    <site name="TRIlat-P2" pos="-0.0203602 -0.126192 0.00806071" />
                    <site name="TRIlat-P3" pos="-0.0276566 -0.196628 -0.010571" />
                    <site name="TRIlat-P4" pos="-0.0151399 -0.232414 -0.0104928" />
                    <site name="TRImed-P1" pos="-0.00727896 -0.118956 -0.00786962" />
                    <site name="TRImed-P2" pos="-0.0225926 -0.131499 -0.009381" />
                    <site name="TRImed-P3" pos="-0.0276566 -0.196628 -0.010571" />
                    <site name="TRImed-P4" pos="-0.0151399 -0.232414 -0.0104928" />
                    <site name="ANC-P1" pos="-0.00646247 -0.246329 0.0085037" />
                    <site name="BIClong-P3" pos="0.0185101 0.0155742 0.00892932" />
                    <site name="BIClong-P4" pos="0.0206556 -0.0044386 0.010432" />
                    <site name="BIClong-P5" pos="0.0116828 -0.0245556 0.00118131" />
                    <site name="BIClong-P6" pos="0.00927677 -0.0671958 -0.00143321" />
                    <site name="BIClong-P7" pos="0.0147924 -0.105319 0.000208467" />
                    <site name="BIClong-P8" pos="0.0198043 -0.152354 -0.00547225" />
                    <site name="BICshort-P3" pos="0.00970239 -0.065806 -0.00956341" />
                    <site name="BICshort-P4" pos="0.0147924 -0.105319 -0.00937232" />
                    <site name="BICshort-P5" pos="0.0198043 -0.152354 -0.00547225" />
                    <site name="BRA-P1" pos="0.00590656 -0.151051 -0.003127" />
                    <site name="BRA-P2" pos="0.0164515 -0.248067 -0.00959815" />
                    <site name="BRD-P1" pos="-0.00851239 -0.173401 0.001937" />
                    <site name="ECRL-P1" pos="-0.00634086 -0.226621 0.00790436" />
                    <site name="ECRB-P1" pos="0.0117176 -0.252314 0.014749" />
                    <site name="ECU-P1" pos="0.000720947 -0.251506 0.0163299" />
                    <site name="FCR-P1" pos="0.00658407 -0.241526 -0.032182" />
                    <site name="FCU-P1" pos="0.00190226 -0.240953 -0.0337021" />
                    <site name="PL-P1" pos="0.00396955 -0.239033 -0.0335718" />
                    <site name="PT-P1" pos="0.003127 -0.23965 -0.0317043" />
                    <site name="FDSL-P1" pos="0.00365685 -0.239719 -0.0335631" />
                    <site name="FDSR-P1" pos="0.00416065 -0.242169 -0.0324079" />
                    <site name="EDCL-P1" pos="-0.000347445 -0.250429 0.016243" />
                    <site name="EDCR-P1" pos="-0.00135503 -0.251341 0.0154787" />
                    <site name="EDCM-P1" pos="0.000442992 -0.251758 0.0169292" />
                    <site name="EDCI-P1" pos="0.000564597 -0.251011 0.0162343" />
                    <site name="EDM-P1" pos="0.000773064 -0.251194 0.0160432" />
                    <joint name="shoulder_rot" type="hinge" pos="0 0 0" axis="  0.0048 0.999089   0.0424" limited="true" range=" -1.5708 0.349066" ref="0" user="1" />
                    <body name="ulna" pos="0.00529853 -0.252245 -0.0106839" quat="1.0 0.0 0.0 0.0">
                      <geom name="ulna" type="mesh" mesh="ulna" />
                      <inertial pos="0.00844102 -0.083344 0.0210951" mass="0.960076019545725" fullinertia="0.00354749 0.000755742 0.00323982 0.000207656 -4.99053e-05 0.000715444" />
                      <site name="TRIlong-P5" pos="-0.0190226 0.00908567 -0.000677517" />
                      <site name="TRIlat-P5" pos="-0.0190226 0.00908567 -0.000677517" />
                      <site name="TRImed-P5" pos="-0.0190226 0.00908567 -0.000677517" />
                      <site name="ANC-P2" pos="-0.0219932 -0.00107708 0.00521167" />
                      <site name="SUP-P3" pos="-0.0118131 -0.0293938 0.0174851" />
                      <site name="BRA-P4" pos="-0.00277956 -0.0207598 0.00078175" />
                      <site name="BRA-P3" pos="0.00432568 -0.0127078 0.00111182" />
                      <site name="ECU-P2" pos="-0.0120824 -0.0278042 0.025598" />
                      <site name="ECU-P3" pos="-0.0148098 -0.0471482 0.0249118" />
                      <site name="ECU-P4" pos="-0.0155742 -0.0831522 0.0284731" />
                      <site name="PT-P2" pos="0.00734845 -0.0292983 -0.0124385" />
                      <site name="PT-P3" pos=" 0.01219 -0.06516 -0.00219" />
                      <site name="PQ-P2" pos="0.00167642 -0.182165 0.031548" />
                      <site name="FDSM-P1" pos="-0.00581101 -0.0235654 -0.00165905" />
                      <site name="FDSI-P1" pos="-0.00587181 -0.0244862 -0.00119" />
                      <site name="FDPL-P1" pos="-0.00545488 -0.0279172 0.00220627" />
                      <site name="FDPR-P1" pos="-0.00436043 -0.0293069 0.00237131" />
                      <site name="FDPM-P1" pos="-0.00453415 -0.0288987 0.00182408" />
                      <site name="FDPI-P1" pos="-0.00561991 -0.0275871 0.00243211" />
                      <site name="EDM-P2" pos="-0.00848633 -0.0339366 0.0267967" />
                      <site name="EDM-P3" pos="-0.00655801 -0.0718081 0.0316696" />
                      <site name="EIP-P1" pos="-0.00342233 -0.144641 0.0319823" />
                      <site name="EIP-P2" pos="0.00148533 -0.151738 0.0351701" />
                      <site name="EPL-P1" pos="-0.0122648 -0.0843074 0.0256414" />
                      <joint name="elbow_flexion" type="hinge" pos="0 0 0" axis="  0.0494   0.0366 0.998108" limited="true" range="       0  4.26893" ref="0" user="1" />
                      <body name="radius" pos="0.000347445 -0.00999164 0.0173714" quat="1.0 0.0 0.0 0.0">
                        <geom name="radius" type="mesh" mesh="radius" />
                        <inertial pos="0.029215 -0.157704 0.0135503" mass="0.202898902927428" fullinertia="0.000287406 5.80579e-05 0.000263833 1.97524e-05 -2.7787e-06 4.20607e-05" />
                        <site name="SUP-P1" pos="0.00865137 -0.0529505 0.000651458" />
                        <site name="SUP-P2" pos="0.010432 -0.0449072 -0.000929414" />
                        <site name="BIClong-P11" pos="-0.00173722 -0.0325729 -0.00173722" />
                        <site name="BIClong-P9" pos=" 0.00273 -0.0343493 -0.0119845" />
                        <site name="BICshort-P8" pos="-0.00173722 -0.0325729 -0.00173722" />
                        <site name="BICshort-P6" pos=" 0.00273 -0.0343493 -0.0119845" />
                        <site name="BRD-P2" pos="0.0310702 -0.110678 0.0201084" />
                        <site name="BRD-P3" pos="0.0363948 -0.191963 0.0194569" />
                        <site name="ECRL-P2" pos="0.0277521 -0.116941 0.0241387" />
                        <site name="ECRL-P3" pos="0.0368552 -0.205722 0.0314437" />
                        <site name="ECRB-P2" pos="0.0252332 -0.113666 0.0207164" />
                        <site name="ECRB-P3" pos="0.030827 -0.198087 0.0341972" />
                        <site name="ECU-P5" pos="-0.012343 -0.19714 0.0302364" />
                        <site name="FCR-P2" pos="0.0183277 -0.190599 0.00110314" />
                        <site name="FCU-P3" pos="0.00939837 -0.193935 0.00841684" />
                        <site name="FCU-P2" pos="0.0101156 -0.183524 0.00202653" />
                        <site name="PL-P2" pos="0.0219846 -0.207728 -0.00239737" />
                        <site name="PT-P5" pos="0.0220627 -0.0945049 0.0171985" />
                        <site name="PT-P4" pos="0.0204992 -0.0811283 0.00816495" />
                        <site name="PQ-P1" pos="0.0281864 -0.173705 0.0170422" />
                        <site name="FDSL-P2" pos="0.0119608 -0.162587 0.00178065" />
                        <site name="FDSR-P2" pos="0.0136459 -0.162135 0.00231919" />
                        <site name="FDSM-P2" pos="0.0164949 -0.162482 0.00368291" />
                        <site name="FDSI-P2" pos="0.0186317 -0.161761 0.00479473" />
                        <site name="FDPL-P2" pos="0.0122387 -0.160832 0.00747874" />
                        <site name="FDPR-P2" pos="0.0137241 -0.161814 0.00697495" />
                        <site name="FDPM-P2" pos="0.0165557 -0.161944 0.0068186" />
                        <site name="FDPI-P2" pos="0.0180671 -0.161214 0.00794779" />
                        <site name="EDCL-P3" pos="0.00862531 -0.193735 0.0314264" />
                        <site name="EDCL-P2" pos="  0.0013 -0.0382544 0.0129514" />
                        <site name="EDCR-P3" pos="0.00766115 -0.194274 0.0372113" />
                        <site name="EDCR-P2" pos="  0.0026 -0.0392844 0.0144214" />
                        <site name="EDCM-P3" pos="0.012508 -0.1939 0.0366815" />
                        <site name="EDCM-P2" pos=" 0.00316 -0.0388544 0.0141814" />
                        <site name="EDCI-P3" pos="0.0133158 -0.193822 0.0364469" />
                        <site name="EDCI-P2" pos=" 0.00228 -0.0385544 0.0137314" />
                        <site name="EDM-P4" pos="0.0039435 -0.196662 0.0319475" />
                        <site name="EIP-P3" pos="0.00934626 -0.197896 0.0318259" />
                        <site name="EPL-P2" pos="0.00107708 -0.118722 0.0197175" />
                        <site name="EPL-P3" pos="0.0234699 -0.189983 0.0332504" />
                        <site name="EPL-P4" pos="0.0293764 -0.197644 0.0400169" />
                        <site name="EPL-P5" pos="0.036777 -0.206478 0.0362471" />
                        <site name="EPB-P1" pos="0.0167121 -0.127642 0.0183624" />
                        <site name="EPB-P2" pos="0.0197696 -0.137736 0.0231485" />
                        <site name="EPB-P3" pos="0.0332765 -0.171308 0.0333026" />
                        <site name="EPB-P4" pos="0.0454718 -0.205088 0.0234438" />
                        <site name="FPL-P1" pos="0.00843422 -0.0821533 0.0153657" />
                        <site name="FPL-P2" pos="0.0144016 -0.11748 0.0166339" />
                        <site name="FPL-P3" pos="0.0162343 -0.155759 0.017268" />
                        <site name="FPL-P4" pos="0.0330072 -0.201266 0.0137241" />
                        <site name="APL-P1" pos="0.0100238 -0.0823183 0.0146014" />
                        <site name="APL-P2" pos="0.0263189 -0.121345 0.0304622" />
                        <site name="APL-P3" pos="0.0346836 -0.139603 0.0295328" />
                        <site name="APL-P4" pos="0.0381928 -0.155004 0.0272223" />
                        <site name="APL-P5" pos="0.047817 -0.20051 0.0205687" />
                        <joint name="pro_sup" type="hinge" pos="0 0 0" axis="-0.017161 0.992666 -0.119668" limited="true" range=" -1.5708   1.5708" ref="0" user="1" />
                        <body name="proximal_row" pos="0.015635 -0.210204 0.0217153" quat="1.0 0.0 0.0 0.0">
                          <geom name="lunate" type="mesh" mesh="lunate" />
                          <geom name="sdfastSCAPHOIDw" type="mesh" mesh="sdfastSCAPHOIDw" />
                          <geom name="sdfastPISIFORMw" type="mesh" mesh="sdfastPISIFORMw" />
                          <geom name="sdfastTRIQUETRALw" type="mesh" mesh="sdfastTRIQUETRALw" />
                          <inertial pos="       0        0        0" mass="8.68611254451936e-05" fullinertia="6.55355e-06 6.55355e-06 6.55355e-06        0        0        0" />
                          <body name="hand" pos="0.0034675 -0.0130761 0.00202126" quat="1.0 0.0 0.0 0.0">
                            <geom name="sdfast_1seg_hand_fr_c_5mc" type="mesh" mesh="sdfast_1seg_hand_fr_c_5mc" />
                            <geom name="sdfast_1seg_hand_fr_c_4mc" type="mesh" mesh="sdfast_1seg_hand_fr_c_4mc" />
                            <geom name="sdfast_1seg_hand_fr_c_3mc" type="mesh" mesh="sdfast_1seg_hand_fr_c_3mc" />
                            <geom name="sdfast_1seg_hand_fr_c_trapezium" type="mesh" mesh="sdfast_1seg_hand_fr_c_trapezium" />
                            <geom name="sdfast_1seg_hand_fr_c_trapezoid" type="mesh" mesh="sdfast_1seg_hand_fr_c_trapezoid" />
                            <geom name="sdfast_1seg_hand_fr_c_hamate" type="mesh" mesh="sdfast_1seg_hand_fr_c_hamate" />
                            <geom name="capitate" type="mesh" mesh="capitate" />
                            <geom name="hand_3proxph" type="mesh" mesh="hand_3proxph" />
                            <geom name="hand_3midph" type="mesh" mesh="hand_3midph" />
                            <geom name="hand_3distph" type="mesh" mesh="hand_3distph" />
                            <geom name="hand_4proxph" type="mesh" mesh="hand_4proxph" />
                            <geom name="hand_4midph" type="mesh" mesh="hand_4midph" />
                            <geom name="hand_4distph" type="mesh" mesh="hand_4distph" />
                            <geom name="hand_5proxph" type="mesh" mesh="hand_5proxph" />
                            <geom name="hand_5midph" type="mesh" mesh="hand_5midph" />
                            <geom name="hand_5distph" type="mesh" mesh="hand_5distph" />
                            <geom name="hand_thumbprox" type="mesh" mesh="hand_thumbprox" />
                            <geom name="hand_thumbdist" type="mesh" mesh="hand_thumbdist" />
                            <geom name="hand_1mc" type="mesh" mesh="hand_1mc" />
                            <inertial pos="-0.00261725 -0.0369154 -0.000974625" mass="0.505444888965581" fullinertia="7.2089e-05 3.93213e-05 9.83032e-05 5.89819e-07 -1.31071e-07 7.86426e-06" />
                            <site name="ECRL-P4" pos="0.0149141 -0.0184319 0.005064" />
                            <site name="ECRB-P4" pos="0.00434306 -0.00986742 0.0073832" />
                            <site name="ECU-P6" pos="-0.0195524 -0.0121692 -0.00111182" />
                            <site name="FCR-P3" pos="0.00976319 -0.0160172 -0.0036308" />
                            <site name="FCU-P4" pos="-0.0176849 -0.015331 -0.00653196" />
                            <site name="PL-P3" pos="0.00796517 -0.0164862 -0.0152354" />
                            <site name="PL-P4" pos="0.00197175 -0.0268922 0.00428225" />
                            <site name="FDSL-P3" pos="-0.00204124 -0.0120998 -0.0119521" />
                            <site name="FDSL-P4" pos="-0.0173288 -0.0371852 -0.0064451" />
                            <site name="FDSL-P5" pos="-0.0177544 -0.0519516 -0.0163125" />
                            <site name="FDSL-P6" pos="-0.0148793 -0.0629309 -0.0239129" />
                            <site name="FDSL-P7" pos="-0.0100411 -0.0631567 -0.0317564" />
                            <site name="FDSL-P8" pos="-0.00919859 -0.0631567 -0.0329725" />
                            <site name="FDSR-P3" pos="-0.000712261 -0.0116741 -0.0118044" />
                            <site name="FDSR-P4" pos="-0.00848633 -0.0449854 3.47445e-005" />
                            <site name="FDSR-P5" pos="-0.0114917 -0.0579364 -0.00885983" />
                            <site name="FDSR-P6" pos="-0.00684466 -0.0697234 -0.0217413" />
                            <site name="FDSR-P7" pos="-0.00259715 -0.0705747 -0.0294894" />
                            <site name="FDSR-P8" pos="0.000538539 -0.070288 -0.0338064" />
                            <site name="FDSM-P3" pos="0.00590656 -0.0119608 -0.0121519" />
                            <site name="FDSM-P4" pos="0.00409116 -0.0289421 -0.00114657" />
                            <site name="FDSM-P5" pos="0.00470787 -0.0491634 0.000521167" />
                            <site name="FDSM-P6" pos="0.00482079 -0.0627485 -0.00293591" />
                            <site name="FDSM-P7" pos="0.0101367 -0.0765247 -0.0145058" />
                            <site name="FDSM-P8" pos="0.0113006 -0.0770458 -0.0258586" />
                            <site name="FDSM-P9" pos="0.0136198 -0.0745008 -0.0327032" />
                            <site name="FDSI-P3" pos="0.00772195 -0.0118652 -0.0120476" />
                            <site name="FDSI-P4" pos="0.00921597 -0.0328943 0.000208467" />
                            <site name="FDSI-P5" pos="0.0154787 -0.0443687 0.0036308" />
                            <site name="FDSI-P6" pos="0.0160606 -0.0633826 -0.00325729" />
                            <site name="FDSI-P7" pos="0.0232614 -0.0756908 -0.0156697" />
                            <site name="FDSI-P8" pos="0.0231659 -0.0759166 -0.0232614" />
                            <site name="FDSI-P9" pos="0.0231051 -0.0749872 -0.0252158" />
                            <site name="FDPL-P3" pos="-0.000764378 -0.00892064 -0.0103191" />
                            <site name="FDPL-P4" pos="-0.0161127 -0.0403557 -0.00636692" />
                            <site name="FDPL-P5" pos="-0.0157045 -0.0507356 -0.0135503" />
                            <site name="FDPL-P6" pos="-0.0124038 -0.0633131 -0.0233048" />
                            <site name="FDPL-P7" pos="-0.00799122 -0.0649982 -0.0319996" />
                            <site name="FDPL-P8" pos="-0.00271007 -0.0643207 -0.0361777" />
                            <site name="FDPL-P9" pos="0.00387401 -0.0613153 -0.0404512" />
                            <site name="FDPR-P3" pos="0.000920728 -0.0102236 -0.0102844" />
                            <site name="FDPR-P4" pos="-0.00742663 -0.0481384 0.000764378" />
                            <site name="FDPR-P5" pos="-0.00937232 -0.0572241 -0.00709655" />
                            <site name="FDPR-P6" pos="-0.0047513 -0.0708266 -0.0195959" />
                            <site name="FDPR-P7" pos="-0.000486422 -0.0714867 -0.0292461" />
                            <site name="FDPR-P8" pos="0.00528984 -0.0680731 -0.0368117" />
                            <site name="FDPR-P9" pos="0.0105189 -0.0641035 -0.0421971" />
                            <site name="FDPM-P3" pos="0.00290985 -0.0111182 -0.00993691" />
                            <site name="FDPM-P4" pos="0.00262321 -0.029941 -0.00530721" />
                            <site name="FDPM-P5" pos="0.0021889 -0.0509267 0.00105971" />
                            <site name="FDPM-P6" pos="0.00247554 -0.0606725 -0.00115525" />
                            <site name="FDPM-P7" pos="0.00749612 -0.0762554 -0.0157653" />
                            <site name="FDPM-P8" pos="0.00870348 -0.0761425 -0.0257456" />
                            <site name="FDPM-P9" pos="0.0141844 -0.0708526 -0.0385229" />
                            <site name="FDPM-P10" pos="0.0165818 -0.0665617 -0.0454197" />
                            <site name="FDPI-P3" pos="0.00778276 -0.0101454 -0.0105276" />
                            <site name="FDPI-P4" pos="0.0166947 -0.0481384 0.00380452" />
                            <site name="FDPI-P5" pos="0.0180063 -0.0609852 -0.00248423" />
                            <site name="FDPI-P6" pos="0.0252245 -0.0745963 -0.0154787" />
                            <site name="FDPI-P7" pos="0.0253982 -0.075326 -0.0240518" />
                            <site name="FDPI-P8" pos="0.0253113 -0.0715301 -0.034562" />
                            <site name="FDPI-P9" pos="0.0247294 -0.0674998 -0.041398" />
                            <site name="EDCL-P4" pos="-0.0214026 -0.0382363 0.00146795" />
                            <site name="EDCL-P5" pos="-0.0206816 -0.0411201 0.000668831" />
                            <site name="EDCL-P6" pos="-0.0208032 -0.0574413 -0.0086948" />
                            <site name="EDCL-P7" pos="-0.0156176 -0.0681599 -0.0235481" />
                            <site name="EDCL-P8" pos="-0.0102322 -0.0684205 -0.0328248" />
                            <site name="EDCL-P9" pos="-0.00130292 -0.0658928 -0.0398345" />
                            <site name="EDCL-P10" pos="0.00174591 -0.0650329 -0.0416412" />
                            <site name="EDCR-P4" pos="-0.0135851 -0.0482079 0.00811283" />
                            <site name="EDCR-P5" pos="-0.0123951 -0.0505445 0.0100846" />
                            <site name="EDCR-P6" pos="-0.0137241 -0.062679 -0.00365685" />
                            <site name="EDCR-P7" pos="-0.00716604 -0.0758732 -0.0196306" />
                            <site name="EDCR-P8" pos="-0.00236262 -0.0764899 -0.029611" />
                            <site name="EDCR-P9" pos="0.0066275 -0.0697147 -0.0404599" />
                            <site name="EDCR-P10" pos="0.00928545 -0.0678299 -0.0429181" />
                            <site name="EDCM-P4" pos="0.000338758 -0.0458106 0.012951" />
                            <site name="EDCM-P5" pos="-0.000755692 -0.0484164 0.0126122" />
                            <site name="EDCM-P6" pos="0.00161562 -0.0670394 0.00518561" />
                            <site name="EDCM-P7" pos="0.00874692 -0.0808938 -0.0154092" />
                            <site name="EDCM-P8" pos="0.0114744 -0.0830219 -0.0265448" />
                            <site name="EDCM-P9" pos="0.0161301 -0.0740491 -0.0413372" />
                            <site name="EDCM-P10" pos="0.0178586 -0.0694281 -0.0463925" />
                            <site name="EDCM-P11" pos="0.019066 -0.0668918 -0.0491895" />
                            <site name="EDCI-P4" pos="0.0134027 -0.040651 0.0142365" />
                            <site name="EDCI-P5" pos="0.0164776 -0.0491113 0.0124906" />
                            <site name="EDCI-P6" pos="0.0173201 -0.066692 0.00515955" />
                            <site name="EDCI-P7" pos="0.0255806 -0.0795822 -0.0108142" />
                            <site name="EDCI-P8" pos="0.0271094 -0.0812065 -0.0252332" />
                            <site name="EDCI-P9" pos="0.0261713 -0.073719 -0.0370723" />
                            <site name="EDCI-P10" pos="0.0254416 -0.0703836 -0.0431352" />
                            <site name="EDM-P5" pos="-0.0178847 -0.00896407 0.00323123" />
                            <site name="EDM-P6" pos="-0.0222625 -0.0410158 0.000199781" />
                            <site name="EDM-P7" pos="-0.0221409 -0.0565553 -0.00953735" />
                            <site name="EDM-P8" pos="-0.0167903 -0.0678385 -0.0236089" />
                            <site name="EDM-P9" pos="-0.0116915 -0.0685508 -0.0338237" />
                            <site name="EDM-P10" pos="-0.0018762 -0.0653283 -0.0398606" />
                            <site name="EDM-P11" pos="0.00114657 -0.0637995 -0.0417194" />
                            <site name="EIP-P4" pos="0.00337021 -0.0194048 0.0102844" />
                            <site name="EIP-P5" pos="0.0147056 -0.0489897 0.0119608" />
                            <site name="EIP-P6" pos="0.0150704 -0.0668136 0.00504663" />
                            <site name="EIP-P7" pos="0.0240171 -0.0809025 -0.0131247" />
                            <site name="EIP-P8" pos="0.0250073 -0.0819708 -0.0245209" />
                            <site name="EIP-P9" pos="0.0249291 -0.0740404 -0.0373069" />
                            <site name="EIP-P10" pos="0.0246164 -0.0676214 -0.0477823" />
                            <site name="EPL-P6" pos="0.0210899 0.000121606 0.00528116" />
                            <site name="EPL-P7" pos="0.0203081 -0.00796517 -0.000338758" />
                            <site name="EPL-P8" pos="0.0252332 -0.0123951 -0.00424751" />
                            <site name="EPL-P9" pos="0.0383405 -0.0296804 -0.0157566" />
                            <site name="EPL-P10" pos="0.0422753 -0.0403557 -0.0216024" />
                            <site name="EPL-P11" pos="0.0412677 -0.0608896 -0.0327814" />
                            <site name="EPL-P12" pos="0.03484 -0.0657104 -0.0372026" />
                            <site name="EPB-P5" pos="0.0271267 0.00222364 -0.00284036" />
                            <site name="EPB-P6" pos="0.0258151 -0.00689677 -0.0124733" />
                            <site name="EPB-P7" pos="0.03841 -0.0286642 -0.0210378" />
                            <site name="EPB-P8" pos="0.0393307 -0.041563 -0.027674" />
                            <site name="FPL-P6" pos="0.0108055 -0.0191703 -0.0181453" />
                            <site name="FPL-P7" pos="0.0142539 -0.0227663 -0.0192919" />
                            <site name="FPL-P8" pos="0.0213418 -0.0286121 -0.0194308" />
                            <site name="FPL-P9" pos="0.0245556 -0.0476173 -0.0265361" />
                            <site name="FPL-P10" pos="0.0304969 -0.0566248 -0.0325642" />
                            <site name="FPL-P11" pos="0.030688 -0.0665009 -0.0357694" />
                            <site name="FPL-P5" pos="0.0178892 0.0064176 -0.0168214" />
                            <site name="APL-P7" pos="0.022471 0.00178065 -0.0143321" />
                            <site name="APL-P8" pos="0.0249986 -0.00585444 -0.016243" />
                            <site name="APL-P9" pos="0.0267185 -0.0137501 -0.0163733" />
                            <site name="APL-P6" pos="0.0332244 0.00608975 -0.00870125" />
                            <body name="index0" pos="0 0 0">
                              <inertial pos="0 0 0" mass="0.001" diaginertia="0.001 0.001 0.001" />
                              <geom name="sdfast_1seg_hand_fr_c_2mc" type="mesh" mesh="sdfast_1seg_hand_fr_c_2mc" />
                              <body name="index1" pos="0 0 0">
                                <inertial pos="0 0 0" mass="0.001" diaginertia="0.001 0.001 0.001" />
                                <geom name="hand_2proxph" type="mesh" mesh="hand_2proxph" />
                                <body name="index2" pos="0 0 0">
                                  <inertial pos="0 0 0" mass="0.001" diaginertia="0.001 0.001 0.001" />
                                  <geom name="hand_2midph" type="mesh" mesh="hand_2midph" />
                                  <body name="index3" pos="0 0 0">
                                    <inertial pos="0 0 0" mass="0.001" diaginertia="0.001 0.001 0.001" />
                                    <geom name="hand_2distph" type="mesh" mesh="hand_2distph" />
                                    <site name="fingertip" pos="0.024 -0.149 -0.0065" type="sphere" rgba="0.1 0.8 0.1 0.0" size="0.004" />
                                  </body>
                                </body>
                              </body>
                            </body>
                          </body>
                        </body>
                      </body>
                    </body>
                  </body>
                </body>
              </body>
            </body>
          </body>
        </body>
      </body>
    </body>

</mujocoinclude>