<mujocoinclude model="MoBL Arms Index Model">

    <body name="thorax" pos="0 0 0" quat="0.7071067811865475 0.7071067811865475 0.0 0.0">
      <light mode="trackcom" directional="false" pos="0 0 4.0" dir="0 0 -1" />
      <geom name="thorax" type="mesh" mesh="thorax" />
      <site name="PECM1-P3" pos="  -7e-05  0.00821  0.10454" />
      <site name="PECM2-P4" pos="0.032434 -0.0411537 0.101835" />
      <site name="PECM2-P5" pos="0.0290552 -0.0471977 0.0238297" />
      <site name="PECM2-P3" pos=" 0.02083 -0.02005  0.11555" />
      <site name="PECM3-P4" pos="0.0550884 -0.0883198 0.0937552" />
      <site name="PECM3-P5" pos="0.0600621 -0.122286 0.0397371" />
      <site name="PECM3-P3" pos=" 0.02984 -0.0544459   0.1151" />
      <site name="LAT1-P4" pos="-0.124112 -0.106168 0.0347949" />
      <site name="LAT1-P5" pos="-0.100502 -0.12302 0.00925485" />
      <site name="LAT2-P4" pos="-0.115339 -0.177416 0.0301989" />
      <site name="LAT2-P5" pos="-0.0754029 -0.197458 0.00855182" />
      <site name="LAT3-P4" pos="-0.117071 -0.203428 0.0580474" />
      <site name="LAT3-P5" pos="-0.0746789 -0.260836 0.00951718" />
      <joint name="r_z" type="hinge" pos="0 0 0" axis="       0        0        1" limited="true" range="-6.28319  6.28319" ref="0" armature="0" damping="0" stiffness="0" />
      <body name="clavicle" pos="0.00663684 0.00727167 0.0267205" quat="1.0 0.0 0.0 0.0">
        <geom name="clavicle" type="mesh" mesh="clavicle" />
        <inertial pos="-0.0116431 0.00668647 0.0568386" mass="0.163691275166673" fullinertia="0.000280269 0.000294907 5.13194e-05 -2.1928e-05 -8.08032e-05 6.20523e-05" />
        <site name="DELT1-P4" pos="-0.0146902 0.0116053 0.0841646" />
        <site name="DELT2-P2" pos="0.0191703 0.0244002 0.162891" />
        <site name="PECM1-P4" pos="0.00336826 -0.000136409 0.0536509" />
        <joint name="sternoclavicular_r2" type="hinge" pos="0 0 0" axis="  0.0153 0.989299  -0.1451" limited="false" range="-99999.9  99999.9" ref="0" />
        <joint name="sternoclavicular_r3" type="hinge" pos="0 0 0" axis="-0.994473        0 -0.104997" limited="false" range="-99999.9  99999.9" ref="0" />
        <body name="clavphant" pos="-0.0150365 0.0210595 0.142217" quat="1.0 0.0 0.0 0.0">
          <inertial pos="       0        0        0" mass="0.000104930304594021" fullinertia=" 1.15532  1.15532  1.15532        0        0        0" />
          <joint name="unrotscap_r3" type="hinge" pos="0 0 0" axis="-0.994473        0 -0.104997" limited="false" range="-99999.9  99999.9" ref="0" />
          <joint name="unrotscap_r2" type="hinge" pos="0 0 0" axis="  0.0153 0.989299  -0.1451" limited="false" range="-99999.9  99999.9" ref="0" />
          <body name="scapula" pos="       0        0        0" quat="1.0 0.0 0.0 0.0">
            <geom name="scapula" type="mesh" mesh="scapula" />
            <inertial pos="-0.0573906 -0.0367592 -0.0458902" mass="0.738667372220071" fullinertia="0.00143595 0.00132908 0.00157713 0.000519201 0.000472781 0.000278548" />
            <site name="DELT1-P3" pos="0.0456132 -0.0341233 0.00103881" />
            <site name="DELT2-P3" pos="5.24652e-005 0.00308495 0.0234309" />
            <site name="DELT2-P4" pos="-0.0113115 -0.000356763 0.00650568" />
            <site name="DELT3-P1" pos="-0.0584777 0.00128015 -0.0263585" />
            <site name="DELT3-P2" pos="-0.076043 -0.0344696 0.0129379" />
            <site name="SUPSP-P2" pos="-0.0201256 0.00133261 -0.0133366" />
            <site name="SUPSP-P3" pos="-0.0461693 -0.0158655 -0.0614367" />
            <site name="INFSP-P2" pos="-0.0774596 -0.0574598 -0.0501672" />
            <site name="SUBSC-P2" pos="-0.0192127 -0.0548051 -0.0257814" />
            <site name="SUBSC-P3" pos="-0.0760325 -0.041374 -0.0679424" />
            <site name="TMIN-P2" pos="-0.0994005 -0.0838498 -0.0497055" />
            <site name="TMIN-P3" pos="-0.101184 -0.0852139 -0.0555921" />
            <site name="TMAJ-P2" pos="-0.1077 -0.108278 -0.0611639" />
            <site name="TMAJ-P3" pos="-0.110061 -0.114322 -0.0746789" />
            <site name="LAT1-P2" pos="-0.08052 -0.06821 -0.02908" />
            <site name="LAT1-P3" pos="-0.10925 -0.07239 -0.07422" />
            <site name="LAT2-P2" pos="-0.08345 -0.08695 -0.02453" />
            <site name="LAT2-P3" pos="-0.11524 -0.10749 -0.08863" />
            <site name="LAT3-P2" pos="-0.08438 -0.11598 -0.02995" />
            <site name="LAT3-P3" pos="-0.11279 -0.13833 -0.08911" />
            <site name="CORB-P1" pos="0.0131163 -0.0433047 -0.0278275" />
            <site name="CORB-P2" pos="0.00506813 -0.0730105 -0.0164006" />
            <site name="TRIlong-P1" pos="-0.0479007 -0.0427381 -0.0144489" />
            <site name="BIClong-P1" pos="-0.0327697 -0.0246901 -0.0136934" />
            <site name="BIClong-P2" pos="-0.0219724 -0.0137354 -0.00483729" />
            <site name="BICshort-P1" pos="0.0133052 -0.0412481 -0.0275442" />
            <site name="BICshort-P2" pos="0.000975852 -0.0703453 -0.0167154" />
            <joint name="acromioclavicular_r2" type="hinge" pos="0 0 0" axis="0.157095 0.947269 -0.279291" limited="false" range="-99999.9  99999.9" ref="0" />
            <joint name="acromioclavicular_r3" type="hinge" pos="0 0 0" axis="-0.754084 0.297594 0.585487" limited="false" range="-99999.9  99999.9" ref="0" />
            <joint name="acromioclavicular_r1" type="hinge" pos="0 0 0" axis="  0.6377   0.1186   0.7611" limited="false" range="-99999.9  99999.9" ref="0" />
            <body name="scapphant" pos="-0.0100208 -0.0356763 0.00944373" quat="1.0 0.0 0.0 0.0">
              <inertial pos="       0        0        0" mass="0.000104930304594021" fullinertia=" 1.15532  1.15532  1.15532        0        0        0" />
              <joint name="unrothum_r1" type="hinge" pos="0 0 0" axis="  0.6377   0.1186   0.7611" limited="false" range="-99999.9  99999.9" ref="0" />
              <joint name="unrothum_r3" type="hinge" pos="0 0 0" axis="-0.754084 0.297594 0.585487" limited="false" range="-99999.9  99999.9" ref="0" />
              <joint name="unrothum_r2" type="hinge" pos="0 0 0" axis="0.157095 0.947269 -0.279291" limited="false" range="-99999.9  99999.9" ref="0" />
              <body name="humphant" pos="       0        0        0" quat="1.0 0.0 0.0 0.0">
                <inertial pos="       0        0        0" mass="0.000104930304594021" fullinertia=" 1.15532  1.15532  1.15532        0        0        0" />
                <joint name="elv_angle" type="hinge" pos="0 0 0" axis="  0.0048 0.999089   0.0424" limited="true" range=" -1.5708  2.26893" ref="0" user="1" />
                <body name="humphant1" pos="       0        0        0" quat="1.0 0.0 0.0 0.0">
                  <inertial pos="       0        0        0" mass="0.000104930304594021" fullinertia=" 1.15532  1.15532  1.15532        0        0        0" />
                  <joint name="shoulder_elv" type="hinge" pos="0 0 0" axis="-0.998261   0.0023 0.058898" limited="true" range="       0  3.14159" ref="0" user="1" />
                  <joint name="shoulder1_r2" type="hinge" pos="0 0 0" axis="  0.0048 0.999089   0.0424" limited="false" range="-99999.9  99999.9" ref="0" />
                  <body name="humerus" pos="       0        0        0" quat="1.0 0.0 0.0 0.0">
                    <geom name="humerus" type="mesh" mesh="humerus" />
                    <inertial pos="0.0189546 -0.14705 -0.0133744" mass="2.09605628547879" fullinertia="0.0141846 0.00294761 0.0145326 -0.00040137 -0.000268612 0.00142024" />
                    <site name="DELT1-P1" pos="0.00940176 -0.124689 0.00613842" />
                    <site name="DELT1-P2" pos="0.0170302 -0.11577 0.00432313" />
                    <site name="DELT2-P1" pos="0.00483729 -0.142821 0.0058761" />
                    <site name="DELT3-P3" pos="0.00216156 -0.079768 0.0109652" />
                    <site name="SUPSP-P1" pos="0.00268622 0.0111541 0.0272084" />
                    <site name="INFSP-P1" pos="-0.00930732 0.00507863 0.0256869" />
                    <site name="SUBSC-P1" pos="0.0147217 0.00881415 -0.0139662" />
                    <site name="TMIN-P1" pos="-0.00115423 -0.0132632 0.022623" />
                    <site name="TMAJ-P1" pos="0.010472 -0.0568617 -0.00596004" />
                    <site name="PECM1-P1" pos="0.0122664 -0.0439763 0.00818456" />
                    <site name="PECM1-P2" pos="  0.0191  -0.0301  0.00143" />
                    <site name="PECM2-P1" pos="0.0133681 -0.0450046 0.00823703" />
                    <site name="PECM2-P2" pos=" 0.01748 -0.03533  0.00033" />
                    <site name="PECM3-P1" pos="0.0133157 -0.045907 0.00786977" />
                    <site name="PECM3-P2" pos="0.0159185 -0.045833 -0.00378312" />
                    <site name="LAT1-P1" pos="0.0110177 -0.0358337 -0.00685195" />
                    <site name="LAT2-P1" pos="0.0101573 -0.0427171 -0.00641124" />
                    <site name="LAT3-P1" pos="0.0126756 -0.0411537 -0.0043651" />
                    <site name="CORB-P3" pos="0.00779632 -0.157899 -0.00820555" />
                    <site name="TRIlong-P2" pos="-0.0284781 -0.120051 -0.00696737" />
                    <site name="TRIlong-P3" pos="-0.0334098 -0.237531 -0.01277" />
                    <site name="TRIlong-P4" pos="-0.0182894 -0.280762 -0.0126756" />
                    <site name="TRIlat-P1" pos="-0.00628533 -0.132695 0.00449102" />
                    <site name="TRIlat-P2" pos="-0.0245957 -0.152443 0.00973753" />
                    <site name="TRIlat-P3" pos="-0.0334098 -0.237531 -0.01277" />
                    <site name="TRIlat-P4" pos="-0.0182894 -0.280762 -0.0126756" />
                    <site name="TRImed-P1" pos="-0.00879316 -0.143702 -0.00950669" />
                    <site name="TRImed-P2" pos="-0.0272924 -0.158854 -0.0113325" />
                    <site name="TRImed-P3" pos="-0.0334098 -0.237531 -0.01277" />
                    <site name="TRImed-P4" pos="-0.0182894 -0.280762 -0.0126756" />
                    <site name="ANC-P1" pos="-0.00780681 -0.297572 0.0102727" />
                    <site name="BIClong-P3" pos="0.0223606 0.018814 0.0107868" />
                    <site name="BIClong-P4" pos="0.0249524 -0.00536194 0.0126021" />
                    <site name="BIClong-P5" pos="0.0141131 -0.0296638 0.00142705" />
                    <site name="BIClong-P6" pos="0.0112066 -0.0811741 -0.00173135" />
                    <site name="BIClong-P7" pos="0.0178696 -0.127228 0.000251833" />
                    <site name="BIClong-P8" pos="0.0239241 -0.184048 -0.00661061" />
                    <site name="BICshort-P3" pos="0.0117207 -0.0794952 -0.0115528" />
                    <site name="BICshort-P4" pos="0.0178696 -0.127228 -0.011322" />
                    <site name="BICshort-P5" pos="0.0239241 -0.184048 -0.00661061" />
                    <site name="BRA-P1" pos="0.00713526 -0.182474 -0.00377749" />
                    <site name="BRA-P2" pos="0.0198738 -0.29967 -0.0115948" />
                    <site name="BRD-P1" pos="-0.0102832 -0.209472 0.00233995" />
                    <site name="ECRL-P1" pos="-0.00765991 -0.273763 0.00954866" />
                    <site name="ECRB-P1" pos="0.0141551 -0.304802 0.0178172" />
                    <site name="ECU-P1" pos="0.000870922 -0.303826 0.0197269" />
                    <site name="FCR-P1" pos="0.00795372 -0.291769 -0.0388767" />
                    <site name="FCU-P1" pos="0.00229797 -0.291077 -0.040713" />
                    <site name="PL-P1" pos="0.00479531 -0.288758 -0.0405556" />
                    <site name="PT-P1" pos="0.00377749 -0.289503 -0.0382996" />
                    <site name="FDSL-P1" pos="0.00441757 -0.289587 -0.0405451" />
                    <site name="FDSR-P1" pos="0.00502616 -0.292546 -0.0391495" />
                    <site name="EDCL-P1" pos="-0.000419721 -0.302525 0.019622" />
                    <site name="EDCR-P1" pos="-0.00163691 -0.303626 0.0186986" />
                    <site name="EDCM-P1" pos="0.000535145 -0.30413 0.0204509" />
                    <site name="EDCI-P1" pos="0.000682047 -0.303228 0.0196115" />
                    <site name="EDM-P1" pos="0.00093388 -0.303448 0.0193806" />
                    <joint name="shoulder_rot" type="hinge" pos="0 0 0" axis="  0.0048 0.999089   0.0424" limited="true" range=" -1.5708 0.349066" ref="0" user="1" />
                    <body name="ulna" pos="0.00640075 -0.304718 -0.0129064" quat="1.0 0.0 0.0 0.0">
                      <geom name="ulna" type="mesh" mesh="ulna" />
                      <inertial pos="0.0101969 -0.100682 0.0254834" mass="1.15979465667772" fullinertia="0.00625386 0.00133229 0.00571146 0.000366075 -8.79777e-05 0.00126125" />
                      <site name="TRIlong-P5" pos="-0.0229797 0.0109757 -0.000818456" />
                      <site name="TRIlat-P5" pos="-0.0229797 0.0109757 -0.000818456" />
                      <site name="TRImed-P5" pos="-0.0229797 0.0109757 -0.000818456" />
                      <site name="ANC-P2" pos="-0.0265684 -0.00130114 0.00629582" />
                      <site name="SUP-P3" pos="-0.0142705 -0.0355084 0.0211225" />
                      <site name="BRA-P4" pos="-0.00335777 -0.0250783 0.000944373" />
                      <site name="BRA-P3" pos="0.00522553 -0.0153513 0.00134311" />
                      <site name="ECU-P2" pos="-0.0145958 -0.0335882 0.030923" />
                      <site name="ECU-P3" pos="-0.0178906 -0.0569562 0.030094" />
                      <site name="ECU-P4" pos="-0.018814 -0.10045 0.0343962" />
                      <site name="PT-P2" pos="0.0088771 -0.035393 -0.015026" />
                      <site name="PT-P3" pos=" 0.01219 -0.06516 -0.00219" />
                      <site name="PQ-P2" pos="0.00202515 -0.22006 0.0381107" />
                      <site name="FDSM-P1" pos="-0.00701984 -0.0284676 -0.00200417" />
                      <site name="FDSI-P1" pos="-0.00709329 -0.0295799 -0.00143755" />
                      <site name="FDPL-P1" pos="-0.00658962 -0.0337246 0.00266523" />
                      <site name="FDPR-P1" pos="-0.0052675 -0.0354035 0.0028646" />
                      <site name="FDPM-P1" pos="-0.00547736 -0.0349103 0.00220354" />
                      <site name="FDPI-P1" pos="-0.00678899 -0.0333259 0.00293805" />
                      <site name="EDM-P2" pos="-0.0102517 -0.0409963 0.032371" />
                      <site name="EDM-P3" pos="-0.00792224 -0.0867459 0.0382576" />
                      <site name="EIP-P1" pos="-0.00413425 -0.17473 0.0386353" />
                      <site name="EIP-P2" pos="0.00179431 -0.183303 0.0424863" />
                      <site name="EPL-P1" pos="-0.0148162 -0.101845 0.0309754" />
                      <joint name="elbow_flexion" type="hinge" pos="0 0 0" axis="  0.0494   0.0366 0.998108" limited="true" range="       0  4.26893" ref="0" user="1" />
                      <body name="radius" pos="0.000419721 -0.0120701 0.020985" quat="1.0 0.0 0.0 0.0">
                        <geom name="radius" type="mesh" mesh="radius" />
                        <inertial pos="0.0352924 -0.19051 0.0163691" mass="0.245106698501174" fullinertia="0.000506666 0.00010235 0.000465109 3.48214e-05 -4.89856e-06 7.41485e-05" />
                        <site name="SUP-P1" pos="0.0104511 -0.0639655 0.000786977" />
                        <site name="SUP-P2" pos="0.0126021 -0.054249 -0.00112275" />
                        <site name="BIClong-P11" pos="-0.00209861 -0.0393489 -0.00209861" />
                        <site name="BIClong-P9" pos=" 0.00273 -0.0343493 -0.0119845" />
                        <site name="BICshort-P8" pos="-0.00209861 -0.0393489 -0.00209861" />
                        <site name="BICshort-P6" pos=" 0.00273 -0.0343493 -0.0119845" />
                        <site name="BRD-P2" pos="0.0375336 -0.133702 0.0242914" />
                        <site name="BRD-P3" pos="0.0439658 -0.231896 0.0235044" />
                        <site name="ECRL-P2" pos="0.0335252 -0.141268 0.0291601" />
                        <site name="ECRL-P3" pos="0.0445219 -0.248517 0.0379848" />
                        <site name="ECRB-P2" pos="0.0304823 -0.137312 0.0250259" />
                        <site name="ECRB-P3" pos="0.0372398 -0.239294 0.0413111" />
                        <site name="ECU-P5" pos="-0.0149106 -0.23815 0.0365262" />
                        <site name="FCR-P2" pos="0.0221403 -0.230249 0.00133261" />
                        <site name="FCU-P3" pos="0.0113535 -0.234278 0.0101677" />
                        <site name="FCU-P2" pos="0.0101156 -0.183524 0.00202653" />
                        <site name="PL-P2" pos="0.0265579 -0.250941 -0.00289608" />
                        <site name="PT-P5" pos="0.0266523 -0.114164 0.0207762" />
                        <site name="PT-P4" pos="0.0247636 -0.0980049 0.00986345" />
                        <site name="PQ-P1" pos="0.0340499 -0.20984 0.0205873" />
                        <site name="FDSL-P2" pos="0.0144489 -0.196409 0.00215107" />
                        <site name="FDSR-P2" pos="0.0164846 -0.195863 0.00280164" />
                        <site name="FDSM-P2" pos="0.0199263 -0.196283 0.00444904" />
                        <site name="FDSI-P2" pos="0.0225076 -0.195412 0.00579215" />
                        <site name="FDPL-P2" pos="0.0147847 -0.194289 0.0090345" />
                        <site name="FDPR-P2" pos="0.016579 -0.195475 0.0084259" />
                        <site name="FDPM-P2" pos="0.0199997 -0.195632 0.00823703" />
                        <site name="FDPI-P2" pos="0.0218255 -0.194751 0.00960112" />
                        <site name="EDCL-P3" pos="0.0104196 -0.234037 0.0379638" />
                        <site name="EDCL-P2" pos="  0.0013 -0.0382544 0.0129514" />
                        <site name="EDCR-P3" pos="0.00925485 -0.234687 0.0449521" />
                        <site name="EDCR-P2" pos="  0.0026 -0.0392844 0.0144214" />
                        <site name="EDCM-P3" pos="0.01511 -0.234236 0.0443121" />
                        <site name="EDCM-P2" pos=" 0.00316 -0.0388544 0.0141814" />
                        <site name="EDCI-P3" pos="0.0160858 -0.234141 0.0440288" />
                        <site name="EDCI-P2" pos=" 0.00228 -0.0385544 0.0137314" />
                        <site name="EDM-P4" pos="0.00476384 -0.237573 0.0385934" />
                        <site name="EIP-P3" pos="0.0112905 -0.239063 0.0384465" />
                        <site name="EPL-P2" pos="0.00130114 -0.143419 0.0238192" />
                        <site name="EPL-P3" pos="0.0283522 -0.229504 0.0401673" />
                        <site name="EPL-P4" pos="0.0354874 -0.238758 0.0483414" />
                        <site name="EPL-P5" pos="0.0444275 -0.24943 0.0437874" />
                        <site name="EPB-P1" pos="0.0201886 -0.154195 0.0221823" />
                        <site name="EPB-P2" pos="0.0238821 -0.166388 0.0279639" />
                        <site name="EPB-P3" pos="0.0401988 -0.206944 0.0402303" />
                        <site name="EPB-P4" pos="0.054931 -0.247751 0.0283207" />
                        <site name="FPL-P1" pos="0.0101887 -0.0992431 0.0185622" />
                        <site name="FPL-P2" pos="0.0173974 -0.141918 0.0200942" />
                        <site name="FPL-P3" pos="0.0196115 -0.188161 0.0208601" />
                        <site name="FPL-P4" pos="0.0398735 -0.243134 0.016579" />
                        <site name="APL-P1" pos="0.012109 -0.0994424 0.0176388" />
                        <site name="APL-P2" pos="0.0317939 -0.146588 0.0367991" />
                        <site name="APL-P3" pos="0.0418987 -0.168644 0.0356763" />
                        <site name="APL-P4" pos="0.0461379 -0.187248 0.0328852" />
                        <site name="APL-P5" pos="0.0577641 -0.242221 0.0248475" />
                        <joint name="pro_sup" type="hinge" pos="0 0 0" axis="-0.017161 0.992666 -0.119668" limited="true" range=" -1.5708   1.5708" ref="0" user="1" />
                        <body name="proximal_row" pos="0.0188875 -0.253931 0.0262326" quat="1.0 0.0 0.0 0.0">
                          <geom name="lunate" type="mesh" mesh="lunate" />
                          <geom name="sdfastSCAPHOIDw" type="mesh" mesh="sdfastSCAPHOIDw" />
                          <geom name="sdfastPISIFORMw" type="mesh" mesh="sdfastPISIFORMw" />
                          <geom name="sdfastTRIQUETRALw" type="mesh" mesh="sdfastTRIQUETRALw" />
                          <inertial pos="       0        0        0" mass="0.000104930304594021" fullinertia="1.15532e-05 1.15532e-05 1.15532e-05        0        0        0" />
                          <body name="hand" pos="0.00418882 -0.0157962 0.00244173" quat="1.0 0.0 0.0 0.0">
                            <geom name="sdfast_1seg_hand_fr_c_5mc" type="mesh" mesh="sdfast_1seg_hand_fr_c_5mc" />
                            <geom name="sdfast_1seg_hand_fr_c_4mc" type="mesh" mesh="sdfast_1seg_hand_fr_c_4mc" />
                            <geom name="sdfast_1seg_hand_fr_c_3mc" type="mesh" mesh="sdfast_1seg_hand_fr_c_3mc" />
                            <geom name="sdfast_1seg_hand_fr_c_trapezium" type="mesh" mesh="sdfast_1seg_hand_fr_c_trapezium" />
                            <geom name="sdfast_1seg_hand_fr_c_trapezoid" type="mesh" mesh="sdfast_1seg_hand_fr_c_trapezoid" />
                            <geom name="sdfast_1seg_hand_fr_c_hamate" type="mesh" mesh="sdfast_1seg_hand_fr_c_hamate" />
                            <geom name="capitate" type="mesh" mesh="capitate" />
                            <geom name="hand_3proxph" type="mesh" mesh="hand_3proxph" />
                            <geom name="hand_3midph" type="mesh" mesh="hand_3midph" />
                            <geom name="hand_3distph" type="mesh" mesh="hand_3distph" />
                            <geom name="hand_4proxph" type="mesh" mesh="hand_4proxph" />
                            <geom name="hand_4midph" type="mesh" mesh="hand_4midph" />
                            <geom name="hand_4distph" type="mesh" mesh="hand_4distph" />
                            <geom name="hand_5proxph" type="mesh" mesh="hand_5proxph" />
                            <geom name="hand_5midph" type="mesh" mesh="hand_5midph" />
                            <geom name="hand_5distph" type="mesh" mesh="hand_5distph" />
                            <geom name="hand_thumbprox" type="mesh" mesh="hand_thumbprox" />
                            <geom name="hand_thumbdist" type="mesh" mesh="hand_thumbdist" />
                            <geom name="hand_1mc" type="mesh" mesh="hand_1mc" />
                            <inertial pos="-0.0031617 -0.0445946 -0.00117737" mass="0.610589442432609" fullinertia="0.000127085 6.93193e-05 0.000173298 1.03979e-06 -2.31064e-07 1.38639e-05" />
                            <site name="ECRL-P4" pos="0.0180165 -0.0222662 0.00611744" />
                            <site name="ECRB-P4" pos="0.00524652 -0.0119201 0.00891908" />
                            <site name="ECU-P6" pos="-0.0236198 -0.0147007 -0.00134311" />
                            <site name="FCR-P3" pos="0.0117942 -0.0193491 -0.00438609" />
                            <site name="FCU-P4" pos="-0.0213638 -0.0185202 -0.00789076" />
                            <site name="PL-P3" pos="0.00962211 -0.0199158 -0.0184048" />
                            <site name="PL-P4" pos="0.00238192 -0.0324864 0.00517306" />
                            <site name="FDSL-P3" pos="-0.00246586 -0.0146168 -0.0144384" />
                            <site name="FDSL-P4" pos="-0.0209336 -0.0449207 -0.00778583" />
                            <site name="FDSL-P5" pos="-0.0214478 -0.0627588 -0.0197059" />
                            <site name="FDSL-P6" pos="-0.0179746 -0.076022 -0.0288873" />
                            <site name="FDSL-P7" pos="-0.0121299 -0.0762948 -0.0383625" />
                            <site name="FDSL-P8" pos="-0.0111121 -0.0762948 -0.0398315" />
                            <site name="FDSR-P3" pos="-0.000860428 -0.0141026 -0.01426" />
                            <site name="FDSR-P4" pos="-0.0102517 -0.0543434 4.19721e-005" />
                            <site name="FDSR-P5" pos="-0.0138823 -0.0699885 -0.0107029" />
                            <site name="FDSR-P6" pos="-0.00826851 -0.0842276 -0.0262641" />
                            <site name="FDSR-P7" pos="-0.00313742 -0.0852559 -0.0356238" />
                            <site name="FDSR-P8" pos="0.000650568 -0.0849096 -0.0408389" />
                            <site name="FDSM-P3" pos="0.00713526 -0.0144489 -0.0146797" />
                            <site name="FDSM-P4" pos="0.00494222 -0.0349628 -0.00138508" />
                            <site name="FDSM-P5" pos="0.00568722 -0.0593906 0.000629582" />
                            <site name="FDSM-P6" pos="0.00582363 -0.0758017 -0.00354664" />
                            <site name="FDSM-P7" pos="0.0122454 -0.0924436 -0.0175234" />
                            <site name="FDSM-P8" pos="0.0136514 -0.0930732 -0.0312378" />
                            <site name="FDSM-P9" pos="0.0164531 -0.0899987 -0.0395063" />
                            <site name="FDSI-P3" pos="0.0093283 -0.0143335 -0.0145538" />
                            <site name="FDSI-P4" pos="0.0111331 -0.0397371 0.000251833" />
                            <site name="FDSI-P5" pos="0.0186986 -0.0535984 0.00438609" />
                            <site name="FDSI-P6" pos="0.0194016 -0.0765676 -0.00393489" />
                            <site name="FDSI-P7" pos="0.0281003 -0.0914363 -0.0189294" />
                            <site name="FDSI-P8" pos="0.0279849 -0.0917091 -0.0281003" />
                            <site name="FDSI-P9" pos="0.0279115 -0.0905863 -0.0304613" />
                            <site name="FDPL-P3" pos="-0.000923387 -0.0107763 -0.0124657" />
                            <site name="FDPL-P4" pos="-0.0194646 -0.0487506 -0.00769139" />
                            <site name="FDPL-P5" pos="-0.0189714 -0.0612898 -0.0163691" />
                            <site name="FDPL-P6" pos="-0.014984 -0.0764837 -0.0281528" />
                            <site name="FDPL-P7" pos="-0.00965359 -0.0785193 -0.0386563" />
                            <site name="FDPL-P8" pos="-0.00327383 -0.0777009 -0.0437035" />
                            <site name="FDPL-P9" pos="0.00467989 -0.0740703 -0.048866" />
                            <site name="FDPR-P3" pos="0.00111226 -0.0123503 -0.0124237" />
                            <site name="FDPR-P4" pos="-0.00897154 -0.0581524 0.000923387" />
                            <site name="FDPR-P5" pos="-0.011322 -0.0691281 -0.00857281" />
                            <site name="FDPR-P6" pos="-0.00573969 -0.0855602 -0.0236723" />
                            <site name="FDPR-P7" pos="-0.00058761 -0.0863576 -0.03533" />
                            <site name="FDPR-P8" pos="0.00639026 -0.0822339 -0.0444695" />
                            <site name="FDPR-P9" pos="0.0127071 -0.0774386 -0.0509751" />
                            <site name="FDPM-P3" pos="0.00351517 -0.0134311 -0.012004" />
                            <site name="FDPM-P4" pos="0.0031689 -0.0361695 -0.00641124" />
                            <site name="FDPM-P5" pos="0.00264424 -0.0615206 0.00128015" />
                            <site name="FDPM-P6" pos="0.00299051 -0.0732938 -0.00139557" />
                            <site name="FDPM-P7" pos="0.00905549 -0.0921183 -0.0190449" />
                            <site name="FDPM-P8" pos="0.010514 -0.0919819 -0.0311013" />
                            <site name="FDPM-P9" pos="0.0171351 -0.0855916 -0.0465366" />
                            <site name="FDPM-P10" pos="0.0200312 -0.0804081 -0.0548681" />
                            <site name="FDPI-P3" pos="0.00940176 -0.0122559 -0.0127176" />
                            <site name="FDPI-P4" pos="0.0201676 -0.0581524 0.00459595" />
                            <site name="FDPI-P5" pos="0.0217521 -0.0736716 -0.00300101" />
                            <site name="FDPI-P6" pos="0.0304718 -0.0901141 -0.0186986" />
                            <site name="FDPI-P7" pos="0.0306816 -0.0909956 -0.0290552" />
                            <site name="FDPI-P8" pos="0.0305767 -0.0864101 -0.0417518" />
                            <site name="FDPI-P9" pos="0.0298737 -0.0815413 -0.0500098" />
                            <site name="EDCL-P4" pos="-0.0258548 -0.0461903 0.00177332" />
                            <site name="EDCL-P5" pos="-0.0249839 -0.049674 0.000807963" />
                            <site name="EDCL-P6" pos="-0.0251308 -0.0693904 -0.0105035" />
                            <site name="EDCL-P7" pos="-0.0188665 -0.0823388 -0.0284466" />
                            <site name="EDCL-P8" pos="-0.0123608 -0.0826536 -0.0396532" />
                            <site name="EDCL-P9" pos="-0.00157395 -0.0796001 -0.048121" />
                            <site name="EDCL-P10" pos="0.0021091 -0.0785613 -0.0503036" />
                            <site name="EDCR-P4" pos="-0.0164111 -0.0582363 0.00980049" />
                            <site name="EDCR-P5" pos="-0.0149736 -0.0610589 0.0121824" />
                            <site name="EDCR-P6" pos="-0.016579 -0.0757177 -0.00441757" />
                            <site name="EDCR-P7" pos="-0.00865675 -0.0916566 -0.0237142" />
                            <site name="EDCR-P8" pos="-0.0028541 -0.0924016 -0.0357707" />
                            <site name="EDCR-P9" pos="0.00800618 -0.0842171 -0.0488765" />
                            <site name="EDCR-P10" pos="0.011217 -0.0819401 -0.0518461" />
                            <site name="EDCM-P4" pos="0.000409228 -0.0553402 0.0156451" />
                            <site name="EDCM-P5" pos="-0.000912894 -0.0584882 0.0152359" />
                            <site name="EDCM-P6" pos="0.0019517 -0.0809852 0.00626434" />
                            <site name="EDCM-P7" pos="0.0105665 -0.0977216 -0.0186146" />
                            <site name="EDCM-P8" pos="0.0138613 -0.100292 -0.0320667" />
                            <site name="EDCM-P9" pos="0.0194856 -0.0894531 -0.0499363" />
                            <site name="EDCM-P10" pos="0.0215737 -0.0838708 -0.0560433" />
                            <site name="EDCM-P11" pos="0.0230322 -0.0808068 -0.059422" />
                            <site name="EDCI-P4" pos="0.0161907 -0.0491074 0.0171981" />
                            <site name="EDCI-P5" pos="0.0199053 -0.0593276 0.015089" />
                            <site name="EDCI-P6" pos="0.0209231 -0.0805655 0.00623286" />
                            <site name="EDCI-P7" pos="0.030902 -0.0961371 -0.0130638" />
                            <site name="EDCI-P8" pos="0.0327487 -0.0980993 -0.0304823" />
                            <site name="EDCI-P9" pos="0.0316155 -0.0890543 -0.0447843" />
                            <site name="EDCI-P10" pos="0.0307341 -0.085025 -0.0521084" />
                            <site name="EDM-P5" pos="-0.0216051 -0.0108288 0.00390341" />
                            <site name="EDM-P6" pos="-0.0268936 -0.0495481 0.00024134" />
                            <site name="EDM-P7" pos="-0.0267467 -0.0683201 -0.0115213" />
                            <site name="EDM-P8" pos="-0.020283 -0.0819506 -0.0285201" />
                            <site name="EDM-P9" pos="-0.0141236 -0.082811 -0.0408599" />
                            <site name="EDM-P10" pos="-0.00226649 -0.0789181 -0.0481525" />
                            <site name="EDM-P11" pos="0.00138508 -0.0770713 -0.050398" />
                            <site name="EIP-P4" pos="0.0040713 -0.0234414 0.0124237" />
                            <site name="EIP-P5" pos="0.0177647 -0.0591807 0.0144489" />
                            <site name="EIP-P6" pos="0.0182054 -0.0807124 0.00609645" />
                            <site name="EIP-P7" pos="0.0290132 -0.0977321 -0.015855" />
                            <site name="EIP-P8" pos="0.0302094 -0.0990227 -0.0296218" />
                            <site name="EIP-P9" pos="0.030115 -0.0894426 -0.0450676" />
                            <site name="EIP-P10" pos="0.0297372 -0.0816882 -0.0577222" />
                            <site name="EPL-P6" pos="0.0254771 0.000146902 0.00637976" />
                            <site name="EPL-P7" pos="0.0245327 -0.00962211 -0.000409228" />
                            <site name="EPL-P8" pos="0.0304823 -0.0149736 -0.00513109" />
                            <site name="EPL-P9" pos="0.0463162 -0.0358547 -0.0190344" />
                            <site name="EPL-P10" pos="0.0510696 -0.0487506 -0.0260962" />
                            <site name="EPL-P11" pos="0.0498524 -0.0735561 -0.0396007" />
                            <site name="EPL-P12" pos="0.0420875 -0.0793798 -0.0449416" />
                            <site name="EPB-P5" pos="0.0327697 0.00268622 -0.00343122" />
                            <site name="EPB-P6" pos="0.0311853 -0.00833147 -0.015068" />
                            <site name="EPB-P7" pos="0.0464002 -0.034627 -0.0254141" />
                            <site name="EPB-P8" pos="0.0475124 -0.0502092 -0.0334308" />
                            <site name="FPL-P6" pos="0.0130533 -0.0231581 -0.0219199" />
                            <site name="FPL-P7" pos="0.0172191 -0.0275022 -0.023305" />
                            <site name="FPL-P8" pos="0.0257814 -0.034564 -0.0234729" />
                            <site name="FPL-P9" pos="0.0296638 -0.0575228 -0.0320562" />
                            <site name="FPL-P10" pos="0.036841 -0.0684041 -0.0393384" />
                            <site name="FPL-P11" pos="0.0370719 -0.0803346 -0.0432103" />
                            <site name="FPL-P5" pos="0.0178892 0.0064176 -0.0168214" />
                            <site name="APL-P7" pos="0.0271455 0.00215107 -0.0173135" />
                            <site name="APL-P8" pos="0.0301989 -0.0070723 -0.019622" />
                            <site name="APL-P9" pos="0.0322766 -0.0166105 -0.0197794" />
                            <site name="APL-P6" pos="0.0332244 0.00608975 -0.00870125" />
                            <body name="index0" pos="0 0 0">
                              <inertial pos="0 0 0" mass="0.001" diaginertia="0.001 0.001 0.001" />
                              <geom name="sdfast_1seg_hand_fr_c_2mc" type="mesh" mesh="sdfast_1seg_hand_fr_c_2mc" />
                              <body name="index1" pos="0 0 0">
                                <inertial pos="0 0 0" mass="0.001" diaginertia="0.001 0.001 0.001" />
                                <geom name="hand_2proxph" type="mesh" mesh="hand_2proxph" />
                                <body name="index2" pos="0 0 0">
                                  <inertial pos="0 0 0" mass="0.001" diaginertia="0.001 0.001 0.001" />
                                  <geom name="hand_2midph" type="mesh" mesh="hand_2midph" />
                                  <body name="index3" pos="0 0 0">
                                    <inertial pos="0 0 0" mass="0.001" diaginertia="0.001 0.001 0.001" />
                                    <geom name="hand_2distph" type="mesh" mesh="hand_2distph" />
                                    <site name="fingertip" pos="0.024 -0.149 -0.0065" type="sphere" rgba="0.1 0.8 0.1 0.0" size="0.004" />
                                  </body>
                                </body>
                              </body>
                            </body>
                          </body>
                        </body>
                      </body>
                    </body>
                  </body>
                </body>
              </body>
            </body>
          </body>
        </body>
      </body>
    </body>

</mujocoinclude>