<mujocoinclude model="MoBL Arms Index Model">

    <body name="thorax" pos="0 0 0" quat="0.7071067811865475 0.7071067811865475 0.0 0.0">
      <light mode="trackcom" directional="false" pos="0 0 4.0" dir="0 0 -1" />
      <geom name="thorax" type="mesh" mesh="thorax" />
      <site name="PECM1-P3" pos="  -7e-05  0.00821  0.10454" />
      <site name="PECM2-P4" pos="0.032035 -0.0406475 0.100582" />
      <site name="PECM2-P5" pos="0.0286978 -0.0466171 0.0235366" />
      <site name="PECM2-P3" pos=" 0.02083 -0.02005  0.11555" />
      <site name="PECM3-P4" pos="0.0544108 -0.0872335 0.092602" />
      <site name="PECM3-P5" pos="0.0593233 -0.120782 0.0392483" />
      <site name="PECM3-P3" pos=" 0.02984 -0.0544459   0.1151" />
      <site name="LAT1-P4" pos="-0.122585 -0.104863 0.0343669" />
      <site name="LAT1-P5" pos="-0.0992661 -0.121507 0.00914102" />
      <site name="LAT2-P4" pos="-0.113921 -0.175234 0.0298275" />
      <site name="LAT2-P5" pos="-0.0744755 -0.195029 0.00844663" />
      <site name="LAT3-P4" pos="-0.115631 -0.200926 0.0573335" />
      <site name="LAT3-P5" pos="-0.0737603 -0.257627 0.00940012" />
      <joint name="r_z" type="hinge" pos="0 0 0" axis="       0        0        1" limited="true" range="-6.28319  6.28319" ref="0" armature="0" damping="0" stiffness="0" />
      <body name="clavicle" pos="0.00655521 0.00718223 0.0263918" quat="1.0 0.0 0.0 0.0">
        <geom name="clavicle" type="mesh" mesh="clavicle" />
        <inertial pos="-0.0114999 0.00660423 0.0561395" mass="0.161677852363554" fullinertia="0.000270054 0.000284158 4.94489e-05 -2.11288e-05 -7.7858e-05 5.97906e-05" />
        <site name="DELT1-P4" pos="-0.0145096 0.0114625 0.0831294" />
        <site name="DELT2-P2" pos="0.0191703 0.0244002 0.162891" />
        <site name="PECM1-P4" pos="0.00332683 -0.000134732 0.052991" />
        <joint name="sternoclavicular_r2" type="hinge" pos="0 0 0" axis="  0.0153 0.989299  -0.1451" limited="false" range="-99999.9  99999.9" ref="0" />
        <joint name="sternoclavicular_r3" type="hinge" pos="0 0 0" axis="-0.994473        0 -0.104997" limited="false" range="-99999.9  99999.9" ref="0" />
        <body name="clavphant" pos="-0.0148516 0.0208005 0.140468" quat="1.0 0.0 0.0 0.0">
          <inertial pos="       0        0        0" mass="0.000103639648950996" fullinertia=" 1.11321  1.11321  1.11321        0        0        0" />
          <joint name="unrotscap_r3" type="hinge" pos="0 0 0" axis="-0.994473        0 -0.104997" limited="false" range="-99999.9  99999.9" ref="0" />
          <joint name="unrotscap_r2" type="hinge" pos="0 0 0" axis="  0.0153 0.989299  -0.1451" limited="false" range="-99999.9  99999.9" ref="0" />
          <body name="scapula" pos="       0        0        0" quat="1.0 0.0 0.0 0.0">
            <geom name="scapula" type="mesh" mesh="scapula" />
            <inertial pos="-0.0566847 -0.036307 -0.0453258" mass="0.729581672755433" fullinertia="0.00138361 0.00128064 0.00151965 0.000500277 0.000455549 0.000268395" />
            <site name="DELT1-P3" pos="0.0450522 -0.0337036 0.00102603" />
            <site name="DELT2-P3" pos="5.18198e-005 0.00304701 0.0231427" />
            <site name="DELT2-P4" pos="-0.0111724 -0.000352375 0.00642566" />
            <site name="DELT3-P1" pos="-0.0577584 0.0012644 -0.0260343" />
            <site name="DELT3-P2" pos="-0.0751077 -0.0340456 0.0127788" />
            <site name="SUPSP-P2" pos="-0.0198781 0.00131622 -0.0131726" />
            <site name="SUPSP-P3" pos="-0.0456014 -0.0156703 -0.060681" />
            <site name="INFSP-P2" pos="-0.0765068 -0.0567531 -0.0495501" />
            <site name="SUBSC-P2" pos="-0.0189764 -0.054131 -0.0254643" />
            <site name="SUBSC-P3" pos="-0.0750973 -0.0408651 -0.0671067" />
            <site name="TMIN-P2" pos="-0.0981778 -0.0828184 -0.0490941" />
            <site name="TMIN-P3" pos="-0.0999397 -0.0841658 -0.0549083" />
            <site name="TMAJ-P2" pos="-0.106376 -0.106946 -0.0604116" />
            <site name="TMAJ-P3" pos="-0.108708 -0.112915 -0.0737603" />
            <site name="LAT1-P2" pos="-0.08052 -0.06821 -0.02908" />
            <site name="LAT1-P3" pos="-0.10925 -0.07239 -0.07422" />
            <site name="LAT2-P2" pos="-0.08345 -0.08695 -0.02453" />
            <site name="LAT2-P3" pos="-0.11524 -0.10749 -0.08863" />
            <site name="LAT3-P2" pos="-0.08438 -0.11598 -0.02995" />
            <site name="LAT3-P3" pos="-0.11279 -0.13833 -0.08911" />
            <site name="CORB-P1" pos="0.012955 -0.0427721 -0.0274852" />
            <site name="CORB-P2" pos="0.0050058 -0.0721125 -0.0161989" />
            <site name="TRIlong-P1" pos="-0.0473115 -0.0422124 -0.0142712" />
            <site name="BIClong-P1" pos="-0.0323667 -0.0243864 -0.013525" />
            <site name="BIClong-P2" pos="-0.0217021 -0.0135664 -0.00477779" />
            <site name="BICshort-P1" pos="0.0131415 -0.0407407 -0.0272054" />
            <site name="BICshort-P2" pos="0.000963849 -0.06948 -0.0165098" />
            <joint name="acromioclavicular_r2" type="hinge" pos="0 0 0" axis="0.157095 0.947269 -0.279291" limited="false" range="-99999.9  99999.9" ref="0" />
            <joint name="acromioclavicular_r3" type="hinge" pos="0 0 0" axis="-0.754084 0.297594 0.585487" limited="false" range="-99999.9  99999.9" ref="0" />
            <joint name="acromioclavicular_r1" type="hinge" pos="0 0 0" axis="  0.6377   0.1186   0.7611" limited="false" range="-99999.9  99999.9" ref="0" />
            <body name="scapphant" pos="-0.00989759 -0.0352375 0.00932757" quat="1.0 0.0 0.0 0.0">
              <inertial pos="       0        0        0" mass="0.000103639648950996" fullinertia=" 1.11321  1.11321  1.11321        0        0        0" />
              <joint name="unrothum_r1" type="hinge" pos="0 0 0" axis="  0.6377   0.1186   0.7611" limited="false" range="-99999.9  99999.9" ref="0" />
              <joint name="unrothum_r3" type="hinge" pos="0 0 0" axis="-0.754084 0.297594 0.585487" limited="false" range="-99999.9  99999.9" ref="0" />
              <joint name="unrothum_r2" type="hinge" pos="0 0 0" axis="0.157095 0.947269 -0.279291" limited="false" range="-99999.9  99999.9" ref="0" />
              <body name="humphant" pos="       0        0        0" quat="1.0 0.0 0.0 0.0">
                <inertial pos="       0        0        0" mass="0.000103639648950996" fullinertia=" 1.11321  1.11321  1.11321        0        0        0" />
                <joint name="elv_angle" type="hinge" pos="0 0 0" axis="  0.0048 0.999089   0.0424" limited="true" range=" -1.5708  2.26893" ref="0" user="1" />
                <body name="humphant1" pos="       0        0        0" quat="1.0 0.0 0.0 0.0">
                  <inertial pos="       0        0        0" mass="0.000103639648950996" fullinertia=" 1.11321  1.11321  1.11321        0        0        0" />
                  <joint name="shoulder_elv" type="hinge" pos="0 0 0" axis="-0.998261   0.0023 0.058898" limited="true" range="       0  3.14159" ref="0" user="1" />
                  <joint name="shoulder1_r2" type="hinge" pos="0 0 0" axis="  0.0048 0.999089   0.0424" limited="false" range="-99999.9  99999.9" ref="0" />
                  <body name="humerus" pos="       0        0        0" quat="1.0 0.0 0.0 0.0">
                    <geom name="humerus" type="mesh" mesh="humerus" />
                    <inertial pos="0.0187215 -0.145242 -0.0132099" mass="2.07027453555042" fullinertia="0.0136676 0.00284017 0.014003 -0.000386741 -0.000258822 0.00136847" />
                    <site name="DELT1-P1" pos="0.00928611 -0.123155 0.00606292" />
                    <site name="DELT1-P2" pos="0.0168207 -0.114346 0.00426995" />
                    <site name="DELT2-P1" pos="0.00477779 -0.141064 0.00580382" />
                    <site name="DELT3-P3" pos="0.00213498 -0.0787869 0.0108303" />
                    <site name="SUPSP-P1" pos="0.00265318 0.0110169 0.0268738" />
                    <site name="INFSP-P1" pos="-0.00919284 0.00501616 0.025371" />
                    <site name="SUBSC-P1" pos="0.0145406 0.00870573 -0.0137944" />
                    <site name="TMIN-P1" pos="-0.00114004 -0.0131001 0.0223447" />
                    <site name="TMAJ-P1" pos="0.0103432 -0.0561623 -0.00588673" />
                    <site name="PECM1-P1" pos="0.0121155 -0.0434354 0.00808389" />
                    <site name="PECM1-P2" pos="  0.0191  -0.0301  0.00143" />
                    <site name="PECM2-P1" pos="0.0132037 -0.044451 0.00813571" />
                    <site name="PECM2-P2" pos=" 0.01748 -0.03533  0.00033" />
                    <site name="PECM3-P1" pos="0.0131519 -0.0453423 0.00777297" />
                    <site name="PECM3-P2" pos="0.0159185 -0.045833 -0.00378312" />
                    <site name="LAT1-P1" pos="0.0108822 -0.0353929 -0.00676767" />
                    <site name="LAT2-P1" pos="0.0100323 -0.0421917 -0.00633238" />
                    <site name="LAT3-P1" pos="0.0125197 -0.0406475 -0.00431141" />
                    <site name="CORB-P3" pos="0.00770043 -0.155957 -0.00810462" />
                    <site name="TRIlong-P2" pos="-0.0281278 -0.118574 -0.00688167" />
                    <site name="TRIlong-P3" pos="-0.0329989 -0.234609 -0.0126129" />
                    <site name="TRIlong-P4" pos="-0.0180644 -0.277309 -0.0125197" />
                    <site name="TRIlat-P1" pos="-0.00620801 -0.131063 0.00443578" />
                    <site name="TRIlat-P2" pos="-0.0242931 -0.150568 0.00961776" />
                    <site name="TRIlat-P3" pos="-0.0329989 -0.234609 -0.0126129" />
                    <site name="TRIlat-P4" pos="-0.0180644 -0.277309 -0.0125197" />
                    <site name="TRImed-P1" pos="-0.008685 -0.141934 -0.00938975" />
                    <site name="TRImed-P2" pos="-0.0269567 -0.1569 -0.0111931" />
                    <site name="TRImed-P3" pos="-0.0329989 -0.234609 -0.0126129" />
                    <site name="TRImed-P4" pos="-0.0180644 -0.277309 -0.0125197" />
                    <site name="ANC-P1" pos="-0.00771079 -0.293912 0.0101463" />
                    <site name="BIClong-P3" pos="0.0220856 0.0185826 0.0106542" />
                    <site name="BIClong-P4" pos="0.0246455 -0.00529599 0.0124471" />
                    <site name="BIClong-P5" pos="0.0139395 -0.0292989 0.0014095" />
                    <site name="BIClong-P6" pos="0.0110687 -0.0801756 -0.00171005" />
                    <site name="BIClong-P7" pos="0.0176498 -0.125663 0.000248735" />
                    <site name="BIClong-P8" pos="0.0236298 -0.181784 -0.0065293" />
                    <site name="BICshort-P3" pos="0.0115765 -0.0785174 -0.0114107" />
                    <site name="BICshort-P4" pos="0.0176498 -0.125663 -0.0111827" />
                    <site name="BICshort-P5" pos="0.0236298 -0.181784 -0.0065293" />
                    <site name="BRA-P1" pos="0.0070475 -0.180229 -0.00373103" />
                    <site name="BRA-P2" pos="0.0196293 -0.295984 -0.0114522" />
                    <site name="BRD-P1" pos="-0.0101567 -0.206896 0.00231116" />
                    <site name="ECRL-P1" pos="-0.00756569 -0.270396 0.00943121" />
                    <site name="ECRB-P1" pos="0.013981 -0.301052 0.017598" />
                    <site name="ECU-P1" pos="0.000860209 -0.300089 0.0194843" />
                    <site name="FCR-P1" pos="0.00785589 -0.28818 -0.0383985" />
                    <site name="FCU-P1" pos="0.00226971 -0.287496 -0.0402122" />
                    <site name="PL-P1" pos="0.00473633 -0.285206 -0.0400567" />
                    <site name="PT-P1" pos="0.00373103 -0.285942 -0.0378285" />
                    <site name="FDSL-P1" pos="0.00436323 -0.286025 -0.0400464" />
                    <site name="FDSR-P1" pos="0.00496434 -0.288947 -0.038668" />
                    <site name="EDCL-P1" pos="-0.000414559 -0.298803 0.0193806" />
                    <site name="EDCR-P1" pos="-0.00161678 -0.299892 0.0184686" />
                    <site name="EDCM-P1" pos="0.000528562 -0.300389 0.0201994" />
                    <site name="EDCI-P1" pos="0.000673658 -0.299498 0.0193703" />
                    <site name="EDM-P1" pos="0.000922393 -0.299716 0.0191422" />
                    <joint name="shoulder_rot" type="hinge" pos="0 0 0" axis="  0.0048 0.999089   0.0424" limited="true" range=" -1.5708 0.349066" ref="0" user="1" />
                    <body name="ulna" pos="0.00632202 -0.30097 -0.0127477" quat="1.0 0.0 0.0 0.0">
                      <geom name="ulna" type="mesh" mesh="ulna" />
                      <inertial pos="0.0100715 -0.0994432 0.0251699" mass="1.14552903985536" fullinertia="0.00602592 0.00128373 0.00550328 0.000352732 -8.47711e-05 0.00121528" />
                      <site name="TRIlong-P5" pos="-0.0226971 0.0108407 -0.000808389" />
                      <site name="TRIlat-P5" pos="-0.0226971 0.0108407 -0.000808389" />
                      <site name="TRImed-P5" pos="-0.0226971 0.0108407 -0.000808389" />
                      <site name="ANC-P2" pos="-0.0262416 -0.00128513 0.00621838" />
                      <site name="SUP-P3" pos="-0.014095 -0.0350717 0.0208627" />
                      <site name="BRA-P4" pos="-0.00331647 -0.0247699 0.000932757" />
                      <site name="BRA-P3" pos="0.00516125 -0.0151625 0.00132659" />
                      <site name="ECU-P2" pos="-0.0144163 -0.0331751 0.0305426" />
                      <site name="ECU-P3" pos="-0.0176706 -0.0562556 0.0297239" />
                      <site name="ECU-P4" pos="-0.0185826 -0.0992142 0.0339731" />
                      <site name="PT-P2" pos="0.00876791 -0.0349577 -0.0148412" />
                      <site name="PT-P3" pos=" 0.01219 -0.06516 -0.00219" />
                      <site name="PQ-P2" pos="0.00200025 -0.217353 0.0376419" />
                      <site name="FDSM-P1" pos="-0.00693349 -0.0281174 -0.00197952" />
                      <site name="FDSI-P1" pos="-0.00700604 -0.029216 -0.00141986" />
                      <site name="FDPL-P1" pos="-0.00650857 -0.0333098 0.00263245" />
                      <site name="FDPR-P1" pos="-0.00520271 -0.034968 0.00282936" />
                      <site name="FDPM-P1" pos="-0.00540999 -0.0344809 0.00217643" />
                      <site name="FDPI-P1" pos="-0.00670549 -0.032916 0.00290191" />
                      <site name="EDM-P2" pos="-0.0101256 -0.040492 0.0319728" />
                      <site name="EDM-P3" pos="-0.00782479 -0.0856789 0.037787" />
                      <site name="EIP-P1" pos="-0.0040834 -0.172581 0.0381601" />
                      <site name="EIP-P2" pos="0.00177224 -0.181048 0.0419637" />
                      <site name="EPL-P1" pos="-0.0146339 -0.100593 0.0305944" />
                      <joint name="elbow_flexion" type="hinge" pos="0 0 0" axis="  0.0494   0.0366 0.998108" limited="true" range="       0  4.26893" ref="0" user="1" />
                      <body name="radius" pos="0.000414559 -0.0119217 0.0207269" quat="1.0 0.0 0.0 0.0">
                        <geom name="radius" type="mesh" mesh="radius" />
                        <inertial pos="0.0348583 -0.188167 0.0161678" mass="0.242091855984632" fullinertia="0.000488199 9.86194e-05 0.000448157 3.35522e-05 -4.72002e-06 7.14459e-05" />
                        <site name="SUP-P1" pos="0.0103225 -0.0631787 0.000777297" />
                        <site name="SUP-P2" pos="0.0124471 -0.0535817 -0.00110894" />
                        <site name="BIClong-P11" pos="-0.00207279 -0.0388649 -0.00207279" />
                        <site name="BIClong-P9" pos=" 0.00273 -0.0343493 -0.0119845" />
                        <site name="BICshort-P8" pos="-0.00207279 -0.0388649 -0.00207279" />
                        <site name="BICshort-P6" pos=" 0.00273 -0.0343493 -0.0119845" />
                        <site name="BRD-P2" pos="0.0370719 -0.132058 0.0239926" />
                        <site name="BRD-P3" pos="0.043425 -0.229044 0.0232153" />
                        <site name="ECRL-P2" pos="0.0331129 -0.13953 0.0288015" />
                        <site name="ECRL-P3" pos="0.0439743 -0.24546 0.0375176" />
                        <site name="ECRB-P2" pos="0.0301073 -0.135623 0.0247181" />
                        <site name="ECRB-P3" pos="0.0367817 -0.23635 0.0408029" />
                        <site name="ECU-P5" pos="-0.0147272 -0.235221 0.036077" />
                        <site name="FCR-P2" pos="0.021868 -0.227416 0.00131622" />
                        <site name="FCU-P3" pos="0.0112138 -0.231396 0.0100427" />
                        <site name="FCU-P2" pos="0.0101156 -0.183524 0.00202653" />
                        <site name="PL-P2" pos="0.0262312 -0.247854 -0.00286045" />
                        <site name="PT-P5" pos="0.0263245 -0.11276 0.0205207" />
                        <site name="PT-P4" pos="0.024459 -0.0967994 0.00974213" />
                        <site name="PQ-P1" pos="0.0336311 -0.207259 0.0203341" />
                        <site name="FDSL-P2" pos="0.0142712 -0.193993 0.00212461" />
                        <site name="FDSR-P2" pos="0.0162818 -0.193454 0.00276718" />
                        <site name="FDSM-P2" pos="0.0196812 -0.193868 0.00439432" />
                        <site name="FDSI-P2" pos="0.0222307 -0.193008 0.00572091" />
                        <site name="FDPL-P2" pos="0.0146028 -0.191899 0.00892337" />
                        <site name="FDPR-P2" pos="0.0163751 -0.19307 0.00832226" />
                        <site name="FDPM-P2" pos="0.0197537 -0.193226 0.00813571" />
                        <site name="FDPI-P2" pos="0.021557 -0.192355 0.00948303" />
                        <site name="EDCL-P3" pos="0.0102914 -0.231158 0.0374968" />
                        <site name="EDCL-P2" pos="  0.0013 -0.0382544 0.0129514" />
                        <site name="EDCR-P3" pos="0.00914102 -0.2318 0.0443992" />
                        <site name="EDCR-P2" pos="  0.0026 -0.0392844 0.0144214" />
                        <site name="EDCM-P3" pos="0.0149241 -0.231355 0.043767" />
                        <site name="EDCM-P2" pos=" 0.00316 -0.0388544 0.0141814" />
                        <site name="EDCI-P3" pos="0.015888 -0.231262 0.0434872" />
                        <site name="EDCI-P2" pos=" 0.00228 -0.0385544 0.0137314" />
                        <site name="EDM-P4" pos="0.00470524 -0.234651 0.0381187" />
                        <site name="EIP-P3" pos="0.0111516 -0.236122 0.0379736" />
                        <site name="EPL-P2" pos="0.00128513 -0.141655 0.0235262" />
                        <site name="EPL-P3" pos="0.0280034 -0.226681 0.0396733" />
                        <site name="EPL-P4" pos="0.0350509 -0.235822 0.0477468" />
                        <site name="EPL-P5" pos="0.043881 -0.246362 0.0432488" />
                        <site name="EPB-P1" pos="0.0199403 -0.152298 0.0219094" />
                        <site name="EPB-P2" pos="0.0235884 -0.164341 0.02762" />
                        <site name="EPB-P3" pos="0.0397043 -0.204398 0.0397354" />
                        <site name="EPB-P4" pos="0.0542554 -0.244704 0.0279723" />
                        <site name="FPL-P1" pos="0.0100634 -0.0980224 0.0183339" />
                        <site name="FPL-P2" pos="0.0171835 -0.140173 0.019847" />
                        <site name="FPL-P3" pos="0.0193703 -0.185847 0.0206036" />
                        <site name="FPL-P4" pos="0.0393831 -0.240143 0.0163751" />
                        <site name="APL-P1" pos="0.01196 -0.0982193 0.0174218" />
                        <site name="APL-P2" pos="0.0314028 -0.144785 0.0363464" />
                        <site name="APL-P3" pos="0.0413833 -0.16657 0.0352375" />
                        <site name="APL-P4" pos="0.0455704 -0.184945 0.0324807" />
                        <site name="APL-P5" pos="0.0570536 -0.239242 0.0245419" />
                        <joint name="pro_sup" type="hinge" pos="0 0 0" axis="-0.017161 0.992666 -0.119668" limited="true" range=" -1.5708   1.5708" ref="0" user="1" />
                        <body name="proximal_row" pos="0.0186551 -0.250808 0.0259099" quat="1.0 0.0 0.0 0.0">
                          <geom name="lunate" type="mesh" mesh="lunate" />
                          <geom name="sdfastSCAPHOIDw" type="mesh" mesh="sdfastSCAPHOIDw" />
                          <geom name="sdfastPISIFORMw" type="mesh" mesh="sdfastPISIFORMw" />
                          <geom name="sdfastTRIQUETRALw" type="mesh" mesh="sdfastTRIQUETRALw" />
                          <inertial pos="       0        0        0" mass="0.000103639648950996" fullinertia="1.11321e-05 1.11321e-05 1.11321e-05        0        0        0" />
                          <body name="hand" pos="0.00413729 -0.0156019 0.00241169" quat="1.0 0.0 0.0 0.0">
                            <geom name="sdfast_1seg_hand_fr_c_5mc" type="mesh" mesh="sdfast_1seg_hand_fr_c_5mc" />
                            <geom name="sdfast_1seg_hand_fr_c_4mc" type="mesh" mesh="sdfast_1seg_hand_fr_c_4mc" />
                            <geom name="sdfast_1seg_hand_fr_c_3mc" type="mesh" mesh="sdfast_1seg_hand_fr_c_3mc" />
                            <geom name="sdfast_1seg_hand_fr_c_trapezium" type="mesh" mesh="sdfast_1seg_hand_fr_c_trapezium" />
                            <geom name="sdfast_1seg_hand_fr_c_trapezoid" type="mesh" mesh="sdfast_1seg_hand_fr_c_trapezoid" />
                            <geom name="sdfast_1seg_hand_fr_c_hamate" type="mesh" mesh="sdfast_1seg_hand_fr_c_hamate" />
                            <geom name="capitate" type="mesh" mesh="capitate" />
                            <geom name="hand_3proxph" type="mesh" mesh="hand_3proxph" />
                            <geom name="hand_3midph" type="mesh" mesh="hand_3midph" />
                            <geom name="hand_3distph" type="mesh" mesh="hand_3distph" />
                            <geom name="hand_4proxph" type="mesh" mesh="hand_4proxph" />
                            <geom name="hand_4midph" type="mesh" mesh="hand_4midph" />
                            <geom name="hand_4distph" type="mesh" mesh="hand_4distph" />
                            <geom name="hand_5proxph" type="mesh" mesh="hand_5proxph" />
                            <geom name="hand_5midph" type="mesh" mesh="hand_5midph" />
                            <geom name="hand_5distph" type="mesh" mesh="hand_5distph" />
                            <geom name="hand_thumbprox" type="mesh" mesh="hand_thumbprox" />
                            <geom name="hand_thumbdist" type="mesh" mesh="hand_thumbdist" />
                            <geom name="hand_1mc" type="mesh" mesh="hand_1mc" />
                            <inertial pos="-0.00312281 -0.0440461 -0.00116289" mass="0.603079117245847" fullinertia="0.000122453 6.67927e-05 0.000166982 1.00189e-06 -2.22642e-07 1.33585e-05" />
                            <site name="ECRL-P4" pos="0.0177949 -0.0219923 0.00604219" />
                            <site name="ECRB-P4" pos="0.00518198 -0.0117735 0.00880937" />
                            <site name="ECU-P6" pos="-0.0233293 -0.0145199 -0.00132659" />
                            <site name="FCR-P3" pos="0.0116491 -0.0191112 -0.00433214" />
                            <site name="FCU-P4" pos="-0.021101 -0.0182924 -0.0077937" />
                            <site name="PL-P3" pos="0.00950376 -0.0196708 -0.0181784" />
                            <site name="PL-P4" pos="0.00235262 -0.0320868 0.00510943" />
                            <site name="FDSL-P3" pos="-0.00243553 -0.014437 -0.0142608" />
                            <site name="FDSL-P4" pos="-0.0206761 -0.0443681 -0.00769006" />
                            <site name="FDSL-P5" pos="-0.0211839 -0.0619869 -0.0194635" />
                            <site name="FDSL-P6" pos="-0.0177535 -0.0750869 -0.028532" />
                            <site name="FDSL-P7" pos="-0.0119807 -0.0753564 -0.0378907" />
                            <site name="FDSL-P8" pos="-0.0109754 -0.0753564 -0.0393416" />
                            <site name="FDSR-P3" pos="-0.000849845 -0.0139292 -0.0140846" />
                            <site name="FDSR-P4" pos="-0.0101256 -0.053675 4.14559e-005" />
                            <site name="FDSR-P5" pos="-0.0137115 -0.0691276 -0.0105712" />
                            <site name="FDSR-P6" pos="-0.0081668 -0.0831915 -0.025941" />
                            <site name="FDSR-P7" pos="-0.00309883 -0.0842072 -0.0351857" />
                            <site name="FDSR-P8" pos="0.000642566 -0.0838652 -0.0403366" />
                            <site name="FDSM-P3" pos="0.0070475 -0.0142712 -0.0144992" />
                            <site name="FDSM-P4" pos="0.00488143 -0.0345327 -0.00136804" />
                            <site name="FDSM-P5" pos="0.00561727 -0.05866 0.000621838" />
                            <site name="FDSM-P6" pos="0.005752 -0.0748693 -0.00350302" />
                            <site name="FDSM-P7" pos="0.0120947 -0.0913065 -0.0173078" />
                            <site name="FDSM-P8" pos="0.0134835 -0.0919284 -0.0308535" />
                            <site name="FDSM-P9" pos="0.0162507 -0.0888917 -0.0390203" />
                            <site name="FDSI-P3" pos="0.00921356 -0.0141572 -0.0143748" />
                            <site name="FDSI-P4" pos="0.0109962 -0.0392483 0.000248735" />
                            <site name="FDSI-P5" pos="0.0184686 -0.0529391 0.00433214" />
                            <site name="FDSI-P6" pos="0.019163 -0.0756259 -0.00388649" />
                            <site name="FDSI-P7" pos="0.0277547 -0.0903116 -0.0186966" />
                            <site name="FDSI-P8" pos="0.0276407 -0.0905811 -0.0277547" />
                            <site name="FDSI-P9" pos="0.0275681 -0.0894721 -0.0300866" />
                            <site name="FDPL-P3" pos="-0.000912029 -0.0106438 -0.0123124" />
                            <site name="FDPL-P4" pos="-0.0192252 -0.048151 -0.00759679" />
                            <site name="FDPL-P5" pos="-0.018738 -0.0605359 -0.0161678" />
                            <site name="FDPL-P6" pos="-0.0147997 -0.0755429 -0.0278065" />
                            <site name="FDPL-P7" pos="-0.00953485 -0.0775535 -0.0381808" />
                            <site name="FDPL-P8" pos="-0.00323356 -0.0767452 -0.0431659" />
                            <site name="FDPL-P9" pos="0.00462233 -0.0731592 -0.048265" />
                            <site name="FDPR-P3" pos="0.00109858 -0.0121984 -0.0122709" />
                            <site name="FDPR-P4" pos="-0.00886119 -0.0574371 0.000912029" />
                            <site name="FDPR-P5" pos="-0.0111827 -0.0682778 -0.00846736" />
                            <site name="FDPR-P6" pos="-0.00566909 -0.0845078 -0.0233811" />
                            <site name="FDPR-P7" pos="-0.000580382 -0.0852954 -0.0348955" />
                            <site name="FDPR-P8" pos="0.00631165 -0.0812224 -0.0439225" />
                            <site name="FDPR-P9" pos="0.0125508 -0.0764861 -0.0503481" />
                            <site name="FDPM-P3" pos="0.00347193 -0.0132659 -0.0118564" />
                            <site name="FDPM-P4" pos="0.00312992 -0.0357246 -0.00633238" />
                            <site name="FDPM-P5" pos="0.00261172 -0.0607639 0.0012644" />
                            <site name="FDPM-P6" pos="0.00295373 -0.0723923 -0.00137841" />
                            <site name="FDPM-P7" pos="0.0089441 -0.0909852 -0.0188106" />
                            <site name="FDPM-P8" pos="0.0103847 -0.0908505 -0.0307188" />
                            <site name="FDPM-P9" pos="0.0169244 -0.0845389 -0.0459642" />
                            <site name="FDPM-P10" pos="0.0197848 -0.0794191 -0.0541932" />
                            <site name="FDPI-P3" pos="0.00928611 -0.0121051 -0.0125611" />
                            <site name="FDPI-P4" pos="0.0199195 -0.0574371 0.00453942" />
                            <site name="FDPI-P5" pos="0.0214845 -0.0727654 -0.00296409" />
                            <site name="FDPI-P6" pos="0.030097 -0.0890057 -0.0184686" />
                            <site name="FDPI-P7" pos="0.0303042 -0.0898763 -0.0286978" />
                            <site name="FDPI-P8" pos="0.0302006 -0.0853473 -0.0412382" />
                            <site name="FDPI-P9" pos="0.0295062 -0.0805384 -0.0493947" />
                            <site name="EDCL-P4" pos="-0.0255368 -0.0456222 0.00175151" />
                            <site name="EDCL-P5" pos="-0.0246766 -0.049063 0.000798025" />
                            <site name="EDCL-P6" pos="-0.0248217 -0.0685369 -0.0103743" />
                            <site name="EDCL-P7" pos="-0.0186344 -0.081326 -0.0280967" />
                            <site name="EDCL-P8" pos="-0.0122088 -0.081637 -0.0391654" />
                            <site name="EDCL-P9" pos="-0.00155459 -0.078621 -0.0475291" />
                            <site name="EDCL-P10" pos="0.00208316 -0.077595 -0.0496848" />
                            <site name="EDCR-P4" pos="-0.0162092 -0.05752 0.00967994" />
                            <site name="EDCR-P5" pos="-0.0147894 -0.0603079 0.0120326" />
                            <site name="EDCR-P6" pos="-0.0163751 -0.0747864 -0.00436323" />
                            <site name="EDCR-P7" pos="-0.00855027 -0.0905292 -0.0234226" />
                            <site name="EDCR-P8" pos="-0.002819 -0.0912651 -0.0353308" />
                            <site name="EDCR-P9" pos="0.00790771 -0.0831812 -0.0482753" />
                            <site name="EDCR-P10" pos="0.0110791 -0.0809322 -0.0512084" />
                            <site name="EDCM-P4" pos="0.000404195 -0.0546596 0.0154527" />
                            <site name="EDCM-P5" pos="-0.000901665 -0.0577687 0.0150485" />
                            <site name="EDCM-P6" pos="0.0019277 -0.0799891 0.00618729" />
                            <site name="EDCM-P7" pos="0.0104365 -0.0965196 -0.0183857" />
                            <site name="EDCM-P8" pos="0.0136908 -0.0990588 -0.0316723" />
                            <site name="EDCM-P9" pos="0.0192459 -0.0883528 -0.0493221" />
                            <site name="EDCM-P10" pos="0.0213083 -0.0828392 -0.0553539" />
                            <site name="EDCM-P11" pos="0.0227489 -0.0798129 -0.0586911" />
                            <site name="EDCI-P4" pos="0.0159916 -0.0485034 0.0169865" />
                            <site name="EDCI-P5" pos="0.0196604 -0.0585979 0.0149034" />
                            <site name="EDCI-P6" pos="0.0206657 -0.0795745 0.0061562" />
                            <site name="EDCI-P7" pos="0.0305219 -0.0949546 -0.0129031" />
                            <site name="EDCI-P8" pos="0.0323459 -0.0968927 -0.0301073" />
                            <site name="EDCI-P9" pos="0.0312266 -0.087959 -0.0442334" />
                            <site name="EDCI-P10" pos="0.0303561 -0.0839792 -0.0514674" />
                            <site name="EDM-P5" pos="-0.0213394 -0.0106956 0.00385539" />
                            <site name="EDM-P6" pos="-0.0265628 -0.0489386 0.000238371" />
                            <site name="EDM-P7" pos="-0.0264177 -0.0674798 -0.0113796" />
                            <site name="EDM-P8" pos="-0.0200335 -0.0809426 -0.0281693" />
                            <site name="EDM-P9" pos="-0.0139499 -0.0817924 -0.0403573" />
                            <site name="EDM-P10" pos="-0.00223862 -0.0779474 -0.0475602" />
                            <site name="EDM-P11" pos="0.00136804 -0.0761233 -0.0497781" />
                            <site name="EIP-P4" pos="0.00402122 -0.0231531 0.0122709" />
                            <site name="EIP-P5" pos="0.0175462 -0.0584528 0.0142712" />
                            <site name="EIP-P6" pos="0.0179815 -0.0797196 0.00602146" />
                            <site name="EIP-P7" pos="0.0286564 -0.09653 -0.01566" />
                            <site name="EIP-P8" pos="0.0298379 -0.0978047 -0.0292575" />
                            <site name="EIP-P9" pos="0.0297446 -0.0883424 -0.0445132" />
                            <site name="EIP-P10" pos="0.0293715 -0.0806835 -0.0570122" />
                            <site name="EPL-P6" pos="0.0251637 0.000145096 0.00630129" />
                            <site name="EPL-P7" pos="0.0242309 -0.00950376 -0.000404195" />
                            <site name="EPL-P8" pos="0.0301073 -0.0147894 -0.00506798" />
                            <site name="EPL-P9" pos="0.0457465 -0.0354137 -0.0188002" />
                            <site name="EPL-P10" pos="0.0504414 -0.048151 -0.0257752" />
                            <site name="EPL-P11" pos="0.0492392 -0.0726514 -0.0391136" />
                            <site name="EPL-P12" pos="0.0415699 -0.0784034 -0.0443889" />
                            <site name="EPB-P5" pos="0.0323667 0.00265318 -0.00338902" />
                            <site name="EPB-P6" pos="0.0308017 -0.00822899 -0.0148827" />
                            <site name="EPB-P7" pos="0.0458295 -0.0342011 -0.0251015" />
                            <site name="EPB-P8" pos="0.046928 -0.0495916 -0.0330196" />
                            <site name="FPL-P6" pos="0.0128928 -0.0228733 -0.0216503" />
                            <site name="FPL-P7" pos="0.0170073 -0.027164 -0.0230184" />
                            <site name="FPL-P8" pos="0.0254643 -0.0341389 -0.0231842" />
                            <site name="FPL-P9" pos="0.0292989 -0.0568153 -0.0316619" />
                            <site name="FPL-P10" pos="0.0363879 -0.0675627 -0.0388545" />
                            <site name="FPL-P11" pos="0.0366159 -0.0793465 -0.0426788" />
                            <site name="FPL-P5" pos="0.0178892 0.0064176 -0.0168214" />
                            <site name="APL-P7" pos="0.0268116 0.00212461 -0.0171005" />
                            <site name="APL-P8" pos="0.0298275 -0.00698531 -0.0193806" />
                            <site name="APL-P9" pos="0.0318796 -0.0164062 -0.0195361" />
                            <site name="APL-P6" pos="0.0332244 0.00608975 -0.00870125" />
                            <body name="index0" pos="0 0 0">
                              <inertial pos="0 0 0" mass="0.001" diaginertia="0.001 0.001 0.001" />
                              <geom name="sdfast_1seg_hand_fr_c_2mc" type="mesh" mesh="sdfast_1seg_hand_fr_c_2mc" />
                              <body name="index1" pos="0 0 0">
                                <inertial pos="0 0 0" mass="0.001" diaginertia="0.001 0.001 0.001" />
                                <geom name="hand_2proxph" type="mesh" mesh="hand_2proxph" />
                                <body name="index2" pos="0 0 0">
                                  <inertial pos="0 0 0" mass="0.001" diaginertia="0.001 0.001 0.001" />
                                  <geom name="hand_2midph" type="mesh" mesh="hand_2midph" />
                                  <body name="index3" pos="0 0 0">
                                    <inertial pos="0 0 0" mass="0.001" diaginertia="0.001 0.001 0.001" />
                                    <geom name="hand_2distph" type="mesh" mesh="hand_2distph" />
                                    <site name="fingertip" pos="0.024 -0.149 -0.0065" type="sphere" rgba="0.1 0.8 0.1 0.0" size="0.004" />
                                  </body>
                                </body>
                              </body>
                            </body>
                          </body>
                        </body>
                      </body>
                    </body>
                  </body>
                </body>
              </body>
            </body>
          </body>
        </body>
      </body>
    </body>

</mujocoinclude>