<mujocoinclude model="MoBL Arms Index Model">

    <body name="thorax" pos="0 0 0" quat="0.7071067811865475 0.7071067811865475 0.0 0.0">
      <light mode="trackcom" directional="false" pos="0 0 4.0" dir="0 0 -1" />
      <geom name="thorax" type="mesh" mesh="thorax" />
      <site name="PECM1-P3" pos="  -7e-05  0.00821  0.10454" />
      <site name="PECM2-P4" pos="0.0280456 -0.0355855 0.0880565" />
      <site name="PECM2-P5" pos="0.025124 -0.0408117 0.0206055" />
      <site name="PECM2-P3" pos=" 0.02083 -0.02005  0.11555" />
      <site name="PECM3-P4" pos="0.0476349 -0.07637 0.08107" />
      <site name="PECM3-P5" pos="0.0519356 -0.10574 0.0343606" />
      <site name="PECM3-P3" pos=" 0.02984 -0.0544459   0.1151" />
      <site name="LAT1-P4" pos="-0.107319 -0.0918037 0.0300871" />
      <site name="LAT1-P5" pos="-0.0869042 -0.106375 0.00800266" />
      <site name="LAT2-P4" pos="-0.0997338 -0.153412 0.026113" />
      <site name="LAT2-P5" pos="-0.0652008 -0.170742 0.00739475" />
      <site name="LAT3-P4" pos="-0.101231 -0.175904 0.0501935" />
      <site name="LAT3-P5" pos="-0.0645747 -0.225544 0.00822949" />
      <joint name="r_z" type="hinge" pos="0 0 0" axis="       0        0        1" limited="true" range="-6.28319  6.28319" ref="0" armature="0" damping="0" stiffness="0" />
      <body name="clavicle" pos="0.00573887 0.0062878 0.0231052" quat="1.0 0.0 0.0 0.0">
        <geom name="clavicle" type="mesh" mesh="clavicle" />
        <inertial pos="-0.0100677 0.00578178 0.0491483" mass="0.141543624169146" fullinertia="0.000181205 0.000190669 3.31799e-05 -1.41773e-05 -5.22424e-05 4.01192e-05" />
        <site name="DELT1-P4" pos="-0.0127026 0.0100351 0.072777" />
        <site name="DELT2-P2" pos="0.0191703 0.0244002 0.162891" />
        <site name="PECM1-P4" pos="0.00291253 -0.000117953 0.0463918" />
        <joint name="sternoclavicular_r2" type="hinge" pos="0 0 0" axis="  0.0153 0.989299  -0.1451" limited="false" range="-99999.9  99999.9" ref="0" />
        <joint name="sternoclavicular_r3" type="hinge" pos="0 0 0" axis="-0.994473        0 -0.104997" limited="false" range="-99999.9  99999.9" ref="0" />
        <body name="clavphant" pos="-0.0130021 0.0182101 0.122975" quat="1.0 0.0 0.0 0.0">
          <inertial pos="       0        0        0" mass="9.07330924161195e-05" fullinertia=" 0.74696  0.74696  0.74696        0        0        0" />
          <joint name="unrotscap_r3" type="hinge" pos="0 0 0" axis="-0.994473        0 -0.104997" limited="false" range="-99999.9  99999.9" ref="0" />
          <joint name="unrotscap_r2" type="hinge" pos="0 0 0" axis="  0.0153 0.989299  -0.1451" limited="false" range="-99999.9  99999.9" ref="0" />
          <body name="scapula" pos="       0        0        0" quat="1.0 0.0 0.0 0.0">
            <geom name="scapula" type="mesh" mesh="scapula" />
            <inertial pos="-0.0496256 -0.0317856 -0.0396812" mass="0.638724677372514" fullinertia="0.000928396 0.000859302 0.00101967 0.000335684 0.000305671 0.000180092" />
            <site name="DELT1-P3" pos="0.0394417 -0.0295064 0.000898258" />
            <site name="DELT2-P3" pos="4.53665e-005 0.00266755 0.0202607" />
            <site name="DELT2-P4" pos="-0.00978103 -0.000308493 0.00562545" />
            <site name="DELT3-P1" pos="-0.0505656 0.00110694 -0.0227922" />
            <site name="DELT3-P2" pos="-0.0657543 -0.0298058 0.0111874" />
            <site name="SUPSP-P2" pos="-0.0174026 0.00115231 -0.0115322" />
            <site name="SUPSP-P3" pos="-0.0399226 -0.0137188 -0.0531242" />
            <site name="INFSP-P2" pos="-0.0669792 -0.0496854 -0.0433795" />
            <site name="SUBSC-P2" pos="-0.0166132 -0.0473899 -0.0222931" />
            <site name="SUBSC-P3" pos="-0.0657452 -0.0357761 -0.0587497" />
            <site name="TMIN-P2" pos="-0.0859515 -0.0725048 -0.0429803" />
            <site name="TMIN-P3" pos="-0.0874939 -0.0736843 -0.0480704" />
            <site name="TMAJ-P2" pos="-0.0931284 -0.0936275 -0.0528883" />
            <site name="TMAJ-P3" pos="-0.0951699 -0.0988537 -0.0645747" />
            <site name="LAT1-P2" pos="-0.08052 -0.06821 -0.02908" />
            <site name="LAT1-P3" pos="-0.10925 -0.07239 -0.07422" />
            <site name="LAT2-P2" pos="-0.08345 -0.08695 -0.02453" />
            <site name="LAT2-P3" pos="-0.11524 -0.10749 -0.08863" />
            <site name="LAT3-P2" pos="-0.08438 -0.11598 -0.02995" />
            <site name="LAT3-P3" pos="-0.11279 -0.13833 -0.08911" />
            <site name="CORB-P1" pos="0.0113416 -0.0374455 -0.0240624" />
            <site name="CORB-P2" pos="0.00438241 -0.0631321 -0.0141816" />
            <site name="TRIlong-P1" pos="-0.0414197 -0.0369556 -0.0124939" />
            <site name="BIClong-P1" pos="-0.0283359 -0.0213495 -0.0118407" />
            <site name="BIClong-P2" pos="-0.0189995 -0.011877 -0.0041828" />
            <site name="BICshort-P1" pos="0.011505 -0.0356672 -0.0238174" />
            <site name="BICshort-P2" pos="0.000843818 -0.0608275 -0.0144538" />
            <joint name="acromioclavicular_r2" type="hinge" pos="0 0 0" axis="0.157095 0.947269 -0.279291" limited="false" range="-99999.9  99999.9" ref="0" />
            <joint name="acromioclavicular_r3" type="hinge" pos="0 0 0" axis="-0.754084 0.297594 0.585487" limited="false" range="-99999.9  99999.9" ref="0" />
            <joint name="acromioclavicular_r1" type="hinge" pos="0 0 0" axis="  0.6377   0.1186   0.7611" limited="false" range="-99999.9  99999.9" ref="0" />
            <body name="scapphant" pos="-0.00866501 -0.0308493 0.00816598" quat="1.0 0.0 0.0 0.0">
              <inertial pos="       0        0        0" mass="9.07330924161195e-05" fullinertia=" 0.74696  0.74696  0.74696        0        0        0" />
              <joint name="unrothum_r1" type="hinge" pos="0 0 0" axis="  0.6377   0.1186   0.7611" limited="false" range="-99999.9  99999.9" ref="0" />
              <joint name="unrothum_r3" type="hinge" pos="0 0 0" axis="-0.754084 0.297594 0.585487" limited="false" range="-99999.9  99999.9" ref="0" />
              <joint name="unrothum_r2" type="hinge" pos="0 0 0" axis="0.157095 0.947269 -0.279291" limited="false" range="-99999.9  99999.9" ref="0" />
              <body name="humphant" pos="       0        0        0" quat="1.0 0.0 0.0 0.0">
                <inertial pos="       0        0        0" mass="9.07330924161195e-05" fullinertia=" 0.74696  0.74696  0.74696        0        0        0" />
                <joint name="elv_angle" type="hinge" pos="0 0 0" axis="  0.0048 0.999089   0.0424" limited="true" range=" -1.5708  2.26893" ref="0" user="1" />
                <body name="humphant1" pos="       0        0        0" quat="1.0 0.0 0.0 0.0">
                  <inertial pos="       0        0        0" mass="9.07330924161195e-05" fullinertia=" 0.74696  0.74696  0.74696        0        0        0" />
                  <joint name="shoulder_elv" type="hinge" pos="0 0 0" axis="-0.998261   0.0023 0.058898" limited="true" range="       0  3.14159" ref="0" user="1" />
                  <joint name="shoulder1_r2" type="hinge" pos="0 0 0" axis="  0.0048 0.999089   0.0424" limited="false" range="-99999.9  99999.9" ref="0" />
                  <body name="humerus" pos="       0        0        0" quat="1.0 0.0 0.0 0.0">
                    <geom name="humerus" type="mesh" mesh="humerus" />
                    <inertial pos=" 0.01639 -0.127154 -0.0115648" mass="1.81245703417668" fullinertia="0.00917089 0.00190574 0.00939592 -0.000259501 -0.000173668 0.000918237" />
                    <site name="DELT1-P1" pos="0.00812969 -0.107818 0.00530789" />
                    <site name="DELT1-P2" pos="0.014726 -0.100106 0.0037382" />
                    <site name="DELT2-P1" pos="0.0041828 -0.123497 0.00508105" />
                    <site name="DELT3-P3" pos="0.0018691 -0.0689753 0.00948161" />
                    <site name="SUPSP-P1" pos="0.00232277 0.00964493 0.0235271" />
                    <site name="INFSP-P1" pos="-0.00804803 0.00439148 0.0222115" />
                    <site name="SUBSC-P1" pos="0.0127299 0.00762158 -0.0120766" />
                    <site name="TMIN-P1" pos="-0.000998064 -0.0114687 0.0195621" />
                    <site name="TMAJ-P1" pos="0.00905516 -0.0491683 -0.00515364" />
                    <site name="PECM1-P1" pos="0.0106067 -0.0380262 0.00707718" />
                    <site name="PECM1-P2" pos="  0.0191  -0.0301  0.00143" />
                    <site name="PECM2-P1" pos="0.0115594 -0.0389154 0.00712255" />
                    <site name="PECM2-P2" pos=" 0.01748 -0.03533  0.00033" />
                    <site name="PECM3-P1" pos="0.011514 -0.0396957 0.00680498" />
                    <site name="PECM3-P2" pos="0.0159185 -0.045833 -0.00378312" />
                    <site name="LAT1-P1" pos="0.00952697 -0.0309854 -0.00592487" />
                    <site name="LAT2-P1" pos="0.00878296 -0.0369374 -0.00554379" />
                    <site name="LAT3-P1" pos="0.0109606 -0.0355855 -0.0037745" />
                    <site name="CORB-P3" pos="0.00674147 -0.136535 -0.00709533" />
                    <site name="TRIlong-P2" pos="-0.024625 -0.103808 -0.00602468" />
                    <site name="TRIlong-P3" pos="-0.0288894 -0.205393 -0.0110422" />
                    <site name="TRIlong-P4" pos="-0.0158148 -0.242775 -0.0109606" />
                    <site name="TRIlat-P1" pos="-0.00543491 -0.114741 0.00388338" />
                    <site name="TRIlat-P2" pos="-0.0212678 -0.131817 0.00842003" />
                    <site name="TRIlat-P3" pos="-0.0288894 -0.205393 -0.0110422" />
                    <site name="TRIlat-P4" pos="-0.0158148 -0.242775 -0.0109606" />
                    <site name="TRImed-P1" pos="-0.00760343 -0.124259 -0.00822042" />
                    <site name="TRImed-P2" pos="-0.0235997 -0.137361 -0.00979917" />
                    <site name="TRImed-P3" pos="-0.0288894 -0.205393 -0.0110422" />
                    <site name="TRImed-P4" pos="-0.0158148 -0.242775 -0.0109606" />
                    <site name="ANC-P1" pos="-0.00675054 -0.25731 0.00888277" />
                    <site name="BIClong-P3" pos="0.0193352 0.0162684 0.00932736" />
                    <site name="BIClong-P4" pos="0.0215763 -0.00463646 0.010897" />
                    <site name="BIClong-P5" pos="0.0122036 -0.0256502 0.00123397" />
                    <site name="BIClong-P6" pos="0.00969029 -0.0701911 -0.0014971" />
                    <site name="BIClong-P7" pos="0.0154518 -0.110014 0.000217759" />
                    <site name="BIClong-P8" pos="0.0206871 -0.159146 -0.00571618" />
                    <site name="BICshort-P3" pos="0.0101349 -0.0687394 -0.00998971" />
                    <site name="BICshort-P4" pos="0.0154518 -0.110014 -0.0097901" />
                    <site name="BICshort-P5" pos="0.0206871 -0.159146 -0.00571618" />
                    <site name="BRA-P1" pos="0.00616985 -0.157785 -0.00326639" />
                    <site name="BRA-P2" pos="0.0171848 -0.259125 -0.010026" />
                    <site name="BRD-P1" pos="-0.00889184 -0.18113 0.00202335" />
                    <site name="ECRL-P1" pos="-0.00662352 -0.236723 0.00825671" />
                    <site name="ECRB-P1" pos="0.0122399 -0.263561 0.0154065" />
                    <site name="ECU-P1" pos="0.000753085 -0.262718 0.0170578" />
                    <site name="FCR-P1" pos="0.00687757 -0.252292 -0.0336166" />
                    <site name="FCU-P1" pos="0.00198705 -0.251694 -0.0352044" />
                    <site name="PL-P1" pos="0.0041465 -0.249688 -0.0350683" />
                    <site name="PT-P1" pos="0.00326639 -0.250333 -0.0331176" />
                    <site name="FDSL-P1" pos="0.00381986 -0.250405 -0.0350593" />
                    <site name="FDSR-P1" pos="0.00434612 -0.252964 -0.0338525" />
                    <site name="EDCL-P1" pos="-0.000362932 -0.261593 0.0169671" />
                    <site name="EDCR-P1" pos="-0.00141544 -0.262545 0.0161686" />
                    <site name="EDCM-P1" pos="0.000462739 -0.262981 0.0176839" />
                    <site name="EDCI-P1" pos="0.000589765 -0.2622 0.016958" />
                    <site name="EDM-P1" pos="0.000807525 -0.262391 0.0167584" />
                    <joint name="shoulder_rot" type="hinge" pos="0 0 0" axis="  0.0048 0.999089   0.0424" limited="true" range=" -1.5708 0.349066" ref="0" user="1" />
                    <body name="ulna" pos="0.00553472 -0.263489 -0.0111602" quat="1.0 0.0 0.0 0.0">
                      <geom name="ulna" type="mesh" mesh="ulna" />
                      <inertial pos="0.00881729 -0.0870592 0.0220354" mass="1.00287287047537" fullinertia="0.00404336 0.000861379 0.00369268 0.000236682 -5.6881e-05 0.000815448" />
                      <site name="TRIlong-P5" pos="-0.0198705 0.00949068 -0.000707718" />
                      <site name="TRIlat-P5" pos="-0.0198705 0.00949068 -0.000707718" />
                      <site name="TRImed-P5" pos="-0.0198705 0.00949068 -0.000707718" />
                      <site name="ANC-P2" pos="-0.0229736 -0.00112509 0.00544399" />
                      <site name="SUP-P3" pos="-0.0123397 -0.0307041 0.0182646" />
                      <site name="BRA-P4" pos="-0.00290346 -0.0216852 0.000816598" />
                      <site name="BRA-P3" pos="0.00451851 -0.0132743 0.00116138" />
                      <site name="ECU-P2" pos="-0.012621 -0.0290437 0.026739" />
                      <site name="ECU-P3" pos="-0.01547 -0.0492499 0.0260223" />
                      <site name="ECU-P4" pos="-0.0162684 -0.0868588 0.0297423" />
                      <site name="PT-P2" pos="0.00767602 -0.0306043 -0.012993" />
                      <site name="PT-P3" pos=" 0.01219 -0.06516 -0.00219" />
                      <site name="PQ-P2" pos="0.00175115 -0.190285 0.0329543" />
                      <site name="FDSM-P1" pos="-0.00607004 -0.0246159 -0.001733" />
                      <site name="FDSI-P1" pos="-0.00613356 -0.0255777 -0.00124304" />
                      <site name="FDPL-P1" pos="-0.00569804 -0.0291616 0.00230462" />
                      <site name="FDPR-P1" pos="-0.0045548 -0.0306133 0.00247701" />
                      <site name="FDPM-P1" pos="-0.00473627 -0.0301869 0.00190539" />
                      <site name="FDPI-P1" pos="-0.00587043 -0.0288168 0.00254053" />
                      <site name="EDM-P2" pos="-0.00886462 -0.0354494 0.0279912" />
                      <site name="EDM-P3" pos="-0.00685035 -0.075009 0.0330813" />
                      <site name="EIP-P1" pos="-0.00357488 -0.151089 0.0334079" />
                      <site name="EIP-P2" pos="0.00155154 -0.158502 0.0367378" />
                      <site name="EPL-P1" pos="-0.0128115 -0.0880655 0.0267844" />
                      <joint name="elbow_flexion" type="hinge" pos="0 0 0" axis="  0.0494   0.0366 0.998108" limited="true" range="       0  4.26893" ref="0" user="1" />
                      <body name="radius" pos="0.000362932 -0.010437 0.0181457" quat="1.0 0.0 0.0 0.0">
                        <geom name="radius" type="mesh" mesh="radius" />
                        <inertial pos="0.0305173 -0.164734 0.0141544" mass="0.211943430574813" fullinertia="0.000327579 6.61732e-05 0.000300711 2.25134e-05 -3.16711e-06 4.79399e-05" />
                        <site name="SUP-P1" pos="0.00903702 -0.0553109 0.000680498" />
                        <site name="SUP-P2" pos="0.010897 -0.046909 -0.000970844" />
                        <site name="BIClong-P11" pos="-0.00181466 -0.0340249 -0.00181466" />
                        <site name="BIClong-P9" pos=" 0.00273 -0.0343493 -0.0119845" />
                        <site name="BICshort-P8" pos="-0.00181466 -0.0340249 -0.00181466" />
                        <site name="BICshort-P6" pos=" 0.00273 -0.0343493 -0.0119845" />
                        <site name="BRD-P2" pos="0.0324552 -0.115612 0.0210047" />
                        <site name="BRD-P3" pos="0.0380172 -0.20052 0.0203242" />
                        <site name="ECRL-P2" pos="0.0289892 -0.122154 0.0252147" />
                        <site name="ECRL-P3" pos="0.0384981 -0.214892 0.0328454" />
                        <site name="ECRB-P2" pos="0.026358 -0.118733 0.0216398" />
                        <site name="ECRB-P3" pos="0.0322012 -0.206917 0.0357216" />
                        <site name="ECU-P5" pos="-0.0128932 -0.205928 0.0315842" />
                        <site name="FCR-P2" pos="0.0191447 -0.199096 0.00115231" />
                        <site name="FCU-P3" pos="0.00981732 -0.20258 0.00879204" />
                        <site name="FCU-P2" pos="0.0101156 -0.183524 0.00202653" />
                        <site name="PL-P2" pos="0.0229645 -0.216988 -0.00250423" />
                        <site name="PT-P5" pos="0.0230462 -0.0987176 0.0179652" />
                        <site name="PT-P4" pos="0.021413 -0.0847447 0.00852891" />
                        <site name="PQ-P1" pos="0.0294429 -0.181448 0.0178018" />
                        <site name="FDSL-P2" pos="0.0124939 -0.169834 0.00186003" />
                        <site name="FDSR-P2" pos="0.0142542 -0.169362 0.00242257" />
                        <site name="FDSM-P2" pos="0.0172302 -0.169725 0.00384708" />
                        <site name="FDSI-P2" pos="0.0194622 -0.168972 0.00500847" />
                        <site name="FDPL-P2" pos="0.0127843 -0.168001 0.00781212" />
                        <site name="FDPR-P2" pos="0.0143358 -0.169027 0.00728587" />
                        <site name="FDPM-P2" pos="0.0172937 -0.169163 0.00712255" />
                        <site name="FDPI-P2" pos="0.0188725 -0.168401 0.00830208" />
                        <site name="EDCL-P3" pos="0.0090098 -0.202371 0.0328272" />
                        <site name="EDCL-P2" pos="  0.0013 -0.0382544 0.0129514" />
                        <site name="EDCR-P3" pos="0.00800266 -0.202934 0.0388701" />
                        <site name="EDCR-P2" pos="  0.0026 -0.0392844 0.0144214" />
                        <site name="EDCM-P3" pos="0.0130656 -0.202543 0.0383166" />
                        <site name="EDCM-P2" pos=" 0.00316 -0.0388544 0.0141814" />
                        <site name="EDCI-P3" pos="0.0139094 -0.202462 0.0380716" />
                        <site name="EDCI-P2" pos=" 0.00228 -0.0385544 0.0137314" />
                        <site name="EDM-P4" pos="0.00411928 -0.205429 0.0333716" />
                        <site name="EIP-P3" pos="0.00976288 -0.206717 0.0332446" />
                        <site name="EPL-P2" pos="0.00112509 -0.124014 0.0205964" />
                        <site name="EPL-P3" pos="0.0245161 -0.198451 0.0347326" />
                        <site name="EPL-P4" pos="0.0306859 -0.206454 0.0418007" />
                        <site name="EPL-P5" pos="0.0384164 -0.215682 0.0378629" />
                        <site name="EPB-P1" pos="0.017457 -0.133332 0.019181" />
                        <site name="EPB-P2" pos="0.0206509 -0.143875 0.0241804" />
                        <site name="EPB-P3" pos="0.0347598 -0.178944 0.0347871" />
                        <site name="EPB-P4" pos="0.0474988 -0.21423 0.0244889" />
                        <site name="FPL-P1" pos="0.00881018 -0.0858154 0.0160507" />
                        <site name="FPL-P2" pos="0.0150435 -0.122717 0.0173754" />
                        <site name="FPL-P3" pos="0.016958 -0.162703 0.0180377" />
                        <site name="FPL-P4" pos="0.0344786 -0.210238 0.0143358" />
                        <site name="APL-P1" pos="0.0104706 -0.0859878 0.0152522" />
                        <site name="APL-P2" pos="0.0274921 -0.126754 0.0318201" />
                        <site name="APL-P3" pos="0.0362297 -0.145826 0.0308493" />
                        <site name="APL-P4" pos="0.0398953 -0.161913 0.0284358" />
                        <site name="APL-P5" pos="0.0499486 -0.209448 0.0214856" />
                        <joint name="pro_sup" type="hinge" pos="0 0 0" axis="-0.017161 0.992666 -0.119668" limited="true" range=" -1.5708   1.5708" ref="0" user="1" />
                        <body name="proximal_row" pos="0.016332 -0.219574 0.0226833" quat="1.0 0.0 0.0 0.0">
                          <geom name="lunate" type="mesh" mesh="lunate" />
                          <geom name="sdfastSCAPHOIDw" type="mesh" mesh="sdfastSCAPHOIDw" />
                          <geom name="sdfastPISIFORMw" type="mesh" mesh="sdfastPISIFORMw" />
                          <geom name="sdfastTRIQUETRALw" type="mesh" mesh="sdfastTRIQUETRALw" />
                          <inertial pos="       0        0        0" mass="9.07330924161195e-05" fullinertia="7.4696e-06 7.4696e-06 7.4696e-06        0        0        0" />
                          <body name="hand" pos="0.00362207 -0.013659 0.00211136" quat="1.0 0.0 0.0 0.0">
                            <geom name="sdfast_1seg_hand_fr_c_5mc" type="mesh" mesh="sdfast_1seg_hand_fr_c_5mc" />
                            <geom name="sdfast_1seg_hand_fr_c_4mc" type="mesh" mesh="sdfast_1seg_hand_fr_c_4mc" />
                            <geom name="sdfast_1seg_hand_fr_c_3mc" type="mesh" mesh="sdfast_1seg_hand_fr_c_3mc" />
                            <geom name="sdfast_1seg_hand_fr_c_trapezium" type="mesh" mesh="sdfast_1seg_hand_fr_c_trapezium" />
                            <geom name="sdfast_1seg_hand_fr_c_trapezoid" type="mesh" mesh="sdfast_1seg_hand_fr_c_trapezoid" />
                            <geom name="sdfast_1seg_hand_fr_c_hamate" type="mesh" mesh="sdfast_1seg_hand_fr_c_hamate" />
                            <geom name="capitate" type="mesh" mesh="capitate" />
                            <geom name="hand_3proxph" type="mesh" mesh="hand_3proxph" />
                            <geom name="hand_3midph" type="mesh" mesh="hand_3midph" />
                            <geom name="hand_3distph" type="mesh" mesh="hand_3distph" />
                            <geom name="hand_4proxph" type="mesh" mesh="hand_4proxph" />
                            <geom name="hand_4midph" type="mesh" mesh="hand_4midph" />
                            <geom name="hand_4distph" type="mesh" mesh="hand_4distph" />
                            <geom name="hand_5proxph" type="mesh" mesh="hand_5proxph" />
                            <geom name="hand_5midph" type="mesh" mesh="hand_5midph" />
                            <geom name="hand_5distph" type="mesh" mesh="hand_5distph" />
                            <geom name="hand_thumbprox" type="mesh" mesh="hand_thumbprox" />
                            <geom name="hand_thumbdist" type="mesh" mesh="hand_thumbdist" />
                            <geom name="hand_1mc" type="mesh" mesh="hand_1mc" />
                            <inertial pos="-0.00273392 -0.0385609 -0.00101807" mass="0.527975864769399" fullinertia="8.21656e-05 4.48176e-05 0.000112044 6.72264e-07 -1.49392e-07 8.96352e-06" />
                            <site name="ECRL-P4" pos="0.0155789 -0.0192536 0.00528974" />
                            <site name="ECRB-P4" pos="0.00453665 -0.0103073 0.00771231" />
                            <site name="ECU-P6" pos="-0.020424 -0.0127117 -0.00116138" />
                            <site name="FCR-P3" pos="0.0101984 -0.0167312 -0.00379264" />
                            <site name="FCU-P4" pos="-0.0184733 -0.0160144 -0.00682313" />
                            <site name="PL-P3" pos="0.00832022 -0.0172211 -0.0159146" />
                            <site name="PL-P4" pos="0.00205964 -0.028091 0.00447314" />
                            <site name="FDSL-P3" pos="-0.00213223 -0.0126391 -0.0124849" />
                            <site name="FDSL-P4" pos="-0.0181013 -0.0388428 -0.0067324" />
                            <site name="FDSL-P5" pos="-0.0185458 -0.0542675 -0.0170397" />
                            <site name="FDSL-P6" pos="-0.0155426 -0.0657361 -0.0249788" />
                            <site name="FDSL-P7" pos="-0.0104887 -0.065972 -0.033172" />
                            <site name="FDSL-P8" pos="-0.00960863 -0.065972 -0.0344423" />
                            <site name="FDSR-P3" pos="-0.000744011 -0.0121945 -0.0123306" />
                            <site name="FDSR-P4" pos="-0.00886462 -0.0469907 3.62932e-005" />
                            <site name="FDSR-P5" pos="-0.012004 -0.060519 -0.00925478" />
                            <site name="FDSR-P6" pos="-0.00714977 -0.0728315 -0.0227105" />
                            <site name="FDSR-P7" pos="-0.00271292 -0.0737206 -0.0308039" />
                            <site name="FDSR-P8" pos="0.000562545 -0.0734212 -0.0353133" />
                            <site name="FDSM-P3" pos="0.00616985 -0.0124939 -0.0126936" />
                            <site name="FDSM-P4" pos="0.00427353 -0.0302323 -0.00119768" />
                            <site name="FDSM-P5" pos="0.00491773 -0.0513549 0.000544399" />
                            <site name="FDSM-P6" pos="0.00503569 -0.0655456 -0.00306678" />
                            <site name="FDSM-P7" pos="0.0105886 -0.0799359 -0.0151524" />
                            <site name="FDSM-P8" pos="0.0118044 -0.0804803 -0.0270112" />
                            <site name="FDSM-P9" pos="0.0142269 -0.0778218 -0.034161" />
                            <site name="FDSI-P3" pos="0.00806617 -0.0123941 -0.0125847" />
                            <site name="FDSI-P4" pos="0.00962678 -0.0343606 0.000217759" />
                            <site name="FDSI-P5" pos="0.0161686 -0.0463465 0.00379264" />
                            <site name="FDSI-P6" pos="0.0167765 -0.0662079 -0.00340249" />
                            <site name="FDSI-P7" pos="0.0242983 -0.0790648 -0.0163682" />
                            <site name="FDSI-P8" pos="0.0241985 -0.0793007 -0.0242983" />
                            <site name="FDSI-P9" pos="0.024135 -0.0783299 -0.0263398" />
                            <site name="FDPL-P3" pos="-0.000798451 -0.00931829 -0.0107791" />
                            <site name="FDPL-P4" pos="-0.016831 -0.0421546 -0.00665074" />
                            <site name="FDPL-P5" pos="-0.0164045 -0.0529972 -0.0141544" />
                            <site name="FDPL-P6" pos="-0.0129567 -0.0661354 -0.0243437" />
                            <site name="FDPL-P7" pos="-0.00834744 -0.0678956 -0.0334261" />
                            <site name="FDPL-P8" pos="-0.00283087 -0.0671879 -0.0377903" />
                            <site name="FDPL-P9" pos="0.0040467 -0.0640485 -0.0422544" />
                            <site name="FDPR-P3" pos="0.000961771 -0.0106793 -0.0107428" />
                            <site name="FDPR-P4" pos="-0.00775768 -0.0502843 0.000798451" />
                            <site name="FDPR-P5" pos="-0.0097901 -0.059775 -0.00741289" />
                            <site name="FDPR-P6" pos="-0.0049631 -0.0739838 -0.0204694" />
                            <site name="FDPR-P7" pos="-0.000508105 -0.0746733 -0.0305498" />
                            <site name="FDPR-P8" pos="0.00552565 -0.0711075 -0.0384527" />
                            <site name="FDPR-P9" pos="0.0109878 -0.066961 -0.0440781" />
                            <site name="FDPM-P3" pos="0.00303956 -0.0116138 -0.0103799" />
                            <site name="FDPM-P4" pos="0.00274014 -0.0312757 -0.00554379" />
                            <site name="FDPM-P5" pos="0.00228647 -0.0531968 0.00110694" />
                            <site name="FDPM-P6" pos="0.00258589 -0.0633771 -0.00120675" />
                            <site name="FDPM-P7" pos="0.00783027 -0.0796546 -0.0164681" />
                            <site name="FDPM-P8" pos="0.00909146 -0.0795366 -0.0268933" />
                            <site name="FDPM-P9" pos="0.0148167 -0.074011 -0.0402401" />
                            <site name="FDPM-P10" pos="0.0173209 -0.0695288 -0.0474443" />
                            <site name="FDPI-P3" pos="0.00812969 -0.0105976 -0.0109969" />
                            <site name="FDPI-P4" pos="0.0174389 -0.0502843 0.00397411" />
                            <site name="FDPI-P5" pos="0.018809 -0.0637037 -0.00259497" />
                            <site name="FDPI-P6" pos="0.0263489 -0.0779216 -0.0161686" />
                            <site name="FDPI-P7" pos="0.0265304 -0.0786837 -0.025124" />
                            <site name="FDPI-P8" pos="0.0264396 -0.0747187 -0.0361027" />
                            <site name="FDPI-P9" pos="0.0258317 -0.0705087 -0.0432434" />
                            <site name="EDCL-P4" pos="-0.0223566 -0.0399407 0.00153339" />
                            <site name="EDCL-P5" pos="-0.0216035 -0.042953 0.000698645" />
                            <site name="EDCL-P6" pos="-0.0217306 -0.0600018 -0.00908238" />
                            <site name="EDCL-P7" pos="-0.0163138 -0.0711983 -0.0245977" />
                            <site name="EDCL-P8" pos="-0.0106884 -0.0714705 -0.034288" />
                            <site name="EDCL-P9" pos="-0.001361 -0.0688301 -0.0416102" />
                            <site name="EDCL-P10" pos="0.00182374 -0.0679319 -0.0434974" />
                            <site name="EDCR-P4" pos="-0.0141907 -0.0503569 0.00847447" />
                            <site name="EDCR-P5" pos="-0.0129476 -0.0527976 0.0105341" />
                            <site name="EDCR-P6" pos="-0.0143358 -0.065473 -0.00381986" />
                            <site name="EDCR-P7" pos="-0.00748548 -0.0792554 -0.0205057" />
                            <site name="EDCR-P8" pos="-0.00246794 -0.0798996 -0.0309309" />
                            <site name="EDCR-P9" pos="0.00692293 -0.0728224 -0.0422635" />
                            <site name="EDCR-P10" pos="0.00969937 -0.0708535 -0.0448312" />
                            <site name="EDCM-P4" pos="0.000353859 -0.0478526 0.0135283" />
                            <site name="EDCM-P5" pos="-0.000789378 -0.0505746 0.0131744" />
                            <site name="EDCM-P6" pos="0.00168764 -0.0700278 0.00541677" />
                            <site name="EDCM-P7" pos="0.00913682 -0.0844997 -0.0160961" />
                            <site name="EDCM-P8" pos="0.0119858 -0.0867227 -0.027728" />
                            <site name="EDCM-P9" pos="0.0168491 -0.07735 -0.0431799" />
                            <site name="EDCM-P10" pos="0.0186547 -0.072523 -0.0484605" />
                            <site name="EDCM-P11" pos="0.0199159 -0.0698736 -0.0513822" />
                            <site name="EDCI-P4" pos="0.0140001 -0.0424631 0.0148712" />
                            <site name="EDCI-P5" pos="0.0172121 -0.0513005 0.0130474" />
                            <site name="EDCI-P6" pos="0.0180922 -0.0696649 0.00538955" />
                            <site name="EDCI-P7" pos="0.0267209 -0.0831297 -0.0112963" />
                            <site name="EDCI-P8" pos="0.0283178 -0.0848264 -0.026358" />
                            <site name="EDCI-P9" pos="0.0273379 -0.0770052 -0.0387249" />
                            <site name="EDCI-P10" pos="0.0265757 -0.073521 -0.0450581" />
                            <site name="EDM-P5" pos="-0.0186819 -0.00936366 0.00337527" />
                            <site name="EDM-P6" pos="-0.0232549 -0.0428442 0.000208686" />
                            <site name="EDM-P7" pos="-0.0231279 -0.0590763 -0.00996249" />
                            <site name="EDM-P8" pos="-0.0175387 -0.0708625 -0.0246613" />
                            <site name="EDM-P9" pos="-0.0122127 -0.0716066 -0.0353315" />
                            <site name="EDM-P10" pos="-0.00195983 -0.0682404 -0.0416374" />
                            <site name="EDM-P11" pos="0.00119768 -0.0666435 -0.0435791" />
                            <site name="EIP-P4" pos="0.00352044 -0.0202698 0.0107428" />
                            <site name="EIP-P5" pos="0.0153611 -0.0511735 0.0124939" />
                            <site name="EIP-P6" pos="0.0157422 -0.0697919 0.00527159" />
                            <site name="EIP-P7" pos="0.0250877 -0.0845088 -0.0137098" />
                            <site name="EIP-P8" pos="0.0261221 -0.0856248 -0.025614" />
                            <site name="EIP-P9" pos="0.0260404 -0.0773409 -0.0389699" />
                            <site name="EIP-P10" pos="0.0257138 -0.0706357 -0.0499123" />
                            <site name="EPL-P6" pos="0.02203 0.000127026 0.00551657" />
                            <site name="EPL-P7" pos="0.0212134 -0.00832022 -0.000353859" />
                            <site name="EPL-P8" pos="0.026358 -0.0129476 -0.00443685" />
                            <site name="EPL-P9" pos="0.0400496 -0.0310035 -0.016459" />
                            <site name="EPL-P10" pos="0.0441598 -0.0421546 -0.0225653" />
                            <site name="EPL-P11" pos="0.0431073 -0.0636039 -0.0342427" />
                            <site name="EPL-P12" pos="0.036393 -0.0686396 -0.038861" />
                            <site name="EPB-P5" pos="0.0283359 0.00232277 -0.00296697" />
                            <site name="EPB-P6" pos="0.0269659 -0.00720421 -0.0130293" />
                            <site name="EPB-P7" pos="0.0401222 -0.0299419 -0.0219756" />
                            <site name="EPB-P8" pos="0.0410839 -0.0434158 -0.0289076" />
                            <site name="FPL-P6" pos="0.0112872 -0.0200248 -0.0189541" />
                            <site name="FPL-P7" pos="0.0148893 -0.0237811 -0.0201518" />
                            <site name="FPL-P8" pos="0.0222931 -0.0298875 -0.020297" />
                            <site name="FPL-P9" pos="0.0256502 -0.0497399 -0.027719" />
                            <site name="FPL-P10" pos="0.0318564 -0.0591489 -0.0340158" />
                            <site name="FPL-P11" pos="0.032056 -0.0694653 -0.0373639" />
                            <site name="FPL-P5" pos="0.0178892 0.0064176 -0.0168214" />
                            <site name="APL-P7" pos="0.0234727 0.00186003 -0.014971" />
                            <site name="APL-P8" pos="0.026113 -0.00611541 -0.0169671" />
                            <site name="APL-P9" pos="0.0279095 -0.014363 -0.0171032" />
                            <site name="APL-P6" pos="0.0332244 0.00608975 -0.00870125" />
                            <body name="index0" pos="0 0 0">
                              <inertial pos="0 0 0" mass="0.001" diaginertia="0.001 0.001 0.001" />
                              <geom name="sdfast_1seg_hand_fr_c_2mc" type="mesh" mesh="sdfast_1seg_hand_fr_c_2mc" />
                              <body name="index1" pos="0 0 0">
                                <inertial pos="0 0 0" mass="0.001" diaginertia="0.001 0.001 0.001" />
                                <geom name="hand_2proxph" type="mesh" mesh="hand_2proxph" />
                                <body name="index2" pos="0 0 0">
                                  <inertial pos="0 0 0" mass="0.001" diaginertia="0.001 0.001 0.001" />
                                  <geom name="hand_2midph" type="mesh" mesh="hand_2midph" />
                                  <body name="index3" pos="0 0 0">
                                    <inertial pos="0 0 0" mass="0.001" diaginertia="0.001 0.001 0.001" />
                                    <geom name="hand_2distph" type="mesh" mesh="hand_2distph" />
                                    <site name="fingertip" pos="0.024 -0.149 -0.0065" type="sphere" rgba="0.1 0.8 0.1 0.0" size="0.004" />
                                  </body>
                                </body>
                              </body>
                            </body>
                          </body>
                        </body>
                      </body>
                    </body>
                  </body>
                </body>
              </body>
            </body>
          </body>
        </body>
      </body>
    </body>

</mujocoinclude>