<mujocoinclude model="MoBL Arms Index Model">

    <body name="thorax" pos="0 0 0" quat="0.7071067811865475 0.7071067811865475 0.0 0.0">
      <light mode="trackcom" directional="false" pos="0 0 4.0" dir="0 0 -1" />
      <geom name="thorax" type="mesh" mesh="thorax" />
      <site name="PECM1-P3" pos="  -7e-05  0.00821  0.10454" />
      <site name="PECM2-P4" pos="0.0328329 -0.0416599 0.103087" />
      <site name="PECM2-P5" pos="0.0294126 -0.0477782 0.0241228" />
      <site name="PECM2-P3" pos=" 0.02083 -0.02005  0.11555" />
      <site name="PECM3-P4" pos="0.055766 -0.0894062 0.0949084" />
      <site name="PECM3-P5" pos="0.0608009 -0.12379 0.0402259" />
      <site name="PECM3-P3" pos=" 0.02984 -0.0544459   0.1151" />
      <site name="LAT1-P4" pos="-0.125638 -0.107474 0.0352229" />
      <site name="LAT1-P5" pos="-0.101738 -0.124533 0.00936869" />
      <site name="LAT2-P4" pos="-0.116758 -0.179598 0.0305704" />
      <site name="LAT2-P5" pos="-0.0763304 -0.199887 0.00865701" />
      <site name="LAT3-P4" pos="-0.118511 -0.205931 0.0587614" />
      <site name="LAT3-P5" pos="-0.0755975 -0.264044 0.00963424" />
      <joint name="r_z" type="hinge" pos="0 0 0" axis="       0        0        1" limited="true" range="-6.28319  6.28319" ref="0" armature="0" damping="0" stiffness="0" />
      <body name="clavicle" pos="0.00671848 0.00736111 0.0270492" quat="1.0 0.0 0.0 0.0">
        <geom name="clavicle" type="mesh" mesh="clavicle" />
        <inertial pos="-0.0117863 0.00676872 0.0575378" mass="0.165704698002436" fullinertia="0.000290739 0.000305924 5.32365e-05 -2.27471e-05 -8.38217e-05 6.43703e-05" />
        <site name="DELT1-P4" pos="-0.0148709 0.011748 0.0851998" />
        <site name="DELT2-P2" pos="0.0191703 0.0244002 0.162891" />
        <site name="PECM1-P4" pos="0.00340969 -0.000138087 0.0543108" />
        <joint name="sternoclavicular_r2" type="hinge" pos="0 0 0" axis="  0.0153 0.989299  -0.1451" limited="false" range="-99999.9  99999.9" ref="0" />
        <joint name="sternoclavicular_r3" type="hinge" pos="0 0 0" axis="-0.994473        0 -0.104997" limited="false" range="-99999.9  99999.9" ref="0" />
        <body name="clavphant" pos="-0.0152215 0.0213185 0.143967" quat="1.0 0.0 0.0 0.0">
          <inertial pos="       0        0        0" mass="0.000106220960257972" fullinertia=" 1.19848  1.19848  1.19848        0        0        0" />
          <joint name="unrotscap_r3" type="hinge" pos="0 0 0" axis="-0.994473        0 -0.104997" limited="false" range="-99999.9  99999.9" ref="0" />
          <joint name="unrotscap_r2" type="hinge" pos="0 0 0" axis="  0.0153 0.989299  -0.1451" limited="false" range="-99999.9  99999.9" ref="0" />
          <body name="scapula" pos="       0        0        0" quat="1.0 0.0 0.0 0.0">
            <geom name="scapula" type="mesh" mesh="scapula" />
            <inertial pos="-0.0580965 -0.0372113 -0.0464547" mass="0.747753071832017" fullinertia="0.00148959 0.00137873 0.00163604 0.000538597 0.000490442 0.000288953" />
            <site name="DELT1-P3" pos="0.0461743 -0.0345431 0.00105159" />
            <site name="DELT2-P3" pos="5.31105e-005 0.0031229 0.0237191" />
            <site name="DELT2-P4" pos="-0.0114506 -0.000361151 0.0065857" />
            <site name="DELT3-P1" pos="-0.0591969 0.0012959 -0.0266827" />
            <site name="DELT3-P2" pos="-0.0769783 -0.0348936 0.013097" />
            <site name="SUPSP-P2" pos="-0.0203732 0.00134901 -0.0135007" />
            <site name="SUPSP-P3" pos="-0.0467372 -0.0160606 -0.0621924" />
            <site name="INFSP-P2" pos="-0.0784123 -0.0581666 -0.0507842" />
            <site name="SUBSC-P2" pos="-0.0194491 -0.0554792 -0.0260985" />
            <site name="SUBSC-P3" pos="-0.0769677 -0.0418829 -0.0687781" />
            <site name="TMIN-P2" pos="-0.100623 -0.0848812 -0.0503169" />
            <site name="TMIN-P3" pos="-0.102429 -0.086262 -0.0562759" />
            <site name="TMAJ-P2" pos="-0.109025 -0.109609 -0.0619162" />
            <site name="TMAJ-P3" pos="-0.111415 -0.115728 -0.0755975" />
            <site name="LAT1-P2" pos="-0.08052 -0.06821 -0.02908" />
            <site name="LAT1-P3" pos="-0.10925 -0.07239 -0.07422" />
            <site name="LAT2-P2" pos="-0.08345 -0.08695 -0.02453" />
            <site name="LAT2-P3" pos="-0.11524 -0.10749 -0.08863" />
            <site name="LAT3-P2" pos="-0.08438 -0.11598 -0.02995" />
            <site name="LAT3-P3" pos="-0.11279 -0.13833 -0.08911" />
            <site name="CORB-P1" pos="0.0132776 -0.0438374 -0.0281698" />
            <site name="CORB-P2" pos="0.00513047 -0.0739085 -0.0166023" />
            <site name="TRIlong-P1" pos="-0.0484899 -0.0432638 -0.0146266" />
            <site name="BIClong-P1" pos="-0.0331728 -0.0249938 -0.0138618" />
            <site name="BIClong-P2" pos="-0.0222427 -0.0139043 -0.00489679" />
            <site name="BICshort-P1" pos="0.0134688 -0.0417555 -0.027883" />
            <site name="BICshort-P2" pos="0.000987855 -0.0712105 -0.016921" />
            <joint name="acromioclavicular_r2" type="hinge" pos="0 0 0" axis="0.157095 0.947269 -0.279291" limited="false" range="-99999.9  99999.9" ref="0" />
            <joint name="acromioclavicular_r3" type="hinge" pos="0 0 0" axis="-0.754084 0.297594 0.585487" limited="false" range="-99999.9  99999.9" ref="0" />
            <joint name="acromioclavicular_r1" type="hinge" pos="0 0 0" axis="  0.6377   0.1186   0.7611" limited="false" range="-99999.9  99999.9" ref="0" />
            <body name="scapphant" pos="-0.0101441 -0.0361151 0.00955989" quat="1.0 0.0 0.0 0.0">
              <inertial pos="       0        0        0" mass="0.000106220960257972" fullinertia=" 1.19848  1.19848  1.19848        0        0        0" />
              <joint name="unrothum_r1" type="hinge" pos="0 0 0" axis="  0.6377   0.1186   0.7611" limited="false" range="-99999.9  99999.9" ref="0" />
              <joint name="unrothum_r3" type="hinge" pos="0 0 0" axis="-0.754084 0.297594 0.585487" limited="false" range="-99999.9  99999.9" ref="0" />
              <joint name="unrothum_r2" type="hinge" pos="0 0 0" axis="0.157095 0.947269 -0.279291" limited="false" range="-99999.9  99999.9" ref="0" />
              <body name="humphant" pos="       0        0        0" quat="1.0 0.0 0.0 0.0">
                <inertial pos="       0        0        0" mass="0.000106220960257972" fullinertia=" 1.19848  1.19848  1.19848        0        0        0" />
                <joint name="elv_angle" type="hinge" pos="0 0 0" axis="  0.0048 0.999089   0.0424" limited="true" range=" -1.5708  2.26893" ref="0" user="1" />
                <body name="humphant1" pos="       0        0        0" quat="1.0 0.0 0.0 0.0">
                  <inertial pos="       0        0        0" mass="0.000106220960257972" fullinertia=" 1.19848  1.19848  1.19848        0        0        0" />
                  <joint name="shoulder_elv" type="hinge" pos="0 0 0" axis="-0.998261   0.0023 0.058898" limited="true" range="       0  3.14159" ref="0" user="1" />
                  <joint name="shoulder1_r2" type="hinge" pos="0 0 0" axis="  0.0048 0.999089   0.0424" limited="false" range="-99999.9  99999.9" ref="0" />
                  <body name="humerus" pos="       0        0        0" quat="1.0 0.0 0.0 0.0">
                    <geom name="humerus" type="mesh" mesh="humerus" />
                    <inertial pos="0.0191878 -0.148859 -0.0135389" mass="2.12183803582516" fullinertia="0.0147145 0.00305772 0.0150755 -0.000416364 -0.000278647 0.00147329" />
                    <site name="DELT1-P1" pos="0.0095174 -0.126222 0.00621393" />
                    <site name="DELT1-P2" pos="0.0172397 -0.117194 0.0043763" />
                    <site name="DELT2-P1" pos="0.00489679 -0.144577 0.00594837" />
                    <site name="DELT3-P3" pos="0.00218815 -0.0807492 0.0111001" />
                    <site name="SUPSP-P1" pos="0.00271926 0.0112913 0.0275431" />
                    <site name="INFSP-P1" pos="-0.0094218 0.00514109 0.0260029" />
                    <site name="SUBSC-P1" pos="0.0149028 0.00892256 -0.014138" />
                    <site name="TMIN-P1" pos="-0.00116843 -0.0134263 0.0229012" />
                    <site name="TMAJ-P1" pos="0.0106009 -0.0575611 -0.00603335" />
                    <site name="PECM1-P1" pos="0.0124172 -0.0445172 0.00828523" />
                    <site name="PECM1-P2" pos="  0.0191  -0.0301  0.00143" />
                    <site name="PECM2-P1" pos="0.0135326 -0.0455582 0.00833835" />
                    <site name="PECM2-P2" pos=" 0.01748 -0.03533  0.00033" />
                    <site name="PECM3-P1" pos="0.0134794 -0.0464717 0.00796657" />
                    <site name="PECM3-P2" pos="0.0159185 -0.045833 -0.00378312" />
                    <site name="LAT1-P1" pos="0.0111532 -0.0362745 -0.00693623" />
                    <site name="LAT2-P1" pos="0.0102822 -0.0432426 -0.0064901" />
                    <site name="LAT3-P1" pos="0.0128315 -0.0416599 -0.00441879" />
                    <site name="CORB-P3" pos="0.00789222 -0.159841 -0.00830648" />
                    <site name="TRIlong-P2" pos="-0.0288284 -0.121527 -0.00705307" />
                    <site name="TRIlong-P3" pos="-0.0338208 -0.240452 -0.0129271" />
                    <site name="TRIlong-P4" pos="-0.0185143 -0.284215 -0.0128315" />
                    <site name="TRIlat-P1" pos="-0.00636264 -0.134327 0.00454626" />
                    <site name="TRIlat-P2" pos="-0.0248982 -0.154318 0.00985731" />
                    <site name="TRIlat-P3" pos="-0.0338208 -0.240452 -0.0129271" />
                    <site name="TRIlat-P4" pos="-0.0185143 -0.284215 -0.0128315" />
                    <site name="TRImed-P1" pos="-0.00890132 -0.14547 -0.00962362" />
                    <site name="TRImed-P2" pos="-0.0276281 -0.160808 -0.0114719" />
                    <site name="TRImed-P3" pos="-0.0338208 -0.240452 -0.0129271" />
                    <site name="TRImed-P4" pos="-0.0185143 -0.284215 -0.0128315" />
                    <site name="ANC-P1" pos="-0.00790284 -0.301232 0.010399" />
                    <site name="BIClong-P3" pos="0.0226357 0.0190454 0.0109195" />
                    <site name="BIClong-P4" pos="0.0252593 -0.00542789 0.0127571" />
                    <site name="BIClong-P5" pos="0.0142867 -0.0300287 0.00144461" />
                    <site name="BIClong-P6" pos="0.0113444 -0.0821725 -0.00175265" />
                    <site name="BIClong-P7" pos="0.0180894 -0.128793 0.00025493" />
                    <site name="BIClong-P8" pos="0.0242184 -0.186312 -0.00669192" />
                    <site name="BICshort-P3" pos="0.0118649 -0.080473 -0.0116949" />
                    <site name="BICshort-P4" pos="0.0180894 -0.128793 -0.0114612" />
                    <site name="BICshort-P5" pos="0.0242184 -0.186312 -0.00669192" />
                    <site name="BRA-P1" pos="0.00722303 -0.184718 -0.00382395" />
                    <site name="BRA-P2" pos="0.0201182 -0.303356 -0.0117374" />
                    <site name="BRD-P1" pos="-0.0104097 -0.212049 0.00236873" />
                    <site name="ECRL-P1" pos="-0.00775413 -0.27713 0.00966611" />
                    <site name="ECRB-P1" pos="0.0143292 -0.308551 0.0180363" />
                    <site name="ECU-P1" pos="0.000881634 -0.307563 0.0199695" />
                    <site name="FCR-P1" pos="0.00805155 -0.295358 -0.0393549" />
                    <site name="FCU-P1" pos="0.00232624 -0.294657 -0.0412137" />
                    <site name="PL-P1" pos="0.0048543 -0.292309 -0.0410544" />
                    <site name="PT-P1" pos="0.00382395 -0.293064 -0.0387707" />
                    <site name="FDSL-P1" pos="0.0044719 -0.293149 -0.0410438" />
                    <site name="FDSR-P1" pos="0.00508798 -0.296144 -0.039631" />
                    <site name="EDCL-P1" pos="-0.000424884 -0.306246 0.0198633" />
                    <site name="EDCR-P1" pos="-0.00165705 -0.307361 0.0189286" />
                    <site name="EDCM-P1" pos="0.000541727 -0.307871 0.0207025" />
                    <site name="EDCI-P1" pos="0.000690436 -0.306957 0.0198527" />
                    <site name="EDM-P1" pos="0.000945367 -0.30718 0.019619" />
                    <joint name="shoulder_rot" type="hinge" pos="0 0 0" axis="  0.0048 0.999089   0.0424" limited="true" range=" -1.5708 0.349066" ref="0" user="1" />
                    <body name="ulna" pos="0.00647948 -0.308466 -0.0130652" quat="1.0 0.0 0.0 0.0">
                      <geom name="ulna" type="mesh" mesh="ulna" />
                      <inertial pos="0.0103224 -0.10192 0.0257968" mass="1.17406027373136" fullinertia="0.00648748 0.00138206 0.00592482 0.00037975 -9.12642e-05 0.00130837" />
                      <site name="TRIlong-P5" pos="-0.0232624 0.0111107 -0.000828523" />
                      <site name="TRIlat-P5" pos="-0.0232624 0.0111107 -0.000828523" />
                      <site name="TRImed-P5" pos="-0.0232624 0.0111107 -0.000828523" />
                      <site name="ANC-P2" pos="-0.0268951 -0.00131714 0.00637326" />
                      <site name="SUP-P3" pos="-0.0144461 -0.0359452 0.0213823" />
                      <site name="BRA-P4" pos="-0.00339907 -0.0253868 0.000955989" />
                      <site name="BRA-P3" pos="0.0052898 -0.0155401 0.00135963" />
                      <site name="ECU-P2" pos="-0.0147753 -0.0340013 0.0313033" />
                      <site name="ECU-P3" pos="-0.0181107 -0.0576567 0.0304642" />
                      <site name="ECU-P4" pos="-0.0190454 -0.101685 0.0348192" />
                      <site name="PT-P2" pos="0.00898629 -0.0358283 -0.0152108" />
                      <site name="PT-P3" pos=" 0.01219 -0.06516 -0.00219" />
                      <site name="PQ-P2" pos="0.00205006 -0.222767 0.0385795" />
                      <site name="FDSM-P1" pos="-0.00710618 -0.0288177 -0.00202882" />
                      <site name="FDSI-P1" pos="-0.00718054 -0.0299437 -0.00145523" />
                      <site name="FDPL-P1" pos="-0.00667068 -0.0341394 0.00269801" />
                      <site name="FDPR-P1" pos="-0.00533229 -0.035839 0.00289983" />
                      <site name="FDPM-P1" pos="-0.00554473 -0.0353397 0.00223064" />
                      <site name="FDPI-P1" pos="-0.0068725 -0.0337358 0.00297419" />
                      <site name="EDM-P2" pos="-0.0103778 -0.0415005 0.0327692" />
                      <site name="EDM-P3" pos="-0.00801968 -0.0878129 0.0387282" />
                      <site name="EIP-P1" pos="-0.00418511 -0.176879 0.0391106" />
                      <site name="EIP-P2" pos="0.00181638 -0.185557 0.0430089" />
                      <site name="EPL-P1" pos="-0.0149984 -0.103098 0.0313564" />
                      <joint name="elbow_flexion" type="hinge" pos="0 0 0" axis="  0.0494   0.0366 0.998108" limited="true" range="       0  4.26893" ref="0" user="1" />
                      <body name="radius" pos="0.000424884 -0.0122186 0.0212431" quat="1.0 0.0 0.0 0.0">
                        <geom name="radius" type="mesh" mesh="radius" />
                        <inertial pos="0.0357265 -0.192854 0.0165705" mass="0.248121541066596" fullinertia="0.000525593 0.000106173 0.000482484 3.61222e-05 -5.08155e-06 7.69184e-05" />
                        <site name="SUP-P1" pos="0.0105796 -0.0647523 0.000796657" />
                        <site name="SUP-P2" pos="0.0127571 -0.0549162 -0.00113656" />
                        <site name="BIClong-P11" pos="-0.00212442 -0.0398329 -0.00212442" />
                        <site name="BIClong-P9" pos=" 0.00273 -0.0343493 -0.0119845" />
                        <site name="BICshort-P8" pos="-0.00212442 -0.0398329 -0.00212442" />
                        <site name="BICshort-P6" pos=" 0.00273 -0.0343493 -0.0119845" />
                        <site name="BRD-P2" pos="0.0379952 -0.135347 0.0245902" />
                        <site name="BRD-P3" pos="0.0445066 -0.234748 0.0237935" />
                        <site name="ECRL-P2" pos="0.0339376 -0.143005 0.0295188" />
                        <site name="ECRL-P3" pos="0.0450696 -0.251574 0.038452" />
                        <site name="ECRB-P2" pos="0.0308572 -0.139001 0.0253337" />
                        <site name="ECRB-P3" pos="0.0376978 -0.242237 0.0418192" />
                        <site name="ECU-P5" pos="-0.015094 -0.241079 0.0369755" />
                        <site name="FCR-P2" pos="0.0224126 -0.233081 0.00134901" />
                        <site name="FCU-P3" pos="0.0114931 -0.23716 0.0102928" />
                        <site name="FCU-P2" pos="0.0101156 -0.183524 0.00202653" />
                        <site name="PL-P2" pos="0.0268845 -0.254027 -0.0029317" />
                        <site name="PT-P5" pos="0.0269801 -0.115568 0.0210318" />
                        <site name="PT-P4" pos="0.0250681 -0.0992104 0.00998477" />
                        <site name="PQ-P1" pos="0.0344687 -0.212421 0.0208406" />
                        <site name="FDSL-P2" pos="0.0146266 -0.198824 0.00217753" />
                        <site name="FDSR-P2" pos="0.0166873 -0.198272 0.0028361" />
                        <site name="FDSM-P2" pos="0.0201714 -0.198697 0.00450377" />
                        <site name="FDSI-P2" pos="0.0227844 -0.197815 0.0058634" />
                        <site name="FDPL-P2" pos="0.0149665 -0.196679 0.00914562" />
                        <site name="FDPR-P2" pos="0.0167829 -0.197879 0.00852954" />
                        <site name="FDPM-P2" pos="0.0202457 -0.198038 0.00833835" />
                        <site name="FDPI-P2" pos="0.022094 -0.197146 0.00971922" />
                        <site name="EDCL-P3" pos="0.0105477 -0.236915 0.0384307" />
                        <site name="EDCL-P2" pos="  0.0013 -0.0382544 0.0129514" />
                        <site name="EDCR-P3" pos="0.00936869 -0.237574 0.0455051" />
                        <site name="EDCR-P2" pos="  0.0026 -0.0392844 0.0144214" />
                        <site name="EDCM-P3" pos="0.0152958 -0.237117 0.0448571" />
                        <site name="EDCM-P2" pos=" 0.00316 -0.0388544 0.0141814" />
                        <site name="EDCI-P3" pos="0.0162837 -0.237021 0.0445703" />
                        <site name="EDCI-P2" pos=" 0.00228 -0.0385544 0.0137314" />
                        <site name="EDM-P4" pos="0.00482243 -0.240495 0.0390681" />
                        <site name="EIP-P3" pos="0.0114294 -0.242003 0.0389194" />
                        <site name="EPL-P2" pos="0.00131714 -0.145183 0.0241122" />
                        <site name="EPL-P3" pos="0.0287009 -0.232326 0.0406614" />
                        <site name="EPL-P4" pos="0.0359239 -0.241695 0.048936" />
                        <site name="EPL-P5" pos="0.044974 -0.252498 0.044326" />
                        <site name="EPB-P1" pos="0.0204369 -0.156092 0.0224551" />
                        <site name="EPB-P2" pos="0.0241759 -0.168435 0.0283079" />
                        <site name="EPB-P3" pos="0.0406932 -0.209489 0.0407251" />
                        <site name="EPB-P4" pos="0.0556067 -0.250798 0.028669" />
                        <site name="FPL-P1" pos="0.0103141 -0.100464 0.0187905" />
                        <site name="FPL-P2" pos="0.0176114 -0.143664 0.0203413" />
                        <site name="FPL-P3" pos="0.0198527 -0.190475 0.0211167" />
                        <site name="FPL-P4" pos="0.040364 -0.246125 0.0167829" />
                        <site name="APL-P1" pos="0.0122579 -0.100666 0.0178557" />
                        <site name="APL-P2" pos="0.032185 -0.148391 0.0372517" />
                        <site name="APL-P3" pos="0.042414 -0.170718 0.0361151" />
                        <site name="APL-P4" pos="0.0467054 -0.189551 0.0332896" />
                        <site name="APL-P5" pos="0.0584746 -0.2452 0.0251531" />
                        <joint name="pro_sup" type="hinge" pos="0 0 0" axis="-0.017161 0.992666 -0.119668" limited="true" range=" -1.5708   1.5708" ref="0" user="1" />
                        <body name="proximal_row" pos="0.0191198 -0.257055 0.0265552" quat="1.0 0.0 0.0 0.0">
                          <geom name="lunate" type="mesh" mesh="lunate" />
                          <geom name="sdfastSCAPHOIDw" type="mesh" mesh="sdfastSCAPHOIDw" />
                          <geom name="sdfastPISIFORMw" type="mesh" mesh="sdfastPISIFORMw" />
                          <geom name="sdfastTRIQUETRALw" type="mesh" mesh="sdfastTRIQUETRALw" />
                          <inertial pos="       0        0        0" mass="0.000106220960257972" fullinertia="1.19848e-05 1.19848e-05 1.19848e-05        0        0        0" />
                          <body name="hand" pos="0.00424034 -0.0159905 0.00247176" quat="1.0 0.0 0.0 0.0">
                            <geom name="sdfast_1seg_hand_fr_c_5mc" type="mesh" mesh="sdfast_1seg_hand_fr_c_5mc" />
                            <geom name="sdfast_1seg_hand_fr_c_4mc" type="mesh" mesh="sdfast_1seg_hand_fr_c_4mc" />
                            <geom name="sdfast_1seg_hand_fr_c_3mc" type="mesh" mesh="sdfast_1seg_hand_fr_c_3mc" />
                            <geom name="sdfast_1seg_hand_fr_c_trapezium" type="mesh" mesh="sdfast_1seg_hand_fr_c_trapezium" />
                            <geom name="sdfast_1seg_hand_fr_c_trapezoid" type="mesh" mesh="sdfast_1seg_hand_fr_c_trapezoid" />
                            <geom name="sdfast_1seg_hand_fr_c_hamate" type="mesh" mesh="sdfast_1seg_hand_fr_c_hamate" />
                            <geom name="capitate" type="mesh" mesh="capitate" />
                            <geom name="hand_3proxph" type="mesh" mesh="hand_3proxph" />
                            <geom name="hand_3midph" type="mesh" mesh="hand_3midph" />
                            <geom name="hand_3distph" type="mesh" mesh="hand_3distph" />
                            <geom name="hand_4proxph" type="mesh" mesh="hand_4proxph" />
                            <geom name="hand_4midph" type="mesh" mesh="hand_4midph" />
                            <geom name="hand_4distph" type="mesh" mesh="hand_4distph" />
                            <geom name="hand_5proxph" type="mesh" mesh="hand_5proxph" />
                            <geom name="hand_5midph" type="mesh" mesh="hand_5midph" />
                            <geom name="hand_5distph" type="mesh" mesh="hand_5distph" />
                            <geom name="hand_thumbprox" type="mesh" mesh="hand_thumbprox" />
                            <geom name="hand_thumbdist" type="mesh" mesh="hand_thumbdist" />
                            <geom name="hand_1mc" type="mesh" mesh="hand_1mc" />
                            <inertial pos="-0.00320059 -0.0451432 -0.00119185" mass="0.618099767741137" fullinertia="0.000131833 7.19088e-05 0.000179772 1.07863e-06 -2.39696e-07 1.43818e-05" />
                            <site name="ECRL-P4" pos="0.0182381 -0.0225401 0.00619268" />
                            <site name="ECRB-P4" pos="0.00531105 -0.0120667 0.00902878" />
                            <site name="ECU-P6" pos="-0.0239103 -0.0148816 -0.00135963" />
                            <site name="FCR-P3" pos="0.0119392 -0.0195871 -0.00444004" />
                            <site name="FCU-P4" pos="-0.0216266 -0.018748 -0.00798782" />
                            <site name="PL-P3" pos="0.00974046 -0.0201607 -0.0186312" />
                            <site name="PL-P4" pos="0.00241122 -0.032886 0.00523669" />
                            <site name="FDSL-P3" pos="-0.00249619 -0.0147966 -0.014616" />
                            <site name="FDSL-P4" pos="-0.0211911 -0.0454732 -0.0078816" />
                            <site name="FDSL-P5" pos="-0.0217116 -0.0635308 -0.0199483" />
                            <site name="FDSL-P6" pos="-0.0181957 -0.0769571 -0.0292426" />
                            <site name="FDSL-P7" pos="-0.0122791 -0.0772333 -0.0388344" />
                            <site name="FDSL-P8" pos="-0.0112488 -0.0772333 -0.0403215" />
                            <site name="FDSR-P3" pos="-0.000871012 -0.0142761 -0.0144354" />
                            <site name="FDSR-P4" pos="-0.0103778 -0.0550118 4.24884e-005" />
                            <site name="FDSR-P5" pos="-0.014053 -0.0708494 -0.0108345" />
                            <site name="FDSR-P6" pos="-0.00837021 -0.0852636 -0.0265871" />
                            <site name="FDSR-P7" pos="-0.00317601 -0.0863045 -0.036062" />
                            <site name="FDSR-P8" pos="0.00065857 -0.085954 -0.0413412" />
                            <site name="FDSM-P3" pos="0.00722303 -0.0146266 -0.0148603" />
                            <site name="FDSM-P4" pos="0.00500301 -0.0353928 -0.00140212" />
                            <site name="FDSM-P5" pos="0.00575718 -0.0601211 0.000637326" />
                            <site name="FDSM-P6" pos="0.00589526 -0.076734 -0.00359027" />
                            <site name="FDSM-P7" pos="0.012396 -0.0935807 -0.0177389" />
                            <site name="FDSM-P8" pos="0.0138193 -0.094218 -0.031622" />
                            <site name="FDSM-P9" pos="0.0166554 -0.0911057 -0.0399922" />
                            <site name="FDSI-P3" pos="0.00944304 -0.0145098 -0.0147328" />
                            <site name="FDSI-P4" pos="0.01127 -0.0402259 0.00025493" />
                            <site name="FDSI-P5" pos="0.0189286 -0.0542577 0.00444004" />
                            <site name="FDSI-P6" pos="0.0196403 -0.0775094 -0.00398329" />
                            <site name="FDSI-P7" pos="0.028446 -0.0925609 -0.0191623" />
                            <site name="FDSI-P8" pos="0.0283291 -0.0928371 -0.028446" />
                            <site name="FDSI-P9" pos="0.0282548 -0.0917006 -0.0308359" />
                            <site name="FDPL-P3" pos="-0.000934744 -0.0109089 -0.0126191" />
                            <site name="FDPL-P4" pos="-0.019704 -0.0493503 -0.007786" />
                            <site name="FDPL-P5" pos="-0.0192047 -0.0620437 -0.0165705" />
                            <site name="FDPL-P6" pos="-0.0151684 -0.0774245 -0.0284991" />
                            <site name="FDPL-P7" pos="-0.00977233 -0.0794851 -0.0391318" />
                            <site name="FDPL-P8" pos="-0.00331409 -0.0786566 -0.044241" />
                            <site name="FDPL-P9" pos="0.00473745 -0.0749814 -0.0494671" />
                            <site name="FDPR-P3" pos="0.00112594 -0.0125022 -0.0125766" />
                            <site name="FDPR-P4" pos="-0.00908189 -0.0588677 0.000934744" />
                            <site name="FDPR-P5" pos="-0.0114612 -0.0699784 -0.00867825" />
                            <site name="FDPR-P6" pos="-0.00581029 -0.0866126 -0.0239634" />
                            <site name="FDPR-P7" pos="-0.000594837 -0.0874199 -0.0357646" />
                            <site name="FDPR-P8" pos="0.00646886 -0.0832454 -0.0450164" />
                            <site name="FDPR-P9" pos="0.0128634 -0.0783911 -0.0516021" />
                            <site name="FDPM-P3" pos="0.0035584 -0.0135963 -0.0121517" />
                            <site name="FDPM-P4" pos="0.00320787 -0.0366144 -0.0064901" />
                            <site name="FDPM-P5" pos="0.00267677 -0.0622773 0.0012959" />
                            <site name="FDPM-P6" pos="0.0030273 -0.0741953 -0.00141274" />
                            <site name="FDPM-P7" pos="0.00916687 -0.0932514 -0.0192791" />
                            <site name="FDPM-P8" pos="0.0106433 -0.0931133 -0.0314839" />
                            <site name="FDPM-P9" pos="0.0173459 -0.0866444 -0.047109" />
                            <site name="FDPM-P10" pos="0.0202776 -0.0813971 -0.0555429" />
                            <site name="FDPI-P3" pos="0.0095174 -0.0124066 -0.012874" />
                            <site name="FDPI-P4" pos="0.0204157 -0.0588677 0.00465248" />
                            <site name="FDPI-P5" pos="0.0220196 -0.0745777 -0.00303792" />
                            <site name="FDPI-P6" pos="0.0308466 -0.0912226 -0.0189286" />
                            <site name="FDPI-P7" pos="0.031059 -0.0921148 -0.0294126" />
                            <site name="FDPI-P8" pos="0.0309528 -0.087473 -0.0422653" />
                            <site name="FDPI-P9" pos="0.0302411 -0.0825443 -0.0506249" />
                            <site name="EDCL-P4" pos="-0.0261728 -0.0467585 0.00179513" />
                            <site name="EDCL-P5" pos="-0.0252912 -0.050285 0.000817901" />
                            <site name="EDCL-P6" pos="-0.0254399 -0.0702439 -0.0106327" />
                            <site name="EDCL-P7" pos="-0.0190985 -0.0833516 -0.0287965" />
                            <site name="EDCL-P8" pos="-0.0125128 -0.0836703 -0.0401409" />
                            <site name="EDCL-P9" pos="-0.00159331 -0.0805792 -0.0487129" />
                            <site name="EDCL-P10" pos="0.00213504 -0.0795276 -0.0509223" />
                            <site name="EDCR-P4" pos="-0.016613 -0.0589526 0.00992104" />
                            <site name="EDCR-P5" pos="-0.0151577 -0.06181 0.0123323" />
                            <site name="EDCR-P6" pos="-0.0167829 -0.076649 -0.0044719" />
                            <site name="EDCR-P7" pos="-0.00876323 -0.092784 -0.0240059" />
                            <site name="EDCR-P8" pos="-0.00288921 -0.0935382 -0.0362107" />
                            <site name="EDCR-P9" pos="0.00810466 -0.0852529 -0.0494777" />
                            <site name="EDCR-P10" pos="0.011355 -0.0829479 -0.0524838" />
                            <site name="EDCM-P4" pos="0.000414262 -0.0560209 0.0158375" />
                            <site name="EDCM-P5" pos="-0.000924122 -0.0592076 0.0154233" />
                            <site name="EDCM-P6" pos="0.00197571 -0.0819813 0.00634139" />
                            <site name="EDCM-P7" pos="0.0106965 -0.0989236 -0.0188436" />
                            <site name="EDCM-P8" pos="0.0140318 -0.101526 -0.0324611" />
                            <site name="EDCM-P9" pos="0.0197252 -0.0905534 -0.0505506" />
                            <site name="EDCM-P10" pos="0.021839 -0.0849024 -0.0567326" />
                            <site name="EDCM-P11" pos="0.0233155 -0.0818008 -0.0601529" />
                            <site name="EDCI-P4" pos="0.0163899 -0.0497114 0.0174096" />
                            <site name="EDCI-P5" pos="0.0201501 -0.0600573 0.0152746" />
                            <site name="EDCI-P6" pos="0.0211805 -0.0815565 0.00630953" />
                            <site name="EDCI-P7" pos="0.0312821 -0.0973196 -0.0132245" />
                            <site name="EDCI-P8" pos="0.0331516 -0.099306 -0.0308572" />
                            <site name="EDCI-P9" pos="0.0320044 -0.0901497 -0.0453351" />
                            <site name="EDCI-P10" pos="0.0311121 -0.0860708 -0.0527493" />
                            <site name="EDM-P5" pos="-0.0218709 -0.010962 0.00395142" />
                            <site name="EDM-P6" pos="-0.0272244 -0.0501575 0.000244308" />
                            <site name="EDM-P7" pos="-0.0270757 -0.0691605 -0.0116631" />
                            <site name="EDM-P8" pos="-0.0205325 -0.0829586 -0.0288709" />
                            <site name="EDM-P9" pos="-0.0142973 -0.0838296 -0.0413624" />
                            <site name="EDM-P10" pos="-0.00229437 -0.0798888 -0.0487448" />
                            <site name="EDM-P11" pos="0.00140212 -0.0780193 -0.0510179" />
                            <site name="EIP-P4" pos="0.00412137 -0.0237298 0.0125766" />
                            <site name="EIP-P5" pos="0.0179832 -0.0599086 0.0146266" />
                            <site name="EIP-P6" pos="0.0184293 -0.0817052 0.00617144" />
                            <site name="EIP-P7" pos="0.0293701 -0.0989342 -0.01605" />
                            <site name="EIP-P8" pos="0.030581 -0.100241 -0.0299862" />
                            <site name="EIP-P9" pos="0.0304854 -0.0905427 -0.0456219" />
                            <site name="EIP-P10" pos="0.030103 -0.082693 -0.0584322" />
                            <site name="EPL-P6" pos="0.0257904 0.000148709 0.00645823" />
                            <site name="EPL-P7" pos="0.0248345 -0.00974046 -0.000414262" />
                            <site name="EPL-P8" pos="0.0308572 -0.0151577 -0.0051942" />
                            <site name="EPL-P9" pos="0.0468859 -0.0362957 -0.0192685" />
                            <site name="EPL-P10" pos="0.0516977 -0.0493503 -0.0264172" />
                            <site name="EPL-P11" pos="0.0504656 -0.0744609 -0.0400878" />
                            <site name="EPL-P12" pos="0.0426052 -0.0803562 -0.0454944" />
                            <site name="EPB-P5" pos="0.0331728 0.00271926 -0.00347343" />
                            <site name="EPB-P6" pos="0.0315689 -0.00843394 -0.0152533" />
                            <site name="EPB-P7" pos="0.0469709 -0.0350529 -0.0257267" />
                            <site name="EPB-P8" pos="0.0480969 -0.0508267 -0.033842" />
                            <site name="FPL-P6" pos="0.0132139 -0.023443 -0.0221896" />
                            <site name="FPL-P7" pos="0.0174309 -0.0278405 -0.0235917" />
                            <site name="FPL-P8" pos="0.0260985 -0.0349892 -0.0237616" />
                            <site name="FPL-P9" pos="0.0300287 -0.0582303 -0.0324505" />
                            <site name="FPL-P10" pos="0.0372942 -0.0692454 -0.0398222" />
                            <site name="FPL-P11" pos="0.0375279 -0.0813228 -0.0437418" />
                            <site name="FPL-P5" pos="0.0178892 0.0064176 -0.0168214" />
                            <site name="APL-P7" pos="0.0274794 0.00217753 -0.0175265" />
                            <site name="APL-P8" pos="0.0305704 -0.00715929 -0.0198633" />
                            <site name="APL-P9" pos="0.0326736 -0.0168148 -0.0200227" />
                            <site name="APL-P6" pos="0.0332244 0.00608975 -0.00870125" />
                            <body name="index0" pos="0 0 0">
                              <inertial pos="0 0 0" mass="0.001" diaginertia="0.001 0.001 0.001" />
                              <geom name="sdfast_1seg_hand_fr_c_2mc" type="mesh" mesh="sdfast_1seg_hand_fr_c_2mc" />
                              <body name="index1" pos="0 0 0">
                                <inertial pos="0 0 0" mass="0.001" diaginertia="0.001 0.001 0.001" />
                                <geom name="hand_2proxph" type="mesh" mesh="hand_2proxph" />
                                <body name="index2" pos="0 0 0">
                                  <inertial pos="0 0 0" mass="0.001" diaginertia="0.001 0.001 0.001" />
                                  <geom name="hand_2midph" type="mesh" mesh="hand_2midph" />
                                  <body name="index3" pos="0 0 0">
                                    <inertial pos="0 0 0" mass="0.001" diaginertia="0.001 0.001 0.001" />
                                    <geom name="hand_2distph" type="mesh" mesh="hand_2distph" />
                                    <site name="fingertip" pos="0.024 -0.149 -0.0065" type="sphere" rgba="0.1 0.8 0.1 0.0" size="0.004" />
                                  </body>
                                </body>
                              </body>
                            </body>
                          </body>
                        </body>
                      </body>
                    </body>
                  </body>
                </body>
              </body>
            </body>
          </body>
        </body>
      </body>
    </body>

</mujocoinclude>