<mujocoinclude model="MoBL Arms Index Model">

    <body name="thorax" pos="0 0 0" quat="0.7071067811865475 0.7071067811865475 0.0 0.0">
      <light mode="trackcom" directional="false" pos="0 0 4.0" dir="0 0 -1" />
      <geom name="thorax" type="mesh" mesh="thorax" />
      <site name="PECM1-P3" pos="  -7e-05  0.00821  0.10454" />
      <site name="PECM2-P4" pos="0.0340297 -0.0431784 0.106845" />
      <site name="PECM2-P5" pos="0.0304847 -0.0495198 0.0250021" />
      <site name="PECM2-P3" pos=" 0.02083 -0.02005  0.11555" />
      <site name="PECM3-P4" pos="0.0577988 -0.0926652 0.098368" />
      <site name="PECM3-P5" pos="0.0630172 -0.128302 0.0416922" />
      <site name="PECM3-P3" pos=" 0.02984 -0.0544459   0.1151" />
      <site name="LAT1-P4" pos="-0.130218 -0.111392 0.0365068" />
      <site name="LAT1-P5" pos="-0.105447 -0.129073 0.0097102" />
      <site name="LAT2-P4" pos="-0.121014 -0.186145 0.0316847" />
      <site name="LAT2-P5" pos="-0.0791128 -0.207173 0.00897257" />
      <site name="LAT3-P4" pos="-0.122831 -0.213437 0.0609034" />
      <site name="LAT3-P5" pos="-0.0783531 -0.273669 0.00998543" />
      <joint name="r_z" type="hinge" pos="0 0 0" axis="       0        0        1" limited="true" range="-6.28319  6.28319" ref="0" armature="0" damping="0" stiffness="0" />
      <body name="clavicle" pos="0.00696338 0.00762944 0.0280352" quat="1.0 0.0 0.0 0.0">
        <geom name="clavicle" type="mesh" mesh="clavicle" />
        <inertial pos="-0.0122159 0.00701545 0.0596351" mass="0.171744966444436" fullinertia="0.000323706 0.000340613 5.9273e-05 -2.53265e-05 -9.33263e-05 7.16693e-05" />
        <site name="DELT1-P4" pos="-0.015413 0.0121763 0.0883055" />
        <site name="DELT2-P2" pos="0.0191703 0.0244002 0.162891" />
        <site name="PECM1-P4" pos="0.00353398 -0.000143121 0.0562905" />
        <joint name="sternoclavicular_r2" type="hinge" pos="0 0 0" axis="  0.0153 0.989299  -0.1451" limited="false" range="-99999.9  99999.9" ref="0" />
        <joint name="sternoclavicular_r3" type="hinge" pos="0 0 0" axis="-0.994473        0 -0.104997" limited="false" range="-99999.9  99999.9" ref="0" />
        <body name="clavphant" pos="-0.0157763 0.0220957 0.149214" quat="1.0 0.0 0.0 0.0">
          <inertial pos="       0        0        0" mass="0.000110092927207972" fullinertia=" 1.33438  1.33438  1.33438        0        0        0" />
          <joint name="unrotscap_r3" type="hinge" pos="0 0 0" axis="-0.994473        0 -0.104997" limited="false" range="-99999.9  99999.9" ref="0" />
          <joint name="unrotscap_r2" type="hinge" pos="0 0 0" axis="  0.0153 0.989299  -0.1451" limited="false" range="-99999.9  99999.9" ref="0" />
          <body name="scapula" pos="       0        0        0" quat="1.0 0.0 0.0 0.0">
            <geom name="scapula" type="mesh" mesh="scapula" />
            <inertial pos="-0.0602142 -0.0385678 -0.048148" mass="0.775010170373239" fullinertia="0.0016585 0.00153507 0.00182156 0.000599669 0.000546053 0.000321718" />
            <site name="DELT1-P3" pos="0.0478574 -0.0358022 0.00108992" />
            <site name="DELT2-P3" pos="5.50465e-005 0.00323673 0.0245838" />
            <site name="DELT2-P4" pos="-0.011868 -0.000374316 0.00682576" />
            <site name="DELT3-P1" pos="-0.0613548 0.00134313 -0.0276553" />
            <site name="DELT3-P2" pos="-0.0797843 -0.0361655 0.0135745" />
            <site name="SUPSP-P2" pos="-0.0211158 0.00139818 -0.0139928" />
            <site name="SUPSP-P3" pos="-0.0484409 -0.0166461 -0.0644594" />
            <site name="INFSP-P2" pos="-0.0812706 -0.0602869 -0.0526354" />
            <site name="SUBSC-P2" pos="-0.020158 -0.0575015 -0.0270498" />
            <site name="SUBSC-P3" pos="-0.0797733 -0.0434096 -0.0712852" />
            <site name="TMIN-P2" pos="-0.104291 -0.0879753 -0.052151" />
            <site name="TMIN-P3" pos="-0.106163 -0.0894065 -0.0583272" />
            <site name="TMAJ-P2" pos="-0.112999 -0.113605 -0.0641732" />
            <site name="TMAJ-P3" pos="-0.115476 -0.119946 -0.0783531" />
            <site name="LAT1-P2" pos="-0.08052 -0.06821 -0.02908" />
            <site name="LAT1-P3" pos="-0.10925 -0.07239 -0.07422" />
            <site name="LAT2-P2" pos="-0.08345 -0.08695 -0.02453" />
            <site name="LAT2-P3" pos="-0.11524 -0.10749 -0.08863" />
            <site name="LAT3-P2" pos="-0.08438 -0.11598 -0.02995" />
            <site name="LAT3-P3" pos="-0.11279 -0.13833 -0.08911" />
            <site name="CORB-P1" pos="0.0137616 -0.0454354 -0.0291966" />
            <site name="CORB-P2" pos="0.00531749 -0.0766027 -0.0172075" />
            <site name="TRIlong-P1" pos="-0.0502574 -0.0448408 -0.0151598" />
            <site name="BIClong-P1" pos="-0.034382 -0.0259049 -0.0143671" />
            <site name="BIClong-P2" pos="-0.0230535 -0.0144112 -0.00507528" />
            <site name="BICshort-P1" pos="0.0139598 -0.0432775 -0.0288994" />
            <site name="BICshort-P2" pos="0.00102386 -0.0738063 -0.0175378" />
            <joint name="acromioclavicular_r2" type="hinge" pos="0 0 0" axis="0.157095 0.947269 -0.279291" limited="false" range="-99999.9  99999.9" ref="0" />
            <joint name="acromioclavicular_r3" type="hinge" pos="0 0 0" axis="-0.754084 0.297594 0.585487" limited="false" range="-99999.9  99999.9" ref="0" />
            <joint name="acromioclavicular_r1" type="hinge" pos="0 0 0" axis="  0.6377   0.1186   0.7611" limited="false" range="-99999.9  99999.9" ref="0" />
            <body name="scapphant" pos="-0.0105139 -0.0374316 0.00990836" quat="1.0 0.0 0.0 0.0">
              <inertial pos="       0        0        0" mass="0.000110092927207972" fullinertia=" 1.33438  1.33438  1.33438        0        0        0" />
              <joint name="unrothum_r1" type="hinge" pos="0 0 0" axis="  0.6377   0.1186   0.7611" limited="false" range="-99999.9  99999.9" ref="0" />
              <joint name="unrothum_r3" type="hinge" pos="0 0 0" axis="-0.754084 0.297594 0.585487" limited="false" range="-99999.9  99999.9" ref="0" />
              <joint name="unrothum_r2" type="hinge" pos="0 0 0" axis="0.157095 0.947269 -0.279291" limited="false" range="-99999.9  99999.9" ref="0" />
              <body name="humphant" pos="       0        0        0" quat="1.0 0.0 0.0 0.0">
                <inertial pos="       0        0        0" mass="0.000110092927207972" fullinertia=" 1.33438  1.33438  1.33438        0        0        0" />
                <joint name="elv_angle" type="hinge" pos="0 0 0" axis="  0.0048 0.999089   0.0424" limited="true" range=" -1.5708  2.26893" ref="0" user="1" />
                <body name="humphant1" pos="       0        0        0" quat="1.0 0.0 0.0 0.0">
                  <inertial pos="       0        0        0" mass="0.000110092927207972" fullinertia=" 1.33438  1.33438  1.33438        0        0        0" />
                  <joint name="shoulder_elv" type="hinge" pos="0 0 0" axis="-0.998261   0.0023 0.058898" limited="true" range="       0  3.14159" ref="0" user="1" />
                  <joint name="shoulder1_r2" type="hinge" pos="0 0 0" axis="  0.0048 0.999089   0.0424" limited="false" range="-99999.9  99999.9" ref="0" />
                  <body name="humerus" pos="       0        0        0" quat="1.0 0.0 0.0 0.0">
                    <geom name="humerus" type="mesh" mesh="humerus" />
                    <inertial pos="0.0198872 -0.154285 -0.0140324" mass="2.19918328602828" fullinertia="0.016383 0.00340443 0.016785 -0.000463576 -0.000310242 0.00164035" />
                    <site name="DELT1-P1" pos="0.00986433 -0.130823 0.00644044" />
                    <site name="DELT1-P2" pos="0.0178681 -0.121466 0.00453583" />
                    <site name="DELT2-P1" pos="0.00507528 -0.149847 0.0061652" />
                    <site name="DELT3-P3" pos="0.00226791 -0.0836926 0.0115047" />
                    <site name="SUPSP-P1" pos="0.00281838 0.0117029 0.0285471" />
                    <site name="INFSP-P1" pos="-0.00976524 0.0053285 0.0269507" />
                    <site name="SUBSC-P1" pos="0.015446 0.00924781 -0.0146534" />
                    <site name="TMIN-P1" pos="-0.00121102 -0.0139157 0.023736" />
                    <site name="TMAJ-P1" pos="0.0109873 -0.0596594 -0.00625328" />
                    <site name="PECM1-P1" pos="0.0128699 -0.0461399 0.00858725" />
                    <site name="PECM1-P2" pos="  0.0191  -0.0301  0.00143" />
                    <site name="PECM2-P1" pos="0.0140258 -0.0472189 0.00864229" />
                    <site name="PECM2-P2" pos=" 0.01748 -0.03533  0.00033" />
                    <site name="PECM3-P1" pos="0.0139708 -0.0481657 0.00825697" />
                    <site name="PECM3-P2" pos="0.0159185 -0.045833 -0.00378312" />
                    <site name="LAT1-P1" pos="0.0115598 -0.0375967 -0.00718907" />
                    <site name="LAT2-P1" pos="0.010657 -0.0448188 -0.00672668" />
                    <site name="LAT3-P1" pos="0.0132992 -0.0431784 -0.00457987" />
                    <site name="CORB-P3" pos="0.0081799 -0.165668 -0.00860927" />
                    <site name="TRIlong-P2" pos="-0.0298792 -0.125957 -0.00731017" />
                    <site name="TRIlong-P3" pos="-0.0350536 -0.249217 -0.0133983" />
                    <site name="TRIlong-P4" pos="-0.0191892 -0.294576 -0.0132992" />
                    <site name="TRIlat-P1" pos="-0.00659457 -0.139224 0.00471198" />
                    <site name="TRIlat-P2" pos="-0.0258058 -0.159943 0.0102166" />
                    <site name="TRIlat-P3" pos="-0.0350536 -0.249217 -0.0133983" />
                    <site name="TRIlat-P4" pos="-0.0191892 -0.294576 -0.0132992" />
                    <site name="TRImed-P1" pos="-0.00922579 -0.150772 -0.00997442" />
                    <site name="TRImed-P2" pos="-0.0286352 -0.16667 -0.01189" />
                    <site name="TRImed-P3" pos="-0.0350536 -0.249217 -0.0133983" />
                    <site name="TRImed-P4" pos="-0.0191892 -0.294576 -0.0132992" />
                    <site name="ANC-P1" pos="-0.00819091 -0.312213 0.0107781" />
                    <site name="BIClong-P3" pos="0.0234608 0.0197397 0.0113176" />
                    <site name="BIClong-P4" pos="0.0261801 -0.00562575 0.0132222" />
                    <site name="BIClong-P5" pos="0.0148075 -0.0311233 0.00149726" />
                    <site name="BIClong-P6" pos="0.0117579 -0.0851679 -0.00181653" />
                    <site name="BIClong-P7" pos="0.0187488 -0.133488 0.000264223" />
                    <site name="BIClong-P8" pos="0.0251012 -0.193103 -0.00693585" />
                    <site name="BICshort-P3" pos="0.0122974 -0.0834064 -0.0121212" />
                    <site name="BICshort-P4" pos="0.0187488 -0.133488 -0.011879" />
                    <site name="BICshort-P5" pos="0.0251012 -0.193103 -0.00693585" />
                    <site name="BRA-P1" pos="0.00748632 -0.191452 -0.00396335" />
                    <site name="BRA-P2" pos="0.0208516 -0.314414 -0.0121653" />
                    <site name="BRD-P1" pos="-0.0107891 -0.219779 0.00245507" />
                    <site name="ECRL-P1" pos="-0.00803678 -0.287232 0.0100185" />
                    <site name="ECRB-P1" pos="0.0148515 -0.319798 0.0186938" />
                    <site name="ECU-P1" pos="0.000913771 -0.318774 0.0206975" />
                    <site name="FCR-P1" pos="0.00834504 -0.306124 -0.0407894" />
                    <site name="FCU-P1" pos="0.00241104 -0.305398 -0.0427161" />
                    <site name="PL-P1" pos="0.00503125 -0.302965 -0.0425509" />
                    <site name="PT-P1" pos="0.00396335 -0.303746 -0.0401839" />
                    <site name="FDSL-P1" pos="0.00463491 -0.303834 -0.0425399" />
                    <site name="FDSR-P1" pos="0.00527345 -0.306939 -0.0410757" />
                    <site name="EDCL-P1" pos="-0.000440372 -0.317409 0.0205874" />
                    <site name="EDCR-P1" pos="-0.00171745 -0.318565 0.0196186" />
                    <site name="EDCM-P1" pos="0.000561474 -0.319093 0.0214571" />
                    <site name="EDCI-P1" pos="0.000715604 -0.318147 0.0205764" />
                    <site name="EDM-P1" pos="0.000979827 -0.318378 0.0203342" />
                    <joint name="shoulder_rot" type="hinge" pos="0 0 0" axis="  0.0048 0.999089   0.0424" limited="true" range=" -1.5708 0.349066" ref="0" user="1" />
                    <body name="ulna" pos="0.00671567 -0.31971 -0.0135414" quat="1.0 0.0 0.0 0.0">
                      <geom name="ulna" type="mesh" mesh="ulna" />
                      <inertial pos="0.0106986 -0.105635 0.0267372" mass="1.21685712442971" fullinertia="0.0072231 0.00153878 0.00659664 0.00042281 -0.000101613 0.00145673" />
                      <site name="TRIlong-P5" pos="-0.0241104 0.0115157 -0.000858725" />
                      <site name="TRIlat-P5" pos="-0.0241104 0.0115157 -0.000858725" />
                      <site name="TRImed-P5" pos="-0.0241104 0.0115157 -0.000858725" />
                      <site name="ANC-P2" pos="-0.0278755 -0.00136515 0.00660558" />
                      <site name="SUP-P3" pos="-0.0149726 -0.0372554 0.0221617" />
                      <site name="BRA-P4" pos="-0.00352297 -0.0263122 0.000990836" />
                      <site name="BRA-P3" pos="0.00548263 -0.0161066 0.00140919" />
                      <site name="ECU-P2" pos="-0.0153139 -0.0352407 0.0324444" />
                      <site name="ECU-P3" pos="-0.0187708 -0.0597584 0.0315747" />
                      <site name="ECU-P4" pos="-0.0197397 -0.105392 0.0360885" />
                      <site name="PT-P2" pos="0.00931386 -0.0371343 -0.0157653" />
                      <site name="PT-P3" pos=" 0.01219 -0.06516 -0.00219" />
                      <site name="PQ-P2" pos="0.00212479 -0.230887 0.0399858" />
                      <site name="FDSM-P1" pos="-0.00736522 -0.0298682 -0.00210277" />
                      <site name="FDSI-P1" pos="-0.00744228 -0.0310352 -0.00150827" />
                      <site name="FDPL-P1" pos="-0.00691384 -0.0353839 0.00279636" />
                      <site name="FDPR-P1" pos="-0.00552666 -0.0371454 0.00300554" />
                      <site name="FDPM-P1" pos="-0.00574685 -0.0366279 0.00231195" />
                      <site name="FDPI-P1" pos="-0.00712301 -0.0349655 0.0030826" />
                      <site name="EDM-P2" pos="-0.0107561 -0.0430133 0.0339637" />
                      <site name="EDM-P3" pos="-0.00831202 -0.0910138 0.0401399" />
                      <site name="EIP-P1" pos="-0.00433766 -0.183327 0.0405362" />
                      <site name="EIP-P2" pos="0.00188259 -0.192321 0.0445766" />
                      <site name="EPL-P1" pos="-0.0155451 -0.106856 0.0324994" />
                      <joint name="elbow_flexion" type="hinge" pos="0 0 0" axis="  0.0494   0.0366 0.998108" limited="true" range="       0  4.26893" ref="0" user="1" />
                      <body name="radius" pos="0.000440372 -0.012664 0.0220175" quat="1.0 0.0 0.0 0.0">
                        <geom name="radius" type="mesh" mesh="radius" />
                        <inertial pos="0.0370288 -0.199884 0.0171745" mass="0.257166068665101" fullinertia="0.000585191 0.000118212 0.000537193 4.02181e-05 -5.65775e-06 8.56403e-05" />
                        <site name="SUP-P1" pos="0.0109653 -0.0671126 0.000825697" />
                        <site name="SUP-P2" pos="0.0132222 -0.056918 -0.00117799" />
                        <site name="BIClong-P11" pos="-0.00220186 -0.0412848 -0.00220186" />
                        <site name="BIClong-P9" pos=" 0.00273 -0.0343493 -0.0119845" />
                        <site name="BICshort-P8" pos="-0.00220186 -0.0412848 -0.00220186" />
                        <site name="BICshort-P6" pos=" 0.00273 -0.0343493 -0.0119845" />
                        <site name="BRD-P2" pos="0.0393802 -0.14028 0.0254865" />
                        <site name="BRD-P3" pos="0.0461289 -0.243305 0.0246608" />
                        <site name="ECRL-P2" pos="0.0351747 -0.148218 0.0305948" />
                        <site name="ECRL-P3" pos="0.0467124 -0.260744 0.0398536" />
                        <site name="ECRB-P2" pos="0.031982 -0.144068 0.0262572" />
                        <site name="ECRB-P3" pos="0.039072 -0.251067 0.0433436" />
                        <site name="ECU-P5" pos="-0.0156442 -0.249867 0.0383233" />
                        <site name="FCR-P2" pos="0.0232296 -0.241577 0.00139818" />
                        <site name="FCU-P3" pos="0.0119121 -0.245804 0.010668" />
                        <site name="FCU-P2" pos="0.0101156 -0.183524 0.00202653" />
                        <site name="PL-P2" pos="0.0278645 -0.263287 -0.00303856" />
                        <site name="PT-P5" pos="0.0279636 -0.119781 0.0217984" />
                        <site name="PT-P4" pos="0.0259819 -0.102827 0.0103487" />
                        <site name="PQ-P1" pos="0.0357252 -0.220164 0.0216002" />
                        <site name="FDSL-P2" pos="0.0151598 -0.206072 0.00225691" />
                        <site name="FDSR-P2" pos="0.0172956 -0.205499 0.00293948" />
                        <site name="FDSM-P2" pos="0.0209066 -0.20594 0.00466794" />
                        <site name="FDSI-P2" pos="0.0236149 -0.205026 0.00607713" />
                        <site name="FDPL-P2" pos="0.0155121 -0.203848 0.009479" />
                        <site name="FDPR-P2" pos="0.0173947 -0.205092 0.00884046" />
                        <site name="FDPM-P2" pos="0.0209837 -0.205257 0.00864229" />
                        <site name="FDPI-P2" pos="0.0228993 -0.204332 0.0100735" />
                        <site name="EDCL-P3" pos="0.0109322 -0.245551 0.0398316" />
                        <site name="EDCL-P2" pos="  0.0013 -0.0382544 0.0129514" />
                        <site name="EDCR-P3" pos="0.0097102 -0.246234 0.0471638" />
                        <site name="EDCR-P2" pos="  0.0026 -0.0392844 0.0144214" />
                        <site name="EDCM-P3" pos="0.0158534 -0.24576 0.0464922" />
                        <site name="EDCM-P2" pos=" 0.00316 -0.0388544 0.0141814" />
                        <site name="EDCI-P3" pos="0.0168772 -0.245661 0.046195" />
                        <site name="EDCI-P2" pos=" 0.00228 -0.0385544 0.0137314" />
                        <site name="EDM-P4" pos="0.00499822 -0.249261 0.0404922" />
                        <site name="EIP-P3" pos="0.011846 -0.250825 0.040338" />
                        <site name="EPL-P2" pos="0.00136515 -0.150475 0.0249911" />
                        <site name="EPL-P3" pos="0.0297471 -0.240795 0.0421436" />
                        <site name="EPL-P4" pos="0.0372334 -0.250505 0.0507198" />
                        <site name="EPL-P5" pos="0.0466133 -0.261702 0.0459418" />
                        <site name="EPB-P1" pos="0.0211819 -0.161782 0.0232736" />
                        <site name="EPB-P2" pos="0.0250572 -0.174574 0.0293398" />
                        <site name="EPB-P3" pos="0.0421766 -0.217125 0.0422096" />
                        <site name="EPB-P4" pos="0.0576336 -0.25994 0.0297141" />
                        <site name="FPL-P1" pos="0.01069 -0.104126 0.0194754" />
                        <site name="FPL-P2" pos="0.0182534 -0.148901 0.0210828" />
                        <site name="FPL-P3" pos="0.0205764 -0.197419 0.0218865" />
                        <site name="FPL-P4" pos="0.0418353 -0.255096 0.0173947" />
                        <site name="APL-P1" pos="0.0127047 -0.104335 0.0185066" />
                        <site name="APL-P2" pos="0.0333582 -0.1538 0.0386096" />
                        <site name="APL-P3" pos="0.0439601 -0.176941 0.0374316" />
                        <site name="APL-P4" pos="0.0484079 -0.196461 0.0345031" />
                        <site name="APL-P5" pos="0.0606062 -0.254139 0.02607" />
                        <joint name="pro_sup" type="hinge" pos="0 0 0" axis="-0.017161 0.992666 -0.119668" limited="true" range=" -1.5708   1.5708" ref="0" user="1" />
                        <body name="proximal_row" pos="0.0198167 -0.266425 0.0275232" quat="1.0 0.0 0.0 0.0">
                          <geom name="lunate" type="mesh" mesh="lunate" />
                          <geom name="sdfastSCAPHOIDw" type="mesh" mesh="sdfastSCAPHOIDw" />
                          <geom name="sdfastPISIFORMw" type="mesh" mesh="sdfastPISIFORMw" />
                          <geom name="sdfastTRIQUETRALw" type="mesh" mesh="sdfastTRIQUETRALw" />
                          <inertial pos="       0        0        0" mass="0.000110092927207972" fullinertia="1.33438e-05 1.33438e-05 1.33438e-05        0        0        0" />
                          <body name="hand" pos="0.00439491 -0.0165734 0.00256186" quat="1.0 0.0 0.0 0.0">
                            <geom name="sdfast_1seg_hand_fr_c_5mc" type="mesh" mesh="sdfast_1seg_hand_fr_c_5mc" />
                            <geom name="sdfast_1seg_hand_fr_c_4mc" type="mesh" mesh="sdfast_1seg_hand_fr_c_4mc" />
                            <geom name="sdfast_1seg_hand_fr_c_3mc" type="mesh" mesh="sdfast_1seg_hand_fr_c_3mc" />
                            <geom name="sdfast_1seg_hand_fr_c_trapezium" type="mesh" mesh="sdfast_1seg_hand_fr_c_trapezium" />
                            <geom name="sdfast_1seg_hand_fr_c_trapezoid" type="mesh" mesh="sdfast_1seg_hand_fr_c_trapezoid" />
                            <geom name="sdfast_1seg_hand_fr_c_hamate" type="mesh" mesh="sdfast_1seg_hand_fr_c_hamate" />
                            <geom name="capitate" type="mesh" mesh="capitate" />
                            <geom name="hand_3proxph" type="mesh" mesh="hand_3proxph" />
                            <geom name="hand_3midph" type="mesh" mesh="hand_3midph" />
                            <geom name="hand_3distph" type="mesh" mesh="hand_3distph" />
                            <geom name="hand_4proxph" type="mesh" mesh="hand_4proxph" />
                            <geom name="hand_4midph" type="mesh" mesh="hand_4midph" />
                            <geom name="hand_4distph" type="mesh" mesh="hand_4distph" />
                            <geom name="hand_5proxph" type="mesh" mesh="hand_5proxph" />
                            <geom name="hand_5midph" type="mesh" mesh="hand_5midph" />
                            <geom name="hand_5distph" type="mesh" mesh="hand_5distph" />
                            <geom name="hand_thumbprox" type="mesh" mesh="hand_thumbprox" />
                            <geom name="hand_thumbdist" type="mesh" mesh="hand_thumbdist" />
                            <geom name="hand_1mc" type="mesh" mesh="hand_1mc" />
                            <inertial pos="-0.00331725 -0.0467887 -0.0012353" mass="0.640630743423188" fullinertia="0.000146781 8.00626e-05 0.000200156 1.20094e-06 -2.66875e-07 1.60125e-05" />
                            <site name="ECRL-P4" pos="0.018903 -0.0233617 0.00641842" />
                            <site name="ECRB-P4" pos="0.00550465 -0.0125066 0.0093579" />
                            <site name="ECU-P6" pos="-0.0247819 -0.015424 -0.00140919" />
                            <site name="FCR-P3" pos="0.0123744 -0.0203011 -0.00460188" />
                            <site name="FCU-P4" pos="-0.0224149 -0.0194314 -0.00827899" />
                            <site name="PL-P3" pos="0.0100955 -0.0208956 -0.0193103" />
                            <site name="PL-P4" pos="0.00249911 -0.0340848 0.00542758" />
                            <site name="FDSL-P3" pos="-0.00258718 -0.0153359 -0.0151488" />
                            <site name="FDSL-P4" pos="-0.0219635 -0.0471308 -0.0081689" />
                            <site name="FDSL-P5" pos="-0.022503 -0.0658466 -0.0206755" />
                            <site name="FDSL-P6" pos="-0.0188589 -0.0797623 -0.0303086" />
                            <site name="FDSL-P7" pos="-0.0127267 -0.0800486 -0.04025" />
                            <site name="FDSL-P8" pos="-0.0116588 -0.0800486 -0.0417913" />
                            <site name="FDSR-P3" pos="-0.000902762 -0.0147965 -0.0149616" />
                            <site name="FDSR-P4" pos="-0.0107561 -0.0570171 4.40372e-005" />
                            <site name="FDSR-P5" pos="-0.0145653 -0.073432 -0.0112295" />
                            <site name="FDSR-P6" pos="-0.00867532 -0.0883716 -0.0275563" />
                            <site name="FDSR-P7" pos="-0.00329178 -0.0894505 -0.0373765" />
                            <site name="FDSR-P8" pos="0.000682576 -0.0890872 -0.0428482" />
                            <site name="FDSM-P3" pos="0.00748632 -0.0151598 -0.015402" />
                            <site name="FDSM-P4" pos="0.00518538 -0.036683 -0.00145323" />
                            <site name="FDSM-P5" pos="0.00596704 -0.0623126 0.000660558" />
                            <site name="FDSM-P6" pos="0.00611016 -0.0795311 -0.00372114" />
                            <site name="FDSM-P7" pos="0.0128478 -0.0969919 -0.0183855" />
                            <site name="FDSM-P8" pos="0.0143231 -0.0976524 -0.0327747" />
                            <site name="FDSM-P9" pos="0.0172626 -0.0944267 -0.04145" />
                            <site name="FDSI-P3" pos="0.00978726 -0.0150387 -0.0152699" />
                            <site name="FDSI-P4" pos="0.0116809 -0.0416922 0.000264223" />
                            <site name="FDSI-P5" pos="0.0196186 -0.0562355 0.00460188" />
                            <site name="FDSI-P6" pos="0.0203562 -0.0803348 -0.00412848" />
                            <site name="FDSI-P7" pos="0.0294829 -0.095935 -0.0198608" />
                            <site name="FDSI-P8" pos="0.0293618 -0.0962212 -0.0294829" />
                            <site name="FDSI-P9" pos="0.0292847 -0.0950432 -0.03196" />
                            <site name="FDPL-P3" pos="-0.000968818 -0.0113065 -0.013079" />
                            <site name="FDPL-P4" pos="-0.0204222 -0.0511492 -0.00806981" />
                            <site name="FDPL-P5" pos="-0.0199048 -0.0643053 -0.0171745" />
                            <site name="FDPL-P6" pos="-0.0157213 -0.0802467 -0.0295379" />
                            <site name="FDPL-P7" pos="-0.0101285 -0.0823825 -0.0405582" />
                            <site name="FDPL-P8" pos="-0.0034349 -0.0815238 -0.0458537" />
                            <site name="FDPL-P9" pos="0.00491014 -0.0777146 -0.0512703" />
                            <site name="FDPR-P3" pos="0.00116699 -0.0129579 -0.013035" />
                            <site name="FDPR-P4" pos="-0.00941295 -0.0610135 0.000968818" />
                            <site name="FDPR-P5" pos="-0.011879 -0.0725292 -0.00899459" />
                            <site name="FDPR-P6" pos="-0.00602208 -0.0897698 -0.024837" />
                            <site name="FDPR-P7" pos="-0.00061652 -0.0906065 -0.0370683" />
                            <site name="FDPR-P8" pos="0.00670466 -0.0862798 -0.0466574" />
                            <site name="FDPR-P9" pos="0.0133323 -0.0812486 -0.0534831" />
                            <site name="FDPM-P3" pos="0.00368811 -0.0140919 -0.0125946" />
                            <site name="FDPM-P4" pos="0.00332481 -0.037949 -0.00672668" />
                            <site name="FDPM-P5" pos="0.00277434 -0.0645475 0.00134313" />
                            <site name="FDPM-P6" pos="0.00313765 -0.0768999 -0.00146424" />
                            <site name="FDPM-P7" pos="0.00950102 -0.0966506 -0.0199819" />
                            <site name="FDPM-P8" pos="0.0110313 -0.0965075 -0.0326315" />
                            <site name="FDPM-P9" pos="0.0179782 -0.0898028 -0.0488262" />
                            <site name="FDPM-P10" pos="0.0210167 -0.0843642 -0.0575676" />
                            <site name="FDPI-P3" pos="0.00986433 -0.0128589 -0.0133433" />
                            <site name="FDPI-P4" pos="0.0211599 -0.0610135 0.00482207" />
                            <site name="FDPI-P5" pos="0.0228223 -0.0772962 -0.00314866" />
                            <site name="FDPI-P6" pos="0.031971 -0.0945478 -0.0196186" />
                            <site name="FDPI-P7" pos="0.0321912 -0.0954726 -0.0304847" />
                            <site name="FDPI-P8" pos="0.0320811 -0.0906615 -0.043806" />
                            <site name="FDPI-P9" pos="0.0313435 -0.0855532 -0.0524703" />
                            <site name="EDCL-P4" pos="-0.0271269 -0.0484629 0.00186057" />
                            <site name="EDCL-P5" pos="-0.0262131 -0.052118 0.000847716" />
                            <site name="EDCL-P6" pos="-0.0263673 -0.0728045 -0.0110203" />
                            <site name="EDCL-P7" pos="-0.0197947 -0.0863899 -0.0298462" />
                            <site name="EDCL-P8" pos="-0.0129689 -0.0867202 -0.0416041" />
                            <site name="EDCL-P9" pos="-0.00165139 -0.0835165 -0.0504886" />
                            <site name="EDCL-P10" pos="0.00221287 -0.0824266 -0.0527785" />
                            <site name="EDCR-P4" pos="-0.0172185 -0.0611016 0.0102827" />
                            <site name="EDCR-P5" pos="-0.0157103 -0.0640631 0.0127818" />
                            <site name="EDCR-P6" pos="-0.0173947 -0.0794431 -0.00463491" />
                            <site name="EDCR-P7" pos="-0.00908267 -0.0961662 -0.024881" />
                            <site name="EDCR-P8" pos="-0.00299453 -0.0969478 -0.0375307" />
                            <site name="EDCR-P9" pos="0.00840009 -0.0883606 -0.0512813" />
                            <site name="EDCR-P10" pos="0.0117689 -0.0859716 -0.0543969" />
                            <site name="EDCM-P4" pos="0.000429362 -0.058063 0.0164149" />
                            <site name="EDCM-P5" pos="-0.000957808 -0.0613658 0.0159855" />
                            <site name="EDCM-P6" pos="0.00204773 -0.0849697 0.00657255" />
                            <site name="EDCM-P7" pos="0.0110864 -0.10253 -0.0195305" />
                            <site name="EDCM-P8" pos="0.0145433 -0.105227 -0.0336444" />
                            <site name="EDCM-P9" pos="0.0204443 -0.0938542 -0.0523932" />
                            <site name="EDCM-P10" pos="0.0226351 -0.0879973 -0.0588006" />
                            <site name="EDCM-P11" pos="0.0241654 -0.0847826 -0.0623456" />
                            <site name="EDCI-P4" pos="0.0169873 -0.0515235 0.0180442" />
                            <site name="EDCI-P5" pos="0.0208846 -0.0622465 0.0158314" />
                            <site name="EDCI-P6" pos="0.0219525 -0.0845293 0.00653952" />
                            <site name="EDCI-P7" pos="0.0324224 -0.100867 -0.0137066" />
                            <site name="EDCI-P8" pos="0.03436 -0.102926 -0.031982" />
                            <site name="EDCI-P9" pos="0.033171 -0.0934359 -0.0469877" />
                            <site name="EDCI-P10" pos="0.0322462 -0.0892083 -0.0546721" />
                            <site name="EDM-P5" pos="-0.0226681 -0.0113616 0.00409546" />
                            <site name="EDM-P6" pos="-0.0282168 -0.0519859 0.000253214" />
                            <site name="EDM-P7" pos="-0.0280627 -0.0716815 -0.0120882" />
                            <site name="EDM-P8" pos="-0.021281 -0.0859826 -0.0299233" />
                            <site name="EDM-P9" pos="-0.0148185 -0.0868853 -0.0428702" />
                            <site name="EDM-P10" pos="-0.00237801 -0.0828009 -0.0505216" />
                            <site name="EDM-P11" pos="0.00145323 -0.0808633 -0.0528776" />
                            <site name="EIP-P4" pos="0.00427161 -0.0245948 0.013035" />
                            <site name="EIP-P5" pos="0.0186387 -0.0620924 0.0151598" />
                            <site name="EIP-P6" pos="0.0191011 -0.0846835 0.0063964" />
                            <site name="EIP-P7" pos="0.0304407 -0.102541 -0.016635" />
                            <site name="EIP-P8" pos="0.0316958 -0.103895 -0.0310792" />
                            <site name="EIP-P9" pos="0.0315967 -0.0938432 -0.0472849" />
                            <site name="EIP-P10" pos="0.0312003 -0.0857073 -0.0605621" />
                            <site name="EPL-P6" pos="0.0267306 0.00015413 0.00669365" />
                            <site name="EPL-P7" pos="0.0257397 -0.0100955 -0.000429362" />
                            <site name="EPL-P8" pos="0.031982 -0.0157103 -0.00538354" />
                            <site name="EPL-P9" pos="0.048595 -0.0376188 -0.0199709" />
                            <site name="EPL-P10" pos="0.0535822 -0.0511492 -0.0273801" />
                            <site name="EPL-P11" pos="0.0523051 -0.0771751 -0.0415491" />
                            <site name="EPL-P12" pos="0.0441583 -0.0832853 -0.0471528" />
                            <site name="EPB-P5" pos="0.034382 0.00281838 -0.00360004" />
                            <site name="EPB-P6" pos="0.0327196 -0.00874138 -0.0158093" />
                            <site name="EPB-P7" pos="0.0486831 -0.0363307 -0.0266645" />
                            <site name="EPB-P8" pos="0.0498501 -0.0526795 -0.0350756" />
                            <site name="FPL-P6" pos="0.0136956 -0.0242975 -0.0229984" />
                            <site name="FPL-P7" pos="0.0180662 -0.0288554 -0.0244516" />
                            <site name="FPL-P8" pos="0.0270498 -0.0362646 -0.0246278" />
                            <site name="FPL-P9" pos="0.0311233 -0.0603529 -0.0336334" />
                            <site name="FPL-P10" pos="0.0386536 -0.0717696 -0.0412738" />
                            <site name="FPL-P11" pos="0.0388958 -0.0842871 -0.0453363" />
                            <site name="FPL-P5" pos="0.0178892 0.0064176 -0.0168214" />
                            <site name="APL-P7" pos="0.028481 0.00225691 -0.0181653" />
                            <site name="APL-P8" pos="0.0316847 -0.00742026 -0.0205874" />
                            <site name="APL-P9" pos="0.0338646 -0.0174277 -0.0207525" />
                            <site name="APL-P6" pos="0.0332244 0.00608975 -0.00870125" />
                            <body name="index0" pos="0 0 0">
                              <inertial pos="0 0 0" mass="0.001" diaginertia="0.001 0.001 0.001" />
                              <geom name="sdfast_1seg_hand_fr_c_2mc" type="mesh" mesh="sdfast_1seg_hand_fr_c_2mc" />
                              <body name="index1" pos="0 0 0">
                                <inertial pos="0 0 0" mass="0.001" diaginertia="0.001 0.001 0.001" />
                                <geom name="hand_2proxph" type="mesh" mesh="hand_2proxph" />
                                <body name="index2" pos="0 0 0">
                                  <inertial pos="0 0 0" mass="0.001" diaginertia="0.001 0.001 0.001" />
                                  <geom name="hand_2midph" type="mesh" mesh="hand_2midph" />
                                  <body name="index3" pos="0 0 0">
                                    <inertial pos="0 0 0" mass="0.001" diaginertia="0.001 0.001 0.001" />
                                    <geom name="hand_2distph" type="mesh" mesh="hand_2distph" />
                                    <site name="fingertip" pos="0.024 -0.149 -0.0065" type="sphere" rgba="0.1 0.8 0.1 0.0" size="0.004" />
                                  </body>
                                </body>
                              </body>
                            </body>
                          </body>
                        </body>
                      </body>
                    </body>
                  </body>
                </body>
              </body>
            </body>
          </body>
        </body>
      </body>
    </body>

</mujocoinclude>