<mujocoinclude model="MoBL Arms Index Model">

    <body name="thorax" pos="0 0 0" quat="0.7071067811865475 0.7071067811865475 0.0 0.0">
      <light mode="trackcom" directional="false" pos="0 0 4.0" dir="0 0 -1" />
      <geom name="thorax" type="mesh" mesh="thorax" />
      <site name="PECM1-P3" pos="  -7e-05  0.00821  0.10454" />
      <site name="PECM2-P4" pos="0.0316361 -0.0401413 0.0993297" />
      <site name="PECM2-P5" pos="0.0283404 -0.0460366 0.0232435" />
      <site name="PECM2-P3" pos=" 0.02083 -0.02005  0.11555" />
      <site name="PECM3-P4" pos="0.0537332 -0.0861471 0.0914488" />
      <site name="PECM3-P5" pos="0.0585846 -0.119278 0.0387596" />
      <site name="PECM3-P3" pos=" 0.02984 -0.0544459   0.1151" />
      <site name="LAT1-P4" pos="-0.121058 -0.103557 0.0339389" />
      <site name="LAT1-P5" pos="-0.0980299 -0.119994 0.00902718" />
      <site name="LAT2-P4" pos="-0.112502 -0.173052 0.029456" />
      <site name="LAT2-P5" pos="-0.073548 -0.1926 0.00834144" />
      <site name="LAT3-P4" pos="-0.114191 -0.198424 0.0566195" />
      <site name="LAT3-P5" pos="-0.0728418 -0.254419 0.00928305" />
      <joint name="r_z" type="hinge" pos="0 0 0" axis="       0        0        1" limited="true" range="-6.28319  6.28319" ref="0" armature="0" damping="0" stiffness="0" />
      <body name="clavicle" pos="0.00647357 0.00709279 0.0260632" quat="1.0 0.0 0.0 0.0">
        <geom name="clavicle" type="mesh" mesh="clavicle" />
        <inertial pos="-0.0113566 0.00652198 0.0554404" mass="0.159664429527791" fullinertia="0.00026009 0.000273674 4.76244e-05 -2.03492e-05 -7.49853e-05 5.75845e-05" />
        <site name="DELT1-P4" pos="-0.0143289 0.0113198 0.0820941" />
        <site name="DELT2-P2" pos="0.0191703 0.0244002 0.162891" />
        <site name="PECM1-P4" pos="0.0032854 -0.000133054 0.052331" />
        <joint name="sternoclavicular_r2" type="hinge" pos="0 0 0" axis="  0.0153 0.989299  -0.1451" limited="false" range="-99999.9  99999.9" ref="0" />
        <joint name="sternoclavicular_r3" type="hinge" pos="0 0 0" axis="-0.994473        0 -0.104997" limited="false" range="-99999.9  99999.9" ref="0" />
        <body name="clavphant" pos="-0.0146666 0.0205414 0.138719" quat="1.0 0.0 0.0 0.0">
          <inertial pos="       0        0        0" mass="0.000102348993287046" fullinertia=" 1.07214  1.07214  1.07214        0        0        0" />
          <joint name="unrotscap_r3" type="hinge" pos="0 0 0" axis="-0.994473        0 -0.104997" limited="false" range="-99999.9  99999.9" ref="0" />
          <joint name="unrotscap_r2" type="hinge" pos="0 0 0" axis="  0.0153 0.989299  -0.1451" limited="false" range="-99999.9  99999.9" ref="0" />
          <body name="scapula" pos="       0        0        0" quat="1.0 0.0 0.0 0.0">
            <geom name="scapula" type="mesh" mesh="scapula" />
            <inertial pos="-0.0559788 -0.0358549 -0.0447613" mass="0.720495973143487" fullinertia="0.00133256 0.00123339 0.00146358 0.000481819 0.00043874 0.000258492" />
            <site name="DELT1-P3" pos="0.0444911 -0.0332839 0.00101326" />
            <site name="DELT2-P3" pos="5.11745e-005 0.00300906 0.0228545" />
            <site name="DELT2-P4" pos="-0.0110332 -0.000347987 0.00634564" />
            <site name="DELT3-P1" pos="-0.0570391 0.00124866 -0.0257101" />
            <site name="DELT3-P2" pos="-0.0741723 -0.0336216 0.0126196" />
            <site name="SUPSP-P2" pos="-0.0196305 0.00129983 -0.0130086" />
            <site name="SUPSP-P3" pos="-0.0450336 -0.0154752 -0.0599253" />
            <site name="INFSP-P2" pos="-0.075554 -0.0560463 -0.0489331" />
            <site name="SUBSC-P2" pos="-0.0187401 -0.0534569 -0.0251471" />
            <site name="SUBSC-P3" pos="-0.0741621 -0.0403562 -0.066271" />
            <site name="TMIN-P2" pos="-0.0969552 -0.0817871 -0.0484827" />
            <site name="TMIN-P3" pos="-0.0986951 -0.0831176 -0.0542245" />
            <site name="TMAJ-P2" pos="-0.105051 -0.105614 -0.0596592" />
            <site name="TMAJ-P3" pos="-0.107354 -0.111509 -0.0728418" />
            <site name="LAT1-P2" pos="-0.08052 -0.06821 -0.02908" />
            <site name="LAT1-P3" pos="-0.10925 -0.07239 -0.07422" />
            <site name="LAT2-P2" pos="-0.08345 -0.08695 -0.02453" />
            <site name="LAT2-P3" pos="-0.11524 -0.10749 -0.08863" />
            <site name="LAT3-P2" pos="-0.08438 -0.11598 -0.02995" />
            <site name="LAT3-P3" pos="-0.11279 -0.13833 -0.08911" />
            <site name="CORB-P1" pos="0.0127936 -0.0422394 -0.027143" />
            <site name="CORB-P2" pos="0.00494346 -0.0712144 -0.0159971" />
            <site name="TRIlong-P1" pos="-0.0467223 -0.0416867 -0.0140935" />
            <site name="BIClong-P1" pos="-0.0319636 -0.0240827 -0.0133565" />
            <site name="BIClong-P2" pos="-0.0214319 -0.0133975 -0.00471829" />
            <site name="BICshort-P1" pos="0.0129779 -0.0402334 -0.0268666" />
            <site name="BICshort-P2" pos="0.000951846 -0.0686148 -0.0163042" />
            <joint name="acromioclavicular_r2" type="hinge" pos="0 0 0" axis="0.157095 0.947269 -0.279291" limited="false" range="-99999.9  99999.9" ref="0" />
            <joint name="acromioclavicular_r3" type="hinge" pos="0 0 0" axis="-0.754084 0.297594 0.585487" limited="false" range="-99999.9  99999.9" ref="0" />
            <joint name="acromioclavicular_r1" type="hinge" pos="0 0 0" axis="  0.6377   0.1186   0.7611" limited="false" range="-99999.9  99999.9" ref="0" />
            <body name="scapphant" pos="-0.00977433 -0.0347987 0.00921141" quat="1.0 0.0 0.0 0.0">
              <inertial pos="       0        0        0" mass="0.000102348993287046" fullinertia=" 1.07214  1.07214  1.07214        0        0        0" />
              <joint name="unrothum_r1" type="hinge" pos="0 0 0" axis="  0.6377   0.1186   0.7611" limited="false" range="-99999.9  99999.9" ref="0" />
              <joint name="unrothum_r3" type="hinge" pos="0 0 0" axis="-0.754084 0.297594 0.585487" limited="false" range="-99999.9  99999.9" ref="0" />
              <joint name="unrothum_r2" type="hinge" pos="0 0 0" axis="0.157095 0.947269 -0.279291" limited="false" range="-99999.9  99999.9" ref="0" />
              <body name="humphant" pos="       0        0        0" quat="1.0 0.0 0.0 0.0">
                <inertial pos="       0        0        0" mass="0.000102348993287046" fullinertia=" 1.07214  1.07214  1.07214        0        0        0" />
                <joint name="elv_angle" type="hinge" pos="0 0 0" axis="  0.0048 0.999089   0.0424" limited="true" range=" -1.5708  2.26893" ref="0" user="1" />
                <body name="humphant1" pos="       0        0        0" quat="1.0 0.0 0.0 0.0">
                  <inertial pos="       0        0        0" mass="0.000102348993287046" fullinertia=" 1.07214  1.07214  1.07214        0        0        0" />
                  <joint name="shoulder_elv" type="hinge" pos="0 0 0" axis="-0.998261   0.0023 0.058898" limited="true" range="       0  3.14159" ref="0" user="1" />
                  <joint name="shoulder1_r2" type="hinge" pos="0 0 0" axis="  0.0048 0.999089   0.0424" limited="false" range="-99999.9  99999.9" ref="0" />
                  <body name="humerus" pos="       0        0        0" quat="1.0 0.0 0.0 0.0">
                    <geom name="humerus" type="mesh" mesh="humerus" />
                    <inertial pos="0.0184883 -0.143433 -0.0130454" mass="2.04449278520404" fullinertia="0.0131633 0.00273538 0.0134863 -0.000372471 -0.000249272 0.00131798" />
                    <site name="DELT1-P1" pos="0.00917047 -0.121621 0.00598742" />
                    <site name="DELT1-P2" pos="0.0166112 -0.112922 0.00421678" />
                    <site name="DELT2-P1" pos="0.00471829 -0.139307 0.00573154" />
                    <site name="DELT3-P3" pos="0.00210839 -0.0778057 0.0106955" />
                    <site name="SUPSP-P1" pos="0.00262013 0.0108797 0.0265391" />
                    <site name="INFSP-P1" pos="-0.00907836 0.00495369 0.025055" />
                    <site name="SUBSC-P1" pos="0.0143596 0.00859732 -0.0136227" />
                    <site name="TMIN-P1" pos="-0.00112584 -0.0129369 0.0220664" />
                    <site name="TMAJ-P1" pos="0.0102144 -0.0554629 -0.00581342" />
                    <site name="PECM1-P1" pos="0.0119646 -0.0428945 0.00798322" />
                    <site name="PECM1-P2" pos="  0.0191  -0.0301  0.00143" />
                    <site name="PECM2-P1" pos="0.0130393 -0.0438975 0.0080344" />
                    <site name="PECM2-P2" pos=" 0.01748 -0.03533  0.00033" />
                    <site name="PECM3-P1" pos="0.0129881 -0.0447777 0.00767617" />
                    <site name="PECM3-P2" pos="0.0159185 -0.045833 -0.00378312" />
                    <site name="LAT1-P1" pos="0.0107466 -0.0349522 -0.00668339" />
                    <site name="LAT2-P1" pos="0.00990738 -0.0416663 -0.00625352" />
                    <site name="LAT3-P1" pos="0.0123638 -0.0401413 -0.00425772" />
                    <site name="CORB-P3" pos="0.00760453 -0.154015 -0.00800369" />
                    <site name="TRIlong-P2" pos="-0.0277775 -0.117097 -0.00679597" />
                    <site name="TRIlong-P3" pos="-0.0325879 -0.231687 -0.0124559" />
                    <site name="TRIlong-P4" pos="-0.0178394 -0.273855 -0.0123638" />
                    <site name="TRIlat-P1" pos="-0.0061307 -0.129431 0.00438054" />
                    <site name="TRIlat-P2" pos="-0.0239906 -0.148693 0.00949799" />
                    <site name="TRIlat-P3" pos="-0.0325879 -0.231687 -0.0124559" />
                    <site name="TRIlat-P4" pos="-0.0178394 -0.273855 -0.0123638" />
                    <site name="TRImed-P1" pos="-0.00857685 -0.140167 -0.00927282" />
                    <site name="TRImed-P2" pos="-0.026621 -0.154946 -0.0110537" />
                    <site name="TRImed-P3" pos="-0.0325879 -0.231687 -0.0124559" />
                    <site name="TRImed-P4" pos="-0.0178394 -0.273855 -0.0123638" />
                    <site name="ANC-P1" pos="-0.00761477 -0.290252 0.01002" />
                    <site name="BIClong-P3" pos="0.0218106 0.0183512 0.0105215" />
                    <site name="BIClong-P4" pos="0.0243386 -0.00523003 0.0122921" />
                    <site name="BIClong-P5" pos="0.0137659 -0.0289341 0.00139195" />
                    <site name="BIClong-P6" pos="0.0109309 -0.0791772 -0.00168876" />
                    <site name="BIClong-P7" pos="0.01743 -0.124098 0.000245638" />
                    <site name="BIClong-P8" pos="0.0233356 -0.17952 -0.00644799" />
                    <site name="BICshort-P3" pos="0.0114324 -0.0775396 -0.0112686" />
                    <site name="BICshort-P4" pos="0.01743 -0.124098 -0.0110435" />
                    <site name="BICshort-P5" pos="0.0233356 -0.17952 -0.00644799" />
                    <site name="BRA-P1" pos="0.00695973 -0.177985 -0.00368456" />
                    <site name="BRA-P2" pos="0.0193849 -0.292298 -0.0113096" />
                    <site name="BRD-P1" pos="-0.0100302 -0.204319 0.00228238" />
                    <site name="ECRL-P1" pos="-0.00747148 -0.267029 0.00931376" />
                    <site name="ECRB-P1" pos="0.0138069 -0.297303 0.0173789" />
                    <site name="ECU-P1" pos="0.000849497 -0.296352 0.0192416" />
                    <site name="FCR-P1" pos="0.00775805 -0.284592 -0.0379203" />
                    <site name="FCU-P1" pos="0.00224144 -0.283916 -0.0397114" />
                    <site name="PL-P1" pos="0.00467735 -0.281654 -0.0395579" />
                    <site name="PT-P1" pos="0.00368456 -0.282381 -0.0373574" />
                    <site name="FDSL-P1" pos="0.00430889 -0.282463 -0.0395477" />
                    <site name="FDSR-P1" pos="0.00490252 -0.285349 -0.0381864" />
                    <site name="EDCL-P1" pos="-0.000409396 -0.295082 0.0191393" />
                    <site name="EDCR-P1" pos="-0.00159664 -0.296157 0.0182386" />
                    <site name="EDCM-P1" pos="0.00052198 -0.296648 0.0199478" />
                    <site name="EDCI-P1" pos="0.000665268 -0.295768 0.019129" />
                    <site name="EDM-P1" pos="0.000910906 -0.295983 0.0189039" />
                    <joint name="shoulder_rot" type="hinge" pos="0 0 0" axis="  0.0048 0.999089   0.0424" limited="true" range=" -1.5708 0.349066" ref="0" user="1" />
                    <body name="ulna" pos="0.00624329 -0.297221 -0.0125889" quat="1.0 0.0 0.0 0.0">
                      <geom name="ulna" type="mesh" mesh="ulna" />
                      <inertial pos="0.0099461 -0.0982048 0.0248565" mass="1.13126342280172" fullinertia="0.00580358 0.00123637 0.00530023 0.000339718 -8.16433e-05 0.00117044" />
                      <site name="TRIlong-P5" pos="-0.0224144 0.0107057 -0.000798322" />
                      <site name="TRIlat-P5" pos="-0.0224144 0.0107057 -0.000798322" />
                      <site name="TRImed-P5" pos="-0.0224144 0.0107057 -0.000798322" />
                      <site name="ANC-P2" pos="-0.0259148 -0.00126913 0.00614094" />
                      <site name="SUP-P3" pos="-0.0139195 -0.0346349 0.0206029" />
                      <site name="BRA-P4" pos="-0.00327517 -0.0244614 0.000921141" />
                      <site name="BRA-P3" pos="0.00509698 -0.0149737 0.00131007" />
                      <site name="ECU-P2" pos="-0.0142367 -0.0327619 0.0301622" />
                      <site name="ECU-P3" pos="-0.0174505 -0.055555 0.0293537" />
                      <site name="ECU-P4" pos="-0.0183512 -0.0979787 0.03355" />
                      <site name="PT-P2" pos="0.00865872 -0.0345223 -0.0146564" />
                      <site name="PT-P3" pos=" 0.01219 -0.06516 -0.00219" />
                      <site name="PQ-P2" pos="0.00197534 -0.214646 0.0371732" />
                      <site name="FDSM-P1" pos="-0.00684715 -0.0277673 -0.00195487" />
                      <site name="FDSI-P1" pos="-0.00691879 -0.0288522 -0.00140218" />
                      <site name="FDPL-P1" pos="-0.00642752 -0.032895 0.00259966" />
                      <site name="FDPR-P1" pos="-0.00513792 -0.0345326 0.00279413" />
                      <site name="FDPM-P1" pos="-0.00534262 -0.0340515 0.00214933" />
                      <site name="FDPI-P1" pos="-0.00662198 -0.032506 0.00286577" />
                      <site name="EDM-P2" pos="-0.0099995 -0.0399878 0.0315747" />
                      <site name="EDM-P3" pos="-0.00772735 -0.0846119 0.0373164" />
                      <site name="EIP-P1" pos="-0.00403255 -0.170432 0.0376849" />
                      <site name="EIP-P2" pos="0.00175017 -0.178793 0.0414411" />
                      <site name="EPL-P1" pos="-0.0144517 -0.0993399 0.0302134" />
                      <joint name="elbow_flexion" type="hinge" pos="0 0 0" axis="  0.0494   0.0366 0.998108" limited="true" range="       0  4.26893" ref="0" user="1" />
                      <body name="radius" pos="0.000409396 -0.0117732 0.0204688" quat="1.0 0.0 0.0 0.0">
                        <geom name="radius" type="mesh" mesh="radius" />
                        <inertial pos="0.0344242 -0.185824 0.0159664" mass="0.23907701341921" fullinertia="0.000470186 9.49807e-05 0.000431621 3.23142e-05 -4.54587e-06 6.88098e-05" />
                        <site name="SUP-P1" pos="0.010194 -0.0623919 0.000767617" />
                        <site name="SUP-P2" pos="0.0122921 -0.0529144 -0.00109513" />
                        <site name="BIClong-P11" pos="-0.00204698 -0.0383809 -0.00204698" />
                        <site name="BIClong-P9" pos=" 0.00273 -0.0343493 -0.0119845" />
                        <site name="BICshort-P8" pos="-0.00204698 -0.0383809 -0.00204698" />
                        <site name="BICshort-P6" pos=" 0.00273 -0.0343493 -0.0119845" />
                        <site name="BRD-P2" pos="0.0366102 -0.130413 0.0236938" />
                        <site name="BRD-P3" pos="0.0428842 -0.226191 0.0229262" />
                        <site name="ECRL-P2" pos="0.0327005 -0.137792 0.0284428" />
                        <site name="ECRL-P3" pos="0.0434267 -0.242403 0.0370503" />
                        <site name="ECRB-P2" pos="0.0297324 -0.133934 0.0244102" />
                        <site name="ECRB-P3" pos="0.0363237 -0.233407 0.0402948" />
                        <site name="ECU-P5" pos="-0.0145438 -0.232291 0.0356277" />
                        <site name="FCR-P2" pos="0.0215956 -0.224584 0.00129983" />
                        <site name="FCU-P3" pos="0.0110742 -0.228515 0.00991762" />
                        <site name="FCU-P2" pos="0.0101156 -0.183524 0.00202653" />
                        <site name="PL-P2" pos="0.0259045 -0.244768 -0.00282483" />
                        <site name="PT-P5" pos="0.0259966 -0.111356 0.0202651" />
                        <site name="PT-P4" pos="0.0241544 -0.095594 0.00962081" />
                        <site name="PQ-P1" pos="0.0332122 -0.204678 0.0200809" />
                        <site name="FDSL-P2" pos="0.0140935 -0.191577 0.00209815" />
                        <site name="FDSR-P2" pos="0.016079 -0.191045 0.00273272" />
                        <site name="FDSM-P2" pos="0.0194361 -0.191454 0.0043396" />
                        <site name="FDSI-P2" pos="0.0219539 -0.190605 0.00564966" />
                        <site name="FDPL-P2" pos="0.014421 -0.189509 0.00881225" />
                        <site name="FDPR-P2" pos="0.0161711 -0.190666 0.00821862" />
                        <site name="FDPM-P2" pos="0.0195077 -0.190819 0.0080344" />
                        <site name="FDPI-P2" pos="0.0212886 -0.18996 0.00936493" />
                        <site name="EDCL-P3" pos="0.0101633 -0.228279 0.0370299" />
                        <site name="EDCL-P2" pos="  0.0013 -0.0382544 0.0129514" />
                        <site name="EDCR-P3" pos="0.00902718 -0.228914 0.0438463" />
                        <site name="EDCR-P2" pos="  0.0026 -0.0392844 0.0144214" />
                        <site name="EDCM-P3" pos="0.0147383 -0.228474 0.043222" />
                        <site name="EDCM-P2" pos=" 0.00316 -0.0388544 0.0141814" />
                        <site name="EDCI-P3" pos="0.0156901 -0.228382 0.0429456" />
                        <site name="EDCI-P2" pos=" 0.00228 -0.0385544 0.0137314" />
                        <site name="EDM-P4" pos="0.00464664 -0.231728 0.037644" />
                        <site name="EIP-P3" pos="0.0110128 -0.233182 0.0375007" />
                        <site name="EPL-P2" pos="0.00126913 -0.139891 0.0232332" />
                        <site name="EPL-P3" pos="0.0276547 -0.223858 0.0391792" />
                        <site name="EPL-P4" pos="0.0346144 -0.232885 0.0471522" />
                        <site name="EPL-P5" pos="0.0433346 -0.243294 0.0427102" />
                        <site name="EPB-P1" pos="0.0196919 -0.150402 0.0216366" />
                        <site name="EPB-P2" pos="0.0232946 -0.162295 0.027276" />
                        <site name="EPB-P3" pos="0.0392099 -0.201853 0.0392406" />
                        <site name="EPB-P4" pos="0.0535797 -0.241656 0.027624" />
                        <site name="FPL-P1" pos="0.00993809 -0.0968017 0.0181055" />
                        <site name="FPL-P2" pos="0.0169695 -0.138427 0.0195998" />
                        <site name="FPL-P3" pos="0.019129 -0.183532 0.020347" />
                        <site name="FPL-P4" pos="0.0388926 -0.237153 0.0161711" />
                        <site name="APL-P1" pos="0.0118111 -0.0969961 0.0172049" />
                        <site name="APL-P2" pos="0.0310117 -0.142982 0.0358938" />
                        <site name="APL-P3" pos="0.040868 -0.164495 0.0347987" />
                        <site name="APL-P4" pos="0.0450029 -0.182642 0.0320762" />
                        <site name="APL-P5" pos="0.0563431 -0.236262 0.0242362" />
                        <joint name="pro_sup" type="hinge" pos="0 0 0" axis="-0.017161 0.992666 -0.119668" limited="true" range=" -1.5708   1.5708" ref="0" user="1" />
                        <body name="proximal_row" pos="0.0184228 -0.247685 0.0255872" quat="1.0 0.0 0.0 0.0">
                          <geom name="lunate" type="mesh" mesh="lunate" />
                          <geom name="sdfastSCAPHOIDw" type="mesh" mesh="sdfastSCAPHOIDw" />
                          <geom name="sdfastPISIFORMw" type="mesh" mesh="sdfastPISIFORMw" />
                          <geom name="sdfastTRIQUETRALw" type="mesh" mesh="sdfastTRIQUETRALw" />
                          <inertial pos="       0        0        0" mass="0.000102348993287046" fullinertia="1.07214e-05 1.07214e-05 1.07214e-05        0        0        0" />
                          <body name="hand" pos="0.00408577 -0.0154076 0.00238166" quat="1.0 0.0 0.0 0.0">
                            <geom name="sdfast_1seg_hand_fr_c_5mc" type="mesh" mesh="sdfast_1seg_hand_fr_c_5mc" />
                            <geom name="sdfast_1seg_hand_fr_c_4mc" type="mesh" mesh="sdfast_1seg_hand_fr_c_4mc" />
                            <geom name="sdfast_1seg_hand_fr_c_3mc" type="mesh" mesh="sdfast_1seg_hand_fr_c_3mc" />
                            <geom name="sdfast_1seg_hand_fr_c_trapezium" type="mesh" mesh="sdfast_1seg_hand_fr_c_trapezium" />
                            <geom name="sdfast_1seg_hand_fr_c_trapezoid" type="mesh" mesh="sdfast_1seg_hand_fr_c_trapezoid" />
                            <geom name="sdfast_1seg_hand_fr_c_hamate" type="mesh" mesh="sdfast_1seg_hand_fr_c_hamate" />
                            <geom name="capitate" type="mesh" mesh="capitate" />
                            <geom name="hand_3proxph" type="mesh" mesh="hand_3proxph" />
                            <geom name="hand_3midph" type="mesh" mesh="hand_3midph" />
                            <geom name="hand_3distph" type="mesh" mesh="hand_3distph" />
                            <geom name="hand_4proxph" type="mesh" mesh="hand_4proxph" />
                            <geom name="hand_4midph" type="mesh" mesh="hand_4midph" />
                            <geom name="hand_4distph" type="mesh" mesh="hand_4distph" />
                            <geom name="hand_5proxph" type="mesh" mesh="hand_5proxph" />
                            <geom name="hand_5midph" type="mesh" mesh="hand_5midph" />
                            <geom name="hand_5distph" type="mesh" mesh="hand_5distph" />
                            <geom name="hand_thumbprox" type="mesh" mesh="hand_thumbprox" />
                            <geom name="hand_thumbdist" type="mesh" mesh="hand_thumbdist" />
                            <geom name="hand_1mc" type="mesh" mesh="hand_1mc" />
                            <inertial pos="-0.00308392 -0.0434976 -0.00114841" mass="0.595568791937319" fullinertia="0.000117935 6.43283e-05 0.000160821 9.64924e-07 -2.14428e-07 1.28657e-05" />
                            <site name="ECRL-P4" pos="0.0175733 -0.0217185 0.00596695" />
                            <site name="ECRB-P4" pos="0.00511745 -0.0116268 0.00869966" />
                            <site name="ECU-P6" pos="-0.0230388 -0.0143391 -0.00131007" />
                            <site name="FCR-P3" pos="0.011504 -0.0188732 -0.00427819" />
                            <site name="FCU-P4" pos="-0.0208383 -0.0180646 -0.00769664" />
                            <site name="PL-P3" pos="0.0093854 -0.0194258 -0.017952" />
                            <site name="PL-P4" pos="0.00232332 -0.0316872 0.00504581" />
                            <site name="FDSL-P3" pos="-0.0024052 -0.0142572 -0.0140832" />
                            <site name="FDSL-P4" pos="-0.0204186 -0.0438156 -0.0075943" />
                            <site name="FDSL-P5" pos="-0.0209201 -0.0612149 -0.0192211" />
                            <site name="FDSL-P6" pos="-0.0175324 -0.0741518 -0.0281767" />
                            <site name="FDSL-P7" pos="-0.0118315 -0.074418 -0.0374188" />
                            <site name="FDSL-P8" pos="-0.0108388 -0.074418 -0.0388517" />
                            <site name="FDSR-P3" pos="-0.000839262 -0.0137557 -0.0139092" />
                            <site name="FDSR-P4" pos="-0.0099995 -0.0530065 4.09396e-005" />
                            <site name="FDSR-P5" pos="-0.0135408 -0.0682668 -0.0104396" />
                            <site name="FDSR-P6" pos="-0.0080651 -0.0821555 -0.025618" />
                            <site name="FDSR-P7" pos="-0.00306023 -0.0831586 -0.0347475" />
                            <site name="FDSR-P8" pos="0.000634564 -0.0828208 -0.0398342" />
                            <site name="FDSM-P3" pos="0.00695973 -0.0140935 -0.0143186" />
                            <site name="FDSM-P4" pos="0.00482064 -0.0341027 -0.00135101" />
                            <site name="FDSM-P5" pos="0.00554732 -0.0579295 0.000614094" />
                            <site name="FDSM-P6" pos="0.00568037 -0.0739369 -0.0034594" />
                            <site name="FDSM-P7" pos="0.0119441 -0.0901695 -0.0170923" />
                            <site name="FDSM-P8" pos="0.0133156 -0.0907836 -0.0304693" />
                            <site name="FDSM-P9" pos="0.0160483 -0.0877847 -0.0385344" />
                            <site name="FDSI-P3" pos="0.00909883 -0.0139809 -0.0141958" />
                            <site name="FDSI-P4" pos="0.0108592 -0.0387596 0.000245638" />
                            <site name="FDSI-P5" pos="0.0182386 -0.0522799 0.00427819" />
                            <site name="FDSI-P6" pos="0.0189243 -0.0746841 -0.00383809" />
                            <site name="FDSI-P7" pos="0.0274091 -0.0891869 -0.0184638" />
                            <site name="FDSI-P8" pos="0.0272965 -0.089453 -0.0274091" />
                            <site name="FDSI-P9" pos="0.0272248 -0.0883579 -0.0297119" />
                            <site name="FDPL-P3" pos="-0.000900671 -0.0105112 -0.0121591" />
                            <site name="FDPL-P4" pos="-0.0189857 -0.0475513 -0.00750218" />
                            <site name="FDPL-P5" pos="-0.0185047 -0.059782 -0.0159664" />
                            <site name="FDPL-P6" pos="-0.0146154 -0.0746022 -0.0274602" />
                            <site name="FDPL-P7" pos="-0.00941611 -0.0765878 -0.0377054" />
                            <site name="FDPL-P8" pos="-0.00319329 -0.0757894 -0.0426284" />
                            <site name="FDPL-P9" pos="0.00456477 -0.0722482 -0.0476639" />
                            <site name="FDPR-P3" pos="0.0010849 -0.0120465 -0.0121181" />
                            <site name="FDPR-P4" pos="-0.00875084 -0.0567218 0.000900671" />
                            <site name="FDPR-P5" pos="-0.0110435 -0.0674275 -0.00836191" />
                            <site name="FDPR-P6" pos="-0.00559849 -0.0834554 -0.0230899" />
                            <site name="FDPR-P7" pos="-0.000573154 -0.0842332 -0.0344609" />
                            <site name="FDPR-P8" pos="0.00623305 -0.0802109 -0.0433755" />
                            <site name="FDPR-P9" pos="0.0123945 -0.0755336 -0.0497211" />
                            <site name="FDPM-P3" pos="0.00342869 -0.0131007 -0.0117087" />
                            <site name="FDPM-P4" pos="0.00309094 -0.0352797 -0.00625352" />
                            <site name="FDPM-P5" pos="0.00257919 -0.0600072 0.00124866" />
                            <site name="FDPM-P6" pos="0.00291695 -0.0714908 -0.00136124" />
                            <site name="FDPM-P7" pos="0.00883272 -0.0898522 -0.0185763" />
                            <site name="FDPM-P8" pos="0.0102554 -0.0897191 -0.0303362" />
                            <site name="FDPM-P9" pos="0.0167136 -0.0834861 -0.0453918" />
                            <site name="FDPM-P10" pos="0.0195384 -0.07843 -0.0535183" />
                            <site name="FDPI-P3" pos="0.00917047 -0.0119544 -0.0124047" />
                            <site name="FDPI-P4" pos="0.0196715 -0.0567218 0.00448289" />
                            <site name="FDPI-P5" pos="0.0212169 -0.0718592 -0.00292718" />
                            <site name="FDPI-P6" pos="0.0297221 -0.0878973 -0.0182386" />
                            <site name="FDPI-P7" pos="0.0299268 -0.088757 -0.0283404" />
                            <site name="FDPI-P8" pos="0.0298245 -0.0842844 -0.0407247" />
                            <site name="FDPI-P9" pos="0.0291388 -0.0795354 -0.0487795" />
                            <site name="EDCL-P4" pos="-0.0252188 -0.045054 0.0017297" />
                            <site name="EDCL-P5" pos="-0.0243693 -0.048452 0.000788087" />
                            <site name="EDCL-P6" pos="-0.0245126 -0.0676834 -0.0102451" />
                            <site name="EDCL-P7" pos="-0.0184023 -0.0803133 -0.0277468" />
                            <site name="EDCL-P8" pos="-0.0120567 -0.0806203 -0.0386777" />
                            <site name="EDCL-P9" pos="-0.00153523 -0.0776419 -0.0469372" />
                            <site name="EDCL-P10" pos="0.00205721 -0.0766287 -0.0490661" />
                            <site name="EDCR-P4" pos="-0.0160074 -0.0568037 0.0095594" />
                            <site name="EDCR-P5" pos="-0.0146052 -0.0595569 0.0118827" />
                            <site name="EDCR-P6" pos="-0.0161711 -0.073855 -0.00430889" />
                            <site name="EDCR-P7" pos="-0.00844379 -0.0894018 -0.0231309" />
                            <site name="EDCR-P8" pos="-0.00278389 -0.0901285 -0.0348908" />
                            <site name="EDCR-P9" pos="0.00780923 -0.0821453 -0.0476742" />
                            <site name="EDCR-P10" pos="0.0109411 -0.0799243 -0.0505706" />
                            <site name="EDCM-P4" pos="0.000399161 -0.0539789 0.0152602" />
                            <site name="EDCM-P5" pos="-0.000890436 -0.0570493 0.0148611" />
                            <site name="EDCM-P6" pos="0.00190369 -0.078993 0.00611023" />
                            <site name="EDCM-P7" pos="0.0103065 -0.0953176 -0.0181567" />
                            <site name="EDCM-P8" pos="0.0135203 -0.0978252 -0.0312779" />
                            <site name="EDCM-P9" pos="0.0190062 -0.0872525 -0.0487079" />
                            <site name="EDCM-P10" pos="0.021043 -0.0818076 -0.0546646" />
                            <site name="EDCM-P11" pos="0.0224656 -0.078819 -0.0579602" />
                            <site name="EDCI-P4" pos="0.0157924 -0.0478993 0.016775" />
                            <site name="EDCI-P5" pos="0.0194156 -0.0578681 0.0147178" />
                            <site name="EDCI-P6" pos="0.0204084 -0.0785836 0.00607953" />
                            <site name="EDCI-P7" pos="0.0301418 -0.0937721 -0.0127424" />
                            <site name="EDCI-P8" pos="0.0319431 -0.0956861 -0.0297324" />
                            <site name="EDCI-P9" pos="0.0308378 -0.0868636 -0.0436826" />
                            <site name="EDCI-P10" pos="0.029978 -0.0829334 -0.0508265" />
                            <site name="EDM-P5" pos="-0.0210737 -0.0105624 0.00380738" />
                            <site name="EDM-P6" pos="-0.026232 -0.0483292 0.000235403" />
                            <site name="EDM-P7" pos="-0.0260888 -0.0666394 -0.0112379" />
                            <site name="EDM-P8" pos="-0.0197841 -0.0799346 -0.0278185" />
                            <site name="EDM-P9" pos="-0.0137762 -0.0807738 -0.0398547" />
                            <site name="EDM-P10" pos="-0.00221074 -0.0769767 -0.046968" />
                            <site name="EDM-P11" pos="0.00135101 -0.0751753 -0.0491582" />
                            <site name="EIP-P4" pos="0.00397114 -0.0228648 0.0121181" />
                            <site name="EIP-P5" pos="0.0173277 -0.0577248 0.0140935" />
                            <site name="EIP-P6" pos="0.0177576 -0.0787268 0.00594648" />
                            <site name="EIP-P7" pos="0.0282995 -0.0953279 -0.0154649" />
                            <site name="EIP-P8" pos="0.0294663 -0.0965867 -0.0288931" />
                            <site name="EIP-P9" pos="0.0293742 -0.0872423 -0.0439589" />
                            <site name="EIP-P10" pos="0.0290057 -0.0796787 -0.0563022" />
                            <site name="EPL-P6" pos="0.0248503 0.000143289 0.00622282" />
                            <site name="EPL-P7" pos="0.0239292 -0.0093854 -0.000399161" />
                            <site name="EPL-P8" pos="0.0297324 -0.0146052 -0.00500487" />
                            <site name="EPL-P9" pos="0.0451768 -0.0349727 -0.0185661" />
                            <site name="EPL-P10" pos="0.0498133 -0.0475513 -0.0254542" />
                            <site name="EPL-P11" pos="0.048626 -0.0717466 -0.0386265" />
                            <site name="EPL-P12" pos="0.0410522 -0.077427 -0.0438361" />
                            <site name="EPB-P5" pos="0.0319636 0.00262013 -0.00334681" />
                            <site name="EPB-P6" pos="0.0304181 -0.00812651 -0.0146973" />
                            <site name="EPB-P7" pos="0.0452587 -0.0337752 -0.0247889" />
                            <site name="EPB-P8" pos="0.0463436 -0.048974 -0.0326084" />
                            <site name="FPL-P6" pos="0.0127322 -0.0225884 -0.0213807" />
                            <site name="FPL-P7" pos="0.0167955 -0.0268257 -0.0227317" />
                            <site name="FPL-P8" pos="0.0251471 -0.0337138 -0.0228955" />
                            <site name="FPL-P9" pos="0.0289341 -0.0561077 -0.0312676" />
                            <site name="FPL-P10" pos="0.0359347 -0.0667213 -0.0383706" />
                            <site name="FPL-P11" pos="0.0361599 -0.0783584 -0.0421473" />
                            <site name="FPL-P5" pos="0.0178892 0.0064176 -0.0168214" />
                            <site name="APL-P7" pos="0.0264777 0.00209815 -0.0168876" />
                            <site name="APL-P8" pos="0.029456 -0.00689832 -0.0191393" />
                            <site name="APL-P9" pos="0.0314826 -0.0162018 -0.0192928" />
                            <site name="APL-P6" pos="0.0332244 0.00608975 -0.00870125" />
                            <body name="index0" pos="0 0 0">
                              <inertial pos="0 0 0" mass="0.001" diaginertia="0.001 0.001 0.001" />
                              <geom name="sdfast_1seg_hand_fr_c_2mc" type="mesh" mesh="sdfast_1seg_hand_fr_c_2mc" />
                              <body name="index1" pos="0 0 0">
                                <inertial pos="0 0 0" mass="0.001" diaginertia="0.001 0.001 0.001" />
                                <geom name="hand_2proxph" type="mesh" mesh="hand_2proxph" />
                                <body name="index2" pos="0 0 0">
                                  <inertial pos="0 0 0" mass="0.001" diaginertia="0.001 0.001 0.001" />
                                  <geom name="hand_2midph" type="mesh" mesh="hand_2midph" />
                                  <body name="index3" pos="0 0 0">
                                    <inertial pos="0 0 0" mass="0.001" diaginertia="0.001 0.001 0.001" />
                                    <geom name="hand_2distph" type="mesh" mesh="hand_2distph" />
                                    <site name="fingertip" pos="0.024 -0.149 -0.0065" type="sphere" rgba="0.1 0.8 0.1 0.0" size="0.004" />
                                  </body>
                                </body>
                              </body>
                            </body>
                          </body>
                        </body>
                      </body>
                    </body>
                  </body>
                </body>
              </body>
            </body>
          </body>
        </body>
      </body>
    </body>

</mujocoinclude>