<mujocoinclude model="MoBL Arms Index Model">

    <body name="thorax" pos="0 0 0" quat="0.7071067811865475 0.7071067811865475 0.0 0.0">
      <light mode="trackcom" directional="false" pos="0 0 4.0" dir="0 0 -1" />
      <geom name="thorax" type="mesh" mesh="thorax" />
      <site name="PECM1-P3" pos="  -7e-05  0.00821  0.10454" />
      <site name="PECM2-P4" pos="0.0304392 -0.0386227 0.095572" />
      <site name="PECM2-P5" pos="0.0272683 -0.044295 0.0223641" />
      <site name="PECM2-P3" pos=" 0.02083 -0.02005  0.11555" />
      <site name="PECM3-P4" pos="0.0517004 -0.0828881 0.0879892" />
      <site name="PECM3-P5" pos="0.0563682 -0.114765 0.0372932" />
      <site name="PECM3-P3" pos=" 0.02984 -0.0544459   0.1151" />
      <site name="LAT1-P4" pos="-0.116479 -0.0996391 0.032655" />
      <site name="LAT1-P5" pos="-0.0943213 -0.115454 0.00868567" />
      <site name="LAT2-P4" pos="-0.108246 -0.166505 0.0283417" />
      <site name="LAT2-P5" pos="-0.0707656 -0.185314 0.00802588" />
      <site name="LAT3-P4" pos="-0.109871 -0.190917 0.0544775" />
      <site name="LAT3-P5" pos="-0.0700861 -0.244794 0.00893187" />
      <joint name="r_z" type="hinge" pos="0 0 0" axis="       0        0        1" limited="true" range="-6.28319  6.28319" ref="0" armature="0" damping="0" stiffness="0" />
      <body name="clavicle" pos="0.00622867 0.00682446 0.0250772" quat="1.0 0.0 0.0 0.0">
        <geom name="clavicle" type="mesh" mesh="clavicle" />
        <inertial pos="-0.010927 0.00627525 0.053343" mass="0.153624161085791" fullinertia="0.000231674 0.000243774 4.24212e-05 -1.8126e-05 -6.67929e-05 5.12932e-05" />
        <site name="DELT1-P4" pos="-0.0137868 0.0108916 0.0789884" />
        <site name="DELT2-P2" pos="0.0191703 0.0244002 0.162891" />
        <site name="PECM1-P4" pos="0.00316111 -0.00012802 0.0503513" />
        <joint name="sternoclavicular_r2" type="hinge" pos="0 0 0" axis="  0.0153 0.989299  -0.1451" limited="false" range="-99999.9  99999.9" ref="0" />
        <joint name="sternoclavicular_r3" type="hinge" pos="0 0 0" axis="-0.994473        0 -0.104997" limited="false" range="-99999.9  99999.9" ref="0" />
        <body name="clavphant" pos="-0.0141118 0.0197643 0.133471" quat="1.0 0.0 0.0 0.0">
          <inertial pos="       0        0        0" mass="9.84770263370455e-05" fullinertia="0.955003 0.955003 0.955003        0        0        0" />
          <joint name="unrotscap_r3" type="hinge" pos="0 0 0" axis="-0.994473        0 -0.104997" limited="false" range="-99999.9  99999.9" ref="0" />
          <joint name="unrotscap_r2" type="hinge" pos="0 0 0" axis="  0.0153 0.989299  -0.1451" limited="false" range="-99999.9  99999.9" ref="0" />
          <body name="scapula" pos="       0        0        0" quat="1.0 0.0 0.0 0.0">
            <geom name="scapula" type="mesh" mesh="scapula" />
            <inertial pos="-0.053861 -0.0344985 -0.0430679" mass="0.693238874602266" fullinertia="0.00118697 0.00109864 0.00130367 0.000429178 0.000390806 0.000230251" />
            <site name="DELT1-P3" pos="0.042808 -0.0320247 0.000974923" />
            <site name="DELT2-P3" pos="4.92385e-005 0.00289522 0.0219899" />
            <site name="DELT2-P4" pos="-0.0106158 -0.000334822 0.00610558" />
            <site name="DELT3-P1" pos="-0.0548812 0.00120142 -0.0247374" />
            <site name="DELT3-P2" pos="-0.0713663 -0.0323497 0.0121422" />
            <site name="SUPSP-P2" pos="-0.0188879 0.00125066 -0.0125164" />
            <site name="SUPSP-P3" pos="-0.0433299 -0.0148897 -0.0576583" />
            <site name="INFSP-P2" pos="-0.0726957 -0.053926 -0.0470819" />
            <site name="SUBSC-P2" pos="-0.0180311 -0.0514346 -0.0241958" />
            <site name="SUBSC-P3" pos="-0.0713565 -0.0388295 -0.0637639" />
            <site name="TMIN-P2" pos="-0.0932873 -0.078693 -0.0466486" />
            <site name="TMIN-P3" pos="-0.0949614 -0.0799732 -0.0521731" />
            <site name="TMAJ-P2" pos="-0.101077 -0.101618 -0.0574023" />
            <site name="TMAJ-P3" pos="-0.103293 -0.107291 -0.0700861" />
            <site name="LAT1-P2" pos="-0.08052 -0.06821 -0.02908" />
            <site name="LAT1-P3" pos="-0.10925 -0.07239 -0.07422" />
            <site name="LAT2-P2" pos="-0.08345 -0.08695 -0.02453" />
            <site name="LAT2-P3" pos="-0.11524 -0.10749 -0.08863" />
            <site name="LAT3-P2" pos="-0.08438 -0.11598 -0.02995" />
            <site name="LAT3-P3" pos="-0.11279 -0.13833 -0.08911" />
            <site name="CORB-P1" pos="0.0123096 -0.0406415 -0.0261161" />
            <site name="CORB-P2" pos="0.00475644 -0.0685203 -0.015392" />
            <site name="TRIlong-P1" pos="-0.0449548 -0.0401097 -0.0135603" />
            <site name="BIClong-P1" pos="-0.0307544 -0.0231716 -0.0128513" />
            <site name="BIClong-P2" pos="-0.0206211 -0.0128906 -0.00453979" />
            <site name="BICshort-P1" pos="0.0124869 -0.0387113 -0.0258502" />
            <site name="BICshort-P2" pos="0.000915836 -0.066019 -0.0156874" />
            <joint name="acromioclavicular_r2" type="hinge" pos="0 0 0" axis="0.157095 0.947269 -0.279291" limited="false" range="-99999.9  99999.9" ref="0" />
            <joint name="acromioclavicular_r3" type="hinge" pos="0 0 0" axis="-0.754084 0.297594 0.585487" limited="false" range="-99999.9  99999.9" ref="0" />
            <joint name="acromioclavicular_r1" type="hinge" pos="0 0 0" axis="  0.6377   0.1186   0.7611" limited="false" range="-99999.9  99999.9" ref="0" />
            <body name="scapphant" pos="-0.00940456 -0.0334822 0.00886293" quat="1.0 0.0 0.0 0.0">
              <inertial pos="       0        0        0" mass="9.84770263370455e-05" fullinertia="0.955003 0.955003 0.955003        0        0        0" />
              <joint name="unrothum_r1" type="hinge" pos="0 0 0" axis="  0.6377   0.1186   0.7611" limited="false" range="-99999.9  99999.9" ref="0" />
              <joint name="unrothum_r3" type="hinge" pos="0 0 0" axis="-0.754084 0.297594 0.585487" limited="false" range="-99999.9  99999.9" ref="0" />
              <joint name="unrothum_r2" type="hinge" pos="0 0 0" axis="0.157095 0.947269 -0.279291" limited="false" range="-99999.9  99999.9" ref="0" />
              <body name="humphant" pos="       0        0        0" quat="1.0 0.0 0.0 0.0">
                <inertial pos="       0        0        0" mass="9.84770263370455e-05" fullinertia="0.955003 0.955003 0.955003        0        0        0" />
                <joint name="elv_angle" type="hinge" pos="0 0 0" axis="  0.0048 0.999089   0.0424" limited="true" range=" -1.5708  2.26893" ref="0" user="1" />
                <body name="humphant1" pos="       0        0        0" quat="1.0 0.0 0.0 0.0">
                  <inertial pos="       0        0        0" mass="9.84770263370455e-05" fullinertia="0.955003 0.955003 0.955003        0        0        0" />
                  <joint name="shoulder_elv" type="hinge" pos="0 0 0" axis="-0.998261   0.0023 0.058898" limited="true" range="       0  3.14159" ref="0" user="1" />
                  <joint name="shoulder1_r2" type="hinge" pos="0 0 0" axis="  0.0048 0.999089   0.0424" limited="false" range="-99999.9  99999.9" ref="0" />
                  <body name="humerus" pos="       0        0        0" quat="1.0 0.0 0.0 0.0">
                    <geom name="humerus" type="mesh" mesh="humerus" />
                    <inertial pos="0.0177889 -0.138007 -0.0125519" mass="1.96714753500092" fullinertia="0.0117252 0.00243653 0.0120129 -0.000331778 -0.000222038 0.00117399" />
                    <site name="DELT1-P1" pos="0.00882354 -0.11702 0.00576091" />
                    <site name="DELT1-P2" pos="0.0159828 -0.10865 0.00405725" />
                    <site name="DELT2-P1" pos="0.00453979 -0.134037 0.00551471" />
                    <site name="DELT3-P3" pos="0.00202863 -0.0748622 0.0102908" />
                    <site name="SUPSP-P1" pos="0.00252101 0.0104681 0.0255351" />
                    <site name="INFSP-P1" pos="-0.00873491 0.00476629 0.0241072" />
                    <site name="SUBSC-P1" pos="0.0138163 0.00827207 -0.0131073" />
                    <site name="TMIN-P1" pos="-0.00108325 -0.0124475 0.0212316" />
                    <site name="TMAJ-P1" pos="0.00982801 -0.0533647 -0.0055935" />
                    <site name="PECM1-P1" pos="0.011512 -0.0412717 0.00768121" />
                    <site name="PECM1-P2" pos="  0.0191  -0.0301  0.00143" />
                    <site name="PECM2-P1" pos="0.012546 -0.0422368 0.00773045" />
                    <site name="PECM2-P2" pos=" 0.01748 -0.03533  0.00033" />
                    <site name="PECM3-P1" pos="0.0124967 -0.0430837 0.00738578" />
                    <site name="PECM3-P2" pos="0.0159185 -0.045833 -0.00378312" />
                    <site name="LAT1-P1" pos="0.0103401 -0.0336299 -0.00643055" />
                    <site name="LAT2-P1" pos="0.00953258 -0.04009 -0.00601695" />
                    <site name="LAT3-P1" pos="0.011896 -0.0386227 -0.00409664" />
                    <site name="CORB-P3" pos="0.00731684 -0.148188 -0.0077009" />
                    <site name="TRIlong-P2" pos="-0.0267267 -0.112668 -0.00653887" />
                    <site name="TRIlong-P3" pos="-0.0313551 -0.222922 -0.0119847" />
                    <site name="TRIlong-P4" pos="-0.0171645 -0.263495 -0.011896" />
                    <site name="TRIlat-P1" pos="-0.00589877 -0.124534 0.00421482" />
                    <site name="TRIlat-P2" pos="-0.023083 -0.143067 0.00913867" />
                    <site name="TRIlat-P3" pos="-0.0313551 -0.222922 -0.0119847" />
                    <site name="TRIlat-P4" pos="-0.0171645 -0.263495 -0.011896" />
                    <site name="TRImed-P1" pos="-0.00825237 -0.134864 -0.00892202" />
                    <site name="TRImed-P2" pos="-0.0256139 -0.149084 -0.0106355" />
                    <site name="TRImed-P3" pos="-0.0313551 -0.222922 -0.0119847" />
                    <site name="TRImed-P4" pos="-0.0171645 -0.263495 -0.011896" />
                    <site name="ANC-P1" pos="-0.00732669 -0.279271 0.0096409" />
                    <site name="BIClong-P3" pos="0.0209855 0.0176569 0.0101234" />
                    <site name="BIClong-P4" pos="0.0234178 -0.00503218 0.0118271" />
                    <site name="BIClong-P5" pos="0.0132452 -0.0278395 0.00133929" />
                    <site name="BIClong-P6" pos="0.0105173 -0.0761818 -0.00162487" />
                    <site name="BIClong-P7" pos="0.0167706 -0.119403 0.000236345" />
                    <site name="BIClong-P8" pos="0.0224528 -0.172729 -0.00620405" />
                    <site name="BICshort-P3" pos="0.0109999 -0.0746062 -0.0108423" />
                    <site name="BICshort-P4" pos="0.0167706 -0.119403 -0.0106257" />
                    <site name="BICshort-P5" pos="0.0224528 -0.172729 -0.00620405" />
                    <site name="BRA-P1" pos="0.00669644 -0.171252 -0.00354517" />
                    <site name="BRA-P2" pos="0.0186515 -0.281241 -0.0108817" />
                    <site name="BRD-P1" pos="-0.00965075 -0.19659 0.00219604" />
                    <site name="ECRL-P1" pos="-0.00718882 -0.256927 0.00896141" />
                    <site name="ECRB-P1" pos="0.0132846 -0.286056 0.0167214" />
                    <site name="ECU-P1" pos="0.000817359 -0.28514 0.0185137" />
                    <site name="FCR-P1" pos="0.00746456 -0.273825 -0.0364857" />
                    <site name="FCU-P1" pos="0.00215665 -0.273175 -0.0382091" />
                    <site name="PL-P1" pos="0.0045004 -0.270999 -0.0380614" />
                    <site name="PT-P1" pos="0.00354517 -0.271698 -0.0359441" />
                    <site name="FDSL-P1" pos="0.00414588 -0.271777 -0.0380515" />
                    <site name="FDSR-P1" pos="0.00471705 -0.274554 -0.0367418" />
                    <site name="EDCL-P1" pos="-0.000393908 -0.283919 0.0184152" />
                    <site name="EDCR-P1" pos="-0.00153624 -0.284953 0.0175486" />
                    <site name="EDCM-P1" pos="0.000502233 -0.285426 0.0191932" />
                    <site name="EDCI-P1" pos="0.000640101 -0.284579 0.0184054" />
                    <site name="EDM-P1" pos="0.000876446 -0.284786 0.0181887" />
                    <joint name="shoulder_rot" type="hinge" pos="0 0 0" axis="  0.0048 0.999089   0.0424" limited="true" range=" -1.5708 0.349066" ref="0" user="1" />
                    <body name="ulna" pos="0.0060071 -0.285977 -0.0121127" quat="1.0 0.0 0.0 0.0">
                      <geom name="ulna" type="mesh" mesh="ulna" />
                      <inertial pos="0.00956983 -0.0944896 0.0239161" mass="1.08846657210336" fullinertia="0.00516952 0.00110129 0.00472116 0.000302602 -7.27235e-05 0.00104257" />
                      <site name="TRIlong-P5" pos="-0.0215665 0.0103007 -0.000768121" />
                      <site name="TRIlat-P5" pos="-0.0215665 0.0103007 -0.000768121" />
                      <site name="TRImed-P5" pos="-0.0215665 0.0103007 -0.000768121" />
                      <site name="ANC-P2" pos="-0.0249344 -0.00122112 0.00590862" />
                      <site name="SUP-P3" pos="-0.0133929 -0.0333246 0.0198234" />
                      <site name="BRA-P4" pos="-0.00315126 -0.023536 0.000886293" />
                      <site name="BRA-P3" pos="0.00490416 -0.0144072 0.00126051" />
                      <site name="ECU-P2" pos="-0.0136982 -0.0315225 0.0290212" />
                      <site name="ECU-P3" pos="-0.0167903 -0.0534533 0.0282432" />
                      <site name="ECU-P4" pos="-0.0176569 -0.0942721 0.0322808" />
                      <site name="PT-P2" pos="0.00833116 -0.0332163 -0.0141019" />
                      <site name="PT-P3" pos=" 0.01219 -0.06516 -0.00219" />
                      <site name="PQ-P2" pos="0.00190061 -0.206526 0.0357669" />
                      <site name="FDSM-P1" pos="-0.00658811 -0.0267168 -0.00188091" />
                      <site name="FDSI-P1" pos="-0.00665705 -0.0277607 -0.00134914" />
                      <site name="FDPL-P1" pos="-0.00618436 -0.0316505 0.00250132" />
                      <site name="FDPR-P1" pos="-0.00494355 -0.0332261 0.00268842" />
                      <site name="FDPM-P1" pos="-0.0051405 -0.0327633 0.00206802" />
                      <site name="FDPI-P1" pos="-0.00637146 -0.0312763 0.00275736" />
                      <site name="EDM-P2" pos="-0.00962121 -0.038475 0.0303802" />
                      <site name="EDM-P3" pos="-0.00743502 -0.081411 0.0359047" />
                      <site name="EIP-P1" pos="-0.00387999 -0.163984 0.0362592" />
                      <site name="EIP-P2" pos="0.00168396 -0.17203 0.0398733" />
                      <site name="EPL-P1" pos="-0.013905 -0.0955818 0.0290704" />
                      <joint name="elbow_flexion" type="hinge" pos="0 0 0" axis="  0.0494   0.0366 0.998108" limited="true" range="       0  4.26893" ref="0" user="1" />
                      <body name="radius" pos="0.000393908 -0.0113278 0.0196944" quat="1.0 0.0 0.0 0.0">
                        <geom name="radius" type="mesh" mesh="radius" />
                        <inertial pos="0.0331219 -0.178794 0.0153624" mass="0.230032485820705" fullinertia="0.000418817 8.46037e-05 0.000384465 2.87838e-05 -4.04921e-06 6.12921e-05" />
                        <site name="SUP-P1" pos="0.00980831 -0.0600316 0.000738578" />
                        <site name="SUP-P2" pos="0.0118271 -0.0509126 -0.0010537" />
                        <site name="BIClong-P11" pos="-0.00196954 -0.0369289 -0.00196954" />
                        <site name="BIClong-P9" pos=" 0.00273 -0.0343493 -0.0119845" />
                        <site name="BICshort-P8" pos="-0.00196954 -0.0369289 -0.00196954" />
                        <site name="BICshort-P6" pos=" 0.00273 -0.0343493 -0.0119845" />
                        <site name="BRD-P2" pos="0.0352252 -0.125479 0.0227974" />
                        <site name="BRD-P3" pos="0.0412619 -0.217634 0.0220589" />
                        <site name="ECRL-P2" pos="0.0314634 -0.13258 0.0273668" />
                        <site name="ECRL-P3" pos="0.0417838 -0.233233 0.0356487" />
                        <site name="ECRB-P2" pos="0.0286076 -0.128867 0.0234868" />
                        <site name="ECRB-P3" pos="0.0349495 -0.224577 0.0387704" />
                        <site name="ECU-P5" pos="-0.0139936 -0.223503 0.0342799" />
                        <site name="FCR-P2" pos="0.0207787 -0.216088 0.00125066" />
                        <site name="FCU-P3" pos="0.0106552 -0.21987 0.00954242" />
                        <site name="FCU-P2" pos="0.0101156 -0.183524 0.00202653" />
                        <site name="PL-P2" pos="0.0249245 -0.235508 -0.00271797" />
                        <site name="PT-P5" pos="0.0250132 -0.107143 0.0194985" />
                        <site name="PT-P4" pos="0.0232406 -0.0919775 0.00925684" />
                        <site name="PQ-P1" pos="0.0319558 -0.196934 0.0193212" />
                        <site name="FDSL-P2" pos="0.0135603 -0.184329 0.00201878" />
                        <site name="FDSR-P2" pos="0.0154707 -0.183817 0.00262934" />
                        <site name="FDSM-P2" pos="0.0187008 -0.184211 0.00417543" />
                        <site name="FDSI-P2" pos="0.0211233 -0.183394 0.00543593" />
                        <site name="FDPL-P2" pos="0.0138754 -0.18234 0.00847887" />
                        <site name="FDPR-P2" pos="0.0155594 -0.183453 0.00790771" />
                        <site name="FDPM-P2" pos="0.0187697 -0.183601 0.00773045" />
                        <site name="FDPI-P2" pos="0.0204832 -0.182773 0.00901065" />
                        <site name="EDCL-P3" pos="0.00977877 -0.219643 0.035629" />
                        <site name="EDCL-P2" pos="  0.0013 -0.0382544 0.0129514" />
                        <site name="EDCR-P3" pos="0.00868567 -0.220254 0.0421876" />
                        <site name="EDCR-P2" pos="  0.0026 -0.0392844 0.0144214" />
                        <site name="EDCM-P3" pos="0.0141807 -0.21983 0.0415868" />
                        <site name="EDCM-P2" pos=" 0.00316 -0.0388544 0.0141814" />
                        <site name="EDCI-P3" pos="0.0150965 -0.219742 0.041321" />
                        <site name="EDCI-P2" pos=" 0.00228 -0.0385544 0.0137314" />
                        <site name="EDM-P4" pos="0.00447086 -0.222962 0.0362199" />
                        <site name="EIP-P3" pos="0.0105961 -0.22436 0.036082" />
                        <site name="EPL-P2" pos="0.00122112 -0.134598 0.0223543" />
                        <site name="EPL-P3" pos="0.0266085 -0.215389 0.037697" />
                        <site name="EPL-P4" pos="0.0333049 -0.224075 0.0453684" />
                        <site name="EPL-P5" pos="0.0416952 -0.23409 0.0410945" />
                        <site name="EPB-P1" pos="0.018947 -0.144712 0.020818" />
                        <site name="EPB-P2" pos="0.0224134 -0.156155 0.0262441" />
                        <site name="EPB-P3" pos="0.0377265 -0.194216 0.0377561" />
                        <site name="EPB-P4" pos="0.0515527 -0.232514 0.0265789" />
                        <site name="FPL-P1" pos="0.00956212 -0.0931396 0.0174206" />
                        <site name="FPL-P2" pos="0.0163275 -0.13319 0.0188584" />
                        <site name="FPL-P3" pos="0.0184054 -0.176589 0.0195772" />
                        <site name="FPL-P4" pos="0.0374213 -0.228181 0.0155594" />
                        <site name="APL-P1" pos="0.0113642 -0.0933267 0.016554" />
                        <site name="APL-P2" pos="0.0298385 -0.137572 0.0345359" />
                        <site name="APL-P3" pos="0.0393219 -0.158272 0.0334822" />
                        <site name="APL-P4" pos="0.0433003 -0.175732 0.0308627" />
                        <site name="APL-P5" pos="0.0542116 -0.227324 0.0233194" />
                        <joint name="pro_sup" type="hinge" pos="0 0 0" axis="-0.017161 0.992666 -0.119668" limited="true" range=" -1.5708   1.5708" ref="0" user="1" />
                        <body name="proximal_row" pos="0.0177259 -0.238314 0.0246193" quat="1.0 0.0 0.0 0.0">
                          <geom name="lunate" type="mesh" mesh="lunate" />
                          <geom name="sdfastSCAPHOIDw" type="mesh" mesh="sdfastSCAPHOIDw" />
                          <geom name="sdfastPISIFORMw" type="mesh" mesh="sdfastPISIFORMw" />
                          <geom name="sdfastTRIQUETRALw" type="mesh" mesh="sdfastTRIQUETRALw" />
                          <inertial pos="       0        0        0" mass="9.84770263370455e-05" fullinertia="9.55003e-06 9.55003e-06 9.55003e-06        0        0        0" />
                          <body name="hand" pos="0.0039312 -0.0148247 0.00229156" quat="1.0 0.0 0.0 0.0">
                            <geom name="sdfast_1seg_hand_fr_c_5mc" type="mesh" mesh="sdfast_1seg_hand_fr_c_5mc" />
                            <geom name="sdfast_1seg_hand_fr_c_4mc" type="mesh" mesh="sdfast_1seg_hand_fr_c_4mc" />
                            <geom name="sdfast_1seg_hand_fr_c_3mc" type="mesh" mesh="sdfast_1seg_hand_fr_c_3mc" />
                            <geom name="sdfast_1seg_hand_fr_c_trapezium" type="mesh" mesh="sdfast_1seg_hand_fr_c_trapezium" />
                            <geom name="sdfast_1seg_hand_fr_c_trapezoid" type="mesh" mesh="sdfast_1seg_hand_fr_c_trapezoid" />
                            <geom name="sdfast_1seg_hand_fr_c_hamate" type="mesh" mesh="sdfast_1seg_hand_fr_c_hamate" />
                            <geom name="capitate" type="mesh" mesh="capitate" />
                            <geom name="hand_3proxph" type="mesh" mesh="hand_3proxph" />
                            <geom name="hand_3midph" type="mesh" mesh="hand_3midph" />
                            <geom name="hand_3distph" type="mesh" mesh="hand_3distph" />
                            <geom name="hand_4proxph" type="mesh" mesh="hand_4proxph" />
                            <geom name="hand_4midph" type="mesh" mesh="hand_4midph" />
                            <geom name="hand_4distph" type="mesh" mesh="hand_4distph" />
                            <geom name="hand_5proxph" type="mesh" mesh="hand_5proxph" />
                            <geom name="hand_5midph" type="mesh" mesh="hand_5midph" />
                            <geom name="hand_5distph" type="mesh" mesh="hand_5distph" />
                            <geom name="hand_thumbprox" type="mesh" mesh="hand_thumbprox" />
                            <geom name="hand_thumbdist" type="mesh" mesh="hand_thumbdist" />
                            <geom name="hand_1mc" type="mesh" mesh="hand_1mc" />
                            <inertial pos="-0.00296725 -0.041852 -0.00110496" mass="0.573037816255268" fullinertia="0.00010505 5.73002e-05 0.00014325 8.59503e-07 -1.91001e-07 1.146e-05" />
                            <site name="ECRL-P4" pos="0.0169085 -0.0208968 0.00574121" />
                            <site name="ECRB-P4" pos="0.00492385 -0.011187 0.00837055" />
                            <site name="ECU-P6" pos="-0.0221672 -0.0137966 -0.00126051" />
                            <site name="FCR-P3" pos="0.0110688 -0.0181592 -0.00411634" />
                            <site name="FCU-P4" pos="-0.0200499 -0.0173812 -0.00740547" />
                            <site name="PL-P3" pos="0.00903034 -0.0186909 -0.0172729" />
                            <site name="PL-P4" pos="0.00223543 -0.0304885 0.00485492" />
                            <site name="FDSL-P3" pos="-0.00231421 -0.0137178 -0.0135504" />
                            <site name="FDSL-P4" pos="-0.0196462 -0.042158 -0.007307" />
                            <site name="FDSL-P5" pos="-0.0201287 -0.0588991 -0.018494" />
                            <site name="FDSL-P6" pos="-0.0168691 -0.0713466 -0.0271107" />
                            <site name="FDSL-P7" pos="-0.0113839 -0.0716026 -0.0360032" />
                            <site name="FDSL-P8" pos="-0.0104287 -0.0716026 -0.0373819" />
                            <site name="FDSR-P3" pos="-0.000807512 -0.0132353 -0.013383" />
                            <site name="FDSR-P4" pos="-0.00962121 -0.0510013 3.93908e-005" />
                            <site name="FDSR-P5" pos="-0.0130285 -0.0656842 -0.0100447" />
                            <site name="FDSR-P6" pos="-0.00775999 -0.0790475 -0.0246488" />
                            <site name="FDSR-P7" pos="-0.00294446 -0.0800126 -0.033433" />
                            <site name="FDSR-P8" pos="0.000610558 -0.0796876 -0.0383273" />
                            <site name="FDSM-P3" pos="0.00669644 -0.0135603 -0.0137769" />
                            <site name="FDSM-P4" pos="0.00463827 -0.0328125 -0.0012999" />
                            <site name="FDSM-P5" pos="0.00533745 -0.055738 0.000590862" />
                            <site name="FDSM-P6" pos="0.00546547 -0.0711398 -0.00332852" />
                            <site name="FDSM-P7" pos="0.0114923 -0.0867583 -0.0164457" />
                            <site name="FDSM-P8" pos="0.0128119 -0.0873491 -0.0293166" />
                            <site name="FDSM-P9" pos="0.0154412 -0.0844637 -0.0370766" />
                            <site name="FDSI-P3" pos="0.00875461 -0.013452 -0.0136588" />
                            <site name="FDSI-P4" pos="0.0104484 -0.0372932 0.000236345" />
                            <site name="FDSI-P5" pos="0.0175486 -0.0503021 0.00411634" />
                            <site name="FDSI-P6" pos="0.0182084 -0.0718587 -0.00369289" />
                            <site name="FDSI-P7" pos="0.0263721 -0.0858129 -0.0177653" />
                            <site name="FDSI-P8" pos="0.0262638 -0.0860689 -0.0263721" />
                            <site name="FDSI-P9" pos="0.0261949 -0.0850152 -0.0285879" />
                            <site name="FDPL-P3" pos="-0.000866598 -0.0101136 -0.0116991" />
                            <site name="FDPL-P4" pos="-0.0182675 -0.0457524 -0.00721837" />
                            <site name="FDPL-P5" pos="-0.0178046 -0.0575204 -0.0153624" />
                            <site name="FDPL-P6" pos="-0.0140625 -0.0717799 -0.0264214" />
                            <site name="FDPL-P7" pos="-0.00905989 -0.0736904 -0.0362789" />
                            <site name="FDPL-P8" pos="-0.00307248 -0.0729222 -0.0410157" />
                            <site name="FDPL-P9" pos="0.00439208 -0.0695149 -0.0458608" />
                            <site name="FDPR-P3" pos="0.00104386 -0.0115907 -0.0116597" />
                            <site name="FDPR-P4" pos="-0.00841979 -0.054576 0.000866598" />
                            <site name="FDPR-P5" pos="-0.0106257 -0.0648767 -0.00804557" />
                            <site name="FDPR-P6" pos="-0.00538669 -0.0802982 -0.0222164" />
                            <site name="FDPR-P7" pos="-0.000551471 -0.0810466 -0.0331572" />
                            <site name="FDPR-P8" pos="0.00599725 -0.0771764 -0.0417346" />
                            <site name="FDPR-P9" pos="0.0119256 -0.072676 -0.0478401" />
                            <site name="FDPM-P3" pos="0.00329898 -0.0126051 -0.0112658" />
                            <site name="FDPM-P4" pos="0.00297401 -0.033945 -0.00601695" />
                            <site name="FDPM-P5" pos="0.00248162 -0.0577371 0.00120142" />
                            <site name="FDPM-P6" pos="0.0028066 -0.0687862 -0.00130974" />
                            <site name="FDPM-P7" pos="0.00849857 -0.086453 -0.0178736" />
                            <site name="FDPM-P8" pos="0.0098674 -0.086325 -0.0291886" />
                            <site name="FDPM-P9" pos="0.0160813 -0.0803277 -0.0436746" />
                            <site name="FDPM-P10" pos="0.0187993 -0.0754629 -0.0514936" />
                            <site name="FDPI-P3" pos="0.00882354 -0.0115021 -0.0119354" />
                            <site name="FDPI-P4" pos="0.0189273 -0.054576 0.00431329" />
                            <site name="FDPI-P5" pos="0.0204143 -0.0691407 -0.00281644" />
                            <site name="FDPI-P6" pos="0.0285977 -0.0845721 -0.0175486" />
                            <site name="FDPI-P7" pos="0.0287947 -0.0853993 -0.0272683" />
                            <site name="FDPI-P8" pos="0.0286962 -0.0810958 -0.039184" />
                            <site name="FDPI-P9" pos="0.0280364 -0.0765265 -0.0469342" />
                            <site name="EDCL-P4" pos="-0.0242647 -0.0433496 0.00166426" />
                            <site name="EDCL-P5" pos="-0.0234474 -0.046619 0.000758273" />
                            <site name="EDCL-P6" pos="-0.0235852 -0.0651229 -0.00985755" />
                            <site name="EDCL-P7" pos="-0.0177062 -0.0772749 -0.0266971" />
                            <site name="EDCL-P8" pos="-0.0116006 -0.0775704 -0.0372145" />
                            <site name="EDCL-P9" pos="-0.00147716 -0.0747047 -0.0451616" />
                            <site name="EDCL-P10" pos="0.00197939 -0.0737297 -0.0472099" />
                            <site name="EDCR-P4" pos="-0.0154018 -0.0546547 0.00919775" />
                            <site name="EDCR-P5" pos="-0.0140527 -0.0573038 0.0114332" />
                            <site name="EDCR-P6" pos="-0.0155594 -0.071061 -0.00414588" />
                            <site name="EDCR-P7" pos="-0.00812435 -0.0860197 -0.0222558" />
                            <site name="EDCR-P8" pos="-0.00267858 -0.0867189 -0.0335708" />
                            <site name="EDCR-P9" pos="0.0075138 -0.0790377 -0.0458706" />
                            <site name="EDCR-P10" pos="0.0105272 -0.0769007 -0.0486575" />
                            <site name="EDCM-P4" pos="0.00038406 -0.0519368 0.0146829" />
                            <site name="EDCM-P5" pos="-0.00085675 -0.0548911 0.0142989" />
                            <site name="EDCM-P6" pos="0.00183167 -0.0760046 0.00587908" />
                            <site name="EDCM-P7" pos="0.00991664 -0.0917117 -0.0174698" />
                            <site name="EDCM-P8" pos="0.0130088 -0.0941243 -0.0300946" />
                            <site name="EDCM-P9" pos="0.0182872 -0.0839517 -0.0468652" />
                            <site name="EDCM-P10" pos="0.0202469 -0.0787127 -0.0525966" />
                            <site name="EDCM-P11" pos="0.0216157 -0.0758372 -0.0557675" />
                            <site name="EDCI-P4" pos="0.015195 -0.0460872 0.0161404" />
                            <site name="EDCI-P5" pos="0.0186811 -0.0556789 0.014161" />
                            <site name="EDCI-P6" pos="0.0196363 -0.0756107 0.00584954" />
                            <site name="EDCI-P7" pos="0.0290015 -0.0902247 -0.0122604" />
                            <site name="EDCI-P8" pos="0.0307347 -0.0920662 -0.0286076" />
                            <site name="EDCI-P9" pos="0.0296711 -0.0835775 -0.04203" />
                            <site name="EDCI-P10" pos="0.0288439 -0.0797959 -0.0489037" />
                            <site name="EDM-P5" pos="-0.0202764 -0.0101628 0.00366335" />
                            <site name="EDM-P6" pos="-0.0252397 -0.0465009 0.000226497" />
                            <site name="EDM-P7" pos="-0.0251018 -0.0641184 -0.0108128" />
                            <site name="EDM-P8" pos="-0.0190356 -0.0769106 -0.0267661" />
                            <site name="EDM-P9" pos="-0.013255 -0.0777181 -0.038347" />
                            <site name="EDM-P10" pos="-0.0021271 -0.0740646 -0.0451911" />
                            <site name="EDM-P11" pos="0.0012999 -0.0723314 -0.0472985" />
                            <site name="EIP-P4" pos="0.00382091 -0.0219998 0.0116597" />
                            <site name="EIP-P5" pos="0.0166722 -0.055541 0.0135603" />
                            <site name="EIP-P6" pos="0.0170858 -0.0757485 0.00572152" />
                            <site name="EIP-P7" pos="0.0272289 -0.0917215 -0.0148799" />
                            <site name="EIP-P8" pos="0.0283515 -0.0929328 -0.0278001" />
                            <site name="EIP-P9" pos="0.0282629 -0.0839418 -0.0422959" />
                            <site name="EIP-P10" pos="0.0279084 -0.0766644 -0.0541722" />
                            <site name="EPL-P6" pos="0.0239102 0.000137868 0.0059874" />
                            <site name="EPL-P7" pos="0.0230239 -0.00903034 -0.00038406" />
                            <site name="EPL-P8" pos="0.0286076 -0.0140527 -0.00481553" />
                            <site name="EPL-P9" pos="0.0434678 -0.0336496 -0.0178637" />
                            <site name="EPL-P10" pos="0.0479288 -0.0457524 -0.0244912" />
                            <site name="EPL-P11" pos="0.0467864 -0.0690324 -0.0371652" />
                            <site name="EPL-P12" pos="0.0394991 -0.0744979 -0.0421777" />
                            <site name="EPB-P5" pos="0.0307544 0.00252101 -0.0032202" />
                            <site name="EPB-P6" pos="0.0292674 -0.00781908 -0.0141413" />
                            <site name="EPB-P7" pos="0.0435465 -0.0324974 -0.0238511" />
                            <site name="EPB-P8" pos="0.0445904 -0.0471213 -0.0313748" />
                            <site name="FPL-P6" pos="0.0122505 -0.0217339 -0.0205719" />
                            <site name="FPL-P7" pos="0.0161601 -0.0258108 -0.0218717" />
                            <site name="FPL-P8" pos="0.0241958 -0.0324383 -0.0220293" />
                            <site name="FPL-P9" pos="0.0278395 -0.0539851 -0.0300847" />
                            <site name="FPL-P10" pos="0.0345753 -0.0641972 -0.036919" />
                            <site name="FPL-P11" pos="0.0347919 -0.075394 -0.0405528" />
                            <site name="FPL-P5" pos="0.0178892 0.0064176 -0.0168214" />
                            <site name="APL-P7" pos="0.025476 0.00201878 -0.0162487" />
                            <site name="APL-P8" pos="0.0283417 -0.00663735 -0.0184152" />
                            <site name="APL-P9" pos="0.0302915 -0.0155889 -0.0185629" />
                            <site name="APL-P6" pos="0.0332244 0.00608975 -0.00870125" />
                            <body name="index0" pos="0 0 0">
                              <inertial pos="0 0 0" mass="0.001" diaginertia="0.001 0.001 0.001" />
                              <geom name="sdfast_1seg_hand_fr_c_2mc" type="mesh" mesh="sdfast_1seg_hand_fr_c_2mc" />
                              <body name="index1" pos="0 0 0">
                                <inertial pos="0 0 0" mass="0.001" diaginertia="0.001 0.001 0.001" />
                                <geom name="hand_2proxph" type="mesh" mesh="hand_2proxph" />
                                <body name="index2" pos="0 0 0">
                                  <inertial pos="0 0 0" mass="0.001" diaginertia="0.001 0.001 0.001" />
                                  <geom name="hand_2midph" type="mesh" mesh="hand_2midph" />
                                  <body name="index3" pos="0 0 0">
                                    <inertial pos="0 0 0" mass="0.001" diaginertia="0.001 0.001 0.001" />
                                    <geom name="hand_2distph" type="mesh" mesh="hand_2distph" />
                                    <site name="fingertip" pos="0.024 -0.149 -0.0065" type="sphere" rgba="0.1 0.8 0.1 0.0" size="0.004" />
                                  </body>
                                </body>
                              </body>
                            </body>
                          </body>
                        </body>
                      </body>
                    </body>
                  </body>
                </body>
              </body>
            </body>
          </body>
        </body>
      </body>
    </body>

</mujocoinclude>