<mujocoinclude model="MoBL Arms Index Model">

    <body name="thorax" pos="0 0 0" quat="0.7071067811865475 0.7071067811865475 0.0 0.0">
      <light mode="trackcom" directional="false" pos="0 0 4.0" dir="0 0 -1" />
      <geom name="thorax" type="mesh" mesh="thorax" />
      <site name="PECM1-P3" pos="  -7e-05  0.00821  0.10454" />
      <site name="PECM2-P4" pos="0.0300403 -0.0381165 0.0943194" />
      <site name="PECM2-P5" pos="0.0269109 -0.0437144 0.022071" />
      <site name="PECM2-P3" pos=" 0.02083 -0.02005  0.11555" />
      <site name="PECM3-P4" pos="0.0510228 -0.0818018 0.086836" />
      <site name="PECM3-P5" pos="0.0556295 -0.113261 0.0368045" />
      <site name="PECM3-P3" pos=" 0.02984 -0.0544459   0.1151" />
      <site name="LAT1-P4" pos="-0.114952 -0.0983332 0.032227" />
      <site name="LAT1-P5" pos="-0.0930851 -0.113941 0.00857184" />
      <site name="LAT2-P4" pos="-0.106827 -0.164323 0.0279702" />
      <site name="LAT2-P5" pos="-0.0698381 -0.182885 0.00792069" />
      <site name="LAT3-P4" pos="-0.108431 -0.188415 0.0537635" />
      <site name="LAT3-P5" pos="-0.0691675 -0.241586 0.0088148" />
      <joint name="r_z" type="hinge" pos="0 0 0" axis="       0        0        1" limited="true" range="-6.28319  6.28319" ref="0" armature="0" damping="0" stiffness="0" />
      <body name="clavicle" pos="0.00614704 0.00673502 0.0247485" quat="1.0 0.0 0.0 0.0">
        <geom name="clavicle" type="mesh" mesh="clavicle" />
        <inertial pos="-0.0107838 0.00619301 0.0526439" mass="0.151610738250028" fullinertia="0.000222684 0.000234314 4.07751e-05 -1.74226e-05 -6.4201e-05 4.93028e-05" />
        <site name="DELT1-P4" pos="-0.0136061 0.0107488 0.0779532" />
        <site name="DELT2-P2" pos="0.0191703 0.0244002 0.162891" />
        <site name="PECM1-P4" pos="0.00311968 -0.000126342 0.0496914" />
        <joint name="sternoclavicular_r2" type="hinge" pos="0 0 0" axis="  0.0153 0.989299  -0.1451" limited="false" range="-99999.9  99999.9" ref="0" />
        <joint name="sternoclavicular_r3" type="hinge" pos="0 0 0" axis="-0.994473        0 -0.104997" limited="false" range="-99999.9  99999.9" ref="0" />
        <body name="clavphant" pos="-0.0139268 0.0195053 0.131722" quat="1.0 0.0 0.0 0.0">
          <inertial pos="       0        0        0" mass="9.7186370673095e-05" fullinertia="0.917944 0.917944 0.917944        0        0        0" />
          <joint name="unrotscap_r3" type="hinge" pos="0 0 0" axis="-0.994473        0 -0.104997" limited="false" range="-99999.9  99999.9" ref="0" />
          <joint name="unrotscap_r2" type="hinge" pos="0 0 0" axis="  0.0153 0.989299  -0.1451" limited="false" range="-99999.9  99999.9" ref="0" />
          <body name="scapula" pos="       0        0        0" quat="1.0 0.0 0.0 0.0">
            <geom name="scapula" type="mesh" mesh="scapula" />
            <inertial pos="-0.0531551 -0.0340463 -0.0425035" mass="0.68415317499032" fullinertia="0.00114091 0.001056 0.00125309 0.000412524 0.000375641 0.000221316" />
            <site name="DELT1-P3" pos="0.0422469 -0.031605 0.000962145" />
            <site name="DELT2-P3" pos="4.85932e-005 0.00285728 0.0217017" />
            <site name="DELT2-P4" pos="-0.0104767 -0.000330434 0.00602555" />
            <site name="DELT3-P1" pos="-0.054162 0.00118567 -0.0244132" />
            <site name="DELT3-P2" pos="-0.070431 -0.0319257 0.0119831" />
            <site name="SUPSP-P2" pos="-0.0186403 0.00123427 -0.0123524" />
            <site name="SUPSP-P3" pos="-0.042762 -0.0146946 -0.0569026" />
            <site name="INFSP-P2" pos="-0.071743 -0.0532193 -0.0464648" />
            <site name="SUBSC-P2" pos="-0.0177948 -0.0507604 -0.0238787" />
            <site name="SUBSC-P3" pos="-0.0704212 -0.0383206 -0.0629282" />
            <site name="TMIN-P2" pos="-0.0920646 -0.0776616 -0.0460372" />
            <site name="TMIN-P3" pos="-0.0937168 -0.0789251 -0.0514893" />
            <site name="TMAJ-P2" pos="-0.0997521 -0.100287 -0.0566499" />
            <site name="TMAJ-P3" pos="-0.101939 -0.105885 -0.0691675" />
            <site name="LAT1-P2" pos="-0.08052 -0.06821 -0.02908" />
            <site name="LAT1-P3" pos="-0.10925 -0.07239 -0.07422" />
            <site name="LAT2-P2" pos="-0.08345 -0.08695 -0.02453" />
            <site name="LAT2-P3" pos="-0.11524 -0.10749 -0.08863" />
            <site name="LAT3-P2" pos="-0.08438 -0.11598 -0.02995" />
            <site name="LAT3-P3" pos="-0.11279 -0.13833 -0.08911" />
            <site name="CORB-P1" pos="0.0121483 -0.0401088 -0.0257738" />
            <site name="CORB-P2" pos="0.0046941 -0.0676223 -0.0151902" />
            <site name="TRIlong-P1" pos="-0.0443656 -0.039584 -0.0133826" />
            <site name="BIClong-P1" pos="-0.0303513 -0.022868 -0.0126828" />
            <site name="BIClong-P2" pos="-0.0203508 -0.0127217 -0.00448029" />
            <site name="BICshort-P1" pos="0.0123232 -0.038204 -0.0255114" />
            <site name="BICshort-P2" pos="0.000903833 -0.0651537 -0.0154818" />
            <joint name="acromioclavicular_r2" type="hinge" pos="0 0 0" axis="0.157095 0.947269 -0.279291" limited="false" range="-99999.9  99999.9" ref="0" />
            <joint name="acromioclavicular_r3" type="hinge" pos="0 0 0" axis="-0.754084 0.297594 0.585487" limited="false" range="-99999.9  99999.9" ref="0" />
            <joint name="acromioclavicular_r1" type="hinge" pos="0 0 0" axis="  0.6377   0.1186   0.7611" limited="false" range="-99999.9  99999.9" ref="0" />
            <body name="scapphant" pos="-0.0092813 -0.0330434 0.00874677" quat="1.0 0.0 0.0 0.0">
              <inertial pos="       0        0        0" mass="9.7186370673095e-05" fullinertia="0.917944 0.917944 0.917944        0        0        0" />
              <joint name="unrothum_r1" type="hinge" pos="0 0 0" axis="  0.6377   0.1186   0.7611" limited="false" range="-99999.9  99999.9" ref="0" />
              <joint name="unrothum_r3" type="hinge" pos="0 0 0" axis="-0.754084 0.297594 0.585487" limited="false" range="-99999.9  99999.9" ref="0" />
              <joint name="unrothum_r2" type="hinge" pos="0 0 0" axis="0.157095 0.947269 -0.279291" limited="false" range="-99999.9  99999.9" ref="0" />
              <body name="humphant" pos="       0        0        0" quat="1.0 0.0 0.0 0.0">
                <inertial pos="       0        0        0" mass="9.7186370673095e-05" fullinertia="0.917944 0.917944 0.917944        0        0        0" />
                <joint name="elv_angle" type="hinge" pos="0 0 0" axis="  0.0048 0.999089   0.0424" limited="true" range=" -1.5708  2.26893" ref="0" user="1" />
                <body name="humphant1" pos="       0        0        0" quat="1.0 0.0 0.0 0.0">
                  <inertial pos="       0        0        0" mass="9.7186370673095e-05" fullinertia="0.917944 0.917944 0.917944        0        0        0" />
                  <joint name="shoulder_elv" type="hinge" pos="0 0 0" axis="-0.998261   0.0023 0.058898" limited="true" range="       0  3.14159" ref="0" user="1" />
                  <joint name="shoulder1_r2" type="hinge" pos="0 0 0" axis="  0.0048 0.999089   0.0424" limited="false" range="-99999.9  99999.9" ref="0" />
                  <body name="humerus" pos="       0        0        0" quat="1.0 0.0 0.0 0.0">
                    <geom name="humerus" type="mesh" mesh="humerus" />
                    <inertial pos="0.0175557 -0.136198 -0.0123874" mass="1.94136578465454" fullinertia="0.0112702 0.00234198 0.0115467 -0.000318903 -0.000213422 0.00112843" />
                    <site name="DELT1-P1" pos="0.0087079 -0.115487 0.0056854" />
                    <site name="DELT1-P2" pos="0.0157733 -0.107226 0.00400408" />
                    <site name="DELT2-P1" pos="0.00448029 -0.13228 0.00544244" />
                    <site name="DELT3-P3" pos="0.00200204 -0.0738811 0.010156" />
                    <site name="SUPSP-P1" pos="0.00248797 0.0103309 0.0252004" />
                    <site name="INFSP-P1" pos="-0.00862043 0.00470382 0.0237912" />
                    <site name="SUBSC-P1" pos="0.0136352 0.00816366 -0.0129355" />
                    <site name="TMIN-P1" pos="-0.00106905 -0.0122844 0.0209534" />
                    <site name="TMAJ-P1" pos="0.0096992 -0.0526653 -0.00552019" />
                    <site name="PECM1-P1" pos="0.0113611 -0.0407308 0.00758054" />
                    <site name="PECM1-P2" pos="  0.0191  -0.0301  0.00143" />
                    <site name="PECM2-P1" pos="0.0123815 -0.0416832 0.00762913" />
                    <site name="PECM2-P2" pos=" 0.01748 -0.03533  0.00033" />
                    <site name="PECM3-P1" pos="0.012333 -0.042519 0.00728898" />
                    <site name="PECM3-P2" pos="0.0159185 -0.045833 -0.00378312" />
                    <site name="LAT1-P1" pos="0.0102046 -0.0331891 -0.00634627" />
                    <site name="LAT2-P1" pos="0.00940764 -0.0395646 -0.00593809" />
                    <site name="LAT3-P1" pos="0.0117401 -0.0381165 -0.00404295" />
                    <site name="CORB-P3" pos="0.00722095 -0.146246 -0.00759997" />
                    <site name="TRIlong-P2" pos="-0.0263764 -0.111191 -0.00645318" />
                    <site name="TRIlong-P3" pos="-0.0309441 -0.220001 -0.0118276" />
                    <site name="TRIlong-P4" pos="-0.0169396 -0.260042 -0.0117401" />
                    <site name="TRIlat-P1" pos="-0.00582146 -0.122902 0.00415958" />
                    <site name="TRIlat-P2" pos="-0.0227805 -0.141192 0.0090189" />
                    <site name="TRIlat-P3" pos="-0.0309441 -0.220001 -0.0118276" />
                    <site name="TRIlat-P4" pos="-0.0169396 -0.260042 -0.0117401" />
                    <site name="TRImed-P1" pos="-0.00814422 -0.133097 -0.00880509" />
                    <site name="TRImed-P2" pos="-0.0252782 -0.14713 -0.0104961" />
                    <site name="TRImed-P3" pos="-0.0309441 -0.220001 -0.0118276" />
                    <site name="TRImed-P4" pos="-0.0169396 -0.260042 -0.0117401" />
                    <site name="ANC-P1" pos="-0.00723067 -0.275611 0.00951455" />
                    <site name="BIClong-P3" pos="0.0207104 0.0174255 0.00999076" />
                    <site name="BIClong-P4" pos="0.0231109 -0.00496622 0.0116721" />
                    <site name="BIClong-P5" pos="0.0130716 -0.0274746 0.00132173" />
                    <site name="BIClong-P6" pos="0.0103795 -0.0751834 -0.00160358" />
                    <site name="BIClong-P7" pos="0.0165508 -0.117838 0.000233247" />
                    <site name="BIClong-P8" pos="0.0221585 -0.170465 -0.00612274" />
                    <site name="BICshort-P3" pos="0.0108557 -0.0736284 -0.0107002" />
                    <site name="BICshort-P4" pos="0.0165508 -0.117838 -0.0104864" />
                    <site name="BICshort-P5" pos="0.0221585 -0.170465 -0.00612274" />
                    <site name="BRA-P1" pos="0.00660867 -0.169007 -0.00349871" />
                    <site name="BRA-P2" pos="0.0184071 -0.277555 -0.0107391" />
                    <site name="BRD-P1" pos="-0.00952426 -0.194013 0.00216726" />
                    <site name="ECRL-P1" pos="-0.00709461 -0.253559 0.00884396" />
                    <site name="ECRB-P1" pos="0.0131104 -0.282307 0.0165022" />
                    <site name="ECU-P1" pos="0.000806647 -0.281403 0.018271" />
                    <site name="FCR-P1" pos="0.00736673 -0.270236 -0.0360076" />
                    <site name="FCU-P1" pos="0.00212838 -0.269595 -0.0377083" />
                    <site name="PL-P1" pos="0.00444142 -0.267447 -0.0375625" />
                    <site name="PT-P1" pos="0.00349871 -0.268137 -0.035473" />
                    <site name="FDSL-P1" pos="0.00409155 -0.268215 -0.0375528" />
                    <site name="FDSR-P1" pos="0.00465523 -0.270956 -0.0362602" />
                    <site name="EDCL-P1" pos="-0.000388745 -0.280198 0.0181739" />
                    <site name="EDCR-P1" pos="-0.00151611 -0.281218 0.0173186" />
                    <site name="EDCM-P1" pos="0.00049565 -0.281685 0.0189416" />
                    <site name="EDCI-P1" pos="0.000631711 -0.280849 0.0181641" />
                    <site name="EDM-P1" pos="0.000864959 -0.281053 0.0179503" />
                    <joint name="shoulder_rot" type="hinge" pos="0 0 0" axis="  0.0048 0.999089   0.0424" limited="true" range=" -1.5708 0.349066" ref="0" user="1" />
                    <body name="ulna" pos="0.00592837 -0.282229 -0.0119539" quat="1.0 0.0 0.0 0.0">
                      <geom name="ulna" type="mesh" mesh="ulna" />
                      <inertial pos="0.00944441 -0.0932512 0.0236027" mass="1.07420095504972" fullinertia="0.00496891 0.00105855 0.00453796 0.00029086 -6.99014e-05 0.00100211" />
                      <site name="TRIlong-P5" pos="-0.0212838 0.0101657 -0.000758054" />
                      <site name="TRIlat-P5" pos="-0.0212838 0.0101657 -0.000758054" />
                      <site name="TRImed-P5" pos="-0.0212838 0.0101657 -0.000758054" />
                      <site name="ANC-P2" pos="-0.0246076 -0.00120511 0.00583118" />
                      <site name="SUP-P3" pos="-0.0132173 -0.0328879 0.0195636" />
                      <site name="BRA-P4" pos="-0.00310996 -0.0232275 0.000874677" />
                      <site name="BRA-P3" pos="0.00483988 -0.0142184 0.00124399" />
                      <site name="ECU-P2" pos="-0.0135186 -0.0311094 0.0286408" />
                      <site name="ECU-P3" pos="-0.0165703 -0.0527528 0.0278731" />
                      <site name="ECU-P4" pos="-0.0174255 -0.0930365 0.0318577" />
                      <site name="PT-P2" pos="0.00822197 -0.032781 -0.0139171" />
                      <site name="PT-P3" pos=" 0.01219 -0.06516 -0.00219" />
                      <site name="PQ-P2" pos="0.0018757 -0.203819 0.0352981" />
                      <site name="FDSM-P1" pos="-0.00650177 -0.0263667 -0.00185626" />
                      <site name="FDSI-P1" pos="-0.0065698 -0.0273968 -0.00133145" />
                      <site name="FDPL-P1" pos="-0.0061033 -0.0312357 0.00246853" />
                      <site name="FDPR-P1" pos="-0.00487876 -0.0327907 0.00265319" />
                      <site name="FDPM-P1" pos="-0.00507313 -0.0323339 0.00204091" />
                      <site name="FDPI-P1" pos="-0.00628796 -0.0308664 0.00272122" />
                      <site name="EDM-P2" pos="-0.00949511 -0.0379707 0.029982" />
                      <site name="EDM-P3" pos="-0.00733757 -0.080344 0.0354342" />
                      <site name="EIP-P1" pos="-0.00382914 -0.161835 0.035784" />
                      <site name="EIP-P2" pos="0.00166189 -0.169775 0.0393508" />
                      <site name="EPL-P1" pos="-0.0137227 -0.0943291 0.0286894" />
                      <joint name="elbow_flexion" type="hinge" pos="0 0 0" axis="  0.0494   0.0366 0.998108" limited="true" range="       0  4.26893" ref="0" user="1" />
                      <body name="radius" pos="0.000388745 -0.0111793 0.0194363" quat="1.0 0.0 0.0 0.0">
                        <geom name="radius" type="mesh" mesh="radius" />
                        <inertial pos="0.0326878 -0.176451 0.0151611" mass="0.227017643255283" fullinertia="0.000402564 8.13206e-05 0.000369546 2.76668e-05 -3.89208e-06 5.89136e-05" />
                        <site name="SUP-P1" pos="0.00967976 -0.0592448 0.000728898" />
                        <site name="SUP-P2" pos="0.0116721 -0.0502454 -0.00103989" />
                        <site name="BIClong-P11" pos="-0.00194373 -0.0364449 -0.00194373" />
                        <site name="BIClong-P9" pos=" 0.00273 -0.0343493 -0.0119845" />
                        <site name="BICshort-P8" pos="-0.00194373 -0.0364449 -0.00194373" />
                        <site name="BICshort-P6" pos=" 0.00273 -0.0343493 -0.0119845" />
                        <site name="BRD-P2" pos="0.0347636 -0.123835 0.0224986" />
                        <site name="BRD-P3" pos="0.0407211 -0.214782 0.0217697" />
                        <site name="ECRL-P2" pos="0.031051 -0.130842 0.0270081" />
                        <site name="ECRL-P3" pos="0.0412362 -0.230176 0.0351815" />
                        <site name="ECRB-P2" pos="0.0282326 -0.127178 0.0231789" />
                        <site name="ECRB-P3" pos="0.0344914 -0.221634 0.0382623" />
                        <site name="ECU-P5" pos="-0.0138102 -0.220574 0.0338306" />
                        <site name="FCR-P2" pos="0.0205063 -0.213256 0.00123427" />
                        <site name="FCU-P3" pos="0.0105156 -0.216988 0.00941736" />
                        <site name="FCU-P2" pos="0.0101156 -0.183524 0.00202653" />
                        <site name="PL-P2" pos="0.0245979 -0.232421 -0.00268234" />
                        <site name="PT-P5" pos="0.0246853 -0.105739 0.0192429" />
                        <site name="PT-P4" pos="0.022936 -0.0907721 0.00913552" />
                        <site name="PQ-P1" pos="0.031537 -0.194353 0.019068" />
                        <site name="FDSL-P2" pos="0.0133826 -0.181913 0.00199232" />
                        <site name="FDSR-P2" pos="0.015268 -0.181408 0.00259488" />
                        <site name="FDSM-P2" pos="0.0184557 -0.181797 0.0041207" />
                        <site name="FDSI-P2" pos="0.0208465 -0.18099 0.00536469" />
                        <site name="FDPL-P2" pos="0.0136936 -0.17995 0.00836775" />
                        <site name="FDPR-P2" pos="0.0153554 -0.181048 0.00780407" />
                        <site name="FDPM-P2" pos="0.0185237 -0.181194 0.00762913" />
                        <site name="FDPI-P2" pos="0.0202148 -0.180378 0.00889255" />
                        <site name="EDCL-P3" pos="0.00965061 -0.216764 0.035162" />
                        <site name="EDCL-P2" pos="  0.0013 -0.0382544 0.0129514" />
                        <site name="EDCR-P3" pos="0.00857184 -0.217367 0.0416346" />
                        <site name="EDCR-P2" pos="  0.0026 -0.0392844 0.0144214" />
                        <site name="EDCM-P3" pos="0.0139948 -0.216949 0.0410418" />
                        <site name="EDCM-P2" pos=" 0.00316 -0.0388544 0.0141814" />
                        <site name="EDCI-P3" pos="0.0148987 -0.216862 0.0407794" />
                        <site name="EDCI-P2" pos=" 0.00228 -0.0385544 0.0137314" />
                        <site name="EDM-P4" pos="0.00441226 -0.22004 0.0357451" />
                        <site name="EIP-P3" pos="0.0104573 -0.22142 0.0356091" />
                        <site name="EPL-P2" pos="0.00120511 -0.132834 0.0220613" />
                        <site name="EPL-P3" pos="0.0262598 -0.212566 0.0372029" />
                        <site name="EPL-P4" pos="0.0328684 -0.221138 0.0447738" />
                        <site name="EPL-P5" pos="0.0411487 -0.231022 0.0405559" />
                        <site name="EPB-P1" pos="0.0186987 -0.142815 0.0205452" />
                        <site name="EPB-P2" pos="0.0221196 -0.154108 0.0259002" />
                        <site name="EPB-P3" pos="0.0372321 -0.191671 0.0372613" />
                        <site name="EPB-P4" pos="0.0508771 -0.229467 0.0262306" />
                        <site name="FPL-P1" pos="0.0094368 -0.0919189 0.0171923" />
                        <site name="FPL-P2" pos="0.0161135 -0.131445 0.0186112" />
                        <site name="FPL-P3" pos="0.0181641 -0.174275 0.0193207" />
                        <site name="FPL-P4" pos="0.0369308 -0.225191 0.0153554" />
                        <site name="APL-P1" pos="0.0112153 -0.0921035 0.016337" />
                        <site name="APL-P2" pos="0.0294475 -0.135769 0.0340833" />
                        <site name="APL-P3" pos="0.0388065 -0.156198 0.0330434" />
                        <site name="APL-P4" pos="0.0427328 -0.173429 0.0304582" />
                        <site name="APL-P5" pos="0.0535011 -0.224345 0.0230137" />
                        <joint name="pro_sup" type="hinge" pos="0 0 0" axis="-0.017161 0.992666 -0.119668" limited="true" range=" -1.5708   1.5708" ref="0" user="1" />
                        <body name="proximal_row" pos="0.0174935 -0.235191 0.0242966" quat="1.0 0.0 0.0 0.0">
                          <geom name="lunate" type="mesh" mesh="lunate" />
                          <geom name="sdfastSCAPHOIDw" type="mesh" mesh="sdfastSCAPHOIDw" />
                          <geom name="sdfastPISIFORMw" type="mesh" mesh="sdfastPISIFORMw" />
                          <geom name="sdfastTRIQUETRALw" type="mesh" mesh="sdfastTRIQUETRALw" />
                          <inertial pos="       0        0        0" mass="9.7186370673095e-05" fullinertia="9.17944e-06 9.17944e-06 9.17944e-06        0        0        0" />
                          <body name="hand" pos="0.00387968 -0.0146304 0.00226153" quat="1.0 0.0 0.0 0.0">
                            <geom name="sdfast_1seg_hand_fr_c_5mc" type="mesh" mesh="sdfast_1seg_hand_fr_c_5mc" />
                            <geom name="sdfast_1seg_hand_fr_c_4mc" type="mesh" mesh="sdfast_1seg_hand_fr_c_4mc" />
                            <geom name="sdfast_1seg_hand_fr_c_3mc" type="mesh" mesh="sdfast_1seg_hand_fr_c_3mc" />
                            <geom name="sdfast_1seg_hand_fr_c_trapezium" type="mesh" mesh="sdfast_1seg_hand_fr_c_trapezium" />
                            <geom name="sdfast_1seg_hand_fr_c_trapezoid" type="mesh" mesh="sdfast_1seg_hand_fr_c_trapezoid" />
                            <geom name="sdfast_1seg_hand_fr_c_hamate" type="mesh" mesh="sdfast_1seg_hand_fr_c_hamate" />
                            <geom name="capitate" type="mesh" mesh="capitate" />
                            <geom name="hand_3proxph" type="mesh" mesh="hand_3proxph" />
                            <geom name="hand_3midph" type="mesh" mesh="hand_3midph" />
                            <geom name="hand_3distph" type="mesh" mesh="hand_3distph" />
                            <geom name="hand_4proxph" type="mesh" mesh="hand_4proxph" />
                            <geom name="hand_4midph" type="mesh" mesh="hand_4midph" />
                            <geom name="hand_4distph" type="mesh" mesh="hand_4distph" />
                            <geom name="hand_5proxph" type="mesh" mesh="hand_5proxph" />
                            <geom name="hand_5midph" type="mesh" mesh="hand_5midph" />
                            <geom name="hand_5distph" type="mesh" mesh="hand_5distph" />
                            <geom name="hand_thumbprox" type="mesh" mesh="hand_thumbprox" />
                            <geom name="hand_thumbdist" type="mesh" mesh="hand_thumbdist" />
                            <geom name="hand_1mc" type="mesh" mesh="hand_1mc" />
                            <inertial pos="-0.00292836 -0.0413035 -0.00109048" mass="0.56552749094674" fullinertia="0.000100974 5.50766e-05 0.000137692 8.26149e-07 -1.83589e-07 1.10153e-05" />
                            <site name="ECRL-P4" pos="0.0166869 -0.0206229 0.00566597" />
                            <site name="ECRB-P4" pos="0.00485932 -0.0110404 0.00826084" />
                            <site name="ECU-P6" pos="-0.0218767 -0.0136158 -0.00124399" />
                            <site name="FCR-P3" pos="0.0109237 -0.0179212 -0.00406239" />
                            <site name="FCU-P4" pos="-0.0197871 -0.0171534 -0.00730842" />
                            <site name="PL-P3" pos="0.00891199 -0.018446 -0.0170465" />
                            <site name="PL-P4" pos="0.00220613 -0.0300889 0.00479129" />
                            <site name="FDSL-P3" pos="-0.00228388 -0.0135381 -0.0133728" />
                            <site name="FDSL-P4" pos="-0.0193887 -0.0416055 -0.00721123" />
                            <site name="FDSL-P5" pos="-0.0198649 -0.0581272 -0.0182516" />
                            <site name="FDSL-P6" pos="-0.016648 -0.0704115 -0.0267554" />
                            <site name="FDSL-P7" pos="-0.0112347 -0.0706642 -0.0355313" />
                            <site name="FDSL-P8" pos="-0.010292 -0.0706642 -0.0368919" />
                            <site name="FDSR-P3" pos="-0.000796928 -0.0130618 -0.0132076" />
                            <site name="FDSR-P4" pos="-0.00949511 -0.0503328 3.88745e-005" />
                            <site name="FDSR-P5" pos="-0.0128578 -0.0648233 -0.00991301" />
                            <site name="FDSR-P6" pos="-0.00765829 -0.0780115 -0.0243257" />
                            <site name="FDSR-P7" pos="-0.00290587 -0.0789639 -0.0329948" />
                            <site name="FDSR-P8" pos="0.000602555 -0.0786432 -0.0378249" />
                            <site name="FDSM-P3" pos="0.00660867 -0.0133826 -0.0135964" />
                            <site name="FDSM-P4" pos="0.00457748 -0.0323825 -0.00128286" />
                            <site name="FDSM-P5" pos="0.0052675 -0.0550075 0.000583118" />
                            <site name="FDSM-P6" pos="0.00539384 -0.0702074 -0.0032849" />
                            <site name="FDSM-P7" pos="0.0113416 -0.0856212 -0.0162301" />
                            <site name="FDSM-P8" pos="0.0126439 -0.0862043 -0.0289324" />
                            <site name="FDSM-P9" pos="0.0152388 -0.0833568 -0.0365907" />
                            <site name="FDSI-P3" pos="0.00863987 -0.0132757 -0.0134797" />
                            <site name="FDSI-P4" pos="0.0103115 -0.0368045 0.000233247" />
                            <site name="FDSI-P5" pos="0.0173186 -0.0496428 0.00406239" />
                            <site name="FDSI-P6" pos="0.0179698 -0.0709169 -0.00364449" />
                            <site name="FDSI-P7" pos="0.0260265 -0.0846882 -0.0175324" />
                            <site name="FDSI-P8" pos="0.0259196 -0.0849409 -0.0260265" />
                            <site name="FDSI-P9" pos="0.0258516 -0.083901 -0.0282132" />
                            <site name="FDPL-P3" pos="-0.00085524 -0.00998104 -0.0115457" />
                            <site name="FDPL-P4" pos="-0.0180281 -0.0451528 -0.00712376" />
                            <site name="FDPL-P5" pos="-0.0175713 -0.0567666 -0.0151611" />
                            <site name="FDPL-P6" pos="-0.0138782 -0.0708391 -0.0260751" />
                            <site name="FDPL-P7" pos="-0.00894115 -0.0727246 -0.0358035" />
                            <site name="FDPL-P8" pos="-0.00303221 -0.0719665 -0.0404781" />
                            <site name="FDPL-P9" pos="0.00433451 -0.0686039 -0.0452597" />
                            <site name="FDPR-P3" pos="0.00103018 -0.0114388 -0.0115069" />
                            <site name="FDPR-P4" pos="-0.00830943 -0.0538607 0.00085524" />
                            <site name="FDPR-P5" pos="-0.0104864 -0.0640264 -0.00794013" />
                            <site name="FDPR-P6" pos="-0.00531609 -0.0792458 -0.0219252" />
                            <site name="FDPR-P7" pos="-0.000544244 -0.0799844 -0.0327227" />
                            <site name="FDPR-P8" pos="0.00591865 -0.076165 -0.0411876" />
                            <site name="FDPR-P9" pos="0.0117693 -0.0717235 -0.0472131" />
                            <site name="FDPM-P3" pos="0.00325574 -0.0124399 -0.0111181" />
                            <site name="FDPM-P4" pos="0.00293503 -0.0335001 -0.00593809" />
                            <site name="FDPM-P5" pos="0.0024491 -0.0569804 0.00118567" />
                            <site name="FDPM-P6" pos="0.00276981 -0.0678847 -0.00129258" />
                            <site name="FDPM-P7" pos="0.00838718 -0.0853199 -0.0176393" />
                            <site name="FDPM-P8" pos="0.00973807 -0.0851936 -0.028806" />
                            <site name="FDPM-P9" pos="0.0158705 -0.0792749 -0.0431022" />
                            <site name="FDPM-P10" pos="0.0185529 -0.0744739 -0.0508188" />
                            <site name="FDPI-P3" pos="0.0087079 -0.0113514 -0.011779" />
                            <site name="FDPI-P4" pos="0.0186792 -0.0538607 0.00425676" />
                            <site name="FDPI-P5" pos="0.0201467 -0.0682346 -0.00277953" />
                            <site name="FDPI-P6" pos="0.0282229 -0.0834637 -0.0173186" />
                            <site name="FDPI-P7" pos="0.0284173 -0.08428 -0.0269109" />
                            <site name="FDPI-P8" pos="0.0283201 -0.080033 -0.0386705" />
                            <site name="FDPI-P9" pos="0.027669 -0.0755235 -0.046319" />
                            <site name="EDCL-P4" pos="-0.0239467 -0.0427814 0.00164245" />
                            <site name="EDCL-P5" pos="-0.0231401 -0.046008 0.000748335" />
                            <site name="EDCL-P6" pos="-0.0232761 -0.0642693 -0.00972836" />
                            <site name="EDCL-P7" pos="-0.0174741 -0.0762621 -0.0263472" />
                            <site name="EDCL-P8" pos="-0.0114486 -0.0765537 -0.0367267" />
                            <site name="EDCL-P9" pos="-0.0014578 -0.0737256 -0.0445697" />
                            <site name="EDCL-P10" pos="0.00195345 -0.0727634 -0.0465911" />
                            <site name="EDCR-P4" pos="-0.0151999 -0.0539384 0.00907721" />
                            <site name="EDCR-P5" pos="-0.0138685 -0.0565527 0.0112833" />
                            <site name="EDCR-P6" pos="-0.0153554 -0.0701297 -0.00409155" />
                            <site name="EDCR-P7" pos="-0.00801788 -0.0848923 -0.0219641" />
                            <site name="EDCR-P8" pos="-0.00264347 -0.0855823 -0.0331308" />
                            <site name="EDCR-P9" pos="0.00741532 -0.0780018 -0.0452694" />
                            <site name="EDCR-P10" pos="0.0103892 -0.0758928 -0.0480198" />
                            <site name="EDCM-P4" pos="0.000379027 -0.0512561 0.0144905" />
                            <site name="EDCM-P5" pos="-0.000845521 -0.0541717 0.0141115" />
                            <site name="EDCM-P6" pos="0.00180767 -0.0750084 0.00580203" />
                            <site name="EDCM-P7" pos="0.00978667 -0.0905097 -0.0172409" />
                            <site name="EDCM-P8" pos="0.0128383 -0.0928907 -0.0297002" />
                            <site name="EDCM-P9" pos="0.0180475 -0.0828514 -0.046251" />
                            <site name="EDCM-P10" pos="0.0199815 -0.0776811 -0.0519072" />
                            <site name="EDCM-P11" pos="0.0213324 -0.0748432 -0.0550366" />
                            <site name="EDCI-P4" pos="0.0149959 -0.0454832 0.0159288" />
                            <site name="EDCI-P5" pos="0.0184363 -0.0549492 0.0139754" />
                            <site name="EDCI-P6" pos="0.019379 -0.0746197 0.00577287" />
                            <site name="EDCI-P7" pos="0.0286214 -0.0890422 -0.0120997" />
                            <site name="EDCI-P8" pos="0.0303319 -0.0908595 -0.0282326" />
                            <site name="EDCI-P9" pos="0.0292823 -0.0824821 -0.0414791" />
                            <site name="EDCI-P10" pos="0.0284659 -0.0787501 -0.0482628" />
                            <site name="EDM-P5" pos="-0.0200107 -0.0100296 0.00361533" />
                            <site name="EDM-P6" pos="-0.0249089 -0.0458914 0.000223529" />
                            <site name="EDM-P7" pos="-0.0247728 -0.063278 -0.0106711" />
                            <site name="EDM-P8" pos="-0.0187861 -0.0759026 -0.0264153" />
                            <site name="EDM-P9" pos="-0.0130813 -0.0766995 -0.0378444" />
                            <site name="EDM-P10" pos="-0.00209923 -0.0730939 -0.0445988" />
                            <site name="EDM-P11" pos="0.00128286 -0.0713834 -0.0466786" />
                            <site name="EIP-P4" pos="0.00377083 -0.0217114 0.0115069" />
                            <site name="EIP-P5" pos="0.0164537 -0.0548131 0.0133826" />
                            <site name="EIP-P6" pos="0.0168618 -0.0747558 0.00564653" />
                            <site name="EIP-P7" pos="0.026872 -0.0905194 -0.0146849" />
                            <site name="EIP-P8" pos="0.02798 -0.0917148 -0.0274357" />
                            <site name="EIP-P9" pos="0.0278925 -0.0828417 -0.0417415" />
                            <site name="EIP-P10" pos="0.0275426 -0.0756596 -0.0534622" />
                            <site name="EPL-P6" pos="0.0235969 0.000136061 0.00590893" />
                            <site name="EPL-P7" pos="0.0227222 -0.00891199 -0.000379027" />
                            <site name="EPL-P8" pos="0.0282326 -0.0138685 -0.00475241" />
                            <site name="EPL-P9" pos="0.0428981 -0.0332086 -0.0176296" />
                            <site name="EPL-P10" pos="0.0473006 -0.0451528 -0.0241703" />
                            <site name="EPL-P11" pos="0.0461732 -0.0681276 -0.0366781" />
                            <site name="EPL-P12" pos="0.0389815 -0.0735215 -0.0416249" />
                            <site name="EPB-P5" pos="0.0303513 0.00248797 -0.00317799" />
                            <site name="EPB-P6" pos="0.0288838 -0.0077166 -0.013956" />
                            <site name="EPB-P7" pos="0.0429758 -0.0320715 -0.0235385" />
                            <site name="EPB-P8" pos="0.044006 -0.0465037 -0.0309636" />
                            <site name="FPL-P6" pos="0.01209 -0.021449 -0.0203022" />
                            <site name="FPL-P7" pos="0.0159483 -0.0254725 -0.0215851" />
                            <site name="FPL-P8" pos="0.0238787 -0.0320132 -0.0217406" />
                            <site name="FPL-P9" pos="0.0274746 -0.0532776 -0.0296904" />
                            <site name="FPL-P10" pos="0.0341221 -0.0633558 -0.0364352" />
                            <site name="FPL-P11" pos="0.0343359 -0.0744059 -0.0400213" />
                            <site name="FPL-P5" pos="0.0178892 0.0064176 -0.0168214" />
                            <site name="APL-P7" pos="0.0251421 0.00199232 -0.0160358" />
                            <site name="APL-P8" pos="0.0279702 -0.00655036 -0.0181739" />
                            <site name="APL-P9" pos="0.0298945 -0.0153846 -0.0183196" />
                            <site name="APL-P6" pos="0.0332244 0.00608975 -0.00870125" />
                            <body name="index0" pos="0 0 0">
                              <inertial pos="0 0 0" mass="0.001" diaginertia="0.001 0.001 0.001" />
                              <geom name="sdfast_1seg_hand_fr_c_2mc" type="mesh" mesh="sdfast_1seg_hand_fr_c_2mc" />
                              <body name="index1" pos="0 0 0">
                                <inertial pos="0 0 0" mass="0.001" diaginertia="0.001 0.001 0.001" />
                                <geom name="hand_2proxph" type="mesh" mesh="hand_2proxph" />
                                <body name="index2" pos="0 0 0">
                                  <inertial pos="0 0 0" mass="0.001" diaginertia="0.001 0.001 0.001" />
                                  <geom name="hand_2midph" type="mesh" mesh="hand_2midph" />
                                  <body name="index3" pos="0 0 0">
                                    <inertial pos="0 0 0" mass="0.001" diaginertia="0.001 0.001 0.001" />
                                    <geom name="hand_2distph" type="mesh" mesh="hand_2distph" />
                                    <site name="fingertip" pos="0.024 -0.149 -0.0065" type="sphere" rgba="0.1 0.8 0.1 0.0" size="0.004" />
                                  </body>
                                </body>
                              </body>
                            </body>
                          </body>
                        </body>
                      </body>
                    </body>
                  </body>
                </body>
              </body>
            </body>
          </body>
        </body>
      </body>
    </body>

</mujocoinclude>