<mujocoinclude model="MoBL Arms Index Model">

  <body name="thorax" pos="0 0 0" quat="0.707107 0.707107 0 0">
    <inertial pos="-0.0194693 -0.124635 3.52071e-05" quat="0.982593 0.00053772 0.000250291 0.185769" mass="8.01418" diaginertia="0.0768128 0.0574863 0.0458735"/>
    <joint name="r_z" pos="0 0 0" axis="0 0 1" stiffness="0" range="-6.28319 6.28319" armature="0" damping="0"/>
    <geom name="thorax" type="mesh" mesh="thorax"/>
    <!-- <body euler="-1.57 0 0" pos=".1 -.455 -.02">
        <geom name="thorax_coll0" type="capsule" class="arm_skin" size="0.080 0.077" pos="-.065 0 .070" euler="1.57 0 0"/>
        <geom name="thorax_coll1" type="ellipsoid" class="arm_skin" size="0.095 0.140 0.140" pos="-.075 0 .200" euler="1.57 0 0"/>
        <geom name="thorax_coll2" type="capsule" class="arm_skin" size="0.110 0.065" pos="-.090 0 .340" euler="1.57 0 0"/>
        <geom name="thorax_coll3" type="capsule" class="arm_skin" size="0.075 0.120" pos="-.110 0 .425" euler="1.57 0 0"/>
    </body> -->
    <site name="PECM1-P3" pos="-7e-05 0.00821 0.10454"/>
    <site name="PECM2-P4" pos="0.03091 -0.03922 0.09705"/>
    <site name="PECM2-P5" pos="0.02769 -0.04498 0.02271"/>
    <site name="PECM2-P3" pos="0.02083 -0.02005 0.11555"/>
    <site name="PECM3-P4" pos="0.0525 -0.08417 0.08935"/>
    <site name="PECM3-P5" pos="0.05724 -0.11654 0.03787"/>
    <site name="PECM3-P3" pos="0.02984 -0.0544459 0.1151"/>
    <site name="LAT1-P4" pos="-0.11828 -0.10118 0.03316"/>
    <site name="LAT1-P5" pos="-0.09578 -0.11724 0.00882"/>
    <site name="LAT2-P4" pos="-0.10992 -0.16908 0.02878"/>
    <site name="LAT2-P5" pos="-0.07186 -0.18818 0.00815"/>
    <site name="LAT3-P4" pos="-0.11157 -0.19387 0.05532"/>
    <site name="LAT3-P5" pos="-0.07117 -0.24858 0.00907"/>
    <light name="default" pos="0 0 4" dir="0 0 -1" mode="trackcom"/>
    <light name="additional" pos="4 0.8 0" dir="-1 0 0" active="false" mode="trackcom"/>
    <body name="clavicle" pos="0.006325 0.00693 0.025465">
      <inertial pos="-0.011096 0.0063723 0.054168" quat="0.906292 0.0334036 0.164622 -0.387838" mass="0.156" diaginertia="0.001 0.001 0.001"/>
      <joint name="sternoclavicular_r2" pos="0 0 0" axis="0.0153 0.989299 -0.1451" limited="false" range="-99999.9 99999.9"/>
      <joint name="sternoclavicular_r3" pos="0 0 0" axis="-0.994473 0 -0.104997" limited="false" range="-99999.9 99999.9"/>
      <geom name="clavicle" type="mesh" mesh="clavicle"/>
      <site name="DELT1-P4" pos="-0.014 0.01106 0.08021"/>
      <site name="DELT2-P2" pos="0.0191703 0.0244002 0.162891"/>
      <site name="PECM1-P4" pos="0.00321 -0.00013 0.05113"/>
      <body name="clavphant" pos="-0.01433 0.02007 0.135535">
        <inertial pos="0 0 0" mass="0.001" diaginertia="1 1 1"/>
        <joint name="unrotscap_r3" pos="0 0 0" axis="-0.994473 0 -0.104997" limited="false" range="-99999.9 99999.9"/>
        <joint name="unrotscap_r2" pos="0 0 0" axis="0.0153 0.989299 -0.1451" limited="false" range="-99999.9 99999.9"/>
        <body name="scapula">
          <inertial pos="-0.054694 -0.035032 -0.043734" quat="0.453021 0.77921 0.0744129 0.426692" mass="0.70396" diaginertia="0.00199576 0.00103993 0.001"/>
          <joint name="acromioclavicular_r2" pos="0 0 0" axis="0.157095 0.947269 -0.279291" limited="false" range="-99999.9 99999.9"/>
          <joint name="acromioclavicular_r3" pos="0 0 0" axis="-0.754084 0.297594 0.585487" limited="false" range="-99999.9 99999.9"/>
          <joint name="acromioclavicular_r1" pos="0 0 0" axis="0.6377 0.1186 0.7611" limited="false" range="-99999.9 99999.9"/>
          <geom name="scapula" type="mesh" mesh="scapula"/>
          <site name="DELT1-P3" pos="0.04347 -0.03252 0.00099"/>
          <site name="DELT2-P3" pos="5e-05 0.00294 0.02233"/>
          <site name="DELT2-P4" pos="-0.01078 -0.00034 0.0062"/>
          <site name="DELT3-P1" pos="-0.05573 0.00122 -0.02512"/>
          <site name="DELT3-P2" pos="-0.07247 -0.03285 0.01233"/>
          <site name="SUPSP-P2" pos="-0.01918 0.00127 -0.01271"/>
          <site name="SUPSP-P3" pos="-0.044 -0.01512 -0.05855"/>
          <site name="INFSP-P2" pos="-0.07382 -0.05476 -0.04781"/>
          <site name="SUBSC-P2" pos="-0.01831 -0.05223 -0.02457"/>
          <site name="SUBSC-P3" pos="-0.07246 -0.03943 -0.06475"/>
          <site name="TMIN-P2" pos="-0.09473 -0.07991 -0.04737"/>
          <site name="TMIN-P3" pos="-0.09643 -0.08121 -0.05298"/>
          <site name="TMAJ-P2" pos="-0.10264 -0.10319 -0.05829"/>
          <site name="TMAJ-P3" pos="-0.10489 -0.10895 -0.07117"/>
          <site name="LAT1-P2" pos="-0.08052 -0.06821 -0.02908"/>
          <site name="LAT1-P3" pos="-0.10925 -0.07239 -0.07422"/>
          <site name="LAT2-P2" pos="-0.08345 -0.08695 -0.02453"/>
          <site name="LAT2-P3" pos="-0.11524 -0.10749 -0.08863"/>
          <site name="LAT3-P2" pos="-0.08438 -0.11598 -0.02995"/>
          <site name="LAT3-P3" pos="-0.11279 -0.13833 -0.08911"/>
          <site name="CORB-P1" pos="0.0125 -0.04127 -0.02652"/>
          <site name="CORB-P2" pos="0.00483 -0.06958 -0.01563"/>
          <site name="TRIlong-P1" pos="-0.04565 -0.04073 -0.01377"/>
          <site name="BIClong-P1" pos="-0.03123 -0.02353 -0.01305"/>
          <site name="BIClong-P2" pos="-0.02094 -0.01309 -0.00461"/>
          <site name="BICshort-P1" pos="0.01268 -0.03931 -0.02625"/>
          <site name="BICshort-P2" pos="0.00093 -0.06704 -0.01593"/>
          <body name="scapphant" pos="-0.00955 -0.034 0.009">
            <inertial pos="0 0 0" mass="0.001" diaginertia="1 1 1"/>
            <joint name="unrothum_r1" pos="0 0 0" axis="0.6377 0.1186 0.7611" limited="false" range="-99999.9 99999.9"/>
            <joint name="unrothum_r3" pos="0 0 0" axis="-0.754084 0.297594 0.585487" limited="false" range="-99999.9 99999.9"/>
            <joint name="unrothum_r2" pos="0 0 0" axis="0.157095 0.947269 -0.279291" limited="false" range="-99999.9 99999.9"/>
            <body name="humphant">
              <site name="humphant" rgba="1 0.1 0.5 0.5" pos="0.01095117 0.0325312 0.00469001" size="0.001"/>
              <inertial pos="0 0 0" mass="0.001" diaginertia="1 1 1"/>
              <joint name="elv_angle" pos="0 0 0" axis="0.0048 0.999089 0.0424" range="-1.5708 2.26893" user="1"/>
              <body name="humphant1">
                <inertial pos="0 0 0" mass="0.001" diaginertia="1 1 1"/>
                <joint name="shoulder_elv" pos="0 0 0" axis="-0.998261 0.0023 0.058898" range="0 3.14159" user="1"/>
                <joint name="shoulder1_r2" pos="0 0 0" axis="0.0048 0.999089 0.0424" limited="false" range="-99999.9 99999.9"/>
                <body name="humerus">
                  <inertial pos="0.018064 -0.140141 -0.012746" quat="0.407851 0.343714 -0.567755 0.627034" mass="1.99757" diaginertia="0.0128576 0.0121576 0.00239265"/>
                  <joint name="shoulder_rot" pos="0 0 0" axis="0.0048 0.999089 0.0424" range="-1.57 2.094" user="1"/>
                  <geom name="humerus" type="mesh" mesh="humerus"/>
                  <geom name="humerus_coll" type="capsule" class="arm_skin" size="0.042 0.140" pos="0 -.13 0" euler="1.57 0 0"/>
                  <site name="DELT1-P1" pos="0.00896 -0.11883 0.00585"/>
                  <site name="DELT1-P2" pos="0.01623 -0.11033 0.00412"/>
                  <site name="DELT2-P1" pos="0.00461 -0.13611 0.0056"/>
                  <site name="DELT3-P3" pos="0.00206 -0.07602 0.01045"/>
                  <site name="SUPSP-P1" pos="0.00256 0.01063 0.02593"/>
                  <site name="INFSP-P1" pos="-0.00887 0.00484 0.02448"/>
                  <site name="SUBSC-P1" pos="0.01403 0.0084 -0.01331"/>
                  <site name="TMIN-P1" pos="-0.0011 -0.01264 0.02156"/>
                  <site name="TMAJ-P1" pos="0.00998 -0.05419 -0.00568"/>
                  <site name="PECM1-P1" pos="0.01169 -0.04191 0.0078"/>
                  <site name="PECM1-P2" pos="0.0191 -0.0301 0.00143"/>
                  <site name="PECM2-P1" pos="0.01274 -0.04289 0.00785"/>
                  <site name="PECM2-P2" pos="0.01748 -0.03533 0.00033"/>
                  <site name="PECM3-P1" pos="0.01269 -0.04375 0.0075"/>
                  <site name="PECM3-P2" pos="0.0159185 -0.045833 -0.00378312"/>
                  <site name="LAT1-P1" pos="0.0105 -0.03415 -0.00653"/>
                  <site name="LAT2-P1" pos="0.00968 -0.04071 -0.00611"/>
                  <site name="LAT3-P1" pos="0.01208 -0.03922 -0.00416"/>
                  <site name="CORB-P3" pos="0.00743 -0.15048 -0.00782"/>
                  <site name="TRIlong-P2" pos="-0.02714 -0.11441 -0.00664"/>
                  <site name="TRIlong-P3" pos="-0.03184 -0.22637 -0.01217"/>
                  <site name="TRIlong-P4" pos="-0.01743 -0.26757 -0.01208"/>
                  <site name="TRIlat-P1" pos="-0.00599 -0.12646 0.00428"/>
                  <site name="TRIlat-P2" pos="-0.02344 -0.14528 0.00928"/>
                  <site name="TRIlat-P3" pos="-0.03184 -0.22637 -0.01217"/>
                  <site name="TRIlat-P4" pos="-0.01743 -0.26757 -0.01208"/>
                  <site name="TRImed-P1" pos="-0.00838 -0.13695 -0.00906"/>
                  <site name="TRImed-P2" pos="-0.02601 -0.15139 -0.0108"/>
                  <site name="TRImed-P3" pos="-0.03184 -0.22637 -0.01217"/>
                  <site name="TRImed-P4" pos="-0.01743 -0.26757 -0.01208"/>
                  <site name="ANC-P1" pos="-0.00744 -0.28359 0.00979"/>
                  <site name="BIClong-P3" pos="0.02131 0.01793 0.01028"/>
                  <site name="BIClong-P4" pos="0.02378 -0.00511 0.01201"/>
                  <site name="BIClong-P5" pos="0.01345 -0.02827 0.00136"/>
                  <site name="BIClong-P6" pos="0.01068 -0.07736 -0.00165"/>
                  <site name="BIClong-P7" pos="0.01703 -0.12125 0.00024"/>
                  <site name="BIClong-P8" pos="0.0228 -0.1754 -0.0063"/>
                  <site name="BICshort-P3" pos="0.01117 -0.07576 -0.01101"/>
                  <site name="BICshort-P4" pos="0.01703 -0.12125 -0.01079"/>
                  <site name="BICshort-P5" pos="0.0228 -0.1754 -0.0063"/>
                  <site name="BRA-P1" pos="0.0068 -0.1739 -0.0036"/>
                  <site name="BRA-P2" pos="0.01894 -0.28559 -0.01105"/>
                  <site name="BRD-P1" pos="-0.0098 -0.19963 0.00223"/>
                  <site name="ECRL-P1" pos="-0.0073 -0.2609 0.0091"/>
                  <site name="ECRB-P1" pos="0.01349 -0.29048 0.01698"/>
                  <site name="ECU-P1" pos="0.00083 -0.28955 0.0188"/>
                  <site name="FCR-P1" pos="0.00758 -0.27806 -0.03705"/>
                  <site name="FCU-P1" pos="0.00219 -0.2774 -0.0388"/>
                  <site name="PL-P1" pos="0.00457 -0.27519 -0.03865"/>
                  <site name="PT-P1" pos="0.0036 -0.2759 -0.0365"/>
                  <site name="FDSL-P1" pos="0.00421 -0.27598 -0.03864"/>
                  <site name="FDSR-P1" pos="0.00479 -0.2788 -0.03731"/>
                  <site name="EDCL-P1" pos="-0.0004 -0.28831 0.0187"/>
                  <site name="EDCR-P1" pos="-0.00156 -0.28936 0.01782"/>
                  <site name="EDCM-P1" pos="0.00051 -0.28984 0.01949"/>
                  <site name="EDCI-P1" pos="0.00065 -0.28898 0.01869"/>
                  <site name="EDM-P1" pos="0.00089 -0.28919 0.01847"/>
                  <body name="ulna" pos="0.0061 -0.2904 -0.0123">
                    <inertial pos="0.00971783 -0.0959509 0.024286" quat="0.792048 0.609078 0.0156735 0.0379256" mass="1.1053" diaginertia="0.00543663 0.00523521 0.001"/>
                    <joint name="elbow_flexion" pos="0 0 0" axis="0.0494 0.0366 0.998108" range="0 2.26893" user="1"/>
                    <geom name="ulna" type="mesh" mesh="ulna"/>
                    <site name="TRIlong-P5" pos="-0.0219 0.01046 -0.00078"/>
                    <site name="TRIlat-P5" pos="-0.0219 0.01046 -0.00078"/>
                    <site name="TRImed-P5" pos="-0.0219 0.01046 -0.00078"/>
                    <site name="ANC-P2" pos="-0.02532 -0.00124 0.006"/>
                    <site name="SUP-P3" pos="-0.0136 -0.03384 0.02013"/>
                    <site name="BRA-P4" pos="-0.0032 -0.0239 0.0009"/>
                    <site name="BRA-P3" pos="0.00498 -0.01463 0.00128"/>
                    <site name="ECU-P2" pos="-0.01391 -0.03201 0.02947"/>
                    <site name="ECU-P3" pos="-0.01705 -0.05428 0.02868"/>
                    <site name="ECU-P4" pos="-0.01793 -0.09573 0.03278"/>
                    <site name="PT-P2" pos="0.00846 -0.03373 -0.01432"/>
                    <site name="PT-P3" pos="0.01219 -0.06516 -0.00219"/>
                    <site name="PQ-P2" pos="0.00193 -0.20972 0.03632"/>
                    <site name="FDSM-P1" pos="-0.00669 -0.02713 -0.00191"/>
                    <site name="FDSI-P1" pos="-0.00676 -0.02819 -0.00137"/>
                    <site name="FDPL-P1" pos="-0.00628 -0.03214 0.00254"/>
                    <site name="FDPR-P1" pos="-0.00502 -0.03374 0.00273"/>
                    <site name="FDPM-P1" pos="-0.00522 -0.03327 0.0021"/>
                    <site name="FDPI-P1" pos="-0.00647 -0.03176 0.0028"/>
                    <site name="EDM-P2" pos="-0.00977 -0.03907 0.03085"/>
                    <site name="EDM-P3" pos="-0.00755 -0.08267 0.03646"/>
                    <site name="EIP-P1" pos="-0.00394 -0.16652 0.03682"/>
                    <site name="EIP-P2" pos="0.00171 -0.17469 0.04049"/>
                    <site name="EPL-P1" pos="-0.01412 -0.09706 0.02952"/>
                    <body name="radius" pos="0.0004 -0.011503 0.019999">
                      <inertial pos="0.0336341 -0.181559 0.0156" quat="0.770264 0.63559 0.0119833 0.0507376" mass="0.23359" diaginertia="0.001 0.001 0.001"/>
                      <geom name="radius_coll" type="capsule" class="arm_skin" size="0.030" fromto="0 0 0 0.015 -0.235841 0.028" euler="1.4 0.1 0.12"/>
                      <camera name="hand_top" pos="0.02 -0.2 0.55" euler="0 0 0"/>
                      <camera name="hand_bottom" pos="0.02 -0.2 -0.55" euler="0 3.14 0"/>
                      <camera name="hand_side_inter" pos="0.5 -0.3 0" euler="1.57 1.57 0"/>
                      <camera name="hand_side_exter" pos="-0.5 -0.3 0" euler="1.57 -1.57 0"/>
                      <joint name="pro_sup" pos="0 0 0" axis="-0.017161 0.992666 -0.119668" range="-1.5708 1.5708" user="1"/>
                      <geom name="radius" type="mesh" mesh="radius"/>
                      <geom class="arm_skin" size="0.02" fromto="0.015 0 -.005 0.025 -0.24 0.025"/>
                      <geom class="arm_skin" size="0.02" fromto="-.01 0 -.010 0.015 -0.24 0.025"/>
                      <site name="SUP-P1" pos="0.00996 -0.06096 0.00075"/>
                      <site name="SUP-P2" pos="0.01201 -0.0517 -0.00107"/>
                      <site name="BIClong-P11" pos="-0.002 -0.0375 -0.002"/>
                      <site name="BIClong-P9" pos="0.00273 -0.0343493 -0.0119845"/>
                      <site name="BICshort-P8" pos="-0.002 -0.0375 -0.002"/>
                      <site name="BICshort-P6" pos="0.00273 -0.0343493 -0.0119845"/>
                      <site name="BRD-P2" pos="0.03577 -0.12742 0.02315"/>
                      <site name="BRD-P3" pos="0.0419 -0.221 0.0224"/>
                      <site name="ECRL-P2" pos="0.03195 -0.13463 0.02779"/>
                      <site name="ECRL-P3" pos="0.04243 -0.23684 0.0362"/>
                      <site name="ECRB-P2" pos="0.02905 -0.13086 0.02385"/>
                      <site name="ECRB-P3" pos="0.03549 -0.22805 0.03937"/>
                      <site name="ECU-P5" pos="-0.01421 -0.22696 0.03481"/>
                      <site name="FCR-P2" pos="0.0211 -0.21943 0.00127"/>
                      <site name="FCU-P3" pos="0.01082 -0.22327 0.00969"/>
                      <site name="FCU-P2" pos="0.0101156 -0.183524 0.00202653"/>
                      <site name="PL-P2" pos="0.02531 -0.23915 -0.00276"/>
                      <site name="PT-P5" pos="0.0254 -0.1088 0.0198"/>
                      <site name="PT-P4" pos="0.0236 -0.0934 0.0094"/>
                      <site name="PQ-P1" pos="0.03245 -0.19998 0.01962"/>
                      <site name="FDSL-P2" pos="0.01377 -0.18718 0.00205"/>
                      <site name="FDSR-P2" pos="0.01571 -0.18666 0.00267"/>
                      <site name="FDSM-P2" pos="0.01899 -0.18706 0.00424"/>
                      <site name="FDSI-P2" pos="0.02145 -0.18623 0.00552"/>
                      <site name="FDPL-P2" pos="0.01409 -0.18516 0.00861"/>
                      <site name="FDPR-P2" pos="0.0158 -0.18629 0.00803"/>
                      <site name="FDPM-P2" pos="0.01906 -0.18644 0.00785"/>
                      <site name="FDPI-P2" pos="0.0208 -0.1856 0.00915"/>
                      <site name="EDCL-P3" pos="0.00993 -0.22304 0.03618"/>
                      <site name="EDCL-P2" pos="0.0013 -0.0382544 0.0129514"/>
                      <site name="EDCR-P3" pos="0.00882 -0.22366 0.04284"/>
                      <site name="EDCR-P2" pos="0.0026 -0.0392844 0.0144214"/>
                      <site name="EDCM-P3" pos="0.0144 -0.22323 0.04223"/>
                      <site name="EDCM-P2" pos="0.00316 -0.0388544 0.0141814"/>
                      <site name="EDCI-P3" pos="0.01533 -0.22314 0.04196"/>
                      <site name="EDCI-P2" pos="0.00228 -0.0385544 0.0137314"/>
                      <site name="EDM-P4" pos="0.00454 -0.22641 0.03678"/>
                      <site name="EIP-P3" pos="0.01076 -0.22783 0.03664"/>
                      <site name="EPL-P2" pos="0.00124 -0.13668 0.0227"/>
                      <site name="EPL-P3" pos="0.02702 -0.21872 0.03828"/>
                      <site name="EPL-P4" pos="0.03382 -0.22754 0.04607"/>
                      <site name="EPL-P5" pos="0.04234 -0.23771 0.04173"/>
                      <site name="EPB-P1" pos="0.01924 -0.14695 0.02114"/>
                      <site name="EPB-P2" pos="0.02276 -0.15857 0.02665"/>
                      <site name="EPB-P3" pos="0.03831 -0.19722 0.03834"/>
                      <site name="EPB-P4" pos="0.05235 -0.23611 0.02699"/>
                      <site name="FPL-P1" pos="0.00971 -0.09458 0.01769"/>
                      <site name="FPL-P2" pos="0.01658 -0.13525 0.01915"/>
                      <site name="FPL-P3" pos="0.01869 -0.17932 0.01988"/>
                      <site name="FPL-P4" pos="0.038 -0.23171 0.0158"/>
                      <site name="APL-P1" pos="0.01154 -0.09477 0.01681"/>
                      <site name="APL-P2" pos="0.0303 -0.1397 0.03507"/>
                      <site name="APL-P3" pos="0.03993 -0.16072 0.034"/>
                      <site name="APL-P4" pos="0.04397 -0.17845 0.03134"/>
                      <site name="APL-P5" pos="0.05505 -0.23084 0.02368"/>
                      <body name="proximal_row" pos="0.018 -0.242 0.025">
                        <inertial pos="0 0 0" mass="0.001" diaginertia="0.001 0.001 0.001"/>
                        <geom name="lunate" type="mesh" mesh="lunate"/>
                        <geom name="sdfastSCAPHOIDw" type="mesh" mesh="sdfastSCAPHOIDw"/>
                        <geom name="sdfastPISIFORMw" type="mesh" mesh="sdfastPISIFORMw"/>
                        <geom name="sdfastTRIQUETRALw" type="mesh" mesh="sdfastTRIQUETRALw"/>
                        <body name="hand" pos="0.003992 -0.015054 0.002327">
                          <inertial pos="-0.00301314 -0.0424993 -0.00112205" quat="0.526799 0.470642 -0.462095 0.536141" mass="0.5819" diaginertia="0.001 0.001 0.001"/>
                          <geom name="sdfast_1seg_hand_fr_c_5mc" type="mesh" mesh="sdfast_1seg_hand_fr_c_5mc"/>
                          <geom name="sdfast_1seg_hand_fr_c_4mc" type="mesh" mesh="sdfast_1seg_hand_fr_c_4mc"/>
                          <geom name="sdfast_1seg_hand_fr_c_3mc" type="mesh" mesh="sdfast_1seg_hand_fr_c_3mc"/>
                          <geom name="sdfast_1seg_hand_fr_c_trapezium" type="mesh" mesh="sdfast_1seg_hand_fr_c_trapezium"/>
                          <geom name="sdfast_1seg_hand_fr_c_trapezoid" type="mesh" mesh="sdfast_1seg_hand_fr_c_trapezoid"/>
                          <geom name="sdfast_1seg_hand_fr_c_hamate" type="mesh" mesh="sdfast_1seg_hand_fr_c_hamate"/>
                          <geom name="capitate" type="mesh" mesh="capitate"/>
                          <geom name="hand_3proxph" type="mesh" mesh="hand_3proxph"/>
                          <geom name="hand_3midph" type="mesh" mesh="hand_3midph"/>
                          <geom name="hand_3distph" type="mesh" mesh="hand_3distph"/>
                          <geom name="hand_4proxph" type="mesh" mesh="hand_4proxph"/>
                          <geom name="hand_4midph" type="mesh" mesh="hand_4midph"/>
                          <geom name="hand_4distph" type="mesh" mesh="hand_4distph"/>
                          <geom name="hand_5proxph" type="mesh" mesh="hand_5proxph"/>
                          <geom name="hand_5midph" type="mesh" mesh="hand_5midph"/>
                          <geom name="hand_5distph" type="mesh" mesh="hand_5distph"/>
                          <geom name="hand_thumbprox" type="mesh" mesh="hand_thumbprox"/>
                          <geom name="hand_thumbdist" type="mesh" mesh="hand_thumbdist"/>
                          <geom name="hand_1mc" type="mesh" mesh="hand_1mc"/>
                          <site name="ECRL-P4" pos="0.01717 -0.02122 0.00583"/>
                          <site name="ECRB-P4" pos="0.005 -0.01136 0.0085"/>
                          <site name="ECU-P6" pos="-0.02251 -0.01401 -0.00128"/>
                          <site name="FCR-P3" pos="0.01124 -0.01844 -0.00418"/>
                          <site name="FCU-P4" pos="-0.02036 -0.01765 -0.00752"/>
                          <site name="PL-P3" pos="0.00917 -0.01898 -0.01754"/>
                          <site name="PL-P4" pos="0.00227 -0.03096 0.00493"/>
                          <site name="FDSL-P3" pos="-0.00235 -0.01393 -0.01376"/>
                          <site name="FDSL-P4" pos="-0.01995 -0.04281 -0.00742"/>
                          <site name="FDSL-P5" pos="-0.02044 -0.05981 -0.01878"/>
                          <site name="FDSL-P6" pos="-0.01713 -0.07245 -0.02753"/>
                          <site name="FDSL-P7" pos="-0.01156 -0.07271 -0.03656"/>
                          <site name="FDSL-P8" pos="-0.01059 -0.07271 -0.03796"/>
                          <site name="FDSR-P3" pos="-0.00082 -0.01344 -0.01359"/>
                          <site name="FDSR-P4" pos="-0.00977 -0.05179 4e-05"/>
                          <site name="FDSR-P5" pos="-0.01323 -0.0667 -0.0102"/>
                          <site name="FDSR-P6" pos="-0.00788 -0.08027 -0.02503"/>
                          <site name="FDSR-P7" pos="-0.00299 -0.08125 -0.03395"/>
                          <site name="FDSR-P8" pos="0.00062 -0.08092 -0.03892"/>
                          <site name="FDSM-P3" pos="0.0068 -0.01377 -0.01399"/>
                          <site name="FDSM-P4" pos="0.00471 -0.03332 -0.00132"/>
                          <site name="FDSM-P5" pos="0.00542 -0.0566 0.0006"/>
                          <site name="FDSM-P6" pos="0.00555 -0.07224 -0.00338"/>
                          <site name="FDSM-P7" pos="0.01167 -0.0881 -0.0167"/>
                          <site name="FDSM-P8" pos="0.01301 -0.0887 -0.02977"/>
                          <site name="FDSM-P9" pos="0.01568 -0.08577 -0.03765"/>
                          <site name="FDSI-P3" pos="0.00889 -0.01366 -0.01387"/>
                          <site name="FDSI-P4" pos="0.01061 -0.03787 0.00024"/>
                          <site name="FDSI-P5" pos="0.01782 -0.05108 0.00418"/>
                          <site name="FDSI-P6" pos="0.01849 -0.07297 -0.00375"/>
                          <site name="FDSI-P7" pos="0.02678 -0.08714 -0.01804"/>
                          <site name="FDSI-P8" pos="0.02667 -0.0874 -0.02678"/>
                          <site name="FDSI-P9" pos="0.0266 -0.08633 -0.02903"/>
                          <site name="FDPL-P3" pos="-0.00088 -0.01027 -0.01188"/>
                          <site name="FDPL-P4" pos="-0.01855 -0.04646 -0.00733"/>
                          <site name="FDPL-P5" pos="-0.01808 -0.05841 -0.0156"/>
                          <site name="FDPL-P6" pos="-0.01428 -0.07289 -0.02683"/>
                          <site name="FDPL-P7" pos="-0.0092 -0.07483 -0.03684"/>
                          <site name="FDPL-P8" pos="-0.00312 -0.07405 -0.04165"/>
                          <site name="FDPL-P9" pos="0.00446 -0.07059 -0.04657"/>
                          <site name="FDPR-P3" pos="0.00106 -0.01177 -0.01184"/>
                          <site name="FDPR-P4" pos="-0.00855 -0.05542 0.00088"/>
                          <site name="FDPR-P5" pos="-0.01079 -0.06588 -0.00817"/>
                          <site name="FDPR-P6" pos="-0.00547 -0.08154 -0.02256"/>
                          <site name="FDPR-P7" pos="-0.00056 -0.0823 -0.03367"/>
                          <site name="FDPR-P8" pos="0.00609 -0.07837 -0.04238"/>
                          <site name="FDPR-P9" pos="0.01211 -0.0738 -0.04858"/>
                          <site name="FDPM-P3" pos="0.00335 -0.0128 -0.01144"/>
                          <site name="FDPM-P4" pos="0.00302 -0.03447 -0.00611"/>
                          <site name="FDPM-P5" pos="0.00252 -0.05863 0.00122"/>
                          <site name="FDPM-P6" pos="0.00285 -0.06985 -0.00133"/>
                          <site name="FDPM-P7" pos="0.00863 -0.08779 -0.01815"/>
                          <site name="FDPM-P8" pos="0.01002 -0.08766 -0.02964"/>
                          <site name="FDPM-P9" pos="0.01633 -0.08157 -0.04435"/>
                          <site name="FDPM-P10" pos="0.01909 -0.07663 -0.05229"/>
                          <site name="FDPI-P3" pos="0.00896 -0.01168 -0.01212"/>
                          <site name="FDPI-P4" pos="0.01922 -0.05542 0.00438"/>
                          <site name="FDPI-P5" pos="0.02073 -0.07021 -0.00286"/>
                          <site name="FDPI-P6" pos="0.02904 -0.08588 -0.01782"/>
                          <site name="FDPI-P7" pos="0.02924 -0.08672 -0.02769"/>
                          <site name="FDPI-P8" pos="0.02914 -0.08235 -0.03979"/>
                          <site name="FDPI-P9" pos="0.02847 -0.07771 -0.04766"/>
                          <site name="EDCL-P4" pos="-0.02464 -0.04402 0.00169"/>
                          <site name="EDCL-P5" pos="-0.02381 -0.04734 0.00077"/>
                          <site name="EDCL-P6" pos="-0.02395 -0.06613 -0.01001"/>
                          <site name="EDCL-P7" pos="-0.01798 -0.07847 -0.02711"/>
                          <site name="EDCL-P8" pos="-0.01178 -0.07877 -0.03779"/>
                          <site name="EDCL-P9" pos="-0.0015 -0.07586 -0.04586"/>
                          <site name="EDCL-P10" pos="0.00201 -0.07487 -0.04794"/>
                          <site name="EDCR-P4" pos="-0.01564 -0.0555 0.00934"/>
                          <site name="EDCR-P5" pos="-0.01427 -0.05819 0.01161"/>
                          <site name="EDCR-P6" pos="-0.0158 -0.07216 -0.00421"/>
                          <site name="EDCR-P7" pos="-0.00825 -0.08735 -0.0226"/>
                          <site name="EDCR-P8" pos="-0.00272 -0.08806 -0.03409"/>
                          <site name="EDCR-P9" pos="0.00763 -0.08026 -0.04658"/>
                          <site name="EDCR-P10" pos="0.01069 -0.07809 -0.04941"/>
                          <site name="EDCM-P4" pos="0.00039 -0.05274 0.01491"/>
                          <site name="EDCM-P5" pos="-0.00087 -0.05574 0.01452"/>
                          <site name="EDCM-P6" pos="0.00186 -0.07718 0.00597"/>
                          <site name="EDCM-P7" pos="0.01007 -0.09313 -0.01774"/>
                          <site name="EDCM-P8" pos="0.01321 -0.09558 -0.03056"/>
                          <site name="EDCM-P9" pos="0.01857 -0.08525 -0.04759"/>
                          <site name="EDCM-P10" pos="0.02056 -0.07993 -0.05341"/>
                          <site name="EDCM-P11" pos="0.02195 -0.07701 -0.05663"/>
                          <site name="EDCI-P4" pos="0.01543 -0.0468 0.01639"/>
                          <site name="EDCI-P5" pos="0.01897 -0.05654 0.01438"/>
                          <site name="EDCI-P6" pos="0.01994 -0.07678 0.00594"/>
                          <site name="EDCI-P7" pos="0.02945 -0.09162 -0.01245"/>
                          <site name="EDCI-P8" pos="0.03121 -0.09349 -0.02905"/>
                          <site name="EDCI-P9" pos="0.03013 -0.08487 -0.04268"/>
                          <site name="EDCI-P10" pos="0.02929 -0.08103 -0.04966"/>
                          <site name="EDM-P5" pos="-0.02059 -0.01032 0.00372"/>
                          <site name="EDM-P6" pos="-0.02563 -0.04722 0.00023"/>
                          <site name="EDM-P7" pos="-0.02549 -0.06511 -0.01098"/>
                          <site name="EDM-P8" pos="-0.01933 -0.0781 -0.02718"/>
                          <site name="EDM-P9" pos="-0.01346 -0.07892 -0.03894"/>
                          <site name="EDM-P10" pos="-0.00216 -0.07521 -0.04589"/>
                          <site name="EDM-P11" pos="0.00132 -0.07345 -0.04803"/>
                          <site name="EIP-P4" pos="0.00388 -0.02234 0.01184"/>
                          <site name="EIP-P5" pos="0.01693 -0.0564 0.01377"/>
                          <site name="EIP-P6" pos="0.01735 -0.07692 0.00581"/>
                          <site name="EIP-P7" pos="0.02765 -0.09314 -0.01511"/>
                          <site name="EIP-P8" pos="0.02879 -0.09437 -0.02823"/>
                          <site name="EIP-P9" pos="0.0287 -0.08524 -0.04295"/>
                          <site name="EIP-P10" pos="0.02834 -0.07785 -0.05501"/>
                          <site name="EPL-P6" pos="0.02428 0.00014 0.00608"/>
                          <site name="EPL-P7" pos="0.02338 -0.00917 -0.00039"/>
                          <site name="EPL-P8" pos="0.02905 -0.01427 -0.00489"/>
                          <site name="EPL-P9" pos="0.04414 -0.03417 -0.01814"/>
                          <site name="EPL-P10" pos="0.04867 -0.04646 -0.02487"/>
                          <site name="EPL-P11" pos="0.04751 -0.0701 -0.03774"/>
                          <site name="EPL-P12" pos="0.04011 -0.07565 -0.04283"/>
                          <site name="EPB-P5" pos="0.03123 0.00256 -0.00327"/>
                          <site name="EPB-P6" pos="0.02972 -0.00794 -0.01436"/>
                          <site name="EPB-P7" pos="0.04422 -0.033 -0.02422"/>
                          <site name="EPB-P8" pos="0.04528 -0.04785 -0.03186"/>
                          <site name="FPL-P6" pos="0.01244 -0.02207 -0.02089"/>
                          <site name="FPL-P7" pos="0.01641 -0.02621 -0.02221"/>
                          <site name="FPL-P8" pos="0.02457 -0.03294 -0.02237"/>
                          <site name="FPL-P9" pos="0.02827 -0.05482 -0.03055"/>
                          <site name="FPL-P10" pos="0.03511 -0.06519 -0.03749"/>
                          <site name="FPL-P11" pos="0.03533 -0.07656 -0.04118"/>
                          <site name="FPL-P5" pos="0.0178892 0.0064176 -0.0168214"/>
                          <site name="APL-P7" pos="0.02587 0.00205 -0.0165"/>
                          <site name="APL-P8" pos="0.02878 -0.00674 -0.0187"/>
                          <site name="APL-P9" pos="0.03076 -0.01583 -0.01885"/>
                          <site name="APL-P6" pos="0.0332244 0.00608975 -0.00870125"/>
                          <body name="index0">
                            <inertial pos="0 0 0" mass="0.001" diaginertia="0.001 0.001 0.001"/>
                            <geom name="sdfast_1seg_hand_fr_c_2mc" class="hand_skin" type="mesh" mesh="sdfast_1seg_hand_fr_c_2mc"/>
                            <body name="index1">
                              <inertial pos="0 0 0" mass="0.001" diaginertia="0.001 0.001 0.001"/>
                              <geom name="hand_2proxph" class="hand_skin" type="mesh" mesh="hand_2proxph"/>
                              <body name="index2">
                                <inertial pos="0 0 0" mass="0.001" diaginertia="0.001 0.001 0.001"/>
                                <geom name="hand_2midph" class="hand_skin" type="mesh" mesh="hand_2midph"/>
                                <body name="index3">
                                  <inertial pos="0 0 0" mass="0.001" diaginertia="0.001 0.001 0.001"/>
                                  <geom name="hand_2distph" class="hand_skin" type="mesh" mesh="hand_2distph"/>
                                  <!-- Have inserted a tiny spherical geom at the fingertip - need to check if it works properly or not -->
                                  <!-- TODO: Check if the fingertip contact actually works as intended or not! -->
                                  <geom name="fingertip_contact" class="hand_skin" size="0.00001" type="sphere" pos="0.024 -0.149 -0.0065"/>
                                  <site name="fingertip" pos="0.024 -0.149 -0.0065" size="0.004" rgba="0.1 0.8 0.1 0"/>
                                </body>
                              </body>
                            </body>
                          </body>
                        </body>
                      </body>
                    </body>
                  </body>
                </body>
              </body>
            </body>
          </body>
        </body>
      </body>
    </body>
  </body>

</mujocoinclude>