<mujocoinclude model="MoBL Arms Index Model">

    <body name="thorax" pos="0 0 0" quat="0.7071067811865475 0.7071067811865475 0.0 0.0">
      <light mode="trackcom" directional="false" pos="0 0 4.0" dir="0 0 -1" />
      <geom name="thorax" type="mesh" mesh="thorax" />
      <site name="PECM1-P3" pos="  -7e-05  0.00821  0.10454" />
      <site name="PECM2-P4" pos="0.0272477 -0.0345731 0.0855513" />
      <site name="PECM2-P5" pos="0.0244092 -0.0396507 0.0200193" />
      <site name="PECM2-P3" pos=" 0.02083 -0.02005  0.11555" />
      <site name="PECM3-P4" pos="0.0462797 -0.0741974 0.0787636" />
      <site name="PECM3-P5" pos="0.0504581 -0.102732 0.0333831" />
      <site name="PECM3-P3" pos=" 0.02984 -0.0544459   0.1151" />
      <site name="LAT1-P4" pos="-0.104266 -0.089192 0.0292311" />
      <site name="LAT1-P5" pos="-0.0844318 -0.103349 0.00777499" />
      <site name="LAT2-P4" pos="-0.0968964 -0.149047 0.0253701" />
      <site name="LAT2-P5" pos="-0.0633459 -0.165884 0.00718437" />
      <site name="LAT3-P4" pos="-0.0983509 -0.1709 0.0487656" />
      <site name="LAT3-P5" pos="-0.0627376 -0.219128 0.00799537" />
      <joint name="r_z" type="hinge" pos="0 0 0" axis="       0        0        1" limited="true" range="-6.28319  6.28319" ref="0" armature="0" damping="0" stiffness="0" />
      <body name="clavicle" pos="0.0055756 0.00610892 0.0224479" quat="1.0 0.0 0.0 0.0">
        <geom name="clavicle" type="mesh" mesh="clavicle" />
        <inertial pos="-0.00978132 0.0056173 0.0477501" mass="0.137516778530265" fullinertia="0.000166175 0.000174854 3.04279e-05 -1.30014e-05 -4.79092e-05 3.67916e-05" />
        <site name="DELT1-P4" pos="-0.0123412 0.00974959 0.0707065" />
        <site name="DELT2-P2" pos="0.0191703 0.0244002 0.162891" />
        <site name="PECM1-P4" pos="0.00282967 -0.000114597 0.045072" />
        <joint name="sternoclavicular_r2" type="hinge" pos="0 0 0" axis="  0.0153 0.989299  -0.1451" limited="false" range="-99999.9  99999.9" ref="0" />
        <joint name="sternoclavicular_r3" type="hinge" pos="0 0 0" axis="-0.994473        0 -0.104997" limited="false" range="-99999.9  99999.9" ref="0" />
        <body name="clavphant" pos="-0.0126322 0.0176921 0.119477" quat="1.0 0.0 0.0 0.0">
          <inertial pos="       0        0        0" mass="8.81517811091441e-05" fullinertia="0.685004 0.685004 0.685004        0        0        0" />
          <joint name="unrotscap_r3" type="hinge" pos="0 0 0" axis="-0.994473        0 -0.104997" limited="false" range="-99999.9  99999.9" ref="0" />
          <joint name="unrotscap_r2" type="hinge" pos="0 0 0" axis="  0.0153 0.989299  -0.1451" limited="false" range="-99999.9  99999.9" ref="0" />
          <body name="scapula" pos="       0        0        0" quat="1.0 0.0 0.0 0.0">
            <geom name="scapula" type="mesh" mesh="scapula" />
            <inertial pos="-0.0482137 -0.0308813 -0.0385523" mass="0.620553278295931" fullinertia="0.000851392 0.000788029 0.000935099 0.000307841 0.000280317 0.000165155" />
            <site name="DELT1-P3" pos="0.0383196 -0.028667 0.000872703" />
            <site name="DELT2-P3" pos="4.40759e-005 0.00259166 0.0196843" />
            <site name="DELT2-P4" pos="-0.00950276 -0.000299716 0.00546541" />
            <site name="DELT3-P1" pos="-0.049127 0.00107545 -0.0221437" />
            <site name="DELT3-P2" pos="-0.0638836 -0.0289579 0.0108691" />
            <site name="SUPSP-P2" pos="-0.0169075 0.00111953 -0.0112041" />
            <site name="SUPSP-P3" pos="-0.0387868 -0.0133285 -0.0516129" />
            <site name="INFSP-P2" pos="-0.0650736 -0.0482719 -0.0421454" />
            <site name="SUBSC-P2" pos="-0.0161406 -0.0460417 -0.0216589" />
            <site name="SUBSC-P3" pos="-0.0638748 -0.0347582 -0.0570783" />
            <site name="TMIN-P2" pos="-0.0835062 -0.0704421 -0.0417575" />
            <site name="TMIN-P3" pos="-0.0850048 -0.0715881 -0.0467028" />
            <site name="TMAJ-P2" pos="-0.090479 -0.0909638 -0.0513837" />
            <site name="TMAJ-P3" pos="-0.0924624 -0.0960414 -0.0627376" />
            <site name="LAT1-P2" pos="-0.08052 -0.06821 -0.02908" />
            <site name="LAT1-P3" pos="-0.10925 -0.07239 -0.07422" />
            <site name="LAT2-P2" pos="-0.08345 -0.08695 -0.02453" />
            <site name="LAT2-P3" pos="-0.11524 -0.10749 -0.08863" />
            <site name="LAT3-P2" pos="-0.08438 -0.11598 -0.02995" />
            <site name="LAT3-P3" pos="-0.11279 -0.13833 -0.08911" />
            <site name="CORB-P1" pos="0.011019 -0.0363802 -0.0233779" />
            <site name="CORB-P2" pos="0.00425773 -0.061336 -0.0137781" />
            <site name="TRIlong-P1" pos="-0.0402413 -0.0359042 -0.0121385" />
            <site name="BIClong-P1" pos="-0.0275298 -0.0207421 -0.0115038" />
            <site name="BIClong-P2" pos="-0.018459 -0.0115391 -0.0040638" />
            <site name="BICshort-P1" pos="0.0111776 -0.0346525 -0.0231398" />
            <site name="BICshort-P2" pos="0.000819812 -0.059097 -0.0140426" />
            <joint name="acromioclavicular_r2" type="hinge" pos="0 0 0" axis="0.157095 0.947269 -0.279291" limited="false" range="-99999.9  99999.9" ref="0" />
            <joint name="acromioclavicular_r3" type="hinge" pos="0 0 0" axis="-0.754084 0.297594 0.585487" limited="false" range="-99999.9  99999.9" ref="0" />
            <joint name="acromioclavicular_r1" type="hinge" pos="0 0 0" axis="  0.6377   0.1186   0.7611" limited="false" range="-99999.9  99999.9" ref="0" />
            <body name="scapphant" pos="-0.0084185 -0.0299716 0.00793366" quat="1.0 0.0 0.0 0.0">
              <inertial pos="       0        0        0" mass="8.81517811091441e-05" fullinertia="0.685004 0.685004 0.685004        0        0        0" />
              <joint name="unrothum_r1" type="hinge" pos="0 0 0" axis="  0.6377   0.1186   0.7611" limited="false" range="-99999.9  99999.9" ref="0" />
              <joint name="unrothum_r3" type="hinge" pos="0 0 0" axis="-0.754084 0.297594 0.585487" limited="false" range="-99999.9  99999.9" ref="0" />
              <joint name="unrothum_r2" type="hinge" pos="0 0 0" axis="0.157095 0.947269 -0.279291" limited="false" range="-99999.9  99999.9" ref="0" />
              <body name="humphant" pos="       0        0        0" quat="1.0 0.0 0.0 0.0">
                <inertial pos="       0        0        0" mass="8.81517811091441e-05" fullinertia="0.685004 0.685004 0.685004        0        0        0" />
                <joint name="elv_angle" type="hinge" pos="0 0 0" axis="  0.0048 0.999089   0.0424" limited="true" range=" -1.5708  2.26893" ref="0" user="1" />
                <body name="humphant1" pos="       0        0        0" quat="1.0 0.0 0.0 0.0">
                  <inertial pos="       0        0        0" mass="8.81517811091441e-05" fullinertia="0.685004 0.685004 0.685004        0        0        0" />
                  <joint name="shoulder_elv" type="hinge" pos="0 0 0" axis="-0.998261   0.0023 0.058898" limited="true" range="       0  3.14159" ref="0" user="1" />
                  <joint name="shoulder1_r2" type="hinge" pos="0 0 0" axis="  0.0048 0.999089   0.0424" limited="false" range="-99999.9  99999.9" ref="0" />
                  <body name="humerus" pos="       0        0        0" quat="1.0 0.0 0.0 0.0">
                    <geom name="humerus" type="mesh" mesh="humerus" />
                    <inertial pos="0.0159237 -0.123537 -0.0112358" mass="1.76089353390193" fullinertia="0.00841023 0.00174767 0.00861659 -0.000237977 -0.000159263 0.000842076" />
                    <site name="DELT1-P1" pos="0.0078984 -0.104751 0.00515688" />
                    <site name="DELT1-P2" pos="0.014307 -0.0972579 0.00363185" />
                    <site name="DELT2-P1" pos="0.0040638 -0.119983 0.0049365" />
                    <site name="DELT3-P3" pos="0.00181593 -0.067013 0.00921186" />
                    <site name="SUPSP-P1" pos="0.00225669 0.00937053 0.0228578" />
                    <site name="INFSP-P1" pos="-0.00781906 0.00426655 0.0215796" />
                    <site name="SUBSC-P1" pos="0.0123677 0.00740475 -0.011733" />
                    <site name="TMIN-P1" pos="-0.00096967 -0.0111424 0.0190055" />
                    <site name="TMAJ-P1" pos="0.00879755 -0.0477695 -0.00500702" />
                    <site name="PECM1-P1" pos="0.0103049 -0.0369444 0.00687584" />
                    <site name="PECM1-P2" pos="  0.0191  -0.0301  0.00143" />
                    <site name="PECM2-P1" pos="0.0112305 -0.0378083 0.00691991" />
                    <site name="PECM2-P2" pos=" 0.01748 -0.03533  0.00033" />
                    <site name="PECM3-P1" pos="0.0111865 -0.0385664 0.00661138" />
                    <site name="PECM3-P2" pos="0.0159185 -0.045833 -0.00378312" />
                    <site name="LAT1-P1" pos="0.00925594 -0.0301038 -0.00575631" />
                    <site name="LAT2-P1" pos="0.00853309 -0.0358866 -0.00538607" />
                    <site name="LAT3-P1" pos="0.0106487 -0.0345731 -0.00366711" />
                    <site name="CORB-P3" pos="0.00654968 -0.132651 -0.00689347" />
                    <site name="TRIlong-P2" pos="-0.0239244 -0.100854 -0.00585328" />
                    <site name="TRIlong-P3" pos="-0.0280675 -0.199549 -0.0107281" />
                    <site name="TRIlong-P4" pos="-0.0153649 -0.235868 -0.0106487" />
                    <site name="TRIlat-P1" pos="-0.00528029 -0.111477 0.0037729" />
                    <site name="TRIlat-P2" pos="-0.0206628 -0.128067 0.00818049" />
                    <site name="TRIlat-P3" pos="-0.0280675 -0.199549 -0.0107281" />
                    <site name="TRIlat-P4" pos="-0.0153649 -0.235868 -0.0106487" />
                    <site name="TRImed-P1" pos="-0.00738712 -0.120724 -0.00798655" />
                    <site name="TRImed-P2" pos="-0.0229283 -0.133453 -0.00952039" />
                    <site name="TRImed-P3" pos="-0.0280675 -0.199549 -0.0107281" />
                    <site name="TRImed-P4" pos="-0.0153649 -0.235868 -0.0106487" />
                    <site name="ANC-P1" pos="-0.00655849 -0.24999 0.00863006" />
                    <site name="BIClong-P3" pos="0.0187851 0.0158056 0.009062" />
                    <site name="BIClong-P4" pos="0.0209625 -0.00450456 0.010587" />
                    <site name="BIClong-P5" pos="0.0118564 -0.0249205 0.00119886" />
                    <site name="BIClong-P6" pos="0.00941461 -0.0681942 -0.0014545" />
                    <site name="BIClong-P7" pos="0.0150122 -0.106884 0.000211564" />
                    <site name="BIClong-P8" pos="0.0200986 -0.154618 -0.00555356" />
                    <site name="BICshort-P3" pos="0.00984655 -0.0667838 -0.00970551" />
                    <site name="BICshort-P4" pos="0.0150122 -0.106884 -0.00951158" />
                    <site name="BICshort-P5" pos="0.0200986 -0.154618 -0.00555356" />
                    <site name="BRA-P1" pos="0.00599432 -0.153296 -0.00317346" />
                    <site name="BRA-P2" pos="0.0166959 -0.251753 -0.00974077" />
                    <site name="BRD-P1" pos="-0.00863887 -0.175977 0.00196578" />
                    <site name="ECRL-P1" pos="-0.00643508 -0.229988 0.00802181" />
                    <site name="ECRB-P1" pos="0.0118917 -0.256063 0.0149682" />
                    <site name="ECU-P1" pos="0.00073166 -0.255243 0.0165725" />
                    <site name="FCR-P1" pos="0.00668191 -0.245115 -0.0326602" />
                    <site name="FCU-P1" pos="0.00193052 -0.244533 -0.0342029" />
                    <site name="PL-P1" pos="0.00402854 -0.242585 -0.0340707" />
                    <site name="PT-P1" pos="0.00317346 -0.243211 -0.0321754" />
                    <site name="FDSL-P1" pos="0.00371119 -0.243281 -0.0340618" />
                    <site name="FDSR-P1" pos="0.00422247 -0.245767 -0.0328894" />
                    <site name="EDCL-P1" pos="-0.000352607 -0.25415 0.0164844" />
                    <site name="EDCR-P1" pos="-0.00137517 -0.255076 0.0157086" />
                    <site name="EDCM-P1" pos="0.000449574 -0.255499 0.0171808" />
                    <site name="EDCI-P1" pos="0.000572987 -0.254741 0.0164756" />
                    <site name="EDM-P1" pos="0.000784551 -0.254926 0.0162816" />
                    <joint name="shoulder_rot" type="hinge" pos="0 0 0" axis="  0.0048 0.999089   0.0424" limited="true" range=" -1.5708 0.349066" ref="0" user="1" />
                    <body name="ulna" pos="0.00537726 -0.255993 -0.0108427" quat="1.0 0.0 0.0 0.0">
                      <geom name="ulna" type="mesh" mesh="ulna" />
                      <inertial pos="0.00856644 -0.0845824 0.0214085" mass="0.97434163659937" fullinertia="0.00370799 0.000789933 0.00338639 0.00021705 -5.21631e-05 0.000747812" />
                      <site name="TRIlong-P5" pos="-0.0193052 0.00922068 -0.000687584" />
                      <site name="TRIlat-P5" pos="-0.0193052 0.00922068 -0.000687584" />
                      <site name="TRImed-P5" pos="-0.0193052 0.00922068 -0.000687584" />
                      <site name="ANC-P2" pos="-0.02232 -0.00109308 0.00528911" />
                      <site name="SUP-P3" pos="-0.0119886 -0.0298306 0.017745" />
                      <site name="BRA-P4" pos="-0.00282086 -0.0210683 0.000793366" />
                      <site name="BRA-P3" pos="0.00438996 -0.0128966 0.00112834" />
                      <site name="ECU-P2" pos="-0.0122619 -0.0282174 0.0259783" />
                      <site name="ECU-P3" pos="-0.0150299 -0.0478488 0.0252819" />
                      <site name="ECU-P4" pos="-0.0158056 -0.0843877 0.0288962" />
                      <site name="PT-P2" pos="0.00745764 -0.0297336 -0.0126233" />
                      <site name="PT-P3" pos=" 0.01219 -0.06516 -0.00219" />
                      <site name="PQ-P2" pos="0.00170133 -0.184872 0.0320167" />
                      <site name="FDSM-P1" pos="-0.00589735 -0.0239156 -0.0016837" />
                      <site name="FDSI-P1" pos="-0.00595906 -0.02485 -0.00120768" />
                      <site name="FDPL-P1" pos="-0.00553593 -0.028332 0.00223906" />
                      <site name="FDPR-P1" pos="-0.00442522 -0.0297424 0.00240654" />
                      <site name="FDPM-P1" pos="-0.00460152 -0.0293281 0.00185119" />
                      <site name="FDPI-P1" pos="-0.00570342 -0.027997 0.00246825" />
                      <site name="EDM-P2" pos="-0.00861243 -0.0344409 0.0271948" />
                      <site name="EDM-P3" pos="-0.00665546 -0.0728751 0.0321401" />
                      <site name="EIP-P1" pos="-0.00347318 -0.14679 0.0324575" />
                      <site name="EIP-P2" pos="0.0015074 -0.153992 0.0356927" />
                      <site name="EPL-P1" pos="-0.012447 -0.0855601 0.0260224" />
                      <joint name="elbow_flexion" type="hinge" pos="0 0 0" axis="  0.0494   0.0366 0.998108" limited="true" range="       0  4.26893" ref="0" user="1" />
                      <body name="radius" pos="0.000352607 -0.0101401 0.0176295" quat="1.0 0.0 0.0 0.0">
                        <geom name="radius" type="mesh" mesh="radius" />
                        <inertial pos="0.0296491 -0.160047 0.0137517" mass="0.20591374549285" fullinertia="0.000300409 6.06845e-05 0.000275769 2.0646e-05 -2.90442e-06 4.39636e-05" />
                        <site name="SUP-P1" pos="0.00877992 -0.0537373 0.000661138" />
                        <site name="SUP-P2" pos="0.010587 -0.0455745 -0.000943224" />
                        <site name="BIClong-P11" pos="-0.00176304 -0.0330569 -0.00176304" />
                        <site name="BIClong-P9" pos=" 0.00273 -0.0343493 -0.0119845" />
                        <site name="BICshort-P8" pos="-0.00176304 -0.0330569 -0.00176304" />
                        <site name="BICshort-P6" pos=" 0.00273 -0.0343493 -0.0119845" />
                        <site name="BRD-P2" pos="0.0315319 -0.112323 0.0204071" />
                        <site name="BRD-P3" pos="0.0369356 -0.194815 0.019746" />
                        <site name="ECRL-P2" pos="0.0281645 -0.118679 0.0244974" />
                        <site name="ECRL-P3" pos="0.0374028 -0.208779 0.0319109" />
                        <site name="ECRB-P2" pos="0.0256081 -0.115355 0.0210242" />
                        <site name="ECRB-P3" pos="0.0312851 -0.20103 0.0347054" />
                        <site name="ECU-P5" pos="-0.0125264 -0.200069 0.0306856" />
                        <site name="FCR-P2" pos="0.0186 -0.193431 0.00111953" />
                        <site name="FCU-P3" pos="0.00953802 -0.196816 0.00854191" />
                        <site name="FCU-P2" pos="0.0101156 -0.183524 0.00202653" />
                        <site name="PL-P2" pos="0.0223112 -0.210815 -0.00243299" />
                        <site name="PT-P5" pos="0.0223906 -0.0959091 0.0174541" />
                        <site name="PT-P4" pos="0.0208038 -0.0823338 0.00828627" />
                        <site name="PQ-P1" pos="0.0286053 -0.176286 0.0172954" />
                        <site name="FDSL-P2" pos="0.0121385 -0.165003 0.00180711" />
                        <site name="FDSR-P2" pos="0.0138486 -0.164544 0.00235365" />
                        <site name="FDSM-P2" pos="0.01674 -0.164897 0.00373764" />
                        <site name="FDSI-P2" pos="0.0189086 -0.164165 0.00486598" />
                        <site name="FDPL-P2" pos="0.0124206 -0.163222 0.00758987" />
                        <site name="FDPR-P2" pos="0.013928 -0.164218 0.00707859" />
                        <site name="FDPM-P2" pos="0.0168017 -0.16435 0.00691991" />
                        <site name="FDPI-P2" pos="0.0183356 -0.16361 0.00806589" />
                        <site name="EDCL-P3" pos="0.00875347 -0.196614 0.0318933" />
                        <site name="EDCL-P2" pos="  0.0013 -0.0382544 0.0129514" />
                        <site name="EDCR-P3" pos="0.00777499 -0.19716 0.0377642" />
                        <site name="EDCR-P2" pos="  0.0026 -0.0392844 0.0144214" />
                        <site name="EDCM-P3" pos="0.0126939 -0.196781 0.0372265" />
                        <site name="EDCM-P2" pos=" 0.00316 -0.0388544 0.0141814" />
                        <site name="EDCI-P3" pos="0.0135137 -0.196702 0.0369885" />
                        <site name="EDCI-P2" pos=" 0.00228 -0.0385544 0.0137314" />
                        <site name="EDM-P4" pos="0.00400209 -0.199584 0.0324222" />
                        <site name="EIP-P3" pos="0.00948513 -0.200836 0.0322988" />
                        <site name="EPL-P2" pos="0.00109308 -0.120486 0.0200105" />
                        <site name="EPL-P3" pos="0.0238186 -0.192806 0.0337445" />
                        <site name="EPL-P4" pos="0.0298129 -0.200581 0.0406115" />
                        <site name="EPL-P5" pos="0.0373235 -0.209546 0.0367857" />
                        <site name="EPB-P1" pos="0.0169604 -0.129539 0.0186353" />
                        <site name="EPB-P2" pos="0.0200633 -0.139782 0.0234924" />
                        <site name="EPB-P3" pos="0.0337709 -0.173853 0.0337974" />
                        <site name="EPB-P4" pos="0.0461475 -0.208135 0.0237922" />
                        <site name="FPL-P1" pos="0.00855954 -0.083374 0.0155941" />
                        <site name="FPL-P2" pos="0.0146156 -0.119225 0.0168811" />
                        <site name="FPL-P3" pos="0.0164756 -0.158074 0.0175246" />
                        <site name="FPL-P4" pos="0.0334977 -0.204256 0.013928" />
                        <site name="APL-P1" pos="0.0101727 -0.0835414 0.0148183" />
                        <site name="APL-P2" pos="0.02671 -0.123148 0.0309148" />
                        <site name="APL-P3" pos="0.035199 -0.141678 0.0299716" />
                        <site name="APL-P4" pos="0.0387603 -0.157307 0.0276268" />
                        <site name="APL-P5" pos="0.0485276 -0.20349 0.0208743" />
                        <joint name="pro_sup" type="hinge" pos="0 0 0" axis="-0.017161 0.992666 -0.119668" limited="true" range=" -1.5708   1.5708" ref="0" user="1" />
                        <body name="proximal_row" pos="0.0158673 -0.213327 0.0220379" quat="1.0 0.0 0.0 0.0">
                          <geom name="lunate" type="mesh" mesh="lunate" />
                          <geom name="sdfastSCAPHOIDw" type="mesh" mesh="sdfastSCAPHOIDw" />
                          <geom name="sdfastPISIFORMw" type="mesh" mesh="sdfastPISIFORMw" />
                          <geom name="sdfastTRIQUETRALw" type="mesh" mesh="sdfastTRIQUETRALw" />
                          <inertial pos="       0        0        0" mass="8.81517811091441e-05" fullinertia="6.85004e-06 6.85004e-06 6.85004e-06        0        0        0" />
                          <body name="hand" pos="0.00351902 -0.0132704 0.00205129" quat="1.0 0.0 0.0 0.0">
                            <geom name="sdfast_1seg_hand_fr_c_5mc" type="mesh" mesh="sdfast_1seg_hand_fr_c_5mc" />
                            <geom name="sdfast_1seg_hand_fr_c_4mc" type="mesh" mesh="sdfast_1seg_hand_fr_c_4mc" />
                            <geom name="sdfast_1seg_hand_fr_c_3mc" type="mesh" mesh="sdfast_1seg_hand_fr_c_3mc" />
                            <geom name="sdfast_1seg_hand_fr_c_trapezium" type="mesh" mesh="sdfast_1seg_hand_fr_c_trapezium" />
                            <geom name="sdfast_1seg_hand_fr_c_trapezoid" type="mesh" mesh="sdfast_1seg_hand_fr_c_trapezoid" />
                            <geom name="sdfast_1seg_hand_fr_c_hamate" type="mesh" mesh="sdfast_1seg_hand_fr_c_hamate" />
                            <geom name="capitate" type="mesh" mesh="capitate" />
                            <geom name="hand_3proxph" type="mesh" mesh="hand_3proxph" />
                            <geom name="hand_3midph" type="mesh" mesh="hand_3midph" />
                            <geom name="hand_3distph" type="mesh" mesh="hand_3distph" />
                            <geom name="hand_4proxph" type="mesh" mesh="hand_4proxph" />
                            <geom name="hand_4midph" type="mesh" mesh="hand_4midph" />
                            <geom name="hand_4distph" type="mesh" mesh="hand_4distph" />
                            <geom name="hand_5proxph" type="mesh" mesh="hand_5proxph" />
                            <geom name="hand_5midph" type="mesh" mesh="hand_5midph" />
                            <geom name="hand_5distph" type="mesh" mesh="hand_5distph" />
                            <geom name="hand_thumbprox" type="mesh" mesh="hand_thumbprox" />
                            <geom name="hand_thumbdist" type="mesh" mesh="hand_thumbdist" />
                            <geom name="hand_1mc" type="mesh" mesh="hand_1mc" />
                            <inertial pos="-0.00265614 -0.0374639 -0.000989107" mass="0.51295521427411" fullinertia="7.53505e-05 4.11003e-05 0.000102751 6.16504e-07 -1.37001e-07 8.22005e-06" />
                            <site name="ECRL-P4" pos="0.0151357 -0.0187058 0.00513925" />
                            <site name="ECRB-P4" pos="0.00440759 -0.010014 0.0074929" />
                            <site name="ECU-P6" pos="-0.019843 -0.0123501 -0.00112834" />
                            <site name="FCR-P3" pos="0.00990826 -0.0162552 -0.00368474" />
                            <site name="FCU-P4" pos="-0.0179477 -0.0155588 -0.00662901" />
                            <site name="PL-P3" pos="0.00808352 -0.0167312 -0.0154618" />
                            <site name="PL-P4" pos="0.00200105 -0.0272918 0.00434588" />
                            <site name="FDSL-P3" pos="-0.00207157 -0.0122795 -0.0121297" />
                            <site name="FDSL-P4" pos="-0.0175863 -0.0377378 -0.00654086" />
                            <site name="FDSL-P5" pos="-0.0180182 -0.0527236 -0.0165549" />
                            <site name="FDSL-P6" pos="-0.0151004 -0.063866 -0.0242682" />
                            <site name="FDSL-P7" pos="-0.0101903 -0.0640952 -0.0322283" />
                            <site name="FDSL-P8" pos="-0.00933527 -0.0640952 -0.0334624" />
                            <site name="FDSR-P3" pos="-0.000722845 -0.0118476 -0.0119798" />
                            <site name="FDSR-P4" pos="-0.00861243 -0.0456538 3.52607e-005" />
                            <site name="FDSR-P5" pos="-0.0116625 -0.0587972 -0.00899148" />
                            <site name="FDSR-P6" pos="-0.00694636 -0.0707594 -0.0220644" />
                            <site name="FDSR-P7" pos="-0.00263574 -0.0716233 -0.0299275" />
                            <site name="FDSR-P8" pos="0.000546541 -0.0713324 -0.0343087" />
                            <site name="FDSM-P3" pos="0.00599432 -0.0121385 -0.0123324" />
                            <site name="FDSM-P4" pos="0.00415195 -0.0293722 -0.0011636" />
                            <site name="FDSM-P5" pos="0.00477783 -0.0498939 0.000528911" />
                            <site name="FDSM-P6" pos="0.00489242 -0.0636808 -0.00297953" />
                            <site name="FDSM-P7" pos="0.0102873 -0.0776617 -0.0147213" />
                            <site name="FDSM-P8" pos="0.0114685 -0.0781906 -0.0262428" />
                            <site name="FDSM-P9" pos="0.0138222 -0.0756078 -0.0331891" />
                            <site name="FDSI-P3" pos="0.00783669 -0.0120415 -0.0122267" />
                            <site name="FDSI-P4" pos="0.0093529 -0.0333831 0.000211564" />
                            <site name="FDSI-P5" pos="0.0157086 -0.0450279 0.00368474" />
                            <site name="FDSI-P6" pos="0.0162993 -0.0643244 -0.00330569" />
                            <site name="FDSI-P7" pos="0.023607 -0.0768155 -0.0159026" />
                            <site name="FDSI-P8" pos="0.0235101 -0.0770447 -0.023607" />
                            <site name="FDSI-P9" pos="0.0234484 -0.0761014 -0.0255905" />
                            <site name="FDPL-P3" pos="-0.000775736 -0.00905319 -0.0104724" />
                            <site name="FDPL-P4" pos="-0.0163522 -0.0409553 -0.00646153" />
                            <site name="FDPL-P5" pos="-0.0159378 -0.0514895 -0.0137517" />
                            <site name="FDPL-P6" pos="-0.0125881 -0.0642538 -0.0236511" />
                            <site name="FDPL-P7" pos="-0.00810996 -0.065964 -0.0324751" />
                            <site name="FDPL-P8" pos="-0.00275034 -0.0652764 -0.0367152" />
                            <site name="FDPL-P9" pos="0.00393157 -0.0622263 -0.0410523" />
                            <site name="FDPR-P3" pos="0.000934409 -0.0103755 -0.0104372" />
                            <site name="FDPR-P4" pos="-0.00753698 -0.0488537 0.000775736" />
                            <site name="FDPR-P5" pos="-0.00951158 -0.0580744 -0.007202" />
                            <site name="FDPR-P6" pos="-0.0048219 -0.071879 -0.019887" />
                            <site name="FDPR-P7" pos="-0.00049365 -0.0725489 -0.0296807" />
                            <site name="FDPR-P8" pos="0.00536844 -0.0690846 -0.0373587" />
                            <site name="FDPR-P9" pos="0.0106752 -0.065056 -0.0428241" />
                            <site name="FDPM-P3" pos="0.00295308 -0.0112834 -0.0100846" />
                            <site name="FDPM-P4" pos="0.00266218 -0.0303859 -0.00538607" />
                            <site name="FDPM-P5" pos="0.00222142 -0.0516834 0.00107545" />
                            <site name="FDPM-P6" pos="0.00251233 -0.061574 -0.00117242" />
                            <site name="FDPM-P7" pos="0.0076075 -0.0773884 -0.0159995" />
                            <site name="FDPM-P8" pos="0.00883281 -0.0772739 -0.0261282" />
                            <site name="FDPM-P9" pos="0.0143952 -0.0719054 -0.0390953" />
                            <site name="FDPM-P10" pos="0.0168282 -0.0675507 -0.0460946" />
                            <site name="FDPI-P3" pos="0.0078984 -0.0102961 -0.010684" />
                            <site name="FDPI-P4" pos="0.0169428 -0.0488537 0.00386105" />
                            <site name="FDPI-P5" pos="0.0182739 -0.0618914 -0.00252114" />
                            <site name="FDPI-P6" pos="0.0255993 -0.0757047 -0.0157086" />
                            <site name="FDPI-P7" pos="0.0257756 -0.0764452 -0.0244092" />
                            <site name="FDPI-P8" pos="0.0256874 -0.072593 -0.0350756" />
                            <site name="FDPI-P9" pos="0.0250968 -0.0685027 -0.0420131" />
                            <site name="EDCL-P4" pos="-0.0217206 -0.0388044 0.00148977" />
                            <site name="EDCL-P5" pos="-0.0209889 -0.0417311 0.000678769" />
                            <site name="EDCL-P6" pos="-0.0211124 -0.0582948 -0.00882399" />
                            <site name="EDCL-P7" pos="-0.0158497 -0.0691727 -0.0238979" />
                            <site name="EDCL-P8" pos="-0.0103843 -0.0694372 -0.0333126" />
                            <site name="EDCL-P9" pos="-0.00132228 -0.0668719 -0.0404264" />
                            <site name="EDCL-P10" pos="0.00177185 -0.0659992 -0.04226" />
                            <site name="EDCR-P4" pos="-0.0137869 -0.0489242 0.00823338" />
                            <site name="EDCR-P5" pos="-0.0125793 -0.0512955 0.0102344" />
                            <site name="EDCR-P6" pos="-0.013928 -0.0636103 -0.00371119" />
                            <site name="EDCR-P7" pos="-0.00727252 -0.0770006 -0.0199223" />
                            <site name="EDCR-P8" pos="-0.00239773 -0.0776265 -0.0300509" />
                            <site name="EDCR-P9" pos="0.00672598 -0.0707506 -0.0410611" />
                            <site name="EDCR-P10" pos="0.00942343 -0.0688377 -0.0435558" />
                            <site name="EDCM-P4" pos="0.000343792 -0.0464912 0.0131434" />
                            <site name="EDCM-P5" pos="-0.00076692 -0.0491358 0.0127996" />
                            <site name="EDCM-P6" pos="0.00163962 -0.0680355 0.00526266" />
                            <site name="EDCM-P7" pos="0.00887688 -0.0820958 -0.0156381" />
                            <site name="EDCM-P8" pos="0.0116449 -0.0842555 -0.0269392" />
                            <site name="EDCM-P9" pos="0.0163698 -0.0751494 -0.0419514" />
                            <site name="EDCM-P10" pos="0.018124 -0.0704597 -0.0470819" />
                            <site name="EDCM-P11" pos="0.0193493 -0.0678857 -0.0499204" />
                            <site name="EDCI-P4" pos="0.0136018 -0.041255 0.0144481" />
                            <site name="EDCI-P5" pos="0.0167224 -0.049841 0.0126762" />
                            <site name="EDCI-P6" pos="0.0175775 -0.0676829 0.00523622" />
                            <site name="EDCI-P7" pos="0.0259607 -0.0807647 -0.0109749" />
                            <site name="EDCI-P8" pos="0.0275122 -0.0824131 -0.0256081" />
                            <site name="EDCI-P9" pos="0.0265601 -0.0748144 -0.0376232" />
                            <site name="EDCI-P10" pos="0.0258197 -0.0714294 -0.0437762" />
                            <site name="EDM-P5" pos="-0.0181505 -0.00909726 0.00327925" />
                            <site name="EDM-P6" pos="-0.0225933 -0.0416253 0.000202749" />
                            <site name="EDM-P7" pos="-0.0224699 -0.0573956 -0.00967907" />
                            <site name="EDM-P8" pos="-0.0170397 -0.0688465 -0.0239597" />
                            <site name="EDM-P9" pos="-0.0118652 -0.0695694 -0.0343263" />
                            <site name="EDM-P10" pos="-0.00190408 -0.066299 -0.0404529" />
                            <site name="EDM-P11" pos="0.0011636 -0.0647475 -0.0423393" />
                            <site name="EIP-P4" pos="0.00342029 -0.0196931 0.0104372" />
                            <site name="EIP-P5" pos="0.0149241 -0.0497176 0.0121385" />
                            <site name="EIP-P6" pos="0.0152943 -0.0678064 0.00512162" />
                            <site name="EIP-P7" pos="0.024374 -0.0821046 -0.0133197" />
                            <site name="EIP-P8" pos="0.0253789 -0.0831888 -0.0248852" />
                            <site name="EIP-P9" pos="0.0252996 -0.0751406 -0.0378612" />
                            <site name="EIP-P10" pos="0.0249822 -0.0686262 -0.0484923" />
                            <site name="EPL-P6" pos="0.0214033 0.000123412 0.00535963" />
                            <site name="EPL-P7" pos="0.0206099 -0.00808352 -0.000343792" />
                            <site name="EPL-P8" pos="0.0256081 -0.0125793 -0.00431062" />
                            <site name="EPL-P9" pos="0.0389102 -0.0301215 -0.0159907" />
                            <site name="EPL-P10" pos="0.0429035 -0.0409553 -0.0219233" />
                            <site name="EPL-P11" pos="0.0418809 -0.0617944 -0.0332685" />
                            <site name="EPL-P12" pos="0.0353577 -0.0666868 -0.0377554" />
                            <site name="EPB-P5" pos="0.0275298 0.00225669 -0.00288256" />
                            <site name="EPB-P6" pos="0.0261987 -0.00699925 -0.0126586" />
                            <site name="EPB-P7" pos="0.0389807 -0.0290901 -0.0213504" />
                            <site name="EPB-P8" pos="0.0399151 -0.0421806 -0.0280852" />
                            <site name="FPL-P6" pos="0.0109661 -0.0194551 -0.0184149" />
                            <site name="FPL-P7" pos="0.0144657 -0.0231046 -0.0195785" />
                            <site name="FPL-P8" pos="0.0216589 -0.0290372 -0.0197196" />
                            <site name="FPL-P9" pos="0.0249205 -0.0483248 -0.0269304" />
                            <site name="FPL-P10" pos="0.0309501 -0.0574661 -0.0330481" />
                            <site name="FPL-P11" pos="0.031144 -0.067489 -0.0363009" />
                            <site name="FPL-P5" pos="0.0178892 0.0064176 -0.0168214" />
                            <site name="APL-P7" pos="0.0228049 0.00180711 -0.014545" />
                            <site name="APL-P8" pos="0.0253701 -0.00594143 -0.0164844" />
                            <site name="APL-P9" pos="0.0271155 -0.0139544 -0.0166166" />
                            <site name="APL-P6" pos="0.0332244 0.00608975 -0.00870125" />
                            <body name="index0" pos="0 0 0">
                              <inertial pos="0 0 0" mass="0.001" diaginertia="0.001 0.001 0.001" />
                              <geom name="sdfast_1seg_hand_fr_c_2mc" type="mesh" mesh="sdfast_1seg_hand_fr_c_2mc" />
                              <body name="index1" pos="0 0 0">
                                <inertial pos="0 0 0" mass="0.001" diaginertia="0.001 0.001 0.001" />
                                <geom name="hand_2proxph" type="mesh" mesh="hand_2proxph" />
                                <body name="index2" pos="0 0 0">
                                  <inertial pos="0 0 0" mass="0.001" diaginertia="0.001 0.001 0.001" />
                                  <geom name="hand_2midph" type="mesh" mesh="hand_2midph" />
                                  <body name="index3" pos="0 0 0">
                                    <inertial pos="0 0 0" mass="0.001" diaginertia="0.001 0.001 0.001" />
                                    <geom name="hand_2distph" type="mesh" mesh="hand_2distph" />
                                    <site name="fingertip" pos="0.024 -0.149 -0.0065" type="sphere" rgba="0.1 0.8 0.1 0.0" size="0.004" />
                                  </body>
                                </body>
                              </body>
                            </body>
                          </body>
                        </body>
                      </body>
                    </body>
                  </body>
                </body>
              </body>
            </body>
          </body>
        </body>
      </body>
    </body>

</mujocoinclude>