<mujocoinclude model="MoBL Arms Index Model">

    <body name="thorax" pos="0 0 0" quat="0.7071067811865475 0.7071067811865475 0.0 0.0">
      <light mode="trackcom" directional="false" pos="0 0 4.0" dir="0 0 -1" />
      <geom name="thorax" type="mesh" mesh="thorax" />
      <site name="PECM1-P3" pos="  -7e-05  0.00821  0.10454" />
      <site name="PECM2-P4" pos="0.0276467 -0.0350793 0.0868039" />
      <site name="PECM2-P5" pos="0.0247666 -0.0402312 0.0203124" />
      <site name="PECM2-P3" pos=" 0.02083 -0.02005  0.11555" />
      <site name="PECM3-P4" pos="0.0469573 -0.0752837 0.0799168" />
      <site name="PECM3-P5" pos="0.0511969 -0.104236 0.0338719" />
      <site name="PECM3-P3" pos=" 0.02984 -0.0544459   0.1151" />
      <site name="LAT1-P4" pos="-0.105793 -0.0904979 0.0296591" />
      <site name="LAT1-P5" pos="-0.085668 -0.104862 0.00788882" />
      <site name="LAT2-P4" pos="-0.0983151 -0.151229 0.0257415" />
      <site name="LAT2-P5" pos="-0.0642733 -0.168313 0.00728956" />
      <site name="LAT3-P4" pos="-0.0997909 -0.173402 0.0494796" />
      <site name="LAT3-P5" pos="-0.0636562 -0.222336 0.00811243" />
      <joint name="r_z" type="hinge" pos="0 0 0" axis="       0        0        1" limited="true" range="-6.28319  6.28319" ref="0" armature="0" damping="0" stiffness="0" />
      <body name="clavicle" pos="0.00565723 0.00619836 0.0227765" quat="1.0 0.0 0.0 0.0">
        <geom name="clavicle" type="mesh" mesh="clavicle" />
        <inertial pos="-0.00992453 0.00569954 0.0484492" mass="0.139530201333384" fullinertia="0.000173582 0.000182647 3.17841e-05 -1.35809e-05 -5.00445e-05 3.84314e-05" />
        <site name="DELT1-P4" pos="-0.0125219 0.00989233 0.0717418" />
        <site name="DELT2-P2" pos="0.0191703 0.0244002 0.162891" />
        <site name="PECM1-P4" pos="0.0028711 -0.000116275 0.0457319" />
        <joint name="sternoclavicular_r2" type="hinge" pos="0 0 0" axis="  0.0153 0.989299  -0.1451" limited="false" range="-99999.9  99999.9" ref="0" />
        <joint name="sternoclavicular_r3" type="hinge" pos="0 0 0" axis="-0.994473        0 -0.104997" limited="false" range="-99999.9  99999.9" ref="0" />
        <body name="clavphant" pos="-0.0128171 0.0179511 0.121226" quat="1.0 0.0 0.0 0.0">
          <inertial pos="       0        0        0" mass="8.9442436752169e-05" fullinertia="0.715535 0.715535 0.715535        0        0        0" />
          <joint name="unrotscap_r3" type="hinge" pos="0 0 0" axis="-0.994473        0 -0.104997" limited="false" range="-99999.9  99999.9" ref="0" />
          <joint name="unrotscap_r2" type="hinge" pos="0 0 0" axis="  0.0153 0.989299  -0.1451" limited="false" range="-99999.9  99999.9" ref="0" />
          <body name="scapula" pos="       0        0        0" quat="1.0 0.0 0.0 0.0">
            <geom name="scapula" type="mesh" mesh="scapula" />
            <inertial pos="-0.0489196 -0.0313335 -0.0391168" mass="0.629638977760569" fullinertia="0.000889338 0.000823151 0.000976777 0.000321561 0.000292811 0.000172515" />
            <site name="DELT1-P3" pos="0.0388806 -0.0290867 0.00088548" />
            <site name="DELT2-P3" pos="4.47212e-005 0.00262961 0.0199725" />
            <site name="DELT2-P4" pos="-0.00964189 -0.000304104 0.00554543" />
            <site name="DELT3-P1" pos="-0.0498463 0.0010912 -0.0224679" />
            <site name="DELT3-P2" pos="-0.0648189 -0.0293818 0.0110283" />
            <site name="SUPSP-P2" pos="-0.0171551 0.00113592 -0.0113681" />
            <site name="SUPSP-P3" pos="-0.0393547 -0.0135237 -0.0523685" />
            <site name="INFSP-P2" pos="-0.0660264 -0.0489787 -0.0427624" />
            <site name="SUBSC-P2" pos="-0.0163769 -0.0467158 -0.021976" />
            <site name="SUBSC-P3" pos="-0.06481 -0.0352672 -0.057914" />
            <site name="TMIN-P2" pos="-0.0847288 -0.0714735 -0.0423689" />
            <site name="TMIN-P3" pos="-0.0862493 -0.0726362 -0.0473866" />
            <site name="TMAJ-P2" pos="-0.0918037 -0.0922957 -0.052136" />
            <site name="TMAJ-P3" pos="-0.0938162 -0.0974475 -0.0636562" />
            <site name="LAT1-P2" pos="-0.08052 -0.06821 -0.02908" />
            <site name="LAT1-P3" pos="-0.10925 -0.07239 -0.07422" />
            <site name="LAT2-P2" pos="-0.08345 -0.08695 -0.02453" />
            <site name="LAT2-P3" pos="-0.11524 -0.10749 -0.08863" />
            <site name="LAT3-P2" pos="-0.08438 -0.11598 -0.02995" />
            <site name="LAT3-P3" pos="-0.11279 -0.13833 -0.08911" />
            <site name="CORB-P1" pos="0.0111803 -0.0369129 -0.0237201" />
            <site name="CORB-P2" pos="0.00432007 -0.062234 -0.0139799" />
            <site name="TRIlong-P1" pos="-0.0408305 -0.0364299 -0.0123162" />
            <site name="BIClong-P1" pos="-0.0279329 -0.0210458 -0.0116722" />
            <site name="BIClong-P2" pos="-0.0187292 -0.011708 -0.0041233" />
            <site name="BICshort-P1" pos="0.0113413 -0.0351598 -0.0234786" />
            <site name="BICshort-P2" pos="0.000831815 -0.0599622 -0.0142482" />
            <joint name="acromioclavicular_r2" type="hinge" pos="0 0 0" axis="0.157095 0.947269 -0.279291" limited="false" range="-99999.9  99999.9" ref="0" />
            <joint name="acromioclavicular_r3" type="hinge" pos="0 0 0" axis="-0.754084 0.297594 0.585487" limited="false" range="-99999.9  99999.9" ref="0" />
            <joint name="acromioclavicular_r1" type="hinge" pos="0 0 0" axis="  0.6377   0.1186   0.7611" limited="false" range="-99999.9  99999.9" ref="0" />
            <body name="scapphant" pos="-0.00854175 -0.0304104 0.00804982" quat="1.0 0.0 0.0 0.0">
              <inertial pos="       0        0        0" mass="8.9442436752169e-05" fullinertia="0.715535 0.715535 0.715535        0        0        0" />
              <joint name="unrothum_r1" type="hinge" pos="0 0 0" axis="  0.6377   0.1186   0.7611" limited="false" range="-99999.9  99999.9" ref="0" />
              <joint name="unrothum_r3" type="hinge" pos="0 0 0" axis="-0.754084 0.297594 0.585487" limited="false" range="-99999.9  99999.9" ref="0" />
              <joint name="unrothum_r2" type="hinge" pos="0 0 0" axis="0.157095 0.947269 -0.279291" limited="false" range="-99999.9  99999.9" ref="0" />
              <body name="humphant" pos="       0        0        0" quat="1.0 0.0 0.0 0.0">
                <inertial pos="       0        0        0" mass="8.9442436752169e-05" fullinertia="0.715535 0.715535 0.715535        0        0        0" />
                <joint name="elv_angle" type="hinge" pos="0 0 0" axis="  0.0048 0.999089   0.0424" limited="true" range=" -1.5708  2.26893" ref="0" user="1" />
                <body name="humphant1" pos="       0        0        0" quat="1.0 0.0 0.0 0.0">
                  <inertial pos="       0        0        0" mass="8.9442436752169e-05" fullinertia="0.715535 0.715535 0.715535        0        0        0" />
                  <joint name="shoulder_elv" type="hinge" pos="0 0 0" axis="-0.998261   0.0023 0.058898" limited="true" range="       0  3.14159" ref="0" user="1" />
                  <joint name="shoulder1_r2" type="hinge" pos="0 0 0" axis="  0.0048 0.999089   0.0424" limited="false" range="-99999.9  99999.9" ref="0" />
                  <body name="humerus" pos="       0        0        0" quat="1.0 0.0 0.0 0.0">
                    <geom name="humerus" type="mesh" mesh="humerus" />
                    <inertial pos="0.0161569 -0.125346 -0.0114003" mass="1.7866752838303" fullinertia="0.00878507 0.00182557 0.00900063 -0.000248584 -0.000166362 0.000879607" />
                    <site name="DELT1-P1" pos="0.00801404 -0.106284 0.00523238" />
                    <site name="DELT1-P2" pos="0.0145165 -0.0986818 0.00368503" />
                    <site name="DELT2-P1" pos="0.0041233 -0.12174 0.00500878" />
                    <site name="DELT3-P3" pos="0.00184251 -0.0679941 0.00934673" />
                    <site name="SUPSP-P1" pos="0.00228973 0.00950773 0.0231924" />
                    <site name="INFSP-P1" pos="-0.00793354 0.00432901 0.0218955" />
                    <site name="SUBSC-P1" pos="0.0125488 0.00751316 -0.0119048" />
                    <site name="TMIN-P1" pos="-0.000983867 -0.0113055 0.0192838" />
                    <site name="TMAJ-P1" pos="0.00892636 -0.0484689 -0.00508033" />
                    <site name="PECM1-P1" pos="0.0104558 -0.0374853 0.00697651" />
                    <site name="PECM1-P2" pos="  0.0191  -0.0301  0.00143" />
                    <site name="PECM2-P1" pos="0.011395 -0.0383619 0.00702123" />
                    <site name="PECM2-P2" pos=" 0.01748 -0.03533  0.00033" />
                    <site name="PECM3-P1" pos="0.0113502 -0.0391311 0.00670818" />
                    <site name="PECM3-P2" pos="0.0159185 -0.045833 -0.00378312" />
                    <site name="LAT1-P1" pos="0.00939146 -0.0305446 -0.00584059" />
                    <site name="LAT2-P1" pos="0.00865803 -0.036412 -0.00546493" />
                    <site name="LAT3-P1" pos="0.0108046 -0.0350793 -0.00372081" />
                    <site name="CORB-P3" pos="0.00664557 -0.134593 -0.0069944" />
                    <site name="TRIlong-P2" pos="-0.0242747 -0.102331 -0.00593898" />
                    <site name="TRIlong-P3" pos="-0.0284785 -0.202471 -0.0108851" />
                    <site name="TRIlong-P4" pos="-0.0155898 -0.239321 -0.0108046" />
                    <site name="TRIlat-P1" pos="-0.0053576 -0.113109 0.00382814" />
                    <site name="TRIlat-P2" pos="-0.0209653 -0.129942 0.00830026" />
                    <site name="TRIlat-P3" pos="-0.0284785 -0.202471 -0.0108851" />
                    <site name="TRIlat-P4" pos="-0.0155898 -0.239321 -0.0108046" />
                    <site name="TRImed-P1" pos="-0.00749528 -0.122491 -0.00810348" />
                    <site name="TRImed-P2" pos="-0.023264 -0.135407 -0.00965978" />
                    <site name="TRImed-P3" pos="-0.0284785 -0.202471 -0.0108851" />
                    <site name="TRImed-P4" pos="-0.0155898 -0.239321 -0.0108046" />
                    <site name="ANC-P1" pos="-0.00665452 -0.25365 0.00875641" />
                    <site name="BIClong-P3" pos="0.0190602 0.016037 0.00919468" />
                    <site name="BIClong-P4" pos="0.0212694 -0.00457051 0.010742" />
                    <site name="BIClong-P5" pos="0.01203 -0.0252854 0.00121642" />
                    <site name="BIClong-P6" pos="0.00955245 -0.0691927 -0.0014758" />
                    <site name="BIClong-P7" pos="0.015232 -0.108449 0.000214662" />
                    <site name="BIClong-P8" pos="0.0203929 -0.156882 -0.00563487" />
                    <site name="BICshort-P3" pos="0.00999072 -0.0677616 -0.00984761" />
                    <site name="BICshort-P4" pos="0.015232 -0.108449 -0.00965084" />
                    <site name="BICshort-P5" pos="0.0203929 -0.156882 -0.00563487" />
                    <site name="BRA-P1" pos="0.00608209 -0.15554 -0.00321993" />
                    <site name="BRA-P2" pos="0.0169404 -0.255439 -0.00988339" />
                    <site name="BRD-P1" pos="-0.00876536 -0.178554 0.00199457" />
                    <site name="ECRL-P1" pos="-0.0065293 -0.233355 0.00813926" />
                    <site name="ECRB-P1" pos="0.0120658 -0.259812 0.0151873" />
                    <site name="ECU-P1" pos="0.000742372 -0.258981 0.0168152" />
                    <site name="FCR-P1" pos="0.00677974 -0.248704 -0.0331384" />
                    <site name="FCU-P1" pos="0.00195879 -0.248113 -0.0347037" />
                    <site name="PL-P1" pos="0.00408752 -0.246137 -0.0345695" />
                    <site name="PT-P1" pos="0.00321993 -0.246772 -0.0326465" />
                    <site name="FDSL-P1" pos="0.00376553 -0.246843 -0.0345606" />
                    <site name="FDSR-P1" pos="0.00428429 -0.249366 -0.033371" />
                    <site name="EDCL-P1" pos="-0.00035777 -0.257871 0.0167257" />
                    <site name="EDCR-P1" pos="-0.0013953 -0.258811 0.0159386" />
                    <site name="EDCM-P1" pos="0.000456156 -0.25924 0.0174323" />
                    <site name="EDCI-P1" pos="0.000581376 -0.258471 0.0167168" />
                    <site name="EDM-P1" pos="0.000796038 -0.258659 0.01652" />
                    <joint name="shoulder_rot" type="hinge" pos="0 0 0" axis="  0.0048 0.999089   0.0424" limited="true" range=" -1.5708 0.349066" ref="0" user="1" />
                    <body name="ulna" pos="0.00545599 -0.259741 -0.0110014" quat="1.0 0.0 0.0 0.0">
                      <geom name="ulna" type="mesh" mesh="ulna" />
                      <inertial pos="0.00869186 -0.0858208 0.021722" mass="0.988607253421723" fullinertia="0.00387326 0.000825141 0.00353733 0.000226724 -5.4488e-05 0.000781142" />
                      <site name="TRIlong-P5" pos="-0.0195879 0.00935568 -0.000697651" />
                      <site name="TRIlat-P5" pos="-0.0195879 0.00935568 -0.000697651" />
                      <site name="TRImed-P5" pos="-0.0195879 0.00935568 -0.000697651" />
                      <site name="ANC-P2" pos="-0.0226468 -0.00110909 0.00536655" />
                      <site name="SUP-P3" pos="-0.0121642 -0.0302673 0.0180048" />
                      <site name="BRA-P4" pos="-0.00286216 -0.0213767 0.000804982" />
                      <site name="BRA-P3" pos="0.00445423 -0.0130854 0.00114486" />
                      <site name="ECU-P2" pos="-0.0124414 -0.0286305 0.0263587" />
                      <site name="ECU-P3" pos="-0.0152499 -0.0485494 0.0256521" />
                      <site name="ECU-P4" pos="-0.016037 -0.0856232 0.0293192" />
                      <site name="PT-P2" pos="0.00756683 -0.0301689 -0.0128082" />
                      <site name="PT-P3" pos=" 0.01219 -0.06516 -0.00219" />
                      <site name="PQ-P2" pos="0.00172624 -0.187579 0.0324855" />
                      <site name="FDSM-P1" pos="-0.0059837 -0.0242657 -0.00170835" />
                      <site name="FDSI-P1" pos="-0.00604631 -0.0252138 -0.00122536" />
                      <site name="FDPL-P1" pos="-0.00561699 -0.0287468 0.00227184" />
                      <site name="FDPR-P1" pos="-0.00449001 -0.0301779 0.00244178" />
                      <site name="FDPM-P1" pos="-0.0046689 -0.0297575 0.00187829" />
                      <site name="FDPI-P1" pos="-0.00578693 -0.0284069 0.00250439" />
                      <site name="EDM-P2" pos="-0.00873853 -0.0349452 0.027593" />
                      <site name="EDM-P3" pos="-0.0067529 -0.0739421 0.0326107" />
                      <site name="EIP-P1" pos="-0.00352403 -0.14894 0.0329327" />
                      <site name="EIP-P2" pos="0.00152947 -0.156247 0.0362152" />
                      <site name="EPL-P1" pos="-0.0126293 -0.0868128 0.0264034" />
                      <joint name="elbow_flexion" type="hinge" pos="0 0 0" axis="  0.0494   0.0366 0.998108" limited="true" range="       0  4.26893" ref="0" user="1" />
                      <body name="radius" pos="0.00035777 -0.0102886 0.0178876" quat="1.0 0.0 0.0 0.0">
                        <geom name="radius" type="mesh" mesh="radius" />
                        <inertial pos="0.0300832 -0.162391 0.013953" mass="0.208928588009391" fullinertia="0.000313798 6.33892e-05 0.00028806 2.15662e-05 -3.03387e-06 4.5923e-05" />
                        <site name="SUP-P1" pos="0.00890847 -0.0545241 0.000670818" />
                        <site name="SUP-P2" pos="0.010742 -0.0462417 -0.000957034" />
                        <site name="BIClong-P11" pos="-0.00178885 -0.0335409 -0.00178885" />
                        <site name="BIClong-P9" pos=" 0.00273 -0.0343493 -0.0119845" />
                        <site name="BICshort-P8" pos="-0.00178885 -0.0335409 -0.00178885" />
                        <site name="BICshort-P6" pos=" 0.00273 -0.0343493 -0.0119845" />
                        <site name="BRD-P2" pos="0.0319936 -0.113968 0.0207059" />
                        <site name="BRD-P3" pos="0.0374764 -0.197668 0.0200351" />
                        <site name="ECRL-P2" pos="0.0285769 -0.120416 0.0248561" />
                        <site name="ECRL-P3" pos="0.0379504 -0.211835 0.0323782" />
                        <site name="ECRB-P2" pos="0.025983 -0.117044 0.021332" />
                        <site name="ECRB-P3" pos="0.0317431 -0.203973 0.0352135" />
                        <site name="ECU-P5" pos="-0.0127098 -0.202999 0.0311349" />
                        <site name="FCR-P2" pos="0.0188724 -0.196264 0.00113592" />
                        <site name="FCU-P3" pos="0.00967767 -0.199698 0.00866697" />
                        <site name="FCU-P2" pos="0.0101156 -0.183524 0.00202653" />
                        <site name="PL-P2" pos="0.0226379 -0.213902 -0.00246861" />
                        <site name="PT-P5" pos="0.0227184 -0.0973134 0.0177096" />
                        <site name="PT-P4" pos="0.0211084 -0.0835392 0.00840759" />
                        <site name="PQ-P1" pos="0.0290241 -0.178867 0.0175486" />
                        <site name="FDSL-P2" pos="0.0123162 -0.167418 0.00183357" />
                        <site name="FDSR-P2" pos="0.0140514 -0.166953 0.00238811" />
                        <site name="FDSM-P2" pos="0.0169851 -0.167311 0.00379236" />
                        <site name="FDSI-P2" pos="0.0191854 -0.166569 0.00493722" />
                        <site name="FDPL-P2" pos="0.0126024 -0.165612 0.00770099" />
                        <site name="FDPR-P2" pos="0.0141319 -0.166622 0.00718223" />
                        <site name="FDPM-P2" pos="0.0170477 -0.166756 0.00702123" />
                        <site name="FDPI-P2" pos="0.018604 -0.166005 0.00818398" />
                        <site name="EDCL-P3" pos="0.00888163 -0.199492 0.0323603" />
                        <site name="EDCL-P2" pos="  0.0013 -0.0382544 0.0129514" />
                        <site name="EDCR-P3" pos="0.00788882 -0.200047 0.0383171" />
                        <site name="EDCR-P2" pos="  0.0026 -0.0392844 0.0144214" />
                        <site name="EDCM-P3" pos="0.0128797 -0.199662 0.0377715" />
                        <site name="EDCM-P2" pos=" 0.00316 -0.0388544 0.0141814" />
                        <site name="EDCI-P3" pos="0.0137115 -0.199582 0.03753" />
                        <site name="EDCI-P2" pos=" 0.00228 -0.0385544 0.0137314" />
                        <site name="EDM-P4" pos="0.00406069 -0.202507 0.0328969" />
                        <site name="EIP-P3" pos="0.00962401 -0.203777 0.0327717" />
                        <site name="EPL-P2" pos="0.00110909 -0.12225 0.0203034" />
                        <site name="EPL-P3" pos="0.0241673 -0.195628 0.0342386" />
                        <site name="EPL-P4" pos="0.0302494 -0.203517 0.0412061" />
                        <site name="EPL-P5" pos="0.0378699 -0.212614 0.0373243" />
                        <site name="EPB-P1" pos="0.0172087 -0.131436 0.0189081" />
                        <site name="EPB-P2" pos="0.0203571 -0.141829 0.0238364" />
                        <site name="EPB-P3" pos="0.0342654 -0.176398 0.0342922" />
                        <site name="EPB-P4" pos="0.0468231 -0.211183 0.0241405" />
                        <site name="FPL-P1" pos="0.00868486 -0.0845947 0.0158224" />
                        <site name="FPL-P2" pos="0.0148296 -0.120971 0.0171282" />
                        <site name="FPL-P3" pos="0.0167168 -0.160388 0.0177812" />
                        <site name="FPL-P4" pos="0.0339881 -0.207247 0.0141319" />
                        <site name="APL-P1" pos="0.0103217 -0.0847646 0.0150353" />
                        <site name="APL-P2" pos="0.0271011 -0.124951 0.0313675" />
                        <site name="APL-P3" pos="0.0357144 -0.143752 0.0304104" />
                        <site name="APL-P4" pos="0.0393278 -0.15961 0.0280313" />
                        <site name="APL-P5" pos="0.0492381 -0.206469 0.02118" />
                        <joint name="pro_sup" type="hinge" pos="0 0 0" axis="-0.017161 0.992666 -0.119668" limited="true" range=" -1.5708   1.5708" ref="0" user="1" />
                        <body name="proximal_row" pos="0.0160996 -0.216451 0.0223606" quat="1.0 0.0 0.0 0.0">
                          <geom name="lunate" type="mesh" mesh="lunate" />
                          <geom name="sdfastSCAPHOIDw" type="mesh" mesh="sdfastSCAPHOIDw" />
                          <geom name="sdfastPISIFORMw" type="mesh" mesh="sdfastPISIFORMw" />
                          <geom name="sdfastTRIQUETRALw" type="mesh" mesh="sdfastTRIQUETRALw" />
                          <inertial pos="       0        0        0" mass="8.9442436752169e-05" fullinertia="7.15535e-06 7.15535e-06 7.15535e-06        0        0        0" />
                          <body name="hand" pos="0.00357054 -0.0134647 0.00208133" quat="1.0 0.0 0.0 0.0">
                            <geom name="sdfast_1seg_hand_fr_c_5mc" type="mesh" mesh="sdfast_1seg_hand_fr_c_5mc" />
                            <geom name="sdfast_1seg_hand_fr_c_4mc" type="mesh" mesh="sdfast_1seg_hand_fr_c_4mc" />
                            <geom name="sdfast_1seg_hand_fr_c_3mc" type="mesh" mesh="sdfast_1seg_hand_fr_c_3mc" />
                            <geom name="sdfast_1seg_hand_fr_c_trapezium" type="mesh" mesh="sdfast_1seg_hand_fr_c_trapezium" />
                            <geom name="sdfast_1seg_hand_fr_c_trapezoid" type="mesh" mesh="sdfast_1seg_hand_fr_c_trapezoid" />
                            <geom name="sdfast_1seg_hand_fr_c_hamate" type="mesh" mesh="sdfast_1seg_hand_fr_c_hamate" />
                            <geom name="capitate" type="mesh" mesh="capitate" />
                            <geom name="hand_3proxph" type="mesh" mesh="hand_3proxph" />
                            <geom name="hand_3midph" type="mesh" mesh="hand_3midph" />
                            <geom name="hand_3distph" type="mesh" mesh="hand_3distph" />
                            <geom name="hand_4proxph" type="mesh" mesh="hand_4proxph" />
                            <geom name="hand_4midph" type="mesh" mesh="hand_4midph" />
                            <geom name="hand_4distph" type="mesh" mesh="hand_4distph" />
                            <geom name="hand_5proxph" type="mesh" mesh="hand_5proxph" />
                            <geom name="hand_5midph" type="mesh" mesh="hand_5midph" />
                            <geom name="hand_5distph" type="mesh" mesh="hand_5distph" />
                            <geom name="hand_thumbprox" type="mesh" mesh="hand_thumbprox" />
                            <geom name="hand_thumbdist" type="mesh" mesh="hand_thumbdist" />
                            <geom name="hand_1mc" type="mesh" mesh="hand_1mc" />
                            <inertial pos="-0.00269503 -0.0380124 -0.00100359" mass="0.520465539460871" fullinertia="7.87088e-05 4.29321e-05 0.00010733 6.43981e-07 -1.43107e-07 8.58642e-06" />
                            <site name="ECRL-P4" pos="0.0153573 -0.0189797 0.00521449" />
                            <site name="ECRB-P4" pos="0.00447212 -0.0101607 0.00760261" />
                            <site name="ECU-P6" pos="-0.0201335 -0.0125309 -0.00114486" />
                            <site name="FCR-P3" pos="0.0100533 -0.0164932 -0.00373869" />
                            <site name="FCU-P4" pos="-0.0182105 -0.0157866 -0.00672607" />
                            <site name="PL-P3" pos="0.00820187 -0.0169762 -0.0156882" />
                            <site name="PL-P4" pos="0.00203034 -0.0276914 0.00440951" />
                            <site name="FDSL-P3" pos="-0.0021019 -0.0124593 -0.0123073" />
                            <site name="FDSL-P4" pos="-0.0178438 -0.0382903 -0.00663663" />
                            <site name="FDSL-P5" pos="-0.018282 -0.0534955 -0.0167973" />
                            <site name="FDSL-P6" pos="-0.0153215 -0.064801 -0.0246235" />
                            <site name="FDSL-P7" pos="-0.0103395 -0.0650336 -0.0327002" />
                            <site name="FDSL-P8" pos="-0.00947195 -0.0650336 -0.0339523" />
                            <site name="FDSR-P3" pos="-0.000733428 -0.0120211 -0.0121552" />
                            <site name="FDSR-P4" pos="-0.00873853 -0.0463222 3.5777e-005" />
                            <site name="FDSR-P5" pos="-0.0118332 -0.0596581 -0.00912313" />
                            <site name="FDSR-P6" pos="-0.00704806 -0.0717954 -0.0223874" />
                            <site name="FDSR-P7" pos="-0.00267433 -0.072672 -0.0303657" />
                            <site name="FDSR-P8" pos="0.000554543 -0.0723768 -0.034811" />
                            <site name="FDSM-P3" pos="0.00608209 -0.0123162 -0.012513" />
                            <site name="FDSM-P4" pos="0.00421274 -0.0298022 -0.00118064" />
                            <site name="FDSM-P5" pos="0.00484778 -0.0506244 0.000536655" />
                            <site name="FDSM-P6" pos="0.00496406 -0.0646132 -0.00302315" />
                            <site name="FDSM-P7" pos="0.0104379 -0.0787988 -0.0149369" />
                            <site name="FDSM-P8" pos="0.0116365 -0.0793354 -0.026627" />
                            <site name="FDSM-P9" pos="0.0140246 -0.0767148 -0.0336751" />
                            <site name="FDSI-P3" pos="0.00795143 -0.0122178 -0.0124057" />
                            <site name="FDSI-P4" pos="0.00948984 -0.0338719 0.000214662" />
                            <site name="FDSI-P5" pos="0.0159386 -0.0456872 0.00373869" />
                            <site name="FDSI-P6" pos="0.0165379 -0.0652661 -0.00335409" />
                            <site name="FDSI-P7" pos="0.0239527 -0.0779401 -0.0161354" />
                            <site name="FDSI-P8" pos="0.0238543 -0.0781727 -0.0239527" />
                            <site name="FDSI-P9" pos="0.0237917 -0.0772157 -0.0259651" />
                            <site name="FDPL-P3" pos="-0.000787093 -0.00918574 -0.0106258" />
                            <site name="FDPL-P4" pos="-0.0165916 -0.041555 -0.00655613" />
                            <site name="FDPL-P5" pos="-0.0161712 -0.0522433 -0.013953" />
                            <site name="FDPL-P6" pos="-0.0127724 -0.0651946 -0.0239974" />
                            <site name="FDPL-P7" pos="-0.0082287 -0.0669298 -0.0329506" />
                            <site name="FDPL-P8" pos="-0.0027906 -0.0662321 -0.0372528" />
                            <site name="FDPL-P9" pos="0.00398913 -0.0631374 -0.0416533" />
                            <site name="FDPR-P3" pos="0.00094809 -0.0105274 -0.01059" />
                            <site name="FDPR-P4" pos="-0.00764733 -0.049569 0.000787093" />
                            <site name="FDPR-P5" pos="-0.00965084 -0.0589247 -0.00730745" />
                            <site name="FDPR-P6" pos="-0.0048925 -0.0729314 -0.0201782" />
                            <site name="FDPR-P7" pos="-0.000500878 -0.0736111 -0.0301153" />
                            <site name="FDPR-P8" pos="0.00544704 -0.070096 -0.0379057" />
                            <site name="FDPR-P9" pos="0.0108315 -0.0660085 -0.0434511" />
                            <site name="FDPM-P3" pos="0.00299632 -0.0114486 -0.0102322" />
                            <site name="FDPM-P4" pos="0.00270116 -0.0308308 -0.00546493" />
                            <site name="FDPM-P5" pos="0.00225395 -0.0524401 0.0010912" />
                            <site name="FDPM-P6" pos="0.00254911 -0.0624755 -0.00118958" />
                            <site name="FDPM-P7" pos="0.00771888 -0.0785215 -0.0162338" />
                            <site name="FDPM-P8" pos="0.00896213 -0.0784052 -0.0265107" />
                            <site name="FDPM-P9" pos="0.0146059 -0.0729582 -0.0396677" />
                            <site name="FDPM-P10" pos="0.0170746 -0.0685397 -0.0467695" />
                            <site name="FDPI-P3" pos="0.00801404 -0.0104469 -0.0108404" />
                            <site name="FDPI-P4" pos="0.0171908 -0.049569 0.00391758" />
                            <site name="FDPI-P5" pos="0.0185414 -0.0627975 -0.00255805" />
                            <site name="FDPI-P6" pos="0.0259741 -0.0768132 -0.0159386" />
                            <site name="FDPI-P7" pos="0.026153 -0.0775645 -0.0247666" />
                            <site name="FDPI-P8" pos="0.0260635 -0.0736558 -0.0355891" />
                            <site name="FDPI-P9" pos="0.0254643 -0.0695057 -0.0426283" />
                            <site name="EDCL-P4" pos="-0.0220386 -0.0393726 0.00151158" />
                            <site name="EDCL-P5" pos="-0.0212962 -0.042342 0.000688707" />
                            <site name="EDCL-P6" pos="-0.0214215 -0.0591483 -0.00895319" />
                            <site name="EDCL-P7" pos="-0.0160818 -0.0701855 -0.0242478" />
                            <site name="EDCL-P8" pos="-0.0105363 -0.0704538 -0.0338003" />
                            <site name="EDCL-P9" pos="-0.00134164 -0.067851 -0.0410183" />
                            <site name="EDCL-P10" pos="0.00179779 -0.0669656 -0.0428787" />
                            <site name="EDCR-P4" pos="-0.0139888 -0.0496406 0.00835392" />
                            <site name="EDCR-P5" pos="-0.0127634 -0.0520466 0.0103843" />
                            <site name="EDCR-P6" pos="-0.0141319 -0.0645417 -0.00376553" />
                            <site name="EDCR-P7" pos="-0.007379 -0.078128 -0.020214" />
                            <site name="EDCR-P8" pos="-0.00243283 -0.078763 -0.0304909" />
                            <site name="EDCR-P9" pos="0.00682446 -0.0717865 -0.0416623" />
                            <site name="EDCR-P10" pos="0.0095614 -0.0698456 -0.0441935" />
                            <site name="EDCM-P4" pos="0.000348826 -0.0471719 0.0133359" />
                            <site name="EDCM-P5" pos="-0.000778149 -0.0498552 0.012987" />
                            <site name="EDCM-P6" pos="0.00166363 -0.0690317 0.00533971" />
                            <site name="EDCM-P7" pos="0.00900685 -0.0832977 -0.0158671" />
                            <site name="EDCM-P8" pos="0.0118153 -0.0854891 -0.0273336" />
                            <site name="EDCM-P9" pos="0.0166095 -0.0762497 -0.0425657" />
                            <site name="EDCM-P10" pos="0.0183894 -0.0714913 -0.0477712" />
                            <site name="EDCM-P11" pos="0.0196326 -0.0688796 -0.0506513" />
                            <site name="EDCI-P4" pos="0.013801 -0.0418591 0.0146596" />
                            <site name="EDCI-P5" pos="0.0169672 -0.0505708 0.0128618" />
                            <site name="EDCI-P6" pos="0.0178348 -0.0686739 0.00531288" />
                            <site name="EDCI-P7" pos="0.0263408 -0.0819472 -0.0111356" />
                            <site name="EDCI-P8" pos="0.027915 -0.0836197 -0.025983" />
                            <site name="EDCI-P9" pos="0.026949 -0.0759098 -0.038174" />
                            <site name="EDCI-P10" pos="0.0261977 -0.0724752 -0.0444171" />
                            <site name="EDM-P5" pos="-0.0184162 -0.00923046 0.00332726" />
                            <site name="EDM-P6" pos="-0.0229241 -0.0422347 0.000205718" />
                            <site name="EDM-P7" pos="-0.0227989 -0.058236 -0.00982078" />
                            <site name="EDM-P8" pos="-0.0172892 -0.0698545 -0.0243105" />
                            <site name="EDM-P9" pos="-0.012039 -0.070588 -0.0348289" />
                            <site name="EDM-P10" pos="-0.00193196 -0.0672697 -0.0410451" />
                            <site name="EDM-P11" pos="0.00118064 -0.0656955 -0.0429592" />
                            <site name="EIP-P4" pos="0.00347037 -0.0199814 0.01059" />
                            <site name="EIP-P5" pos="0.0151426 -0.0504455 0.0123162" />
                            <site name="EIP-P6" pos="0.0155183 -0.0687991 0.00519661" />
                            <site name="EIP-P7" pos="0.0247308 -0.0833067 -0.0135148" />
                            <site name="EIP-P8" pos="0.0257505 -0.0844068 -0.0252496" />
                            <site name="EIP-P9" pos="0.02567 -0.0762407 -0.0384155" />
                            <site name="EIP-P10" pos="0.025348 -0.0696309 -0.0492023" />
                            <site name="EPL-P6" pos="0.0217166 0.000125219 0.0054381" />
                            <site name="EPL-P7" pos="0.0209116 -0.00820187 -0.000348826" />
                            <site name="EPL-P8" pos="0.025983 -0.0127634 -0.00437374" />
                            <site name="EPL-P9" pos="0.0394799 -0.0305625 -0.0162249" />
                            <site name="EPL-P10" pos="0.0435316 -0.041555 -0.0222443" />
                            <site name="EPL-P11" pos="0.0424941 -0.0626991 -0.0337556" />
                            <site name="EPL-P12" pos="0.0358754 -0.0676632 -0.0383082" />
                            <site name="EPB-P5" pos="0.0279329 0.00228973 -0.00292477" />
                            <site name="EPB-P6" pos="0.0265823 -0.00710173 -0.0128439" />
                            <site name="EPB-P7" pos="0.0395514 -0.029516 -0.021663" />
                            <site name="EPB-P8" pos="0.0404995 -0.0427982 -0.0284964" />
                            <site name="FPL-P6" pos="0.0111266 -0.0197399 -0.0186845" />
                            <site name="FPL-P7" pos="0.0146775 -0.0234429 -0.0198652" />
                            <site name="FPL-P8" pos="0.021976 -0.0294623 -0.0200083" />
                            <site name="FPL-P9" pos="0.0252854 -0.0490323 -0.0273247" />
                            <site name="FPL-P10" pos="0.0314032 -0.0583075 -0.033532" />
                            <site name="FPL-P11" pos="0.0316 -0.0684771 -0.0368324" />
                            <site name="FPL-P5" pos="0.0178892 0.0064176 -0.0168214" />
                            <site name="APL-P7" pos="0.0231388 0.00183357 -0.014758" />
                            <site name="APL-P8" pos="0.0257415 -0.00602842 -0.0167257" />
                            <site name="APL-P9" pos="0.0275125 -0.0141587 -0.0168599" />
                            <site name="APL-P6" pos="0.0332244 0.00608975 -0.00870125" />
                            <body name="index0" pos="0 0 0">
                              <inertial pos="0 0 0" mass="0.001" diaginertia="0.001 0.001 0.001" />
                              <geom name="sdfast_1seg_hand_fr_c_2mc" type="mesh" mesh="sdfast_1seg_hand_fr_c_2mc" />
                              <body name="index1" pos="0 0 0">
                                <inertial pos="0 0 0" mass="0.001" diaginertia="0.001 0.001 0.001" />
                                <geom name="hand_2proxph" type="mesh" mesh="hand_2proxph" />
                                <body name="index2" pos="0 0 0">
                                  <inertial pos="0 0 0" mass="0.001" diaginertia="0.001 0.001 0.001" />
                                  <geom name="hand_2midph" type="mesh" mesh="hand_2midph" />
                                  <body name="index3" pos="0 0 0">
                                    <inertial pos="0 0 0" mass="0.001" diaginertia="0.001 0.001 0.001" />
                                    <geom name="hand_2distph" type="mesh" mesh="hand_2distph" />
                                    <site name="fingertip" pos="0.024 -0.149 -0.0065" type="sphere" rgba="0.1 0.8 0.1 0.0" size="0.004" />
                                  </body>
                                </body>
                              </body>
                            </body>
                          </body>
                        </body>
                      </body>
                    </body>
                  </body>
                </body>
              </body>
            </body>
          </body>
        </body>
      </body>
    </body>

</mujocoinclude>