<mujocoinclude model="MoBL Arms Index Model">

    <body name="thorax" pos="0 0 0" quat="0.7071067811865475 0.7071067811865475 0.0 0.0">
      <light mode="trackcom" directional="false" pos="0 0 4.0" dir="0 0 -1" />
      <geom name="thorax" type="mesh" mesh="thorax" />
      <site name="PECM1-P3" pos="  -7e-05  0.00821  0.10454" />
      <site name="PECM2-P4" pos="0.0312371 -0.0396351 0.0980771" />
      <site name="PECM2-P5" pos="0.0279831 -0.045456 0.0229503" />
      <site name="PECM2-P3" pos=" 0.02083 -0.02005  0.11555" />
      <site name="PECM3-P4" pos="0.0530556 -0.0850608 0.0902956" />
      <site name="PECM3-P5" pos="0.0578458 -0.117773 0.0382708" />
      <site name="PECM3-P3" pos=" 0.02984 -0.0544459   0.1151" />
      <site name="LAT1-P4" pos="-0.119532 -0.102251 0.0335109" />
      <site name="LAT1-P5" pos="-0.0967937 -0.118481 0.00891335" />
      <site name="LAT2-P4" pos="-0.111083 -0.170869 0.0290846" />
      <site name="LAT2-P5" pos="-0.0726205 -0.190172 0.00823625" />
      <site name="LAT3-P4" pos="-0.112751 -0.195922 0.0559055" />
      <site name="LAT3-P5" pos="-0.0719232 -0.251211 0.00916599" />
      <joint name="r_z" type="hinge" pos="0 0 0" axis="       0        0        1" limited="true" range="-6.28319  6.28319" ref="0" armature="0" damping="0" stiffness="0" />
      <body name="clavicle" pos="0.00639194 0.00700334 0.0257345" quat="1.0 0.0 0.0 0.0">
        <geom name="clavicle" type="mesh" mesh="clavicle" />
        <inertial pos="-0.0112134 0.00643974 0.0547413" mass="0.157651006724673" fullinertia="0.000250374 0.000263451 4.58453e-05 -1.9589e-05 -7.21842e-05 5.54334e-05" />
        <site name="DELT1-P4" pos="-0.0141482 0.0111771 0.0810589" />
        <site name="DELT2-P2" pos="0.0191703 0.0244002 0.162891" />
        <site name="PECM1-P4" pos="0.00324397 -0.000131376 0.0516711" />
        <joint name="sternoclavicular_r2" type="hinge" pos="0 0 0" axis="  0.0153 0.989299  -0.1451" limited="false" range="-99999.9  99999.9" ref="0" />
        <joint name="sternoclavicular_r3" type="hinge" pos="0 0 0" axis="-0.994473        0 -0.104997" limited="false" range="-99999.9  99999.9" ref="0" />
        <body name="clavphant" pos="-0.0144817 0.0202824 0.136969" quat="1.0 0.0 0.0 0.0">
          <inertial pos="       0        0        0" mass="0.000101058337644021" fullinertia=" 1.03209  1.03209  1.03209        0        0        0" />
          <joint name="unrotscap_r3" type="hinge" pos="0 0 0" axis="-0.994473        0 -0.104997" limited="false" range="-99999.9  99999.9" ref="0" />
          <joint name="unrotscap_r2" type="hinge" pos="0 0 0" axis="  0.0153 0.989299  -0.1451" limited="false" range="-99999.9  99999.9" ref="0" />
          <body name="scapula" pos="       0        0        0" quat="1.0 0.0 0.0 0.0">
            <geom name="scapula" type="mesh" mesh="scapula" />
            <inertial pos="-0.0552728 -0.0354028 -0.0441969" mass="0.71141027367885" fullinertia="0.00128278 0.00118731 0.0014089 0.00046382 0.000422351 0.000248836" />
            <site name="DELT1-P3" pos="0.0439301 -0.0328642 0.00100048" />
            <site name="DELT2-P3" pos="5.05292e-005 0.00297112 0.0225663" />
            <site name="DELT2-P4" pos="-0.0108941 -0.000343598 0.00626562" />
            <site name="DELT3-P1" pos="-0.0563198 0.00123291 -0.0253859" />
            <site name="DELT3-P2" pos="-0.073237 -0.0331977 0.0124605" />
            <site name="SUPSP-P2" pos="-0.019383 0.00128344 -0.0128445" />
            <site name="SUPSP-P3" pos="-0.0444657 -0.01528 -0.0591697" />
            <site name="INFSP-P2" pos="-0.0746013 -0.0553395 -0.048316" />
            <site name="SUBSC-P2" pos="-0.0185038 -0.0527828 -0.02483" />
            <site name="SUBSC-P3" pos="-0.0732269 -0.0398473 -0.0654353" />
            <site name="TMIN-P2" pos="-0.0957326 -0.0807557 -0.0478713" />
            <site name="TMIN-P3" pos="-0.0974506 -0.0820695 -0.0535407" />
            <site name="TMAJ-P2" pos="-0.103726 -0.104282 -0.0589069" />
            <site name="TMAJ-P3" pos="-0.106 -0.110103 -0.0719232" />
            <site name="LAT1-P2" pos="-0.08052 -0.06821 -0.02908" />
            <site name="LAT1-P3" pos="-0.10925 -0.07239 -0.07422" />
            <site name="LAT2-P2" pos="-0.08345 -0.08695 -0.02453" />
            <site name="LAT2-P3" pos="-0.11524 -0.10749 -0.08863" />
            <site name="LAT3-P2" pos="-0.08438 -0.11598 -0.02995" />
            <site name="LAT3-P3" pos="-0.11279 -0.13833 -0.08911" />
            <site name="CORB-P1" pos="0.0126323 -0.0417068 -0.0268007" />
            <site name="CORB-P2" pos="0.00488112 -0.0703164 -0.0157954" />
            <site name="TRIlong-P1" pos="-0.0461331 -0.0411611 -0.0139157" />
            <site name="BIClong-P1" pos="-0.0315605 -0.023779 -0.0131881" />
            <site name="BIClong-P2" pos="-0.0211616 -0.0132285 -0.00465879" />
            <site name="BICshort-P1" pos="0.0128142 -0.039726 -0.0265278" />
            <site name="BICshort-P2" pos="0.000939843 -0.0677495 -0.0160986" />
            <joint name="acromioclavicular_r2" type="hinge" pos="0 0 0" axis="0.157095 0.947269 -0.279291" limited="false" range="-99999.9  99999.9" ref="0" />
            <joint name="acromioclavicular_r3" type="hinge" pos="0 0 0" axis="-0.754084 0.297594 0.585487" limited="false" range="-99999.9  99999.9" ref="0" />
            <joint name="acromioclavicular_r1" type="hinge" pos="0 0 0" axis="  0.6377   0.1186   0.7611" limited="false" range="-99999.9  99999.9" ref="0" />
            <body name="scapphant" pos="-0.00965107 -0.0343598 0.00909525" quat="1.0 0.0 0.0 0.0">
              <inertial pos="       0        0        0" mass="0.000101058337644021" fullinertia=" 1.03209  1.03209  1.03209        0        0        0" />
              <joint name="unrothum_r1" type="hinge" pos="0 0 0" axis="  0.6377   0.1186   0.7611" limited="false" range="-99999.9  99999.9" ref="0" />
              <joint name="unrothum_r3" type="hinge" pos="0 0 0" axis="-0.754084 0.297594 0.585487" limited="false" range="-99999.9  99999.9" ref="0" />
              <joint name="unrothum_r2" type="hinge" pos="0 0 0" axis="0.157095 0.947269 -0.279291" limited="false" range="-99999.9  99999.9" ref="0" />
              <body name="humphant" pos="       0        0        0" quat="1.0 0.0 0.0 0.0">
                <inertial pos="       0        0        0" mass="0.000101058337644021" fullinertia=" 1.03209  1.03209  1.03209        0        0        0" />
                <joint name="elv_angle" type="hinge" pos="0 0 0" axis="  0.0048 0.999089   0.0424" limited="true" range=" -1.5708  2.26893" ref="0" user="1" />
                <body name="humphant1" pos="       0        0        0" quat="1.0 0.0 0.0 0.0">
                  <inertial pos="       0        0        0" mass="0.000101058337644021" fullinertia=" 1.03209  1.03209  1.03209        0        0        0" />
                  <joint name="shoulder_elv" type="hinge" pos="0 0 0" axis="-0.998261   0.0023 0.058898" limited="true" range="       0  3.14159" ref="0" user="1" />
                  <joint name="shoulder1_r2" type="hinge" pos="0 0 0" axis="  0.0048 0.999089   0.0424" limited="false" range="-99999.9  99999.9" ref="0" />
                  <body name="humerus" pos="       0        0        0" quat="1.0 0.0 0.0 0.0">
                    <geom name="humerus" type="mesh" mesh="humerus" />
                    <inertial pos="0.0182552 -0.141624 -0.0128809" mass="2.01871103527567" fullinertia="0.0126716 0.0026332 0.0129825 -0.000358557 -0.00023996 0.00126874" />
                    <site name="DELT1-P1" pos="0.00905483 -0.120088 0.00591191" />
                    <site name="DELT1-P2" pos="0.0164018 -0.111498 0.0041636" />
                    <site name="DELT2-P1" pos="0.00465879 -0.137551 0.00565927" />
                    <site name="DELT3-P3" pos="0.0020818 -0.0768245 0.0105606" />
                    <site name="SUPSP-P1" pos="0.00258709 0.0107425 0.0262044" />
                    <site name="INFSP-P1" pos="-0.00896387 0.00489122 0.0247391" />
                    <site name="SUBSC-P1" pos="0.0141785 0.0084889 -0.0134509" />
                    <site name="TMIN-P1" pos="-0.00111164 -0.0127738 0.0217882" />
                    <site name="TMAJ-P1" pos="0.0100856 -0.0547635 -0.00574011" />
                    <site name="PECM1-P1" pos="0.0118137 -0.0423535 0.00788255" />
                    <site name="PECM1-P2" pos="  0.0191  -0.0301  0.00143" />
                    <site name="PECM2-P1" pos="0.0128748 -0.0433439 0.00793308" />
                    <site name="PECM2-P2" pos=" 0.01748 -0.03533  0.00033" />
                    <site name="PECM3-P1" pos="0.0128243 -0.044213 0.00757938" />
                    <site name="PECM3-P2" pos="0.0159185 -0.045833 -0.00378312" />
                    <site name="LAT1-P1" pos="0.0106111 -0.0345114 -0.00659911" />
                    <site name="LAT2-P1" pos="0.00978245 -0.0411408 -0.00617466" />
                    <site name="LAT3-P1" pos="0.0122078 -0.0396351 -0.00420403" />
                    <site name="CORB-P3" pos="0.00750863 -0.152073 -0.00790276" />
                    <site name="TRIlong-P2" pos="-0.0274272 -0.115621 -0.00671027" />
                    <site name="TRIlong-P3" pos="-0.032177 -0.228766 -0.0122988" />
                    <site name="TRIlong-P4" pos="-0.0176145 -0.270402 -0.0122078" />
                    <site name="TRIlat-P1" pos="-0.00605339 -0.127798 0.0043253" />
                    <site name="TRIlat-P2" pos="-0.0236881 -0.146818 0.00937821" />
                    <site name="TRIlat-P3" pos="-0.032177 -0.228766 -0.0122988" />
                    <site name="TRIlat-P4" pos="-0.0176145 -0.270402 -0.0122078" />
                    <site name="TRImed-P1" pos="-0.00846869 -0.138399 -0.00915589" />
                    <site name="TRImed-P2" pos="-0.0262853 -0.152992 -0.0109143" />
                    <site name="TRImed-P3" pos="-0.032177 -0.228766 -0.0122988" />
                    <site name="TRImed-P4" pos="-0.0176145 -0.270402 -0.0122078" />
                    <site name="ANC-P1" pos="-0.00751874 -0.286591 0.00989361" />
                    <site name="BIClong-P3" pos="0.0215355 0.0181198 0.0103888" />
                    <site name="BIClong-P4" pos="0.0240317 -0.00516408 0.0121371" />
                    <site name="BIClong-P5" pos="0.0135923 -0.0285692 0.00137439" />
                    <site name="BIClong-P6" pos="0.010793 -0.0781787 -0.00166746" />
                    <site name="BIClong-P7" pos="0.0172102 -0.122533 0.00024254" />
                    <site name="BIClong-P8" pos="0.0230413 -0.177256 -0.00636668" />
                    <site name="BICshort-P3" pos="0.0112882 -0.0765618 -0.0111265" />
                    <site name="BICshort-P4" pos="0.0172102 -0.122533 -0.0109042" />
                    <site name="BICshort-P5" pos="0.0230413 -0.177256 -0.00636668" />
                    <site name="BRA-P1" pos="0.00687197 -0.17574 -0.0036381" />
                    <site name="BRA-P2" pos="0.0191404 -0.288613 -0.0111669" />
                    <site name="BRD-P1" pos="-0.00990372 -0.201743 0.0022536" />
                    <site name="ECRL-P1" pos="-0.00737726 -0.263661 0.00919631" />
                    <site name="ECRB-P1" pos="0.0136328 -0.293554 0.0171597" />
                    <site name="ECU-P1" pos="0.000838784 -0.292614 0.018999" />
                    <site name="FCR-P1" pos="0.00766022 -0.281003 -0.0374421" />
                    <site name="FCU-P1" pos="0.00221318 -0.280336 -0.0392106" />
                    <site name="PL-P1" pos="0.00461837 -0.278102 -0.039059" />
                    <site name="PT-P1" pos="0.0036381 -0.27882 -0.0368863" />
                    <site name="FDSL-P1" pos="0.00425456 -0.278901 -0.0390489" />
                    <site name="FDSR-P1" pos="0.00484069 -0.281751 -0.0377049" />
                    <site name="EDCL-P1" pos="-0.000404233 -0.291361 0.0188979" />
                    <site name="EDCR-P1" pos="-0.00157651 -0.292422 0.0180086" />
                    <site name="EDCM-P1" pos="0.000515398 -0.292907 0.0196963" />
                    <site name="EDCI-P1" pos="0.000656879 -0.292038 0.0188878" />
                    <site name="EDM-P1" pos="0.000899419 -0.292251 0.0186655" />
                    <joint name="shoulder_rot" type="hinge" pos="0 0 0" axis="  0.0048 0.999089   0.0424" limited="true" range=" -1.5708 0.349066" ref="0" user="1" />
                    <body name="ulna" pos="0.00616456 -0.293473 -0.0124302" quat="1.0 0.0 0.0 0.0">
                      <geom name="ulna" type="mesh" mesh="ulna" />
                      <inertial pos="0.00982068 -0.0969664 0.024543" mass="1.11699780597936" fullinertia="0.00558678 0.00119018 0.00510224 0.000327027 -7.85935e-05 0.00112672" />
                      <site name="TRIlong-P5" pos="-0.0221318 0.0105707 -0.000788255" />
                      <site name="TRIlat-P5" pos="-0.0221318 0.0105707 -0.000788255" />
                      <site name="TRImed-P5" pos="-0.0221318 0.0105707 -0.000788255" />
                      <site name="ANC-P2" pos="-0.025588 -0.00125312 0.0060635" />
                      <site name="SUP-P3" pos="-0.0137439 -0.0341981 0.020343" />
                      <site name="BRA-P4" pos="-0.00323387 -0.0241529 0.000909525" />
                      <site name="BRA-P3" pos="0.00503271 -0.0147848 0.00129355" />
                      <site name="ECU-P2" pos="-0.0140572 -0.0323488 0.0297819" />
                      <site name="ECU-P3" pos="-0.0172304 -0.0548545 0.0289835" />
                      <site name="ECU-P4" pos="-0.0181198 -0.0967431 0.0331269" />
                      <site name="PT-P2" pos="0.00854954 -0.034087 -0.0144716" />
                      <site name="PT-P3" pos=" 0.01219 -0.06516 -0.00219" />
                      <site name="PQ-P2" pos="0.00195043 -0.21194 0.0367044" />
                      <site name="FDSM-P1" pos="-0.0067608 -0.0274171 -0.00193021" />
                      <site name="FDSI-P1" pos="-0.00683154 -0.0284883 -0.0013845" />
                      <site name="FDPL-P1" pos="-0.00634646 -0.0324801 0.00256688" />
                      <site name="FDPR-P1" pos="-0.00507313 -0.0340971 0.00275889" />
                      <site name="FDPM-P1" pos="-0.00527525 -0.0336221 0.00212223" />
                      <site name="FDPI-P1" pos="-0.00653847 -0.0320961 0.00282963" />
                      <site name="EDM-P2" pos="-0.0098734 -0.0394835 0.0311765" />
                      <site name="EDM-P3" pos="-0.0076299 -0.0835449 0.0368459" />
                      <site name="EIP-P1" pos="-0.0039817 -0.168282 0.0372097" />
                      <site name="EIP-P2" pos="0.0017281 -0.176539 0.0409185" />
                      <site name="EPL-P1" pos="-0.0142694 -0.0980872 0.0298324" />
                      <joint name="elbow_flexion" type="hinge" pos="0 0 0" axis="  0.0494   0.0366 0.998108" limited="true" range="       0  4.26893" ref="0" user="1" />
                      <body name="radius" pos="0.000404233 -0.0116247 0.0202107" quat="1.0 0.0 0.0 0.0">
                        <geom name="radius" type="mesh" mesh="radius" />
                        <inertial pos="0.0339901 -0.183481 0.0157651" mass="0.236062170902668" fullinertia="0.000452622 9.14326e-05 0.000415498 3.11071e-05 -4.37605e-06 6.62394e-05" />
                        <site name="SUP-P1" pos="0.0100654 -0.0616052 0.000757938" />
                        <site name="SUP-P2" pos="0.0121371 -0.0522472 -0.00108132" />
                        <site name="BIClong-P11" pos="-0.00202117 -0.0378969 -0.00202117" />
                        <site name="BIClong-P9" pos=" 0.00273 -0.0343493 -0.0119845" />
                        <site name="BICshort-P8" pos="-0.00202117 -0.0378969 -0.00202117" />
                        <site name="BICshort-P6" pos=" 0.00273 -0.0343493 -0.0119845" />
                        <site name="BRD-P2" pos="0.0361486 -0.128769 0.023395" />
                        <site name="BRD-P3" pos="0.0423434 -0.223339 0.0226371" />
                        <site name="ECRL-P2" pos="0.0322881 -0.136055 0.0280841" />
                        <site name="ECRL-P3" pos="0.0428791 -0.239347 0.0365831" />
                        <site name="ECRB-P2" pos="0.0293574 -0.132245 0.0241024" />
                        <site name="ECRB-P3" pos="0.0358656 -0.230464 0.0397867" />
                        <site name="ECU-P5" pos="-0.0143604 -0.229362 0.0351784" />
                        <site name="FCR-P2" pos="0.0213233 -0.221752 0.00128344" />
                        <site name="FCU-P3" pos="0.0109345 -0.225633 0.00979255" />
                        <site name="FCU-P2" pos="0.0101156 -0.183524 0.00202653" />
                        <site name="PL-P2" pos="0.0255779 -0.241681 -0.00278921" />
                        <site name="PT-P5" pos="0.0256688 -0.109951 0.0200096" />
                        <site name="PT-P4" pos="0.0238498 -0.0943885 0.00949948" />
                        <site name="PQ-P1" pos="0.0327934 -0.202096 0.0198276" />
                        <site name="FDSL-P2" pos="0.0139157 -0.189161 0.0020717" />
                        <site name="FDSR-P2" pos="0.0158763 -0.188635 0.00269826" />
                        <site name="FDSM-P2" pos="0.019191 -0.18904 0.00428487" />
                        <site name="FDSI-P2" pos="0.021677 -0.188201 0.00557842" />
                        <site name="FDPL-P2" pos="0.0142391 -0.18712 0.00870112" />
                        <site name="FDPR-P2" pos="0.0159672 -0.188262 0.00811498" />
                        <site name="FDPM-P2" pos="0.0192617 -0.188413 0.00793308" />
                        <site name="FDPI-P2" pos="0.0210201 -0.187564 0.00924684" />
                        <site name="EDCL-P3" pos="0.0100351 -0.225401 0.0365629" />
                        <site name="EDCL-P2" pos="  0.0013 -0.0382544 0.0129514" />
                        <site name="EDCR-P3" pos="0.00891335 -0.226027 0.0432934" />
                        <site name="EDCR-P2" pos="  0.0026 -0.0392844 0.0144214" />
                        <site name="EDCM-P3" pos="0.0145524 -0.225593 0.0426769" />
                        <site name="EDCM-P2" pos=" 0.00316 -0.0388544 0.0141814" />
                        <site name="EDCI-P3" pos="0.0154922 -0.225502 0.0424041" />
                        <site name="EDCI-P2" pos=" 0.00228 -0.0385544 0.0137314" />
                        <site name="EDM-P4" pos="0.00458805 -0.228806 0.0371693" />
                        <site name="EIP-P3" pos="0.0108739 -0.230241 0.0370278" />
                        <site name="EPL-P2" pos="0.00125312 -0.138127 0.0229402" />
                        <site name="EPL-P3" pos="0.027306 -0.221035 0.0386851" />
                        <site name="EPL-P4" pos="0.0341779 -0.229948 0.0465576" />
                        <site name="EPL-P5" pos="0.0427881 -0.240226 0.0421716" />
                        <site name="EPB-P1" pos="0.0194436 -0.148505 0.0213637" />
                        <site name="EPB-P2" pos="0.0230009 -0.160248 0.026932" />
                        <site name="EPB-P3" pos="0.0387154 -0.199307 0.0387458" />
                        <site name="EPB-P4" pos="0.052904 -0.238609 0.0272756" />
                        <site name="FPL-P1" pos="0.00981276 -0.095581 0.0178772" />
                        <site name="FPL-P2" pos="0.0167555 -0.136681 0.0193527" />
                        <site name="FPL-P3" pos="0.0188878 -0.181218 0.0200904" />
                        <site name="FPL-P4" pos="0.0384022 -0.234162 0.0159672" />
                        <site name="APL-P1" pos="0.0116621 -0.095773 0.0169879" />
                        <site name="APL-P2" pos="0.0306207 -0.141178 0.0354412" />
                        <site name="APL-P3" pos="0.0403526 -0.162421 0.0343598" />
                        <site name="APL-P4" pos="0.0444354 -0.180339 0.0316717" />
                        <site name="APL-P5" pos="0.0556326 -0.233283 0.0239306" />
                        <joint name="pro_sup" type="hinge" pos="0 0 0" axis="-0.017161 0.992666 -0.119668" limited="true" range=" -1.5708   1.5708" ref="0" user="1" />
                        <body name="proximal_row" pos="0.0181905 -0.244561 0.0252646" quat="1.0 0.0 0.0 0.0">
                          <geom name="lunate" type="mesh" mesh="lunate" />
                          <geom name="sdfastSCAPHOIDw" type="mesh" mesh="sdfastSCAPHOIDw" />
                          <geom name="sdfastPISIFORMw" type="mesh" mesh="sdfastPISIFORMw" />
                          <geom name="sdfastTRIQUETRALw" type="mesh" mesh="sdfastTRIQUETRALw" />
                          <inertial pos="       0        0        0" mass="0.000101058337644021" fullinertia="1.03209e-05 1.03209e-05 1.03209e-05        0        0        0" />
                          <body name="hand" pos="0.00403425 -0.0152133 0.00235163" quat="1.0 0.0 0.0 0.0">
                            <geom name="sdfast_1seg_hand_fr_c_5mc" type="mesh" mesh="sdfast_1seg_hand_fr_c_5mc" />
                            <geom name="sdfast_1seg_hand_fr_c_4mc" type="mesh" mesh="sdfast_1seg_hand_fr_c_4mc" />
                            <geom name="sdfast_1seg_hand_fr_c_3mc" type="mesh" mesh="sdfast_1seg_hand_fr_c_3mc" />
                            <geom name="sdfast_1seg_hand_fr_c_trapezium" type="mesh" mesh="sdfast_1seg_hand_fr_c_trapezium" />
                            <geom name="sdfast_1seg_hand_fr_c_trapezoid" type="mesh" mesh="sdfast_1seg_hand_fr_c_trapezoid" />
                            <geom name="sdfast_1seg_hand_fr_c_hamate" type="mesh" mesh="sdfast_1seg_hand_fr_c_hamate" />
                            <geom name="capitate" type="mesh" mesh="capitate" />
                            <geom name="hand_3proxph" type="mesh" mesh="hand_3proxph" />
                            <geom name="hand_3midph" type="mesh" mesh="hand_3midph" />
                            <geom name="hand_3distph" type="mesh" mesh="hand_3distph" />
                            <geom name="hand_4proxph" type="mesh" mesh="hand_4proxph" />
                            <geom name="hand_4midph" type="mesh" mesh="hand_4midph" />
                            <geom name="hand_4distph" type="mesh" mesh="hand_4distph" />
                            <geom name="hand_5proxph" type="mesh" mesh="hand_5proxph" />
                            <geom name="hand_5midph" type="mesh" mesh="hand_5midph" />
                            <geom name="hand_5distph" type="mesh" mesh="hand_5distph" />
                            <geom name="hand_thumbprox" type="mesh" mesh="hand_thumbprox" />
                            <geom name="hand_thumbdist" type="mesh" mesh="hand_thumbdist" />
                            <geom name="hand_1mc" type="mesh" mesh="hand_1mc" />
                            <inertial pos="-0.00304503 -0.0429491 -0.00113393" mass="0.588058466750558" fullinertia="0.00011353 6.19252e-05 0.000154813 9.28879e-07 -2.06417e-07 1.2385e-05" />
                            <site name="ECRL-P4" pos="0.0173517 -0.0214446 0.0058917" />
                            <site name="ECRB-P4" pos="0.00505292 -0.0114802 0.00858996" />
                            <site name="ECU-P6" pos="-0.0227482 -0.0141583 -0.00129355" />
                            <site name="FCR-P3" pos="0.011359 -0.0186352 -0.00422424" />
                            <site name="FCU-P4" pos="-0.0205755 -0.0178368 -0.00759959" />
                            <site name="PL-P3" pos="0.00926705 -0.0191809 -0.0177256" />
                            <site name="PL-P4" pos="0.00229402 -0.0312877 0.00498218" />
                            <site name="FDSL-P3" pos="-0.00237487 -0.0140774 -0.0139056" />
                            <site name="FDSL-P4" pos="-0.0201611 -0.0432631 -0.00749853" />
                            <site name="FDSL-P5" pos="-0.0206563 -0.060443 -0.0189788" />
                            <site name="FDSL-P6" pos="-0.0173113 -0.0732168 -0.0278214" />
                            <site name="FDSL-P7" pos="-0.0116823 -0.0734795 -0.0369469" />
                            <site name="FDSL-P8" pos="-0.0107021 -0.0734795 -0.0383617" />
                            <site name="FDSR-P3" pos="-0.000828678 -0.0135822 -0.0137338" />
                            <site name="FDSR-P4" pos="-0.0098734 -0.0523381 4.04233e-005" />
                            <site name="FDSR-P5" pos="-0.01337 -0.0674059 -0.010308" />
                            <site name="FDSR-P6" pos="-0.0079634 -0.0811195 -0.0252949" />
                            <site name="FDSR-P7" pos="-0.00302164 -0.0821099 -0.0343093" />
                            <site name="FDSR-P8" pos="0.000626562 -0.0817764 -0.0393319" />
                            <site name="FDSM-P3" pos="0.00687197 -0.0139157 -0.0141381" />
                            <site name="FDSM-P4" pos="0.00475985 -0.0336726 -0.00133397" />
                            <site name="FDSM-P5" pos="0.00547736 -0.057199 0.00060635" />
                            <site name="FDSM-P6" pos="0.00560874 -0.0730045 -0.00341577" />
                            <site name="FDSM-P7" pos="0.0117935 -0.0890324 -0.0168767" />
                            <site name="FDSM-P8" pos="0.0131477 -0.0896387 -0.0300851" />
                            <site name="FDSM-P9" pos="0.0158459 -0.0866777 -0.0380485" />
                            <site name="FDSI-P3" pos="0.00898409 -0.0138046 -0.0140168" />
                            <site name="FDSI-P4" pos="0.0107223 -0.0382708 0.00024254" />
                            <site name="FDSI-P5" pos="0.0180086 -0.0516206 0.00422424" />
                            <site name="FDSI-P6" pos="0.0186857 -0.0737423 -0.00378969" />
                            <site name="FDSI-P7" pos="0.0270634 -0.0880622 -0.0182309" />
                            <site name="FDSI-P8" pos="0.0269523 -0.088325 -0.0270634" />
                            <site name="FDSI-P9" pos="0.0268815 -0.0872437 -0.0293372" />
                            <site name="FDPL-P3" pos="-0.000889313 -0.0103787 -0.0120057" />
                            <site name="FDPL-P4" pos="-0.0187463 -0.0469517 -0.00740758" />
                            <site name="FDPL-P5" pos="-0.0182713 -0.0590282 -0.0157651" />
                            <site name="FDPL-P6" pos="-0.0144311 -0.0736614 -0.027114" />
                            <site name="FDPL-P7" pos="-0.00929737 -0.075622 -0.0372299" />
                            <site name="FDPL-P8" pos="-0.00315302 -0.0748337 -0.0420908" />
                            <site name="FDPL-P9" pos="0.0045072 -0.0713371 -0.0470629" />
                            <site name="FDPR-P3" pos="0.00107122 -0.0118946 -0.0119653" />
                            <site name="FDPR-P4" pos="-0.00864049 -0.0560065 0.000889313" />
                            <site name="FDPR-P5" pos="-0.0109042 -0.0665772 -0.00825647" />
                            <site name="FDPR-P6" pos="-0.00552789 -0.082403 -0.0227988" />
                            <site name="FDPR-P7" pos="-0.000565927 -0.083171 -0.0340263" />
                            <site name="FDPR-P8" pos="0.00615445 -0.0791994 -0.0428285" />
                            <site name="FDPR-P9" pos="0.0122382 -0.0745811 -0.0490941" />
                            <site name="FDPM-P3" pos="0.00338545 -0.0129355 -0.0115611" />
                            <site name="FDPM-P4" pos="0.00305196 -0.0348348 -0.00617466" />
                            <site name="FDPM-P5" pos="0.00254667 -0.0592505 0.00123291" />
                            <site name="FDPM-P6" pos="0.00288016 -0.0705892 -0.00134408" />
                            <site name="FDPM-P7" pos="0.00872133 -0.0887191 -0.0183421" />
                            <site name="FDPM-P8" pos="0.010126 -0.0885877 -0.0299537" />
                            <site name="FDPM-P9" pos="0.0165028 -0.0824333 -0.0448194" />
                            <site name="FDPM-P10" pos="0.019292 -0.077441 -0.0528434" />
                            <site name="FDPI-P3" pos="0.00905483 -0.0118036 -0.0122483" />
                            <site name="FDPI-P4" pos="0.0194234 -0.0560065 0.00442636" />
                            <site name="FDPI-P5" pos="0.0209494 -0.0709531 -0.00289027" />
                            <site name="FDPI-P6" pos="0.0293473 -0.0867889 -0.0180086" />
                            <site name="FDPI-P7" pos="0.0295495 -0.0876378 -0.0279831" />
                            <site name="FDPI-P8" pos="0.0294484 -0.0832215 -0.0402111" />
                            <site name="FDPI-P9" pos="0.0287713 -0.0785324 -0.0481644" />
                            <site name="EDCL-P4" pos="-0.0249008 -0.0444859 0.00170789" />
                            <site name="EDCL-P5" pos="-0.024062 -0.047841 0.000778149" />
                            <site name="EDCL-P6" pos="-0.0242035 -0.0668299 -0.0101159" />
                            <site name="EDCL-P7" pos="-0.0181703 -0.0793005 -0.0273969" />
                            <site name="EDCL-P8" pos="-0.0119047 -0.0796037 -0.0381899" />
                            <site name="EDCL-P9" pos="-0.00151588 -0.0766629 -0.0463454" />
                            <site name="EDCL-P10" pos="0.00203127 -0.0756624 -0.0484474" />
                            <site name="EDCR-P4" pos="-0.0158055 -0.0560874 0.00943885" />
                            <site name="EDCR-P5" pos="-0.014421 -0.0588058 0.0117329" />
                            <site name="EDCR-P6" pos="-0.0159672 -0.0729237 -0.00425456" />
                            <site name="EDCR-P7" pos="-0.00833731 -0.0882745 -0.0228392" />
                            <site name="EDCR-P8" pos="-0.00274879 -0.088992 -0.0344508" />
                            <site name="EDCR-P9" pos="0.00771075 -0.0811094 -0.047073" />
                            <site name="EDCR-P10" pos="0.0108031 -0.0789165 -0.0499329" />
                            <site name="EDCM-P4" pos="0.000394128 -0.0532982 0.0150678" />
                            <site name="EDCM-P5" pos="-0.000879208 -0.0563299 0.0146737" />
                            <site name="EDCM-P6" pos="0.00187969 -0.0779968 0.00603318" />
                            <site name="EDCM-P7" pos="0.0101766 -0.0941156 -0.0179277" />
                            <site name="EDCM-P8" pos="0.0133498 -0.0965916 -0.0308834" />
                            <site name="EDCM-P9" pos="0.0187665 -0.0861522 -0.0480937" />
                            <site name="EDCM-P10" pos="0.0207776 -0.0807759 -0.0539753" />
                            <site name="EDCM-P11" pos="0.0221823 -0.077825 -0.0572293" />
                            <site name="EDCI-P4" pos="0.0155933 -0.0472953 0.0165635" />
                            <site name="EDCI-P5" pos="0.0191708 -0.0571384 0.0145322" />
                            <site name="EDCI-P6" pos="0.020151 -0.0775926 0.00600287" />
                            <site name="EDCI-P7" pos="0.0297617 -0.0925896 -0.0125818" />
                            <site name="EDCI-P8" pos="0.0315403 -0.0944794 -0.0293574" />
                            <site name="EDCI-P9" pos="0.0304489 -0.0857682 -0.0431317" />
                            <site name="EDCI-P10" pos="0.0296 -0.0818876 -0.0501856" />
                            <site name="EDM-P5" pos="-0.0208079 -0.0104292 0.00375937" />
                            <site name="EDM-P6" pos="-0.0259013 -0.0477197 0.000232434" />
                            <site name="EDM-P7" pos="-0.0257598 -0.0657991 -0.0110962" />
                            <site name="EDM-P8" pos="-0.0195346 -0.0789266 -0.0274677" />
                            <site name="EDM-P9" pos="-0.0136025 -0.0797552 -0.0393521" />
                            <site name="EDM-P10" pos="-0.00218286 -0.076006 -0.0463757" />
                            <site name="EDM-P11" pos="0.00133397 -0.0742273 -0.0485383" />
                            <site name="EIP-P4" pos="0.00392106 -0.0225764 0.0119653" />
                            <site name="EIP-P5" pos="0.0171092 -0.0569969 0.0139157" />
                            <site name="EIP-P6" pos="0.0175336 -0.0777341 0.00587149" />
                            <site name="EIP-P7" pos="0.0279426 -0.0941257 -0.0152699" />
                            <site name="EIP-P8" pos="0.0290947 -0.0953688 -0.0285288" />
                            <site name="EIP-P9" pos="0.0290037 -0.0861421 -0.0434046" />
                            <site name="EIP-P10" pos="0.0286399 -0.0786739 -0.0555922" />
                            <site name="EPL-P6" pos="0.024537 0.000141482 0.00614435" />
                            <site name="EPL-P7" pos="0.0236274 -0.00926705 -0.000394128" />
                            <site name="EPL-P8" pos="0.0293574 -0.014421 -0.00494175" />
                            <site name="EPL-P9" pos="0.0446072 -0.0345316 -0.018332" />
                            <site name="EPL-P10" pos="0.0491851 -0.0469517 -0.0251332" />
                            <site name="EPL-P11" pos="0.0480128 -0.0708419 -0.0381394" />
                            <site name="EPL-P12" pos="0.0405345 -0.0764506 -0.0432833" />
                            <site name="EPB-P5" pos="0.0315605 0.00258709 -0.00330461" />
                            <site name="EPB-P6" pos="0.0300345 -0.00802403 -0.014512" />
                            <site name="EPB-P7" pos="0.044688 -0.0333493 -0.0244763" />
                            <site name="EPB-P8" pos="0.0457592 -0.0483564 -0.0321972" />
                            <site name="FPL-P6" pos="0.0125717 -0.0223036 -0.0211111" />
                            <site name="FPL-P7" pos="0.0165837 -0.0264874 -0.0224451" />
                            <site name="FPL-P8" pos="0.02483 -0.0332886 -0.0226068" />
                            <site name="FPL-P9" pos="0.0285692 -0.0554002 -0.0308733" />
                            <site name="FPL-P10" pos="0.0354816 -0.0658799 -0.0378868" />
                            <site name="FPL-P11" pos="0.0357039 -0.0773703 -0.0416158" />
                            <site name="FPL-P5" pos="0.0178892 0.0064176 -0.0168214" />
                            <site name="APL-P7" pos="0.0261438 0.0020717 -0.0166746" />
                            <site name="APL-P8" pos="0.0290846 -0.00681133 -0.0188979" />
                            <site name="APL-P9" pos="0.0310855 -0.0159975 -0.0190495" />
                            <site name="APL-P6" pos="0.0332244 0.00608975 -0.00870125" />
                            <body name="index0" pos="0 0 0">
                              <inertial pos="0 0 0" mass="0.001" diaginertia="0.001 0.001 0.001" />
                              <geom name="sdfast_1seg_hand_fr_c_2mc" type="mesh" mesh="sdfast_1seg_hand_fr_c_2mc" />
                              <body name="index1" pos="0 0 0">
                                <inertial pos="0 0 0" mass="0.001" diaginertia="0.001 0.001 0.001" />
                                <geom name="hand_2proxph" type="mesh" mesh="hand_2proxph" />
                                <body name="index2" pos="0 0 0">
                                  <inertial pos="0 0 0" mass="0.001" diaginertia="0.001 0.001 0.001" />
                                  <geom name="hand_2midph" type="mesh" mesh="hand_2midph" />
                                  <body name="index3" pos="0 0 0">
                                    <inertial pos="0 0 0" mass="0.001" diaginertia="0.001 0.001 0.001" />
                                    <geom name="hand_2distph" type="mesh" mesh="hand_2distph" />
                                    <site name="fingertip" pos="0.024 -0.149 -0.0065" type="sphere" rgba="0.1 0.8 0.1 0.0" size="0.004" />
                                  </body>
                                </body>
                              </body>
                            </body>
                          </body>
                        </body>
                      </body>
                    </body>
                  </body>
                </body>
              </body>
            </body>
          </body>
        </body>
      </body>
    </body>

</mujocoinclude>