<mujocoinclude model="MoBL Arms Index Model">

    <body name="thorax" pos="0 0 0" quat="0.7071067811865475 0.7071067811865475 0.0 0.0">
      <light mode="trackcom" directional="false" pos="0 0 4.0" dir="0 0 -1" />
      <geom name="thorax" type="mesh" mesh="thorax" />
      <site name="PECM1-P3" pos="  -7e-05  0.00821  0.10454" />
      <site name="PECM2-P4" pos="0.0308382 -0.0391289 0.0968245" />
      <site name="PECM2-P5" pos="0.0276257 -0.0448755 0.0226572" />
      <site name="PECM2-P3" pos=" 0.02083 -0.02005  0.11555" />
      <site name="PECM3-P4" pos="0.052378 -0.0839745 0.0891424" />
      <site name="PECM3-P5" pos="0.057107 -0.116269 0.037782" />
      <site name="PECM3-P3" pos=" 0.02984 -0.0544459   0.1151" />
      <site name="LAT1-P4" pos="-0.118005 -0.100945 0.033083" />
      <site name="LAT1-P5" pos="-0.0955575 -0.116968 0.00879951" />
      <site name="LAT2-P4" pos="-0.109665 -0.168687 0.0287131" />
      <site name="LAT2-P5" pos="-0.0716931 -0.187743 0.00813107" />
      <site name="LAT3-P4" pos="-0.111311 -0.19342 0.0551915" />
      <site name="LAT3-P5" pos="-0.0710047 -0.248003 0.00904893" />
      <joint name="r_z" type="hinge" pos="0 0 0" axis="       0        0        1" limited="true" range="-6.28319  6.28319" ref="0" armature="0" damping="0" stiffness="0" />
      <body name="clavicle" pos="0.00631031 0.0069139 0.0254058" quat="1.0 0.0 0.0 0.0">
        <geom name="clavicle" type="mesh" mesh="clavicle" />
        <inertial pos="-0.0110702 0.0063575 0.0540422" mass="0.15563758388891" fullinertia="0.000240903 0.000253485 4.41111e-05 -1.8848e-05 -6.94537e-05 5.33365e-05" />
        <site name="DELT1-P4" pos="-0.0139675 0.0110343 0.0800237" />
        <site name="DELT2-P2" pos="0.0191703 0.0244002 0.162891" />
        <site name="PECM1-P4" pos="0.00320254 -0.000129698 0.0510112" />
        <joint name="sternoclavicular_r2" type="hinge" pos="0 0 0" axis="  0.0153 0.989299  -0.1451" limited="false" range="-99999.9  99999.9" ref="0" />
        <joint name="sternoclavicular_r3" type="hinge" pos="0 0 0" axis="-0.994473        0 -0.104997" limited="false" range="-99999.9  99999.9" ref="0" />
        <body name="clavphant" pos="-0.0142967 0.0200234  0.13522" quat="1.0 0.0 0.0 0.0">
          <inertial pos="       0        0        0" mass="9.97676819800704e-05" fullinertia="0.993047 0.993047 0.993047        0        0        0" />
          <joint name="unrotscap_r3" type="hinge" pos="0 0 0" axis="-0.994473        0 -0.104997" limited="false" range="-99999.9  99999.9" ref="0" />
          <joint name="unrotscap_r2" type="hinge" pos="0 0 0" axis="  0.0153 0.989299  -0.1451" limited="false" range="-99999.9  99999.9" ref="0" />
          <body name="scapula" pos="       0        0        0" quat="1.0 0.0 0.0 0.0">
            <geom name="scapula" type="mesh" mesh="scapula" />
            <inertial pos="-0.0545669 -0.0349506 -0.0436324" mass="0.702324574066903" fullinertia="0.00123426 0.0011424 0.00135561 0.000446275 0.000406375 0.000239424" />
            <site name="DELT1-P3" pos="0.043369 -0.0324445 0.0009877" />
            <site name="DELT2-P3" pos="4.98838e-005 0.00293317 0.0222781" />
            <site name="DELT2-P4" pos="-0.010755 -0.00033921 0.0061856" />
            <site name="DELT3-P1" pos="-0.0556005 0.00121717 -0.0250616" />
            <site name="DELT3-P2" pos="-0.0723016 -0.0327737 0.0123014" />
            <site name="SUPSP-P2" pos="-0.0191354 0.00126705 -0.0126805" />
            <site name="SUPSP-P3" pos="-0.0438978 -0.0150849 -0.058414" />
            <site name="INFSP-P2" pos="-0.0736485 -0.0546328 -0.0476989" />
            <site name="SUBSC-P2" pos="-0.0182675 -0.0521087 -0.0245129" />
            <site name="SUBSC-P3" pos="-0.0722917 -0.0393384 -0.0645996" />
            <site name="TMIN-P2" pos="-0.0945099 -0.0797244 -0.04726" />
            <site name="TMIN-P3" pos="-0.096206 -0.0810213 -0.0528569" />
            <site name="TMAJ-P2" pos="-0.102402 -0.10295 -0.0581546" />
            <site name="TMAJ-P3" pos="-0.104646 -0.108697 -0.0710047" />
            <site name="LAT1-P2" pos="-0.08052 -0.06821 -0.02908" />
            <site name="LAT1-P3" pos="-0.10925 -0.07239 -0.07422" />
            <site name="LAT2-P2" pos="-0.08345 -0.08695 -0.02453" />
            <site name="LAT2-P3" pos="-0.11524 -0.10749 -0.08863" />
            <site name="LAT3-P2" pos="-0.08438 -0.11598 -0.02995" />
            <site name="LAT3-P3" pos="-0.11279 -0.13833 -0.08911" />
            <site name="CORB-P1" pos="0.012471 -0.0411741 -0.0264584" />
            <site name="CORB-P2" pos="0.00481878 -0.0694184 -0.0155937" />
            <site name="TRIlong-P1" pos="-0.0455439 -0.0406354 -0.013738" />
            <site name="BIClong-P1" pos="-0.0311574 -0.0234753 -0.0130197" />
            <site name="BIClong-P2" pos="-0.0208914 -0.0130596 -0.00459929" />
            <site name="BICshort-P1" pos="0.0126505 -0.0392187 -0.026189" />
            <site name="BICshort-P2" pos="0.000927839 -0.0668843 -0.015893" />
            <joint name="acromioclavicular_r2" type="hinge" pos="0 0 0" axis="0.157095 0.947269 -0.279291" limited="false" range="-99999.9  99999.9" ref="0" />
            <joint name="acromioclavicular_r3" type="hinge" pos="0 0 0" axis="-0.754084 0.297594 0.585487" limited="false" range="-99999.9  99999.9" ref="0" />
            <joint name="acromioclavicular_r1" type="hinge" pos="0 0 0" axis="  0.6377   0.1186   0.7611" limited="false" range="-99999.9  99999.9" ref="0" />
            <body name="scapphant" pos="-0.00952781 -0.033921 0.00897909" quat="1.0 0.0 0.0 0.0">
              <inertial pos="       0        0        0" mass="9.97676819800704e-05" fullinertia="0.993047 0.993047 0.993047        0        0        0" />
              <joint name="unrothum_r1" type="hinge" pos="0 0 0" axis="  0.6377   0.1186   0.7611" limited="false" range="-99999.9  99999.9" ref="0" />
              <joint name="unrothum_r3" type="hinge" pos="0 0 0" axis="-0.754084 0.297594 0.585487" limited="false" range="-99999.9  99999.9" ref="0" />
              <joint name="unrothum_r2" type="hinge" pos="0 0 0" axis="0.157095 0.947269 -0.279291" limited="false" range="-99999.9  99999.9" ref="0" />
              <body name="humphant" pos="       0        0        0" quat="1.0 0.0 0.0 0.0">
                <inertial pos="       0        0        0" mass="9.97676819800704e-05" fullinertia="0.993047 0.993047 0.993047        0        0        0" />
                <joint name="elv_angle" type="hinge" pos="0 0 0" axis="  0.0048 0.999089   0.0424" limited="true" range=" -1.5708  2.26893" ref="0" user="1" />
                <body name="humphant1" pos="       0        0        0" quat="1.0 0.0 0.0 0.0">
                  <inertial pos="       0        0        0" mass="9.97676819800704e-05" fullinertia="0.993047 0.993047 0.993047        0        0        0" />
                  <joint name="shoulder_elv" type="hinge" pos="0 0 0" axis="-0.998261   0.0023 0.058898" limited="true" range="       0  3.14159" ref="0" user="1" />
                  <joint name="shoulder1_r2" type="hinge" pos="0 0 0" axis="  0.0048 0.999089   0.0424" limited="false" range="-99999.9  99999.9" ref="0" />
                  <body name="humerus" pos="       0        0        0" quat="1.0 0.0 0.0 0.0">
                    <geom name="humerus" type="mesh" mesh="humerus" />
                    <inertial pos="0.018022 -0.139815 -0.0127164" mass="1.99292928492929" fullinertia="0.0121923 0.00253359 0.0124914 -0.000344994 -0.000230883 0.00122075" />
                    <site name="DELT1-P1" pos="0.00893918 -0.118554 0.00583641" />
                    <site name="DELT1-P2" pos="0.0161923 -0.110074 0.00411043" />
                    <site name="DELT2-P1" pos="0.00459929 -0.135794 0.00558699" />
                    <site name="DELT3-P3" pos="0.00205521 -0.0758434 0.0104257" />
                    <site name="SUPSP-P1" pos="0.00255405 0.0106053 0.0258698" />
                    <site name="INFSP-P1" pos="-0.00884939 0.00482876 0.0244231" />
                    <site name="SUBSC-P1" pos="0.0139974 0.00838049 -0.0132791" />
                    <site name="TMIN-P1" pos="-0.00109744 -0.0126106 0.0215099" />
                    <site name="TMAJ-P1" pos="0.00995681 -0.0540641 -0.0056668" />
                    <site name="PECM1-P1" pos="0.0116628 -0.0418126 0.00778188" />
                    <site name="PECM1-P2" pos="  0.0191  -0.0301  0.00143" />
                    <site name="PECM2-P1" pos="0.0127104 -0.0427904 0.00783176" />
                    <site name="PECM2-P2" pos=" 0.01748 -0.03533  0.00033" />
                    <site name="PECM3-P1" pos="0.0126605 -0.0436484 0.00748258" />
                    <site name="PECM3-P2" pos="0.0159185 -0.045833 -0.00378312" />
                    <site name="LAT1-P1" pos="0.0104756 -0.0340707 -0.00651483" />
                    <site name="LAT2-P1" pos="0.00965751 -0.0406154 -0.00609581" />
                    <site name="LAT3-P1" pos="0.0120519 -0.0391289 -0.00415034" />
                    <site name="CORB-P3" pos="0.00741274 -0.15013 -0.00780183" />
                    <site name="TRIlong-P2" pos="-0.0270769 -0.114144 -0.00662457" />
                    <site name="TRIlong-P3" pos="-0.031766 -0.225844 -0.0121417" />
                    <site name="TRIlong-P4" pos="-0.0173895 -0.266948 -0.0120519" />
                    <site name="TRIlat-P1" pos="-0.00597608 -0.126166 0.00427006" />
                    <site name="TRIlat-P2" pos="-0.0233855 -0.144942 0.00925844" />
                    <site name="TRIlat-P3" pos="-0.031766 -0.225844 -0.0121417" />
                    <site name="TRIlat-P4" pos="-0.0173895 -0.266948 -0.0120519" />
                    <site name="TRImed-P1" pos="-0.00836053 -0.136632 -0.00903895" />
                    <site name="TRImed-P2" pos="-0.0259496 -0.151038 -0.0107749" />
                    <site name="TRImed-P3" pos="-0.031766 -0.225844 -0.0121417" />
                    <site name="TRImed-P4" pos="-0.0173895 -0.266948 -0.0120519" />
                    <site name="ANC-P1" pos="-0.00742272 -0.282931 0.00976726" />
                    <site name="BIClong-P3" pos="0.0212605 0.0178883 0.0102561" />
                    <site name="BIClong-P4" pos="0.0237248 -0.00509813 0.0119821" />
                    <site name="BIClong-P5" pos="0.0134188 -0.0282043 0.00135684" />
                    <site name="BIClong-P6" pos="0.0106552 -0.0771803 -0.00164617" />
                    <site name="BIClong-P7" pos="0.0169904 -0.120968 0.000239442" />
                    <site name="BIClong-P8" pos="0.022747 -0.174993 -0.00628536" />
                    <site name="BICshort-P3" pos="0.0111441 -0.075584 -0.0109844" />
                    <site name="BICshort-P4" pos="0.0169904 -0.120968 -0.0107649" />
                    <site name="BICshort-P5" pos="0.022747 -0.174993 -0.00628536" />
                    <site name="BRA-P1" pos="0.0067842 -0.173496 -0.00359164" />
                    <site name="BRA-P2" pos="0.018896 -0.284927 -0.0110243" />
                    <site name="BRD-P1" pos="-0.00977723 -0.199166 0.00222482" />
                    <site name="ECRL-P1" pos="-0.00728304 -0.260294 0.00907886" />
                    <site name="ECRB-P1" pos="0.0134587 -0.289805 0.0169406" />
                    <site name="ECU-P1" pos="0.000828072 -0.288877 0.0187563" />
                    <site name="FCR-P1" pos="0.00756239 -0.277414 -0.0369639" />
                    <site name="FCU-P1" pos="0.00218491 -0.276756 -0.0387099" />
                    <site name="PL-P1" pos="0.00455938 -0.274551 -0.0385602" />
                    <site name="PT-P1" pos="0.00359164 -0.275259 -0.0364152" />
                    <site name="FDSL-P1" pos="0.00420022 -0.275339 -0.0385502" />
                    <site name="FDSR-P1" pos="0.00477887 -0.278152 -0.0372233" />
                    <site name="EDCL-P1" pos="-0.000399071 -0.28764 0.0186566" />
                    <site name="EDCR-P1" pos="-0.00155638 -0.288688 0.0177786" />
                    <site name="EDCM-P1" pos="0.000508815 -0.289167 0.0194447" />
                    <site name="EDCI-P1" pos="0.00064849 -0.288309 0.0186466" />
                    <site name="EDM-P1" pos="0.000887932 -0.288518 0.0184271" />
                    <joint name="shoulder_rot" type="hinge" pos="0 0 0" axis="  0.0048 0.999089   0.0424" limited="true" range=" -1.5708 0.349066" ref="0" user="1" />
                    <body name="ulna" pos="0.00608583 -0.289725 -0.0122714" quat="1.0 0.0 0.0 0.0">
                      <geom name="ulna" type="mesh" mesh="ulna" />
                      <inertial pos="0.00969525 -0.095728 0.0242296" mass="1.10273218892572" fullinertia="0.00537545 0.00114516 0.00490924 0.000314657 -7.56205e-05 0.0010841" />
                      <site name="TRIlong-P5" pos="-0.0218491 0.0104357 -0.000778188" />
                      <site name="TRIlat-P5" pos="-0.0218491 0.0104357 -0.000778188" />
                      <site name="TRImed-P5" pos="-0.0218491 0.0104357 -0.000778188" />
                      <site name="ANC-P2" pos="-0.0252612 -0.00123712 0.00598606" />
                      <site name="SUP-P3" pos="-0.0135684 -0.0337614 0.0200832" />
                      <site name="BRA-P4" pos="-0.00319257 -0.0238445 0.000897909" />
                      <site name="BRA-P3" pos="0.00496843 -0.014596 0.00127703" />
                      <site name="ECU-P2" pos="-0.0138777 -0.0319356 0.0294015" />
                      <site name="ECU-P3" pos="-0.0170104 -0.0541539 0.0286134" />
                      <site name="ECU-P4" pos="-0.0178883 -0.0955076 0.0327038" />
                      <site name="PT-P2" pos="0.00844035 -0.0336516 -0.0142867" />
                      <site name="PT-P3" pos=" 0.01219 -0.06516 -0.00219" />
                      <site name="PQ-P2" pos="0.00192552 -0.209233 0.0362356" />
                      <site name="FDSM-P1" pos="-0.00667446 -0.027067 -0.00190556" />
                      <site name="FDSI-P1" pos="-0.0067443 -0.0281245 -0.00136682" />
                      <site name="FDPL-P1" pos="-0.00626541 -0.0320653 0.0025341" />
                      <site name="FDPR-P1" pos="-0.00500834 -0.0336616 0.00272366" />
                      <site name="FDPM-P1" pos="-0.00520787 -0.0331927 0.00209512" />
                      <site name="FDPI-P1" pos="-0.00645497 -0.0316862 0.0027935" />
                      <site name="EDM-P2" pos="-0.0097473 -0.0389792 0.0307783" />
                      <site name="EDM-P3" pos="-0.00753246 -0.0824779 0.0363753" />
                      <site name="EIP-P1" pos="-0.00393085 -0.166133 0.0367345" />
                      <site name="EIP-P2" pos="0.00170603 -0.174284 0.0403959" />
                      <site name="EPL-P1" pos="-0.0140872 -0.0968345 0.0294514" />
                      <joint name="elbow_flexion" type="hinge" pos="0 0 0" axis="  0.0494   0.0366 0.998108" limited="true" range="       0  4.26893" ref="0" user="1" />
                      <body name="radius" pos="0.000399071 -0.0114763 0.0199525" quat="1.0 0.0 0.0 0.0">
                        <geom name="radius" type="mesh" mesh="radius" />
                        <inertial pos="0.033556 -0.181137 0.0155638" mass="0.233047328337246" fullinertia="0.000435501 8.7974e-05 0.000399781 2.99304e-05 -4.21052e-06 6.37337e-05" />
                        <site name="SUP-P1" pos="0.00993686 -0.0608184 0.000748258" />
                        <site name="SUP-P2" pos="0.0119821 -0.0515799 -0.00106751" />
                        <site name="BIClong-P11" pos="-0.00199535 -0.0374129 -0.00199535" />
                        <site name="BIClong-P9" pos=" 0.00273 -0.0343493 -0.0119845" />
                        <site name="BICshort-P8" pos="-0.00199535 -0.0374129 -0.00199535" />
                        <site name="BICshort-P6" pos=" 0.00273 -0.0343493 -0.0119845" />
                        <site name="BRD-P2" pos="0.0356869 -0.127124 0.0230962" />
                        <site name="BRD-P3" pos="0.0418027 -0.220487 0.022348" />
                        <site name="ECRL-P2" pos="0.0318758 -0.134317 0.0277254" />
                        <site name="ECRL-P3" pos="0.0423314 -0.23629 0.0361159" />
                        <site name="ECRB-P2" pos="0.0289825 -0.130556 0.0237946" />
                        <site name="ECRB-P3" pos="0.0354076 -0.22752 0.0392785" />
                        <site name="ECU-P5" pos="-0.014177 -0.226433 0.0347291" />
                        <site name="FCR-P2" pos="0.021051 -0.21892 0.00126705" />
                        <site name="FCU-P3" pos="0.0107949 -0.222751 0.00966749" />
                        <site name="FCU-P2" pos="0.0101156 -0.183524 0.00202653" />
                        <site name="PL-P2" pos="0.0252512 -0.238594 -0.00275359" />
                        <site name="PT-P5" pos="0.025341 -0.108547 0.019754" />
                        <site name="PT-P4" pos="0.0235452 -0.093183 0.00937816" />
                        <site name="PQ-P1" pos="0.0323746 -0.199515 0.0195744" />
                        <site name="FDSL-P2" pos="0.013738 -0.186745 0.00204524" />
                        <site name="FDSR-P2" pos="0.0156735 -0.186226 0.0026638" />
                        <site name="FDSM-P2" pos="0.0189459 -0.186625 0.00423015" />
                        <site name="FDSI-P2" pos="0.0214002 -0.185797 0.00550718" />
                        <site name="FDPL-P2" pos="0.0140573 -0.18473 0.00859" />
                        <site name="FDPR-P2" pos="0.0157633 -0.185857 0.00801134" />
                        <site name="FDPM-P2" pos="0.0190157 -0.186007 0.00783176" />
                        <site name="FDPI-P2" pos="0.0207517 -0.185169 0.00912874" />
                        <site name="EDCL-P3" pos="0.00990693 -0.222522 0.0360959" />
                        <site name="EDCL-P2" pos="  0.0013 -0.0382544 0.0129514" />
                        <site name="EDCR-P3" pos="0.00879951 -0.22314 0.0427405" />
                        <site name="EDCR-P2" pos="  0.0026 -0.0392844 0.0144214" />
                        <site name="EDCM-P3" pos="0.0143665 -0.222711 0.0421319" />
                        <site name="EDCM-P2" pos=" 0.00316 -0.0388544 0.0141814" />
                        <site name="EDCI-P3" pos="0.0152944 -0.222622 0.0418625" />
                        <site name="EDCI-P2" pos=" 0.00228 -0.0385544 0.0137314" />
                        <site name="EDM-P4" pos="0.00452945 -0.225884 0.0366946" />
                        <site name="EIP-P3" pos="0.010735 -0.227301 0.0365549" />
                        <site name="EPL-P2" pos="0.00123712 -0.136362 0.0226473" />
                        <site name="EPL-P3" pos="0.0269572 -0.218212 0.0381911" />
                        <site name="EPL-P4" pos="0.0337414 -0.227011 0.045963" />
                        <site name="EPL-P5" pos="0.0422416 -0.237158 0.0416331" />
                        <site name="EPB-P1" pos="0.0191953 -0.146609 0.0210909" />
                        <site name="EPB-P2" pos="0.0227071 -0.158202 0.0265881" />
                        <site name="EPB-P3" pos="0.038221 -0.196762 0.0382509" />
                        <site name="EPB-P4" pos="0.0522284 -0.235561 0.0269273" />
                        <site name="FPL-P1" pos="0.00968744 -0.0943603 0.0176489" />
                        <site name="FPL-P2" pos="0.0165415 -0.134936 0.0191055" />
                        <site name="FPL-P3" pos="0.0186466 -0.178903 0.0198338" />
                        <site name="FPL-P4" pos="0.0379117 -0.231172 0.0157633" />
                        <site name="APL-P1" pos="0.0115132 -0.0945498 0.0167709" />
                        <site name="APL-P2" pos="0.0302296 -0.139375 0.0349885" />
                        <site name="APL-P3" pos="0.0398372 -0.160347 0.033921" />
                        <site name="APL-P4" pos="0.0438678 -0.178035 0.0312672" />
                        <site name="APL-P5" pos="0.0549221 -0.230304 0.023625" />
                        <joint name="pro_sup" type="hinge" pos="0 0 0" axis="-0.017161 0.992666 -0.119668" limited="true" range=" -1.5708   1.5708" ref="0" user="1" />
                        <body name="proximal_row" pos="0.0179582 -0.241438 0.0249419" quat="1.0 0.0 0.0 0.0">
                          <geom name="lunate" type="mesh" mesh="lunate" />
                          <geom name="sdfastSCAPHOIDw" type="mesh" mesh="sdfastSCAPHOIDw" />
                          <geom name="sdfastPISIFORMw" type="mesh" mesh="sdfastPISIFORMw" />
                          <geom name="sdfastTRIQUETRALw" type="mesh" mesh="sdfastTRIQUETRALw" />
                          <inertial pos="       0        0        0" mass="9.97676819800704e-05" fullinertia="9.93047e-06 9.93047e-06 9.93047e-06        0        0        0" />
                          <body name="hand" pos="0.00398273 -0.015019 0.00232159" quat="1.0 0.0 0.0 0.0">
                            <geom name="sdfast_1seg_hand_fr_c_5mc" type="mesh" mesh="sdfast_1seg_hand_fr_c_5mc" />
                            <geom name="sdfast_1seg_hand_fr_c_4mc" type="mesh" mesh="sdfast_1seg_hand_fr_c_4mc" />
                            <geom name="sdfast_1seg_hand_fr_c_3mc" type="mesh" mesh="sdfast_1seg_hand_fr_c_3mc" />
                            <geom name="sdfast_1seg_hand_fr_c_trapezium" type="mesh" mesh="sdfast_1seg_hand_fr_c_trapezium" />
                            <geom name="sdfast_1seg_hand_fr_c_trapezoid" type="mesh" mesh="sdfast_1seg_hand_fr_c_trapezoid" />
                            <geom name="sdfast_1seg_hand_fr_c_hamate" type="mesh" mesh="sdfast_1seg_hand_fr_c_hamate" />
                            <geom name="capitate" type="mesh" mesh="capitate" />
                            <geom name="hand_3proxph" type="mesh" mesh="hand_3proxph" />
                            <geom name="hand_3midph" type="mesh" mesh="hand_3midph" />
                            <geom name="hand_3distph" type="mesh" mesh="hand_3distph" />
                            <geom name="hand_4proxph" type="mesh" mesh="hand_4proxph" />
                            <geom name="hand_4midph" type="mesh" mesh="hand_4midph" />
                            <geom name="hand_4distph" type="mesh" mesh="hand_4distph" />
                            <geom name="hand_5proxph" type="mesh" mesh="hand_5proxph" />
                            <geom name="hand_5midph" type="mesh" mesh="hand_5midph" />
                            <geom name="hand_5distph" type="mesh" mesh="hand_5distph" />
                            <geom name="hand_thumbprox" type="mesh" mesh="hand_thumbprox" />
                            <geom name="hand_thumbdist" type="mesh" mesh="hand_thumbdist" />
                            <geom name="hand_1mc" type="mesh" mesh="hand_1mc" />
                            <inertial pos="-0.00300614 -0.0424006 -0.00111944" mass="0.580548141442029" fullinertia="0.000109235 5.95828e-05 0.000148957 8.93742e-07 -1.98609e-07 1.19166e-05" />
                            <site name="ECRL-P4" pos="0.0171301 -0.0211707 0.00581646" />
                            <site name="ECRB-P4" pos="0.00498838 -0.0113336 0.00848025" />
                            <site name="ECU-P6" pos="-0.0224577 -0.0139775 -0.00127703" />
                            <site name="FCR-P3" pos="0.0112139 -0.0183972 -0.00417029" />
                            <site name="FCU-P4" pos="-0.0203127 -0.017609 -0.00750253" />
                            <site name="PL-P3" pos="0.0091487 -0.0189359 -0.0174993" />
                            <site name="PL-P4" pos="0.00226473 -0.0308881 0.00491855" />
                            <site name="FDSL-P3" pos="-0.00234454 -0.0138976 -0.013728" />
                            <site name="FDSL-P4" pos="-0.0199037 -0.0427105 -0.00740276" />
                            <site name="FDSL-P5" pos="-0.0203925 -0.0596711 -0.0187364" />
                            <site name="FDSL-P6" pos="-0.0170902 -0.0722817 -0.027466" />
                            <site name="FDSL-P7" pos="-0.0115331 -0.0725411 -0.0364751" />
                            <site name="FDSL-P8" pos="-0.0105654 -0.0725411 -0.0378718" />
                            <site name="FDSR-P3" pos="-0.000818095 -0.0134088 -0.0135584" />
                            <site name="FDSR-P4" pos="-0.0097473 -0.0516697 3.99071e-005" />
                            <site name="FDSR-P5" pos="-0.0131993 -0.066545 -0.0101763" />
                            <site name="FDSR-P6" pos="-0.00786169 -0.0800835 -0.0249719" />
                            <site name="FDSR-P7" pos="-0.00298305 -0.0810612 -0.0338711" />
                            <site name="FDSR-P8" pos="0.00061856 -0.080732 -0.0388296" />
                            <site name="FDSM-P3" pos="0.0067842 -0.013738 -0.0139575" />
                            <site name="FDSM-P4" pos="0.00469906 -0.0332426 -0.00131693" />
                            <site name="FDSM-P5" pos="0.00540741 -0.0564685 0.000598606" />
                            <site name="FDSM-P6" pos="0.00553711 -0.0720722 -0.00337215" />
                            <site name="FDSM-P7" pos="0.0116429 -0.0878953 -0.0166612" />
                            <site name="FDSM-P8" pos="0.0129798 -0.0884939 -0.0297008" />
                            <site name="FDSM-P9" pos="0.0156436 -0.0855707 -0.0375625" />
                            <site name="FDSI-P3" pos="0.00886935 -0.0136283 -0.0138378" />
                            <site name="FDSI-P4" pos="0.0105854 -0.037782 0.000239442" />
                            <site name="FDSI-P5" pos="0.0177786 -0.0509613 0.00417029" />
                            <site name="FDSI-P6" pos="0.018447 -0.0728005 -0.00374129" />
                            <site name="FDSI-P7" pos="0.0267178 -0.0869376 -0.0179981" />
                            <site name="FDSI-P8" pos="0.026608 -0.087197 -0.0267178" />
                            <site name="FDSI-P9" pos="0.0265382 -0.0861294 -0.0289626" />
                            <site name="FDPL-P3" pos="-0.000877956 -0.0102461 -0.0118524" />
                            <site name="FDPL-P4" pos="-0.0185069 -0.0463521 -0.00731297" />
                            <site name="FDPL-P5" pos="-0.018038 -0.0582743 -0.0155638" />
                            <site name="FDPL-P6" pos="-0.0142468 -0.0727207 -0.0267677" />
                            <site name="FDPL-P7" pos="-0.00917863 -0.0746562 -0.0367544" />
                            <site name="FDPL-P8" pos="-0.00311275 -0.073878 -0.0415532" />
                            <site name="FDPL-P9" pos="0.00444964 -0.070426 -0.0464618" />
                            <site name="FDPR-P3" pos="0.00105754 -0.0117427 -0.0118125" />
                            <site name="FDPR-P4" pos="-0.00853014 -0.0552912 0.000877956" />
                            <site name="FDPR-P5" pos="-0.0107649 -0.0657269 -0.00815102" />
                            <site name="FDPR-P6" pos="-0.00545729 -0.0813506 -0.0225076" />
                            <site name="FDPR-P7" pos="-0.000558699 -0.0821088 -0.0335918" />
                            <site name="FDPR-P8" pos="0.00607585 -0.0781879 -0.0422815" />
                            <site name="FDPR-P9" pos="0.0120819 -0.0736285 -0.0484671" />
                            <site name="FDPM-P3" pos="0.00334222 -0.0127703 -0.0114134" />
                            <site name="FDPM-P4" pos="0.00301298 -0.0343899 -0.00609581" />
                            <site name="FDPM-P5" pos="0.00251415 -0.0584938 0.00121717" />
                            <site name="FDPM-P6" pos="0.00284338 -0.0696877 -0.00132691" />
                            <site name="FDPM-P7" pos="0.00860995 -0.087586 -0.0181078" />
                            <site name="FDPM-P8" pos="0.00999672 -0.0874564 -0.0295711" />
                            <site name="FDPM-P9" pos="0.0162921 -0.0813805 -0.044247" />
                            <site name="FDPM-P10" pos="0.0190457 -0.076452 -0.0521685" />
                            <site name="FDPI-P3" pos="0.00893918 -0.0116529 -0.0120918" />
                            <site name="FDPI-P4" pos="0.0191753 -0.0552912 0.00436982" />
                            <site name="FDPI-P5" pos="0.0206818 -0.0700469 -0.00285336" />
                            <site name="FDPI-P6" pos="0.0289725 -0.0856805 -0.0177786" />
                            <site name="FDPI-P7" pos="0.0291721 -0.0865185 -0.0276257" />
                            <site name="FDPI-P8" pos="0.0290723 -0.0821587 -0.0396976" />
                            <site name="FDPI-P9" pos="0.0284039 -0.0775295 -0.0475493" />
                            <site name="EDCL-P4" pos="-0.0245828 -0.0439177 0.00168607" />
                            <site name="EDCL-P5" pos="-0.0237547 -0.04723 0.000768211" />
                            <site name="EDCL-P6" pos="-0.0238944 -0.0659764 -0.00998674" />
                            <site name="EDCL-P7" pos="-0.0179382 -0.0782877 -0.027047" />
                            <site name="EDCL-P8" pos="-0.0117526 -0.078587 -0.0377022" />
                            <site name="EDCL-P9" pos="-0.00149652 -0.0756838 -0.0457535" />
                            <site name="EDCL-P10" pos="0.00200533 -0.0746961 -0.0478286" />
                            <site name="EDCR-P4" pos="-0.0156037 -0.0553711 0.0093183" />
                            <site name="EDCR-P5" pos="-0.0142368 -0.0580548 0.011583" />
                            <site name="EDCR-P6" pos="-0.0157633 -0.0719924 -0.00420022" />
                            <site name="EDCR-P7" pos="-0.00823083 -0.0871471 -0.0225475" />
                            <site name="EDCR-P8" pos="-0.00271368 -0.0878554 -0.0340108" />
                            <site name="EDCR-P9" pos="0.00761227 -0.0800735 -0.0464718" />
                            <site name="EDCR-P10" pos="0.0106652 -0.0779086 -0.0492952" />
                            <site name="EDCM-P4" pos="0.000389094 -0.0526175 0.0148754" />
                            <site name="EDCM-P5" pos="-0.000867979 -0.0556105 0.0144863" />
                            <site name="EDCM-P6" pos="0.00185568 -0.0770007 0.00595613" />
                            <site name="EDCM-P7" pos="0.0100466 -0.0929136 -0.0176988" />
                            <site name="EDCM-P8" pos="0.0131793 -0.095358 -0.030489" />
                            <site name="EDCM-P9" pos="0.0185269 -0.0850519 -0.0474794" />
                            <site name="EDCM-P10" pos="0.0205122 -0.0797443 -0.0532859" />
                            <site name="EDCM-P11" pos="0.021899 -0.0768311 -0.0564984" />
                            <site name="EDCI-P4" pos="0.0153942 -0.0466913 0.0163519" />
                            <site name="EDCI-P5" pos="0.0189259 -0.0564086 0.0143466" />
                            <site name="EDCI-P6" pos="0.0198937 -0.0766016 0.0059262" />
                            <site name="EDCI-P7" pos="0.0293816 -0.0914072 -0.0124211" />
                            <site name="EDCI-P8" pos="0.0311375 -0.0932728 -0.0289825" />
                            <site name="EDCI-P9" pos="0.03006 -0.0846728 -0.0425808" />
                            <site name="EDCI-P10" pos="0.029222 -0.0808418 -0.0495446" />
                            <site name="EDM-P5" pos="-0.0205422 -0.010296 0.00371136" />
                            <site name="EDM-P6" pos="-0.0255705 -0.0471103 0.000229466" />
                            <site name="EDM-P7" pos="-0.0254308 -0.0649587 -0.0109545" />
                            <site name="EDM-P8" pos="-0.0192851 -0.0779186 -0.0271169" />
                            <site name="EDM-P9" pos="-0.0134287 -0.0787367 -0.0388495" />
                            <site name="EDM-P10" pos="-0.00215498 -0.0750353 -0.0457834" />
                            <site name="EDM-P11" pos="0.00131693 -0.0732794 -0.0479184" />
                            <site name="EIP-P4" pos="0.00387099 -0.0222881 0.0118125" />
                            <site name="EIP-P5" pos="0.0168907 -0.056269 0.013738" />
                            <site name="EIP-P6" pos="0.0173097 -0.0767413 0.0057965" />
                            <site name="EIP-P7" pos="0.0275858 -0.0929236 -0.0150749" />
                            <site name="EIP-P8" pos="0.0287231 -0.0941508 -0.0281644" />
                            <site name="EIP-P9" pos="0.0286333 -0.085042 -0.0428502" />
                            <site name="EIP-P10" pos="0.0282742 -0.0776691 -0.0548822" />
                            <site name="EPL-P6" pos="0.0242236 0.000139675 0.00606588" />
                            <site name="EPL-P7" pos="0.0233257 -0.0091487 -0.000389094" />
                            <site name="EPL-P8" pos="0.0289825 -0.0142368 -0.00487864" />
                            <site name="EPL-P9" pos="0.0440375 -0.0340906 -0.0180979" />
                            <site name="EPL-P10" pos="0.0485569 -0.0463521 -0.0248122" />
                            <site name="EPL-P11" pos="0.0473996 -0.0699371 -0.0376523" />
                            <site name="EPL-P12" pos="0.0400168 -0.0754743 -0.0427305" />
                            <site name="EPB-P5" pos="0.0311574 0.00255405 -0.0032624" />
                            <site name="EPB-P6" pos="0.029651 -0.00792155 -0.0143266" />
                            <site name="EPB-P7" pos="0.0441173 -0.0329233 -0.0241637" />
                            <site name="EPB-P8" pos="0.0451748 -0.0477388 -0.031786" />
                            <site name="FPL-P6" pos="0.0124111 -0.0220187 -0.0208415" />
                            <site name="FPL-P7" pos="0.0163719 -0.0261491 -0.0221584" />
                            <site name="FPL-P8" pos="0.0245129 -0.0328635 -0.022318" />
                            <site name="FPL-P9" pos="0.0282043 -0.0546926 -0.030479" />
                            <site name="FPL-P10" pos="0.0350284 -0.0650386 -0.0374029" />
                            <site name="FPL-P11" pos="0.0352479 -0.0763821 -0.0410843" />
                            <site name="FPL-P5" pos="0.0178892 0.0064176 -0.0168214" />
                            <site name="APL-P7" pos="0.0258099 0.00204524 -0.0164617" />
                            <site name="APL-P8" pos="0.0287131 -0.00672434 -0.0186566" />
                            <site name="APL-P9" pos="0.0306885 -0.0157932 -0.0188062" />
                            <site name="APL-P6" pos="0.0332244 0.00608975 -0.00870125" />
                            <body name="index0" pos="0 0 0">
                              <inertial pos="0 0 0" mass="0.001" diaginertia="0.001 0.001 0.001" />
                              <geom name="sdfast_1seg_hand_fr_c_2mc" type="mesh" mesh="sdfast_1seg_hand_fr_c_2mc" />
                              <body name="index1" pos="0 0 0">
                                <inertial pos="0 0 0" mass="0.001" diaginertia="0.001 0.001 0.001" />
                                <geom name="hand_2proxph" type="mesh" mesh="hand_2proxph" />
                                <body name="index2" pos="0 0 0">
                                  <inertial pos="0 0 0" mass="0.001" diaginertia="0.001 0.001 0.001" />
                                  <geom name="hand_2midph" type="mesh" mesh="hand_2midph" />
                                  <body name="index3" pos="0 0 0">
                                    <inertial pos="0 0 0" mass="0.001" diaginertia="0.001 0.001 0.001" />
                                    <geom name="hand_2distph" type="mesh" mesh="hand_2distph" />
                                    <site name="fingertip" pos="0.024 -0.149 -0.0065" type="sphere" rgba="0.1 0.8 0.1 0.0" size="0.004" />
                                  </body>
                                </body>
                              </body>
                            </body>
                          </body>
                        </body>
                      </body>
                    </body>
                  </body>
                </body>
              </body>
            </body>
          </body>
        </body>
      </body>
    </body>

</mujocoinclude>