<mujocoinclude model="MoBL Arms Index Model">

    <body name="thorax" pos="0 0 0" quat="0.7071067811865475 0.7071067811865475 0.0 0.0">
      <light mode="trackcom" directional="false" pos="0 0 4.0" dir="0 0 -1" />
      <geom name="thorax" type="mesh" mesh="thorax" />
      <site name="PECM1-P3" pos="  -7e-05  0.00821  0.10454" />
      <site name="PECM2-P4" pos="0.0292424 -0.0371041 0.0918142" />
      <site name="PECM2-P5" pos="0.0261961 -0.0425534 0.0214848" />
      <site name="PECM2-P3" pos=" 0.02083 -0.02005  0.11555" />
      <site name="PECM3-P4" pos="0.0496677 -0.0796291 0.0845296" />
      <site name="PECM3-P5" pos="0.0541519 -0.110253 0.0358269" />
      <site name="PECM3-P3" pos=" 0.02984 -0.0544459   0.1151" />
      <site name="LAT1-P4" pos="-0.111899 -0.0957214 0.031371" />
      <site name="LAT1-P5" pos="-0.0906127 -0.110915 0.00834417" />
      <site name="LAT2-P4" pos="-0.10399 -0.159958 0.0272273" />
      <site name="LAT2-P5" pos="-0.0679832 -0.178028 0.00771031" />
      <site name="LAT3-P4" pos="-0.105551 -0.183411 0.0523355" />
      <site name="LAT3-P5" pos="-0.0673304 -0.235169 0.00858068" />
      <joint name="r_z" type="hinge" pos="0 0 0" axis="       0        0        1" limited="true" range="-6.28319  6.28319" ref="0" armature="0" damping="0" stiffness="0" />
      <body name="clavicle" pos="0.00598377 0.00655613 0.0240912" quat="1.0 0.0 0.0 0.0">
        <geom name="clavicle" type="mesh" mesh="clavicle" />
        <inertial pos="-0.0104974 0.00602852 0.0512457" mass="0.147583892611147" fullinertia="0.000205407 0.000216135 3.76116e-05 -1.60709e-05 -5.922e-05 4.54777e-05" />
        <site name="DELT1-P4" pos="-0.0132447 0.0104633 0.0758827" />
        <site name="DELT2-P2" pos="0.0191703 0.0244002 0.162891" />
        <site name="PECM1-P4" pos="0.00303682 -0.000122987 0.0483716" />
        <joint name="sternoclavicular_r2" type="hinge" pos="0 0 0" axis="  0.0153 0.989299  -0.1451" limited="false" range="-99999.9  99999.9" ref="0" />
        <joint name="sternoclavicular_r3" type="hinge" pos="0 0 0" axis="-0.994473        0 -0.104997" limited="false" range="-99999.9  99999.9" ref="0" />
        <body name="clavphant" pos="-0.0135569 0.0189872 0.128223" quat="1.0 0.0 0.0 0.0">
          <inertial pos="       0        0        0" mass="9.46050593661197e-05" fullinertia="0.846726 0.846726 0.846726        0        0        0" />
          <joint name="unrotscap_r3" type="hinge" pos="0 0 0" axis="-0.994473        0 -0.104997" limited="false" range="-99999.9  99999.9" ref="0" />
          <joint name="unrotscap_r2" type="hinge" pos="0 0 0" axis="  0.0153 0.989299  -0.1451" limited="false" range="-99999.9  99999.9" ref="0" />
          <body name="scapula" pos="       0        0        0" quat="1.0 0.0 0.0 0.0">
            <geom name="scapula" type="mesh" mesh="scapula" />
            <inertial pos="-0.0517433 -0.033142 -0.0413746" mass="0.665981775913736" fullinertia="0.0010524 0.000974074 0.00115587 0.000380519 0.000346497 0.000204146" />
            <site name="DELT1-P3" pos="0.0411248 -0.0307656 0.00093659" />
            <site name="DELT2-P3" pos="4.73025e-005 0.00278139 0.0211253" />
            <site name="DELT2-P4" pos="-0.0101984 -0.000321657 0.00586551" />
            <site name="DELT3-P1" pos="-0.0527234 0.00115418 -0.0237648" />
            <site name="DELT3-P2" pos="-0.0685603 -0.0310778 0.0116648" />
            <site name="SUPSP-P2" pos="-0.0181453 0.00120148 -0.0120243" />
            <site name="SUPSP-P3" pos="-0.0416262 -0.0143043 -0.0553913" />
            <site name="INFSP-P2" pos="-0.0698375 -0.0518057 -0.0452307" />
            <site name="SUBSC-P2" pos="-0.0173222 -0.0494122 -0.0232445" />
            <site name="SUBSC-P3" pos="-0.0685508 -0.0373028 -0.0612568" />
            <site name="TMIN-P2" pos="-0.0896194 -0.0755989 -0.0448144" />
            <site name="TMIN-P3" pos="-0.0912277 -0.0768288 -0.0501218" />
            <site name="TMAJ-P2" pos="-0.0971026 -0.097623 -0.0551453" />
            <site name="TMAJ-P3" pos="-0.0992312 -0.103072 -0.0673304" />
            <site name="LAT1-P2" pos="-0.08052 -0.06821 -0.02908" />
            <site name="LAT1-P3" pos="-0.10925 -0.07239 -0.07422" />
            <site name="LAT2-P2" pos="-0.08345 -0.08695 -0.02453" />
            <site name="LAT2-P3" pos="-0.11524 -0.10749 -0.08863" />
            <site name="LAT3-P2" pos="-0.08438 -0.11598 -0.02995" />
            <site name="LAT3-P3" pos="-0.11279 -0.13833 -0.08911" />
            <site name="CORB-P1" pos="0.0118256 -0.0390435 -0.0250893" />
            <site name="CORB-P2" pos="0.00456942 -0.0658262 -0.0147868" />
            <site name="TRIlong-P1" pos="-0.0431872 -0.0385326 -0.0130271" />
            <site name="BIClong-P1" pos="-0.0295452 -0.0222606 -0.012346" />
            <site name="BIClong-P2" pos="-0.0198103 -0.0123838 -0.00436129" />
            <site name="BICshort-P1" pos="0.0119959 -0.0371892 -0.0248338" />
            <site name="BICshort-P2" pos="0.000879827 -0.0634232 -0.0150706" />
            <joint name="acromioclavicular_r2" type="hinge" pos="0 0 0" axis="0.157095 0.947269 -0.279291" limited="false" range="-99999.9  99999.9" ref="0" />
            <joint name="acromioclavicular_r3" type="hinge" pos="0 0 0" axis="-0.754084 0.297594 0.585487" limited="false" range="-99999.9  99999.9" ref="0" />
            <joint name="acromioclavicular_r1" type="hinge" pos="0 0 0" axis="  0.6377   0.1186   0.7611" limited="false" range="-99999.9  99999.9" ref="0" />
            <body name="scapphant" pos="-0.00903478 -0.0321657 0.00851446" quat="1.0 0.0 0.0 0.0">
              <inertial pos="       0        0        0" mass="9.46050593661197e-05" fullinertia="0.846726 0.846726 0.846726        0        0        0" />
              <joint name="unrothum_r1" type="hinge" pos="0 0 0" axis="  0.6377   0.1186   0.7611" limited="false" range="-99999.9  99999.9" ref="0" />
              <joint name="unrothum_r3" type="hinge" pos="0 0 0" axis="-0.754084 0.297594 0.585487" limited="false" range="-99999.9  99999.9" ref="0" />
              <joint name="unrothum_r2" type="hinge" pos="0 0 0" axis="0.157095 0.947269 -0.279291" limited="false" range="-99999.9  99999.9" ref="0" />
              <body name="humphant" pos="       0        0        0" quat="1.0 0.0 0.0 0.0">
                <inertial pos="       0        0        0" mass="9.46050593661197e-05" fullinertia="0.846726 0.846726 0.846726        0        0        0" />
                <joint name="elv_angle" type="hinge" pos="0 0 0" axis="  0.0048 0.999089   0.0424" limited="true" range=" -1.5708  2.26893" ref="0" user="1" />
                <body name="humphant1" pos="       0        0        0" quat="1.0 0.0 0.0 0.0">
                  <inertial pos="       0        0        0" mass="9.46050593661197e-05" fullinertia="0.846726 0.846726 0.846726        0        0        0" />
                  <joint name="shoulder_elv" type="hinge" pos="0 0 0" axis="-0.998261   0.0023 0.058898" limited="true" range="       0  3.14159" ref="0" user="1" />
                  <joint name="shoulder1_r2" type="hinge" pos="0 0 0" axis="  0.0048 0.999089   0.0424" limited="false" range="-99999.9  99999.9" ref="0" />
                  <body name="humerus" pos="       0        0        0" quat="1.0 0.0 0.0 0.0">
                    <geom name="humerus" type="mesh" mesh="humerus" />
                    <inertial pos="0.0170895 -0.13258 -0.0120584" mass="1.8898022843798" fullinertia="0.0103958 0.00216028 0.0106509 -0.000294161 -0.000196864 0.00104088" />
                    <site name="DELT1-P1" pos="0.00847661 -0.112419 0.0055344" />
                    <site name="DELT1-P2" pos="0.0153544 -0.104378 0.00389773" />
                    <site name="DELT2-P1" pos="0.00436129 -0.128767 0.00529788" />
                    <site name="DELT3-P3" pos="0.00194886 -0.0719188 0.00988623" />
                    <site name="SUPSP-P1" pos="0.00242189 0.0100565 0.0245311" />
                    <site name="INFSP-P1" pos="-0.00839147 0.00457888 0.0231593" />
                    <site name="SUBSC-P1" pos="0.0132731 0.00794682 -0.0125919" />
                    <site name="TMIN-P1" pos="-0.00104066 -0.0119581 0.0203969" />
                    <site name="TMAJ-P1" pos="0.00944158 -0.0512665 -0.00537357" />
                    <site name="PECM1-P1" pos="0.0110593 -0.039649 0.00737919" />
                    <site name="PECM1-P2" pos="  0.0191  -0.0301  0.00143" />
                    <site name="PECM2-P1" pos="0.0120527 -0.0405761 0.0074265" />
                    <site name="PECM2-P2" pos=" 0.01748 -0.03533  0.00033" />
                    <site name="PECM3-P1" pos="0.0120054 -0.0413897 0.00709538" />
                    <site name="PECM3-P2" pos="0.0159185 -0.045833 -0.00378312" />
                    <site name="LAT1-P1" pos="0.00993353 -0.0323076 -0.00617771" />
                    <site name="LAT2-P1" pos="0.00915777 -0.0385137 -0.00578037" />
                    <site name="LAT3-P1" pos="0.0114283 -0.0371041 -0.00393557" />
                    <site name="CORB-P3" pos="0.00702916 -0.142362 -0.00739812" />
                    <site name="TRIlong-P2" pos="-0.0256758 -0.108238 -0.00628178" />
                    <site name="TRIlong-P3" pos="-0.0301223 -0.214157 -0.0115134" />
                    <site name="TRIlong-P4" pos="-0.0164897 -0.253135 -0.0114283" />
                    <site name="TRIlat-P1" pos="-0.00566684 -0.119638 0.0040491" />
                    <site name="TRIlat-P2" pos="-0.0221754 -0.137442 0.00877935" />
                    <site name="TRIlat-P3" pos="-0.0301223 -0.214157 -0.0115134" />
                    <site name="TRIlat-P4" pos="-0.0164897 -0.253135 -0.0114283" />
                    <site name="TRImed-P1" pos="-0.0079279 -0.129562 -0.00857122" />
                    <site name="TRImed-P2" pos="-0.0246068 -0.143223 -0.0102173" />
                    <site name="TRImed-P3" pos="-0.0301223 -0.214157 -0.0115134" />
                    <site name="TRImed-P4" pos="-0.0164897 -0.253135 -0.0114283" />
                    <site name="ANC-P1" pos="-0.00703862 -0.26829 0.00926184" />
                    <site name="BIClong-P3" pos="0.0201603 0.0169627 0.0097254" />
                    <site name="BIClong-P4" pos="0.0224971 -0.00483432 0.0113621" />
                    <site name="BIClong-P5" pos="0.0127244 -0.0267449 0.00128663" />
                    <site name="BIClong-P6" pos="0.0101038 -0.0731865 -0.00156098" />
                    <site name="BIClong-P7" pos="0.0161112 -0.114709 0.000227052" />
                    <site name="BIClong-P8" pos="0.02157 -0.165937 -0.00596012" />
                    <site name="BICshort-P3" pos="0.0105674 -0.0716728 -0.010416" />
                    <site name="BICshort-P4" pos="0.0161112 -0.114709 -0.0102079" />
                    <site name="BICshort-P5" pos="0.02157 -0.165937 -0.00596012" />
                    <site name="BRA-P1" pos="0.00643314 -0.164518 -0.00340578" />
                    <site name="BRA-P2" pos="0.0179182 -0.270183 -0.0104539" />
                    <site name="BRD-P1" pos="-0.0092713 -0.18886 0.00210969" />
                    <site name="ECRL-P1" pos="-0.00690617 -0.246825 0.00860906" />
                    <site name="ECRB-P1" pos="0.0127622 -0.274809 0.0160639" />
                    <site name="ECU-P1" pos="0.000785222 -0.273929 0.0177858" />
                    <site name="FCR-P1" pos="0.00717106 -0.263059 -0.0350512" />
                    <site name="FCU-P1" pos="0.00207185 -0.262434 -0.0367068" />
                    <site name="PL-P1" pos="0.00432345 -0.260344 -0.0365649" />
                    <site name="PT-P1" pos="0.00340578 -0.261015 -0.0345308" />
                    <site name="FDSL-P1" pos="0.00398287 -0.261091 -0.0365554" />
                    <site name="FDSR-P1" pos="0.00453158 -0.263759 -0.0352971" />
                    <site name="EDCL-P1" pos="-0.00037842 -0.272756 0.0176911" />
                    <site name="EDCR-P1" pos="-0.00147584 -0.273749 0.0168586" />
                    <site name="EDCM-P1" pos="0.000482486 -0.274203 0.0184385" />
                    <site name="EDCI-P1" pos="0.000614933 -0.27339 0.0176817" />
                    <site name="EDM-P1" pos="0.000841985 -0.273588 0.0174736" />
                    <joint name="shoulder_rot" type="hinge" pos="0 0 0" axis="  0.0048 0.999089   0.0424" limited="true" range=" -1.5708 0.349066" ref="0" user="1" />
                    <body name="ulna" pos="0.00577091 -0.274733 -0.0116364" quat="1.0 0.0 0.0 0.0">
                      <geom name="ulna" type="mesh" mesh="ulna" />
                      <inertial pos="0.00919356 -0.0907744 0.0229758" mass="1.04566972117372" fullinertia="0.00458341 0.000976428 0.00418588 0.000268294 -6.44782e-05 0.000924363" />
                      <site name="TRIlong-P5" pos="-0.0207185 0.00989569 -0.000737919" />
                      <site name="TRIlat-P5" pos="-0.0207185 0.00989569 -0.000737919" />
                      <site name="TRImed-P5" pos="-0.0207185 0.00989569 -0.000737919" />
                      <site name="ANC-P2" pos="-0.023954 -0.0011731 0.0056763" />
                      <site name="SUP-P3" pos="-0.0128663 -0.0320144 0.019044" />
                      <site name="BRA-P4" pos="-0.00302736 -0.0226106 0.000851446" />
                      <site name="BRA-P3" pos="0.00471133 -0.0138407 0.00121094" />
                      <site name="ECU-P2" pos="-0.0131596 -0.0302831 0.0278801" />
                      <site name="ECU-P3" pos="-0.0161302 -0.0513516 0.0271327" />
                      <site name="ECU-P4" pos="-0.0169627 -0.0905654 0.0310115" />
                      <site name="PT-P2" pos="0.00800359 -0.0319103 -0.0135474" />
                      <site name="PT-P3" pos=" 0.01219 -0.06516 -0.00219" />
                      <site name="PQ-P2" pos="0.00182588 -0.198406 0.0343606" />
                      <site name="FDSM-P1" pos="-0.00632908 -0.0256664 -0.00180696" />
                      <site name="FDSI-P1" pos="-0.0063953 -0.0266692 -0.00129609" />
                      <site name="FDPL-P1" pos="-0.0059412 -0.0304061 0.00240297" />
                      <site name="FDPR-P1" pos="-0.00474917 -0.0319197 0.00258272" />
                      <site name="FDPM-P1" pos="-0.00493838 -0.0314751 0.00198671" />
                      <site name="FDPI-P1" pos="-0.00612095 -0.0300466 0.00264894" />
                      <site name="EDM-P2" pos="-0.00924291 -0.0369622 0.0291857" />
                      <site name="EDM-P3" pos="-0.00714268 -0.07821 0.034493" />
                      <site name="EIP-P1" pos="-0.00372744 -0.157536 0.0348336" />
                      <site name="EIP-P2" pos="0.00161775 -0.165266 0.0383056" />
                      <site name="EPL-P1" pos="-0.0133582 -0.0918237 0.0279274" />
                      <joint name="elbow_flexion" type="hinge" pos="0 0 0" axis="  0.0494   0.0366 0.998108" limited="true" range="       0  4.26893" ref="0" user="1" />
                      <body name="radius" pos="0.00037842 -0.0108824 0.0189201" quat="1.0 0.0 0.0 0.0">
                        <geom name="radius" type="mesh" mesh="radius" />
                        <inertial pos="0.0318196 -0.171764 0.0147584" mass="0.220987958173319" fullinertia="0.000371332 7.50115e-05 0.000340875 2.55203e-05 -3.59012e-06 5.43429e-05" />
                        <site name="SUP-P1" pos="0.00942266 -0.0576712 0.000709538" />
                        <site name="SUP-P2" pos="0.0113621 -0.0489108 -0.00101227" />
                        <site name="BIClong-P11" pos="-0.0018921 -0.0354769 -0.0018921" />
                        <site name="BIClong-P9" pos=" 0.00273 -0.0343493 -0.0119845" />
                        <site name="BICshort-P8" pos="-0.0018921 -0.0354769 -0.0018921" />
                        <site name="BICshort-P6" pos=" 0.00273 -0.0343493 -0.0119845" />
                        <site name="BRD-P2" pos="0.0338402 -0.120546 0.0219011" />
                        <site name="BRD-P3" pos="0.0396395 -0.209077 0.0211915" />
                        <site name="ECRL-P2" pos="0.0302263 -0.127367 0.0262907" />
                        <site name="ECRL-P3" pos="0.0401409 -0.224063 0.034247" />
                        <site name="ECRB-P2" pos="0.0274828 -0.1238 0.0225633" />
                        <site name="ECRB-P3" pos="0.0335753 -0.215747 0.037246" />
                        <site name="ECU-P5" pos="-0.0134434 -0.214716 0.032932" />
                        <site name="FCR-P2" pos="0.0199617 -0.207592 0.00120148" />
                        <site name="FCU-P3" pos="0.0102363 -0.211225 0.00916723" />
                        <site name="FCU-P2" pos="0.0101156 -0.183524 0.00202653" />
                        <site name="PL-P2" pos="0.0239445 -0.226248 -0.0026111" />
                        <site name="PT-P5" pos="0.0240297 -0.10293 0.0187318" />
                        <site name="PT-P4" pos="0.0223268 -0.0883611 0.00889288" />
                        <site name="PQ-P1" pos="0.0306993 -0.189191 0.0185615" />
                        <site name="FDSL-P2" pos="0.0130271 -0.177082 0.0019394" />
                        <site name="FDSR-P2" pos="0.0148625 -0.17659 0.00252596" />
                        <site name="FDSM-P2" pos="0.0179655 -0.176968 0.00401125" />
                        <site name="FDSI-P2" pos="0.0202928 -0.176183 0.0052222" />
                        <site name="FDPL-P2" pos="0.0133299 -0.175171 0.0081455" />
                        <site name="FDPR-P2" pos="0.0149476 -0.17624 0.00759679" />
                        <site name="FDPM-P2" pos="0.0180317 -0.176382 0.0074265" />
                        <site name="FDPI-P2" pos="0.0196779 -0.175587 0.00865636" />
                        <site name="EDCL-P3" pos="0.00939428 -0.211007 0.0342281" />
                        <site name="EDCL-P2" pos="  0.0013 -0.0382544 0.0129514" />
                        <site name="EDCR-P3" pos="0.00834417 -0.211594 0.0405288" />
                        <site name="EDCR-P2" pos="  0.0026 -0.0392844 0.0144214" />
                        <site name="EDCM-P3" pos="0.0136231 -0.211187 0.0399517" />
                        <site name="EDCM-P2" pos=" 0.00316 -0.0388544 0.0141814" />
                        <site name="EDCI-P3" pos="0.014503 -0.211102 0.0396963" />
                        <site name="EDCI-P2" pos=" 0.00228 -0.0385544 0.0137314" />
                        <site name="EDM-P4" pos="0.00429507 -0.214195 0.0347957" />
                        <site name="EIP-P3" pos="0.0101795 -0.215539 0.0346633" />
                        <site name="EPL-P2" pos="0.0011731 -0.129306 0.0214753" />
                        <site name="EPL-P3" pos="0.0255623 -0.20692 0.0362148" />
                        <site name="EPL-P4" pos="0.0319954 -0.215264 0.0435846" />
                        <site name="EPL-P5" pos="0.0400558 -0.224886 0.0394787" />
                        <site name="EPB-P1" pos="0.018202 -0.139022 0.0199995" />
                        <site name="EPB-P2" pos="0.0215321 -0.150015 0.0252122" />
                        <site name="EPB-P3" pos="0.0362432 -0.18658 0.0362716" />
                        <site name="EPB-P4" pos="0.0495257 -0.223372 0.0255339" />
                        <site name="FPL-P1" pos="0.00918615 -0.0894775 0.0167356" />
                        <site name="FPL-P2" pos="0.0156855 -0.127953 0.0181169" />
                        <site name="FPL-P3" pos="0.0176817 -0.169646 0.0188075" />
                        <site name="FPL-P4" pos="0.0359499 -0.219209 0.0149476" />
                        <site name="APL-P1" pos="0.0109174 -0.0896572 0.0159031" />
                        <site name="APL-P2" pos="0.0286653 -0.132163 0.033178" />
                        <site name="APL-P3" pos="0.0377758 -0.152049 0.0321657" />
                        <site name="APL-P4" pos="0.0415978 -0.168823 0.0296492" />
                        <site name="APL-P5" pos="0.0520801 -0.218386 0.0224025" />
                        <joint name="pro_sup" type="hinge" pos="0 0 0" axis="-0.017161 0.992666 -0.119668" limited="true" range=" -1.5708   1.5708" ref="0" user="1" />
                        <body name="proximal_row" pos="0.0170289 -0.228944 0.0236513" quat="1.0 0.0 0.0 0.0">
                          <geom name="lunate" type="mesh" mesh="lunate" />
                          <geom name="sdfastSCAPHOIDw" type="mesh" mesh="sdfastSCAPHOIDw" />
                          <geom name="sdfastPISIFORMw" type="mesh" mesh="sdfastPISIFORMw" />
                          <geom name="sdfastTRIQUETRALw" type="mesh" mesh="sdfastTRIQUETRALw" />
                          <inertial pos="       0        0        0" mass="9.46050593661197e-05" fullinertia="8.46726e-06 8.46726e-06 8.46726e-06        0        0        0" />
                          <body name="hand" pos="0.00377663 -0.0142418 0.00220146" quat="1.0 0.0 0.0 0.0">
                            <geom name="sdfast_1seg_hand_fr_c_5mc" type="mesh" mesh="sdfast_1seg_hand_fr_c_5mc" />
                            <geom name="sdfast_1seg_hand_fr_c_4mc" type="mesh" mesh="sdfast_1seg_hand_fr_c_4mc" />
                            <geom name="sdfast_1seg_hand_fr_c_3mc" type="mesh" mesh="sdfast_1seg_hand_fr_c_3mc" />
                            <geom name="sdfast_1seg_hand_fr_c_trapezium" type="mesh" mesh="sdfast_1seg_hand_fr_c_trapezium" />
                            <geom name="sdfast_1seg_hand_fr_c_trapezoid" type="mesh" mesh="sdfast_1seg_hand_fr_c_trapezoid" />
                            <geom name="sdfast_1seg_hand_fr_c_hamate" type="mesh" mesh="sdfast_1seg_hand_fr_c_hamate" />
                            <geom name="capitate" type="mesh" mesh="capitate" />
                            <geom name="hand_3proxph" type="mesh" mesh="hand_3proxph" />
                            <geom name="hand_3midph" type="mesh" mesh="hand_3midph" />
                            <geom name="hand_3distph" type="mesh" mesh="hand_3distph" />
                            <geom name="hand_4proxph" type="mesh" mesh="hand_4proxph" />
                            <geom name="hand_4midph" type="mesh" mesh="hand_4midph" />
                            <geom name="hand_4distph" type="mesh" mesh="hand_4distph" />
                            <geom name="hand_5proxph" type="mesh" mesh="hand_5proxph" />
                            <geom name="hand_5midph" type="mesh" mesh="hand_5midph" />
                            <geom name="hand_5distph" type="mesh" mesh="hand_5distph" />
                            <geom name="hand_thumbprox" type="mesh" mesh="hand_thumbprox" />
                            <geom name="hand_thumbdist" type="mesh" mesh="hand_thumbdist" />
                            <geom name="hand_1mc" type="mesh" mesh="hand_1mc" />
                            <inertial pos="-0.00285058 -0.0402065 -0.00106152" mass="0.55050684045145" fullinertia="9.31399e-05 5.08036e-05 0.000127009 7.62054e-07 -1.69345e-07 1.01607e-05" />
                            <site name="ECRL-P4" pos="0.0162437 -0.0200752 0.00551547" />
                            <site name="ECRB-P4" pos="0.00473025 -0.0107471 0.00804143" />
                            <site name="ECU-P6" pos="-0.0212956 -0.0132542 -0.00121094" />
                            <site name="FCR-P3" pos="0.0106336 -0.0174452 -0.00395449" />
                            <site name="FCU-P4" pos="-0.0192616 -0.0166978 -0.0071143" />
                            <site name="PL-P3" pos="0.00867528 -0.017956 -0.0165937" />
                            <site name="PL-P4" pos="0.00214753 -0.0292897 0.00466403" />
                            <site name="FDSL-P3" pos="-0.00222322 -0.0131785 -0.0130177" />
                            <site name="FDSL-P4" pos="-0.0188737 -0.0405004 -0.0070197" />
                            <site name="FDSL-P5" pos="-0.0193373 -0.0565833 -0.0177668" />
                            <site name="FDSL-P6" pos="-0.0162058 -0.0685414 -0.0260448" />
                            <site name="FDSL-P7" pos="-0.0109363 -0.0687873 -0.0345876" />
                            <site name="FDSL-P8" pos="-0.0100187 -0.0687873 -0.0359121" />
                            <site name="FDSR-P3" pos="-0.000775761 -0.0127149 -0.0128568" />
                            <site name="FDSR-P4" pos="-0.00924291 -0.048996 3.7842e-005" />
                            <site name="FDSR-P5" pos="-0.0125162 -0.0631016 -0.00964972" />
                            <site name="FDSR-P6" pos="-0.00745488 -0.0759395 -0.0236796" />
                            <site name="FDSR-P7" pos="-0.00282869 -0.0768666 -0.0321184" />
                            <site name="FDSR-P8" pos="0.000586551 -0.0765544 -0.0368203" />
                            <site name="FDSM-P3" pos="0.00643314 -0.0130271 -0.0132352" />
                            <site name="FDSM-P4" pos="0.0044559 -0.0315224 -0.00124879" />
                            <site name="FDSM-P5" pos="0.00512759 -0.0535465 0.00056763" />
                            <site name="FDSM-P6" pos="0.00525058 -0.0683427 -0.00319765" />
                            <site name="FDSM-P7" pos="0.0110404 -0.0833471 -0.015799" />
                            <site name="FDSM-P8" pos="0.0123081 -0.0839147 -0.0281639" />
                            <site name="FDSM-P9" pos="0.0148341 -0.0811428 -0.0356188" />
                            <site name="FDSI-P3" pos="0.00841039 -0.0129231 -0.0131217" />
                            <site name="FDSI-P4" pos="0.0100376 -0.0358269 0.000227052" />
                            <site name="FDSI-P5" pos="0.0168586 -0.0483243 0.00395449" />
                            <site name="FDSI-P6" pos="0.0174925 -0.0690333 -0.00354769" />
                            <site name="FDSI-P7" pos="0.0253352 -0.0824388 -0.0170668" />
                            <site name="FDSI-P8" pos="0.0252312 -0.0826848 -0.0253352" />
                            <site name="FDSI-P9" pos="0.0251649 -0.0816725 -0.0274638" />
                            <site name="FDPL-P3" pos="-0.000832525 -0.00971594 -0.0112391" />
                            <site name="FDPL-P4" pos="-0.0175492 -0.0439535 -0.00693455" />
                            <site name="FDPL-P5" pos="-0.0171046 -0.0552588 -0.0147584" />
                            <site name="FDPL-P6" pos="-0.0135096 -0.0689576 -0.0253825" />
                            <site name="FDPL-P7" pos="-0.00870367 -0.070793 -0.0348525" />
                            <site name="FDPL-P8" pos="-0.00295168 -0.070055 -0.039403" />
                            <site name="FDPL-P9" pos="0.00421939 -0.0667817 -0.0440576" />
                            <site name="FDPR-P3" pos="0.00100281 -0.011135 -0.0112012" />
                            <site name="FDPR-P4" pos="-0.00808873 -0.0524301 0.000832525" />
                            <site name="FDPR-P5" pos="-0.0102079 -0.0623258 -0.00772923" />
                            <site name="FDPR-P6" pos="-0.0051749 -0.077141 -0.0213429" />
                            <site name="FDPR-P7" pos="-0.000529788 -0.07786 -0.0318535" />
                            <site name="FDPR-P8" pos="0.00576145 -0.074142 -0.0400936" />
                            <site name="FDPR-P9" pos="0.0114567 -0.0698185 -0.0459591" />
                            <site name="FDPM-P3" pos="0.00316927 -0.0121094 -0.0108228" />
                            <site name="FDPM-P4" pos="0.00285707 -0.0326104 -0.00578037" />
                            <site name="FDPM-P5" pos="0.00238405 -0.0554669 0.00115418" />
                            <site name="FDPM-P6" pos="0.00269624 -0.0660816 -0.00125825" />
                            <site name="FDPM-P7" pos="0.00816442 -0.0830538 -0.0171708" />
                            <site name="FDPM-P8" pos="0.00947943 -0.0829308 -0.0280409" />
                            <site name="FDPM-P9" pos="0.015449 -0.0771693 -0.0419573" />
                            <site name="FDPM-P10" pos="0.0180601 -0.0724959 -0.049469" />
                            <site name="FDPI-P3" pos="0.00847661 -0.0110499 -0.0114661" />
                            <site name="FDPI-P4" pos="0.0181831 -0.0524301 0.0041437" />
                            <site name="FDPI-P5" pos="0.0196116 -0.0664222 -0.0027057" />
                            <site name="FDPI-P6" pos="0.0274733 -0.0812468 -0.0168586" />
                            <site name="FDPI-P7" pos="0.0276625 -0.0820415 -0.0261961" />
                            <site name="FDPI-P8" pos="0.0275679 -0.0779073 -0.0376434" />
                            <site name="FDPI-P9" pos="0.0269341 -0.0735176 -0.0450888" />
                            <site name="EDCL-P4" pos="-0.0233107 -0.0416451 0.00159883" />
                            <site name="EDCL-P5" pos="-0.0225255 -0.044786 0.000728459" />
                            <site name="EDCL-P6" pos="-0.0226579 -0.0625623 -0.00946997" />
                            <site name="EDCL-P7" pos="-0.01701 -0.0742366 -0.0256474" />
                            <site name="EDCL-P8" pos="-0.0111445 -0.0745204 -0.0357513" />
                            <site name="EDCL-P9" pos="-0.00141908 -0.0717674 -0.0433859" />
                            <site name="EDCL-P10" pos="0.00190156 -0.0708308 -0.0453537" />
                            <site name="EDCR-P4" pos="-0.0147962 -0.0525058 0.00883611" />
                            <site name="EDCR-P5" pos="-0.0135001 -0.0550507 0.0109836" />
                            <site name="EDCR-P6" pos="-0.0149476 -0.068267 -0.00398287" />
                            <site name="EDCR-P7" pos="-0.00780492 -0.0826375 -0.0213807" />
                            <site name="EDCR-P8" pos="-0.00257326 -0.0833092 -0.0322509" />
                            <site name="EDCR-P9" pos="0.00721837 -0.07593 -0.044067" />
                            <site name="EDCR-P10" pos="0.0101133 -0.0738771 -0.0467444" />
                            <site name="EDCM-P4" pos="0.00036896 -0.0498947 0.0141056" />
                            <site name="EDCM-P5" pos="-0.000823064 -0.0527329 0.0137367" />
                            <site name="EDCM-P6" pos="0.00175965 -0.0730162 0.00564792" />
                            <site name="EDCM-P7" pos="0.00952673 -0.0881057 -0.0167829" />
                            <site name="EDCM-P8" pos="0.0124973 -0.0904235 -0.0289113" />
                            <site name="EDCM-P9" pos="0.0175682 -0.0806508 -0.0450225" />
                            <site name="EDCM-P10" pos="0.0194508 -0.0756178 -0.0505286" />
                            <site name="EDCM-P11" pos="0.0207658 -0.0728554 -0.0535748" />
                            <site name="EDCI-P4" pos="0.0145976 -0.0442752 0.0155058" />
                            <site name="EDCI-P5" pos="0.0179466 -0.0534897 0.0136042" />
                            <site name="EDCI-P6" pos="0.0188642 -0.0726378 0.00561954" />
                            <site name="EDCI-P7" pos="0.0278612 -0.0866772 -0.0117783" />
                            <site name="EDCI-P8" pos="0.0295262 -0.0884463 -0.0274828" />
                            <site name="EDCI-P9" pos="0.0285045 -0.0802913 -0.0403774" />
                            <site name="EDCI-P10" pos="0.0277098 -0.0766585 -0.0469809" />
                            <site name="EDM-P5" pos="-0.0194792 -0.00976324 0.00351931" />
                            <site name="EDM-P6" pos="-0.0242473 -0.0446725 0.000217592" />
                            <site name="EDM-P7" pos="-0.0241148 -0.0615974 -0.0103876" />
                            <site name="EDM-P8" pos="-0.0182872 -0.0738866 -0.0257137" />
                            <site name="EDM-P9" pos="-0.0127338 -0.0746623 -0.0368392" />
                            <site name="EDM-P10" pos="-0.00204347 -0.0711525 -0.0434143" />
                            <site name="EDM-P11" pos="0.00124879 -0.0694874 -0.0454388" />
                            <site name="EIP-P4" pos="0.00367068 -0.0211348 0.0112012" />
                            <site name="EIP-P5" pos="0.0160166 -0.0533573 0.0130271" />
                            <site name="EIP-P6" pos="0.016414 -0.0727702 0.00549655" />
                            <site name="EIP-P7" pos="0.0261583 -0.0881152 -0.0142948" />
                            <site name="EIP-P8" pos="0.0272368 -0.0892788 -0.026707" />
                            <site name="EIP-P9" pos="0.0271517 -0.0806414 -0.0406329" />
                            <site name="EIP-P10" pos="0.0268111 -0.07365 -0.0520422" />
                            <site name="EPL-P6" pos="0.0229701 0.000132447 0.00575199" />
                            <site name="EPL-P7" pos="0.0221187 -0.00867528 -0.00036896" />
                            <site name="EPL-P8" pos="0.0274828 -0.0135001 -0.00462619" />
                            <site name="EPL-P9" pos="0.0417587 -0.0323265 -0.0171614" />
                            <site name="EPL-P10" pos="0.0460443 -0.0439535 -0.0235283" />
                            <site name="EPL-P11" pos="0.0449469 -0.0663181 -0.0357039" />
                            <site name="EPL-P12" pos="0.0379461 -0.0715687 -0.0405193" />
                            <site name="EPB-P5" pos="0.0295452 0.00242189 -0.00309359" />
                            <site name="EPB-P6" pos="0.0281166 -0.00751164 -0.0135853" />
                            <site name="EPB-P7" pos="0.0418344 -0.0312197 -0.0229133" />
                            <site name="EPB-P8" pos="0.0428372 -0.0452685 -0.0301412" />
                            <site name="FPL-P6" pos="0.0117689 -0.0208793 -0.019763" />
                            <site name="FPL-P7" pos="0.0155247 -0.024796 -0.0210118" />
                            <site name="FPL-P8" pos="0.0232445 -0.0311629 -0.0211632" />
                            <site name="FPL-P9" pos="0.0267449 -0.0518625 -0.0289018" />
                            <site name="FPL-P10" pos="0.0332158 -0.061673 -0.0354674" />
                            <site name="FPL-P11" pos="0.033424 -0.0724296 -0.0389584" />
                            <site name="FPL-P5" pos="0.0178892 0.0064176 -0.0168214" />
                            <site name="APL-P7" pos="0.0244743 0.0019394 -0.0156098" />
                            <site name="APL-P8" pos="0.0272273 -0.00637638 -0.0176911" />
                            <site name="APL-P9" pos="0.0291005 -0.014976 -0.0178331" />
                            <site name="APL-P6" pos="0.0332244 0.00608975 -0.00870125" />
                            <body name="index0" pos="0 0 0">
                              <inertial pos="0 0 0" mass="0.001" diaginertia="0.001 0.001 0.001" />
                              <geom name="sdfast_1seg_hand_fr_c_2mc" type="mesh" mesh="sdfast_1seg_hand_fr_c_2mc" />
                              <body name="index1" pos="0 0 0">
                                <inertial pos="0 0 0" mass="0.001" diaginertia="0.001 0.001 0.001" />
                                <geom name="hand_2proxph" type="mesh" mesh="hand_2proxph" />
                                <body name="index2" pos="0 0 0">
                                  <inertial pos="0 0 0" mass="0.001" diaginertia="0.001 0.001 0.001" />
                                  <geom name="hand_2midph" type="mesh" mesh="hand_2midph" />
                                  <body name="index3" pos="0 0 0">
                                    <inertial pos="0 0 0" mass="0.001" diaginertia="0.001 0.001 0.001" />
                                    <geom name="hand_2distph" type="mesh" mesh="hand_2distph" />
                                    <site name="fingertip" pos="0.024 -0.149 -0.0065" type="sphere" rgba="0.1 0.8 0.1 0.0" size="0.004" />
                                  </body>
                                </body>
                              </body>
                            </body>
                          </body>
                        </body>
                      </body>
                    </body>
                  </body>
                </body>
              </body>
            </body>
          </body>
        </body>
      </body>
    </body>

</mujocoinclude>