<mujocoinclude model="MoBL Arms Index Model">

    <body name="thorax" pos="0 0 0" quat="0.7071067811865475 0.7071067811865475 0.0 0.0">
      <light mode="trackcom" directional="false" pos="0 0 4.0" dir="0 0 -1" />
      <geom name="thorax" type="mesh" mesh="thorax" />
      <site name="PECM1-P3" pos="  -7e-05  0.00821  0.10454" />
      <site name="PECM2-P4" pos="0.0284445 -0.0360917 0.089309" />
      <site name="PECM2-P5" pos="0.0254814 -0.0413923 0.0208986" />
      <site name="PECM2-P3" pos=" 0.02083 -0.02005  0.11555" />
      <site name="PECM3-P4" pos="0.0483125 -0.0774564 0.0822232" />
      <site name="PECM3-P5" pos="0.0526744 -0.107244 0.0348494" />
      <site name="PECM3-P3" pos=" 0.02984 -0.0544459   0.1151" />
      <site name="LAT1-P4" pos="-0.108846 -0.0931096 0.0305151" />
      <site name="LAT1-P5" pos="-0.0881403 -0.107889 0.00811649" />
      <site name="LAT2-P4" pos="-0.101153 -0.155594 0.0264844" />
      <site name="LAT2-P5" pos="-0.0661283 -0.17317 0.00749994" />
      <site name="LAT3-P4" pos="-0.102671 -0.178406 0.0509075" />
      <site name="LAT3-P5" pos="-0.0654933 -0.228753 0.00834655" />
      <joint name="r_z" type="hinge" pos="0 0 0" axis="       0        0        1" limited="true" range="-6.28319  6.28319" ref="0" armature="0" damping="0" stiffness="0" />
      <body name="clavicle" pos="0.0058205 0.00637725 0.0234338" quat="1.0 0.0 0.0 0.0">
        <geom name="clavicle" type="mesh" mesh="clavicle" />
        <inertial pos="-0.010211 0.00586403 0.0498474" mass="0.143557046972265" fullinertia="0.000189048 0.000198922 3.46161e-05 -1.47909e-05 -5.45036e-05 4.18557e-05" />
        <site name="DELT1-P4" pos="-0.0128833 0.0101778 0.0738122" />
        <site name="DELT2-P2" pos="0.0191703 0.0244002 0.162891" />
        <site name="PECM1-P4" pos="0.00295396 -0.000119631 0.0470517" />
        <joint name="sternoclavicular_r2" type="hinge" pos="0 0 0" axis="  0.0153 0.989299  -0.1451" limited="false" range="-99999.9  99999.9" ref="0" />
        <joint name="sternoclavicular_r3" type="hinge" pos="0 0 0" axis="-0.994473        0 -0.104997" limited="false" range="-99999.9  99999.9" ref="0" />
        <body name="clavphant" pos="-0.013187 0.0184692 0.124724" quat="1.0 0.0 0.0 0.0">
          <inertial pos="       0        0        0" mass="9.20237480591443e-05" fullinertia="0.779291 0.779291 0.779291        0        0        0" />
          <joint name="unrotscap_r3" type="hinge" pos="0 0 0" axis="-0.994473        0 -0.104997" limited="false" range="-99999.9  99999.9" ref="0" />
          <joint name="unrotscap_r2" type="hinge" pos="0 0 0" axis="  0.0153 0.989299  -0.1451" limited="false" range="-99999.9  99999.9" ref="0" />
          <body name="scapula" pos="       0        0        0" quat="1.0 0.0 0.0 0.0">
            <geom name="scapula" type="mesh" mesh="scapula" />
            <inertial pos="-0.0503315 -0.0322378 -0.0402457" mass="0.647810376837152" fullinertia="0.000968581 0.000896497 0.00106381 0.000350213 0.000318902 0.000187887" />
            <site name="DELT1-P3" pos="0.0400027 -0.0299261 0.000911035" />
            <site name="DELT2-P3" pos="4.60119e-005 0.0027055 0.0205489" />
            <site name="DELT2-P4" pos="-0.00992016 -0.000312881 0.00570547" />
            <site name="DELT3-P1" pos="-0.0512848 0.00112269 -0.0231164" />
            <site name="DELT3-P2" pos="-0.0666896 -0.0302298 0.0113465" />
            <site name="SUPSP-P2" pos="-0.0176502 0.0011687 -0.0116962" />
            <site name="SUPSP-P3" pos="-0.0404904 -0.013914 -0.0538799" />
            <site name="INFSP-P2" pos="-0.0679319 -0.0503922 -0.0439966" />
            <site name="SUBSC-P2" pos="-0.0168495 -0.048064 -0.0226102" />
            <site name="SUBSC-P3" pos="-0.0666804 -0.036285 -0.0595854" />
            <site name="TMIN-P2" pos="-0.0871741 -0.0735362 -0.0435916" />
            <site name="TMIN-P3" pos="-0.0887385 -0.0747325 -0.0487542" />
            <site name="TMAJ-P2" pos="-0.0944532 -0.0949593 -0.0536406" />
            <site name="TMAJ-P3" pos="-0.0965237 -0.10026 -0.0654933" />
            <site name="LAT1-P2" pos="-0.08052 -0.06821 -0.02908" />
            <site name="LAT1-P3" pos="-0.10925 -0.07239 -0.07422" />
            <site name="LAT2-P2" pos="-0.08345 -0.08695 -0.02453" />
            <site name="LAT2-P3" pos="-0.11524 -0.10749 -0.08863" />
            <site name="LAT3-P2" pos="-0.08438 -0.11598 -0.02995" />
            <site name="LAT3-P3" pos="-0.11279 -0.13833 -0.08911" />
            <site name="CORB-P1" pos="0.011503 -0.0379782 -0.0244047" />
            <site name="CORB-P2" pos="0.00444475 -0.0640301 -0.0143833" />
            <site name="TRIlong-P1" pos="-0.0420088 -0.0374813 -0.0126717" />
            <site name="BIClong-P1" pos="-0.028739 -0.0216532 -0.0120091" />
            <site name="BIClong-P2" pos="-0.0192698 -0.0120459 -0.00424229" />
            <site name="BICshort-P1" pos="0.0116686 -0.0361745 -0.0241562" />
            <site name="BICshort-P2" pos="0.000855821 -0.0616927 -0.0146594" />
            <joint name="acromioclavicular_r2" type="hinge" pos="0 0 0" axis="0.157095 0.947269 -0.279291" limited="false" range="-99999.9  99999.9" ref="0" />
            <joint name="acromioclavicular_r3" type="hinge" pos="0 0 0" axis="-0.754084 0.297594 0.585487" limited="false" range="-99999.9  99999.9" ref="0" />
            <joint name="acromioclavicular_r1" type="hinge" pos="0 0 0" axis="  0.6377   0.1186   0.7611" limited="false" range="-99999.9  99999.9" ref="0" />
            <body name="scapphant" pos="-0.00878827 -0.0312881 0.00828214" quat="1.0 0.0 0.0 0.0">
              <inertial pos="       0        0        0" mass="9.20237480591443e-05" fullinertia="0.779291 0.779291 0.779291        0        0        0" />
              <joint name="unrothum_r1" type="hinge" pos="0 0 0" axis="  0.6377   0.1186   0.7611" limited="false" range="-99999.9  99999.9" ref="0" />
              <joint name="unrothum_r3" type="hinge" pos="0 0 0" axis="-0.754084 0.297594 0.585487" limited="false" range="-99999.9  99999.9" ref="0" />
              <joint name="unrothum_r2" type="hinge" pos="0 0 0" axis="0.157095 0.947269 -0.279291" limited="false" range="-99999.9  99999.9" ref="0" />
              <body name="humphant" pos="       0        0        0" quat="1.0 0.0 0.0 0.0">
                <inertial pos="       0        0        0" mass="9.20237480591443e-05" fullinertia="0.779291 0.779291 0.779291        0        0        0" />
                <joint name="elv_angle" type="hinge" pos="0 0 0" axis="  0.0048 0.999089   0.0424" limited="true" range=" -1.5708  2.26893" ref="0" user="1" />
                <body name="humphant1" pos="       0        0        0" quat="1.0 0.0 0.0 0.0">
                  <inertial pos="       0        0        0" mass="9.20237480591443e-05" fullinertia="0.779291 0.779291 0.779291        0        0        0" />
                  <joint name="shoulder_elv" type="hinge" pos="0 0 0" axis="-0.998261   0.0023 0.058898" limited="true" range="       0  3.14159" ref="0" user="1" />
                  <joint name="shoulder1_r2" type="hinge" pos="0 0 0" axis="  0.0048 0.999089   0.0424" limited="false" range="-99999.9  99999.9" ref="0" />
                  <body name="humerus" pos="       0        0        0" quat="1.0 0.0 0.0 0.0">
                    <geom name="humerus" type="mesh" mesh="humerus" />
                    <inertial pos="0.0166232 -0.128963 -0.0117293" mass="1.83823878410505" fullinertia="0.00956785 0.00198823 0.00980261 -0.000270734 -0.000181185 0.000957983" />
                    <site name="DELT1-P1" pos="0.00824533 -0.109352 0.00538339" />
                    <site name="DELT1-P2" pos="0.0149355 -0.10153 0.00379138" />
                    <site name="DELT2-P1" pos="0.00424229 -0.125254 0.00515333" />
                    <site name="DELT3-P3" pos="0.00189569 -0.0699565 0.00961648" />
                    <site name="SUPSP-P1" pos="0.00235581 0.00978212 0.0238618" />
                    <site name="INFSP-P1" pos="-0.00816251 0.00445395 0.0225274" />
                    <site name="SUBSC-P1" pos="0.0129109 0.00772999 -0.0122484" />
                    <site name="TMIN-P1" pos="-0.00101226 -0.0116318 0.0198403" />
                    <site name="TMAJ-P1" pos="0.00918397 -0.0498677 -0.00522695" />
                    <site name="PECM1-P1" pos="0.0107576 -0.0385672 0.00717785" />
                    <site name="PECM1-P2" pos="  0.0191  -0.0301  0.00143" />
                    <site name="PECM2-P1" pos="0.0117238 -0.039469 0.00722386" />
                    <site name="PECM2-P2" pos=" 0.01748 -0.03533  0.00033" />
                    <site name="PECM3-P1" pos="0.0116778 -0.0402604 0.00690178" />
                    <site name="PECM3-P2" pos="0.0159185 -0.045833 -0.00378312" />
                    <site name="LAT1-P1" pos="0.00966249 -0.0314261 -0.00600915" />
                    <site name="LAT2-P1" pos="0.0089079 -0.0374629 -0.00562265" />
                    <site name="LAT3-P1" pos="0.0111165 -0.0360917 -0.00382819" />
                    <site name="CORB-P3" pos="0.00683736 -0.138477 -0.00719626" />
                    <site name="TRIlong-P2" pos="-0.0249752 -0.105284 -0.00611038" />
                    <site name="TRIlong-P3" pos="-0.0293004 -0.208314 -0.0111993" />
                    <site name="TRIlong-P4" pos="-0.0160397 -0.246228 -0.0111165" />
                    <site name="TRIlat-P1" pos="-0.00551222 -0.116373 0.00393862" />
                    <site name="TRIlat-P2" pos="-0.0215704 -0.133692 0.0085398" />
                    <site name="TRIlat-P3" pos="-0.0293004 -0.208314 -0.0111993" />
                    <site name="TRIlat-P4" pos="-0.0160397 -0.246228 -0.0111165" />
                    <site name="TRImed-P1" pos="-0.00771159 -0.126027 -0.00833735" />
                    <site name="TRImed-P2" pos="-0.0239354 -0.139315 -0.00993856" />
                    <site name="TRImed-P3" pos="-0.0293004 -0.208314 -0.0111993" />
                    <site name="TRImed-P4" pos="-0.0160397 -0.246228 -0.0111165" />
                    <site name="ANC-P1" pos="-0.00684657 -0.26097 0.00900912" />
                    <site name="BIClong-P3" pos="0.0196103 0.0164999 0.00946004" />
                    <site name="BIClong-P4" pos="0.0218832 -0.00470241 0.0110521" />
                    <site name="BIClong-P5" pos="0.0123772 -0.0260151 0.00125152" />
                    <site name="BIClong-P6" pos="0.00982814 -0.0711896 -0.00151839" />
                    <site name="BIClong-P7" pos="0.0156716 -0.111579 0.000220857" />
                    <site name="BIClong-P8" pos="0.0209814 -0.16141 -0.0057975" />
                    <site name="BICshort-P3" pos="0.0102791 -0.0697172 -0.0101318" />
                    <site name="BICshort-P4" pos="0.0156716 -0.111579 -0.00992936" />
                    <site name="BICshort-P5" pos="0.0209814 -0.16141 -0.0057975" />
                    <site name="BRA-P1" pos="0.00625761 -0.160029 -0.00331285" />
                    <site name="BRA-P2" pos="0.0174293 -0.262811 -0.0101686" />
                    <site name="BRD-P1" pos="-0.00901833 -0.183707 0.00205213" />
                    <site name="ECRL-P1" pos="-0.00671773 -0.24009 0.00837416" />
                    <site name="ECRB-P1" pos="0.012414 -0.267311 0.0156256" />
                    <site name="ECU-P1" pos="0.000763797 -0.266455 0.0173005" />
                    <site name="FCR-P1" pos="0.0069754 -0.255881 -0.0340948" />
                    <site name="FCU-P1" pos="0.00201532 -0.255274 -0.0357052" />
                    <site name="PL-P1" pos="0.00420549 -0.25324 -0.0355672" />
                    <site name="PT-P1" pos="0.00331285 -0.253894 -0.0335887" />
                    <site name="FDSL-P1" pos="0.0038742 -0.253967 -0.035558" />
                    <site name="FDSR-P1" pos="0.00440794 -0.256562 -0.0343341" />
                    <site name="EDCL-P1" pos="-0.000368095 -0.265314 0.0172084" />
                    <site name="EDCR-P1" pos="-0.00143557 -0.26628 0.0163986" />
                    <site name="EDCM-P1" pos="0.000469321 -0.266722 0.0179354" />
                    <site name="EDCI-P1" pos="0.000598154 -0.26593 0.0171992" />
                    <site name="EDM-P1" pos="0.000819011 -0.266123 0.0169968" />
                    <joint name="shoulder_rot" type="hinge" pos="0 0 0" axis="  0.0048 0.999089   0.0424" limited="true" range=" -1.5708 0.349066" ref="0" user="1" />
                    <body name="ulna" pos="0.00561345 -0.267237 -0.0113189" quat="1.0 0.0 0.0 0.0">
                      <geom name="ulna" type="mesh" mesh="ulna" />
                      <inertial pos="0.00894271 -0.0882976 0.0223489" mass="1.01713848729772" fullinertia="0.00421837 0.000898663 0.00385251 0.000246926 -5.9343e-05 0.000850744" />
                      <site name="TRIlong-P5" pos="-0.0201532 0.00962568 -0.000717785" />
                      <site name="TRIlat-P5" pos="-0.0201532 0.00962568 -0.000717785" />
                      <site name="TRImed-P5" pos="-0.0201532 0.00962568 -0.000717785" />
                      <site name="ANC-P2" pos="-0.0233004 -0.00114109 0.00552142" />
                      <site name="SUP-P3" pos="-0.0125152 -0.0311408 0.0185244" />
                      <site name="BRA-P4" pos="-0.00294476 -0.0219937 0.000828214" />
                      <site name="BRA-P3" pos="0.00458278 -0.0134631 0.0011779" />
                      <site name="ECU-P2" pos="-0.0128005 -0.0294568 0.0271194" />
                      <site name="ECU-P3" pos="-0.01569 -0.0499505 0.0263924" />
                      <site name="ECU-P4" pos="-0.0164999 -0.0880943 0.0301654" />
                      <site name="PT-P2" pos="0.00778521 -0.0310396 -0.0131778" />
                      <site name="PT-P3" pos=" 0.01219 -0.06516 -0.00219" />
                      <site name="PQ-P2" pos="0.00177606 -0.192992 0.033423" />
                      <site name="FDSM-P1" pos="-0.00615639 -0.024966 -0.00175765" />
                      <site name="FDSI-P1" pos="-0.00622081 -0.0259415 -0.00126073" />
                      <site name="FDPL-P1" pos="-0.00577909 -0.0295764 0.0023374" />
                      <site name="FDPR-P1" pos="-0.00461959 -0.0310488 0.00251225" />
                      <site name="FDPM-P1" pos="-0.00480364 -0.0306163 0.0019325" />
                      <site name="FDPI-P1" pos="-0.00595394 -0.0292267 0.00257666" />
                      <site name="EDM-P2" pos="-0.00899072 -0.0359537 0.0283893" />
                      <site name="EDM-P3" pos="-0.00694779 -0.076076 0.0335519" />
                      <site name="EIP-P1" pos="-0.00362574 -0.153238 0.0338831" />
                      <site name="EIP-P2" pos="0.00157361 -0.160756 0.0372604" />
                      <site name="EPL-P1" pos="-0.0129938 -0.0893182 0.0271654" />
                      <joint name="elbow_flexion" type="hinge" pos="0 0 0" axis="  0.0494   0.0366 0.998108" limited="true" range="       0  4.26893" ref="0" user="1" />
                      <body name="radius" pos="0.000368095 -0.0105855 0.0184038" quat="1.0 0.0 0.0 0.0">
                        <geom name="radius" type="mesh" mesh="radius" />
                        <inertial pos="0.0309514 -0.167077 0.0143557" mass="0.214958273091355" fullinertia="0.000341758 6.90374e-05 0.000313727 2.34878e-05 -3.30419e-06 5.00149e-05" />
                        <site name="SUP-P1" pos="0.00916557 -0.0560977 0.000690178" />
                        <site name="SUP-P2" pos="0.0110521 -0.0475763 -0.000984654" />
                        <site name="BIClong-P11" pos="-0.00184047 -0.0345089 -0.00184047" />
                        <site name="BIClong-P9" pos=" 0.00273 -0.0343493 -0.0119845" />
                        <site name="BICshort-P8" pos="-0.00184047 -0.0345089 -0.00184047" />
                        <site name="BICshort-P6" pos=" 0.00273 -0.0343493 -0.0119845" />
                        <site name="BRD-P2" pos="0.0329169 -0.117257 0.0213035" />
                        <site name="BRD-P3" pos="0.038558 -0.203372 0.0206133" />
                        <site name="ECRL-P2" pos="0.0294016 -0.123892 0.0255734" />
                        <site name="ECRL-P3" pos="0.0390457 -0.217949 0.0333126" />
                        <site name="ECRB-P2" pos="0.0267329 -0.120422 0.0219477" />
                        <site name="ECRB-P3" pos="0.0326592 -0.20986 0.0362297" />
                        <site name="ECU-P5" pos="-0.0130766 -0.208857 0.0320335" />
                        <site name="FCR-P2" pos="0.019417 -0.201928 0.0011687" />
                        <site name="FCU-P3" pos="0.00995697 -0.205461 0.0089171" />
                        <site name="FCU-P2" pos="0.0101156 -0.183524 0.00202653" />
                        <site name="PL-P2" pos="0.0232912 -0.220075 -0.00253986" />
                        <site name="PT-P5" pos="0.023374 -0.100122 0.0182207" />
                        <site name="PT-P4" pos="0.0217176 -0.0859502 0.00865023" />
                        <site name="PQ-P1" pos="0.0298617 -0.184029 0.0180551" />
                        <site name="FDSL-P2" pos="0.0126717 -0.17225 0.00188649" />
                        <site name="FDSR-P2" pos="0.0144569 -0.171772 0.00245703" />
                        <site name="FDSM-P2" pos="0.0174753 -0.17214 0.00390181" />
                        <site name="FDSI-P2" pos="0.0197391 -0.171376 0.00507971" />
                        <site name="FDPL-P2" pos="0.0129661 -0.170391 0.00792324" />
                        <site name="FDPR-P2" pos="0.0145398 -0.171431 0.00738951" />
                        <site name="FDPM-P2" pos="0.0175397 -0.171569 0.00722386" />
                        <site name="FDPI-P2" pos="0.0191409 -0.170796 0.00842017" />
                        <site name="EDCL-P3" pos="0.00913796 -0.20525 0.0332942" />
                        <site name="EDCL-P2" pos="  0.0013 -0.0382544 0.0129514" />
                        <site name="EDCR-P3" pos="0.00811649 -0.20582 0.039423" />
                        <site name="EDCR-P2" pos="  0.0026 -0.0392844 0.0144214" />
                        <site name="EDCM-P3" pos="0.0132514 -0.205425 0.0388616" />
                        <site name="EDCM-P2" pos=" 0.00316 -0.0388544 0.0141814" />
                        <site name="EDCI-P3" pos="0.0141072 -0.205342 0.0386132" />
                        <site name="EDCI-P2" pos=" 0.00228 -0.0385544 0.0137314" />
                        <site name="EDM-P4" pos="0.00417788 -0.208351 0.0338463" />
                        <site name="EIP-P3" pos="0.00990176 -0.209658 0.0337175" />
                        <site name="EPL-P2" pos="0.00114109 -0.125778 0.0208894" />
                        <site name="EPL-P3" pos="0.0248648 -0.201274 0.0352267" />
                        <site name="EPL-P4" pos="0.0311224 -0.209391 0.0423953" />
                        <site name="EPL-P5" pos="0.0389629 -0.21875 0.0384015" />
                        <site name="EPB-P1" pos="0.0177054 -0.135229 0.0194538" />
                        <site name="EPB-P2" pos="0.0209446 -0.145922 0.0245243" />
                        <site name="EPB-P3" pos="0.0352543 -0.181489 0.0352819" />
                        <site name="EPB-P4" pos="0.0481744 -0.217277 0.0248372" />
                        <site name="FPL-P1" pos="0.00893551 -0.0870361 0.016279" />
                        <site name="FPL-P2" pos="0.0152575 -0.124462 0.0176225" />
                        <site name="FPL-P3" pos="0.0171992 -0.165017 0.0182943" />
                        <site name="FPL-P4" pos="0.034969 -0.213228 0.0145398" />
                        <site name="APL-P1" pos="0.0106195 -0.0872109 0.0154692" />
                        <site name="APL-P2" pos="0.0278832 -0.128557 0.0322727" />
                        <site name="APL-P3" pos="0.0367451 -0.147901 0.0312881" />
                        <site name="APL-P4" pos="0.0404628 -0.164216 0.0288402" />
                        <site name="APL-P5" pos="0.0506591 -0.212428 0.0217912" />
                        <joint name="pro_sup" type="hinge" pos="0 0 0" axis="-0.017161 0.992666 -0.119668" limited="true" range=" -1.5708   1.5708" ref="0" user="1" />
                        <body name="proximal_row" pos="0.0165643 -0.222697 0.0230059" quat="1.0 0.0 0.0 0.0">
                          <geom name="lunate" type="mesh" mesh="lunate" />
                          <geom name="sdfastSCAPHOIDw" type="mesh" mesh="sdfastSCAPHOIDw" />
                          <geom name="sdfastPISIFORMw" type="mesh" mesh="sdfastPISIFORMw" />
                          <geom name="sdfastTRIQUETRALw" type="mesh" mesh="sdfastTRIQUETRALw" />
                          <inertial pos="       0        0        0" mass="9.20237480591443e-05" fullinertia="7.79291e-06 7.79291e-06 7.79291e-06        0        0        0" />
                          <body name="hand" pos="0.00367359 -0.0138533 0.00214139" quat="1.0 0.0 0.0 0.0">
                            <geom name="sdfast_1seg_hand_fr_c_5mc" type="mesh" mesh="sdfast_1seg_hand_fr_c_5mc" />
                            <geom name="sdfast_1seg_hand_fr_c_4mc" type="mesh" mesh="sdfast_1seg_hand_fr_c_4mc" />
                            <geom name="sdfast_1seg_hand_fr_c_3mc" type="mesh" mesh="sdfast_1seg_hand_fr_c_3mc" />
                            <geom name="sdfast_1seg_hand_fr_c_trapezium" type="mesh" mesh="sdfast_1seg_hand_fr_c_trapezium" />
                            <geom name="sdfast_1seg_hand_fr_c_trapezoid" type="mesh" mesh="sdfast_1seg_hand_fr_c_trapezoid" />
                            <geom name="sdfast_1seg_hand_fr_c_hamate" type="mesh" mesh="sdfast_1seg_hand_fr_c_hamate" />
                            <geom name="capitate" type="mesh" mesh="capitate" />
                            <geom name="hand_3proxph" type="mesh" mesh="hand_3proxph" />
                            <geom name="hand_3midph" type="mesh" mesh="hand_3midph" />
                            <geom name="hand_3distph" type="mesh" mesh="hand_3distph" />
                            <geom name="hand_4proxph" type="mesh" mesh="hand_4proxph" />
                            <geom name="hand_4midph" type="mesh" mesh="hand_4midph" />
                            <geom name="hand_4distph" type="mesh" mesh="hand_4distph" />
                            <geom name="hand_5proxph" type="mesh" mesh="hand_5proxph" />
                            <geom name="hand_5midph" type="mesh" mesh="hand_5midph" />
                            <geom name="hand_5distph" type="mesh" mesh="hand_5distph" />
                            <geom name="hand_thumbprox" type="mesh" mesh="hand_thumbprox" />
                            <geom name="hand_thumbdist" type="mesh" mesh="hand_thumbdist" />
                            <geom name="hand_1mc" type="mesh" mesh="hand_1mc" />
                            <inertial pos="-0.0027728 -0.0391094 -0.00103255" mass="0.535486189956161" fullinertia="8.5722e-05 4.67575e-05 0.000116894 7.01362e-07 -1.55858e-07 9.35149e-06" />
                            <site name="ECRL-P4" pos="0.0158005 -0.0195274 0.00536498" />
                            <site name="ECRB-P4" pos="0.00460119 -0.0104539 0.00782202" />
                            <site name="ECU-P6" pos="-0.0207145 -0.0128925 -0.0011779" />
                            <site name="FCR-P3" pos="0.0103435 -0.0169692 -0.00384659" />
                            <site name="FCU-P4" pos="-0.018736 -0.0162422 -0.00692019" />
                            <site name="PL-P3" pos="0.00843858 -0.0174661 -0.016141" />
                            <site name="PL-P4" pos="0.00208894 -0.0284906 0.00453677" />
                            <site name="FDSL-P3" pos="-0.00216256 -0.0128189 -0.0126625" />
                            <site name="FDSL-P4" pos="-0.0183587 -0.0393954 -0.00682816" />
                            <site name="FDSL-P5" pos="-0.0188097 -0.0550394 -0.0172821" />
                            <site name="FDSL-P6" pos="-0.0157637 -0.0666712 -0.0253341" />
                            <site name="FDSL-P7" pos="-0.0106379 -0.0669105 -0.0336439" />
                            <site name="FDSL-P8" pos="-0.00974531 -0.0669105 -0.0349322" />
                            <site name="FDSR-P3" pos="-0.000754595 -0.012368 -0.012506" />
                            <site name="FDSR-P4" pos="-0.00899072 -0.0476591 3.68095e-005" />
                            <site name="FDSR-P5" pos="-0.0121747 -0.0613798 -0.00938642" />
                            <site name="FDSR-P6" pos="-0.00725147 -0.0738675 -0.0230335" />
                            <site name="FDSR-P7" pos="-0.00275151 -0.0747693 -0.0312421" />
                            <site name="FDSR-P8" pos="0.000570547 -0.0744656 -0.0358156" />
                            <site name="FDSM-P3" pos="0.00625761 -0.0126717 -0.0128741" />
                            <site name="FDSM-P4" pos="0.00433432 -0.0306623 -0.00121471" />
                            <site name="FDSM-P5" pos="0.00498769 -0.0520854 0.000552142" />
                            <site name="FDSM-P6" pos="0.00510732 -0.066478 -0.0031104" />
                            <site name="FDSM-P7" pos="0.0107392 -0.0810729 -0.015368" />
                            <site name="FDSM-P8" pos="0.0119723 -0.0816251 -0.0273955" />
                            <site name="FDSM-P9" pos="0.0144293 -0.0789288 -0.0346469" />
                            <site name="FDSI-P3" pos="0.00818091 -0.0125704 -0.0127637" />
                            <site name="FDSI-P4" pos="0.00976372 -0.0348494 0.000220857" />
                            <site name="FDSI-P5" pos="0.0163986 -0.0470057 0.00384659" />
                            <site name="FDSI-P6" pos="0.0170152 -0.0671497 -0.00345089" />
                            <site name="FDSI-P7" pos="0.024644 -0.0801895 -0.0166011" />
                            <site name="FDSI-P8" pos="0.0245427 -0.0804288 -0.024644" />
                            <site name="FDSI-P9" pos="0.0244783 -0.0794441 -0.0267145" />
                            <site name="FDPL-P3" pos="-0.000809809 -0.00945084 -0.0109324" />
                            <site name="FDPL-P4" pos="-0.0170704 -0.0427542 -0.00674534" />
                            <site name="FDPL-P5" pos="-0.0166379 -0.0537511 -0.0143557" />
                            <site name="FDPL-P6" pos="-0.013141 -0.0670761 -0.02469" />
                            <site name="FDPL-P7" pos="-0.00846618 -0.0688614 -0.0339015" />
                            <site name="FDPL-P8" pos="-0.00287114 -0.0681436 -0.0383279" />
                            <site name="FDPL-P9" pos="0.00410426 -0.0649596 -0.0428555" />
                            <site name="FDPR-P3" pos="0.000975452 -0.0108312 -0.0108956" />
                            <site name="FDPR-P4" pos="-0.00786803 -0.0509996 0.000809809" />
                            <site name="FDPR-P5" pos="-0.00992936 -0.0606252 -0.00751834" />
                            <site name="FDPR-P6" pos="-0.0050337 -0.0750362 -0.0207606" />
                            <site name="FDPR-P7" pos="-0.000515333 -0.0757355 -0.0309844" />
                            <site name="FDPR-P8" pos="0.00560425 -0.072119 -0.0389997" />
                            <site name="FDPR-P9" pos="0.0111441 -0.0679135 -0.0447051" />
                            <site name="FDPM-P3" pos="0.0030828 -0.011779 -0.0105275" />
                            <site name="FDPM-P4" pos="0.00277912 -0.0317206 -0.00562265" />
                            <site name="FDPM-P5" pos="0.002319 -0.0539535 0.00112269" />
                            <site name="FDPM-P6" pos="0.00262268 -0.0642786 -0.00122392" />
                            <site name="FDPM-P7" pos="0.00794165 -0.0807876 -0.0167023" />
                            <site name="FDPM-P8" pos="0.00922078 -0.080668 -0.0272758" />
                            <site name="FDPM-P9" pos="0.0150275 -0.0750638 -0.0408125" />
                            <site name="FDPM-P10" pos="0.0175673 -0.0705178 -0.0481192" />
                            <site name="FDPI-P3" pos="0.00824533 -0.0107484 -0.0111533" />
                            <site name="FDPI-P4" pos="0.017687 -0.0509996 0.00403064" />
                            <site name="FDPI-P5" pos="0.0190765 -0.0646099 -0.00263188" />
                            <site name="FDPI-P6" pos="0.0267237 -0.07903 -0.0163986" />
                            <site name="FDPI-P7" pos="0.0269077 -0.079803 -0.0254814" />
                            <site name="FDPI-P8" pos="0.0268157 -0.0757816 -0.0366162" />
                            <site name="FDPI-P9" pos="0.0261992 -0.0715117 -0.0438585" />
                            <site name="EDCL-P4" pos="-0.0226747 -0.0405089 0.0015552" />
                            <site name="EDCL-P5" pos="-0.0219109 -0.043564 0.000708583" />
                            <site name="EDCL-P6" pos="-0.0220397 -0.0608553 -0.00921158" />
                            <site name="EDCL-P7" pos="-0.0165459 -0.072211 -0.0249476" />
                            <site name="EDCL-P8" pos="-0.0108404 -0.0724871 -0.0347758" />
                            <site name="EDCL-P9" pos="-0.00138036 -0.0698092 -0.0422021" />
                            <site name="EDCL-P10" pos="0.00184968 -0.0688982 -0.0441162" />
                            <site name="EDCR-P4" pos="-0.0143925 -0.0510732 0.00859502" />
                            <site name="EDCR-P5" pos="-0.0131318 -0.0535486 0.010684" />
                            <site name="EDCR-P6" pos="-0.0145398 -0.0664043 -0.0038742" />
                            <site name="EDCR-P7" pos="-0.00759196 -0.0803827 -0.0207974" />
                            <site name="EDCR-P8" pos="-0.00250305 -0.0810361 -0.0313709" />
                            <site name="EDCR-P9" pos="0.00702141 -0.0738583 -0.0428647" />
                            <site name="EDCR-P10" pos="0.00983734 -0.0718613 -0.0454689" />
                            <site name="EDCM-P4" pos="0.000358893 -0.0485333 0.0137207" />
                            <site name="EDCM-P5" pos="-0.000800607 -0.051294 0.0133618" />
                            <site name="EDCM-P6" pos="0.00171164 -0.0710239 0.00549382" />
                            <site name="EDCM-P7" pos="0.00926679 -0.0857017 -0.016325" />
                            <site name="EDCM-P8" pos="0.0121563 -0.0879563 -0.0281225" />
                            <site name="EDCM-P9" pos="0.0170888 -0.0784502 -0.0437941" />
                            <site name="EDCM-P10" pos="0.0189201 -0.0735546 -0.0491499" />
                            <site name="EDCM-P11" pos="0.0201992 -0.0708675 -0.052113" />
                            <site name="EDCI-P4" pos="0.0141993 -0.0430671 0.0150827" />
                            <site name="EDCI-P5" pos="0.0174569 -0.0520302 0.013233" />
                            <site name="EDCI-P6" pos="0.0183495 -0.0706558 0.00546621" />
                            <site name="EDCI-P7" pos="0.027101 -0.0843122 -0.011457" />
                            <site name="EDCI-P8" pos="0.0287206 -0.086033 -0.0267329" />
                            <site name="EDCI-P9" pos="0.0277268 -0.0781006 -0.0392757" />
                            <site name="EDCI-P10" pos="0.0269538 -0.0745668 -0.045699" />
                            <site name="EDM-P5" pos="-0.0189477 -0.00949685 0.00342328" />
                            <site name="EDM-P6" pos="-0.0235857 -0.0434536 0.000211655" />
                            <site name="EDM-P7" pos="-0.0234569 -0.0599167 -0.0101042" />
                            <site name="EDM-P8" pos="-0.0177882 -0.0718705 -0.0250121" />
                            <site name="EDM-P9" pos="-0.0123864 -0.0726251 -0.035834" />
                            <site name="EDM-P10" pos="-0.00198771 -0.0692111 -0.0422297" />
                            <site name="EDM-P11" pos="0.00121471 -0.0675914 -0.044199" />
                            <site name="EIP-P4" pos="0.00357052 -0.0205581 0.0108956" />
                            <site name="EIP-P5" pos="0.0155796 -0.0519014 0.0126717" />
                            <site name="EIP-P6" pos="0.0159661 -0.0707847 0.00534658" />
                            <site name="EIP-P7" pos="0.0254446 -0.0857109 -0.0139048" />
                            <site name="EIP-P8" pos="0.0264936 -0.0868428 -0.0259783" />
                            <site name="EIP-P9" pos="0.0264108 -0.078441 -0.0395242" />
                            <site name="EIP-P10" pos="0.0260795 -0.0716405 -0.0506223" />
                            <site name="EPL-P6" pos="0.0223434 0.000128833 0.00559504" />
                            <site name="EPL-P7" pos="0.0215152 -0.00843858 -0.000358893" />
                            <site name="EPL-P8" pos="0.0267329 -0.0131318 -0.00449996" />
                            <site name="EPL-P9" pos="0.0406193 -0.0314445 -0.0166931" />
                            <site name="EPL-P10" pos="0.044788 -0.0427542 -0.0228863" />
                            <site name="EPL-P11" pos="0.0437205 -0.0645086 -0.0347298" />
                            <site name="EPL-P12" pos="0.0369107 -0.069616 -0.0394138" />
                            <site name="EPB-P5" pos="0.028739 0.00235581 -0.00300918" />
                            <site name="EPB-P6" pos="0.0273495 -0.00730669 -0.0132146" />
                            <site name="EPB-P7" pos="0.0406929 -0.0303678 -0.0222882" />
                            <site name="EPB-P8" pos="0.0416684 -0.0440334 -0.0293188" />
                            <site name="FPL-P6" pos="0.0114478 -0.0203096 -0.0192238" />
                            <site name="FPL-P7" pos="0.0151011 -0.0241194 -0.0204385" />
                            <site name="FPL-P8" pos="0.0226102 -0.0303126 -0.0205857" />
                            <site name="FPL-P9" pos="0.0260151 -0.0504474 -0.0281133" />
                            <site name="FPL-P10" pos="0.0323095 -0.0599903 -0.0344997" />
                            <site name="FPL-P11" pos="0.032512 -0.0704534 -0.0378954" />
                            <site name="FPL-P5" pos="0.0178892 0.0064176 -0.0168214" />
                            <site name="APL-P7" pos="0.0238065 0.00188649 -0.0151839" />
                            <site name="APL-P8" pos="0.0264844 -0.0062024 -0.0172084" />
                            <site name="APL-P9" pos="0.0283065 -0.0145674 -0.0173465" />
                            <site name="APL-P6" pos="0.0332244 0.00608975 -0.00870125" />
                            <body name="index0" pos="0 0 0">
                              <inertial pos="0 0 0" mass="0.001" diaginertia="0.001 0.001 0.001" />
                              <geom name="sdfast_1seg_hand_fr_c_2mc" type="mesh" mesh="sdfast_1seg_hand_fr_c_2mc" />
                              <body name="index1" pos="0 0 0">
                                <inertial pos="0 0 0" mass="0.001" diaginertia="0.001 0.001 0.001" />
                                <geom name="hand_2proxph" type="mesh" mesh="hand_2proxph" />
                                <body name="index2" pos="0 0 0">
                                  <inertial pos="0 0 0" mass="0.001" diaginertia="0.001 0.001 0.001" />
                                  <geom name="hand_2midph" type="mesh" mesh="hand_2midph" />
                                  <body name="index3" pos="0 0 0">
                                    <inertial pos="0 0 0" mass="0.001" diaginertia="0.001 0.001 0.001" />
                                    <geom name="hand_2distph" type="mesh" mesh="hand_2distph" />
                                    <site name="fingertip" pos="0.024 -0.149 -0.0065" type="sphere" rgba="0.1 0.8 0.1 0.0" size="0.004" />
                                  </body>
                                </body>
                              </body>
                            </body>
                          </body>
                        </body>
                      </body>
                    </body>
                  </body>
                </body>
              </body>
            </body>
          </body>
        </body>
      </body>
    </body>

</mujocoinclude>