<mujocoinclude model="MoBL Arms Index Model">

    <body name="thorax" pos="0 0 0" quat="0.7071067811865475 0.7071067811865475 0.0 0.0">
      <light mode="trackcom" directional="false" pos="0 0 4.0" dir="0 0 -1" />
      <geom name="thorax" type="mesh" mesh="thorax" />
      <site name="PECM1-P3" pos="  -7e-05  0.00821  0.10454" />
      <site name="PECM2-P4" pos="0.0296414 -0.0376103 0.0930668" />
      <site name="PECM2-P5" pos="0.0265535 -0.0431339 0.0217779" />
      <site name="PECM2-P3" pos=" 0.02083 -0.02005  0.11555" />
      <site name="PECM3-P4" pos="0.0503453 -0.0807154 0.0856828" />
      <site name="PECM3-P5" pos="0.0548907 -0.111757 0.0363157" />
      <site name="PECM3-P3" pos=" 0.02984 -0.0544459   0.1151" />
      <site name="LAT1-P4" pos="-0.113425 -0.0970273 0.031799" />
      <site name="LAT1-P5" pos="-0.0918489 -0.112428 0.008458" />
      <site name="LAT2-P4" pos="-0.105409 -0.16214 0.0275988" />
      <site name="LAT2-P5" pos="-0.0689107 -0.180457 0.0078155" />
      <site name="LAT3-P4" pos="-0.106991 -0.185913 0.0530495" />
      <site name="LAT3-P5" pos="-0.068249 -0.238378 0.00869774" />
      <joint name="r_z" type="hinge" pos="0 0 0" axis="       0        0        1" limited="true" range="-6.28319  6.28319" ref="0" armature="0" damping="0" stiffness="0" />
      <body name="clavicle" pos="0.0060654 0.00664557 0.0244198" quat="1.0 0.0 0.0 0.0">
        <geom name="clavicle" type="mesh" mesh="clavicle" />
        <inertial pos="-0.0106406 0.00611076 0.0519448" mass="0.149597315446909" fullinertia="0.000213929 0.000225103 3.9172e-05 -1.67376e-05 -6.1677e-05 4.73645e-05" />
        <site name="DELT1-P4" pos="-0.0134254 0.0106061 0.076918" />
        <site name="DELT2-P2" pos="0.0191703 0.0244002 0.162891" />
        <site name="PECM1-P4" pos="0.00307825 -0.000124664 0.0490315" />
        <joint name="sternoclavicular_r2" type="hinge" pos="0 0 0" axis="  0.0153 0.989299  -0.1451" limited="false" range="-99999.9  99999.9" ref="0" />
        <joint name="sternoclavicular_r3" type="hinge" pos="0 0 0" axis="-0.994473        0 -0.104997" limited="false" range="-99999.9  99999.9" ref="0" />
        <body name="clavphant" pos="-0.0137419 0.0192463 0.129972" quat="1.0 0.0 0.0 0.0">
          <inertial pos="       0        0        0" mass="9.58957150300702e-05" fullinertia="0.881856 0.881856 0.881856        0        0        0" />
          <joint name="unrotscap_r3" type="hinge" pos="0 0 0" axis="-0.994473        0 -0.104997" limited="false" range="-99999.9  99999.9" ref="0" />
          <joint name="unrotscap_r2" type="hinge" pos="0 0 0" axis="  0.0153 0.989299  -0.1451" limited="false" range="-99999.9  99999.9" ref="0" />
          <body name="scapula" pos="       0        0        0" quat="1.0 0.0 0.0 0.0">
            <geom name="scapula" type="mesh" mesh="scapula" />
            <inertial pos="-0.0524492 -0.0335942 -0.041939" mass="0.675067475525682" fullinertia="0.00109606 0.00101449 0.00120382 0.000396306 0.000360873 0.000212615" />
            <site name="DELT1-P3" pos="0.0416859 -0.0311853 0.000949368" />
            <site name="DELT2-P3" pos="4.79479e-005 0.00281933 0.0214135" />
            <site name="DELT2-P4" pos="-0.0103376 -0.000326045 0.00594553" />
            <site name="DELT3-P1" pos="-0.0534427 0.00116993 -0.024089" />
            <site name="DELT3-P2" pos="-0.0694956 -0.0315017 0.0118239" />
            <site name="SUPSP-P2" pos="-0.0183928 0.00121788 -0.0121883" />
            <site name="SUPSP-P3" pos="-0.0421941 -0.0144994 -0.0561469" />
            <site name="INFSP-P2" pos="-0.0707902 -0.0525125 -0.0458477" />
            <site name="SUBSC-P2" pos="-0.0175585 -0.0500863 -0.0235616" />
            <site name="SUBSC-P3" pos="-0.069486 -0.0378117 -0.0620925" />
            <site name="TMIN-P2" pos="-0.090842 -0.0766303 -0.0454258" />
            <site name="TMIN-P3" pos="-0.0924722 -0.0778769 -0.0508055" />
            <site name="TMAJ-P2" pos="-0.0984274 -0.0989548 -0.0558976" />
            <site name="TMAJ-P3" pos="-0.100585 -0.104478 -0.068249" />
            <site name="LAT1-P2" pos="-0.08052 -0.06821 -0.02908" />
            <site name="LAT1-P3" pos="-0.10925 -0.07239 -0.07422" />
            <site name="LAT2-P2" pos="-0.08345 -0.08695 -0.02453" />
            <site name="LAT2-P3" pos="-0.11524 -0.10749 -0.08863" />
            <site name="LAT3-P2" pos="-0.08438 -0.11598 -0.02995" />
            <site name="LAT3-P3" pos="-0.11279 -0.13833 -0.08911" />
            <site name="CORB-P1" pos="0.011987 -0.0395762 -0.0254315" />
            <site name="CORB-P2" pos="0.00463176 -0.0667242 -0.0149885" />
            <site name="TRIlong-P1" pos="-0.0437764 -0.0390583 -0.0132048" />
            <site name="BIClong-P1" pos="-0.0299482 -0.0225643 -0.0125144" />
            <site name="BIClong-P2" pos="-0.0200806 -0.0125527 -0.00442079" />
            <site name="BICshort-P1" pos="0.0121596 -0.0376966 -0.0251726" />
            <site name="BICshort-P2" pos="0.00089183 -0.0642885 -0.0152762" />
            <joint name="acromioclavicular_r2" type="hinge" pos="0 0 0" axis="0.157095 0.947269 -0.279291" limited="false" range="-99999.9  99999.9" ref="0" />
            <joint name="acromioclavicular_r3" type="hinge" pos="0 0 0" axis="-0.754084 0.297594 0.585487" limited="false" range="-99999.9  99999.9" ref="0" />
            <joint name="acromioclavicular_r1" type="hinge" pos="0 0 0" axis="  0.6377   0.1186   0.7611" limited="false" range="-99999.9  99999.9" ref="0" />
            <body name="scapphant" pos="-0.00915804 -0.0326045 0.00863061" quat="1.0 0.0 0.0 0.0">
              <inertial pos="       0        0        0" mass="9.58957150300702e-05" fullinertia="0.881856 0.881856 0.881856        0        0        0" />
              <joint name="unrothum_r1" type="hinge" pos="0 0 0" axis="  0.6377   0.1186   0.7611" limited="false" range="-99999.9  99999.9" ref="0" />
              <joint name="unrothum_r3" type="hinge" pos="0 0 0" axis="-0.754084 0.297594 0.585487" limited="false" range="-99999.9  99999.9" ref="0" />
              <joint name="unrothum_r2" type="hinge" pos="0 0 0" axis="0.157095 0.947269 -0.279291" limited="false" range="-99999.9  99999.9" ref="0" />
              <body name="humphant" pos="       0        0        0" quat="1.0 0.0 0.0 0.0">
                <inertial pos="       0        0        0" mass="9.58957150300702e-05" fullinertia="0.881856 0.881856 0.881856        0        0        0" />
                <joint name="elv_angle" type="hinge" pos="0 0 0" axis="  0.0048 0.999089   0.0424" limited="true" range=" -1.5708  2.26893" ref="0" user="1" />
                <body name="humphant1" pos="       0        0        0" quat="1.0 0.0 0.0 0.0">
                  <inertial pos="       0        0        0" mass="9.58957150300702e-05" fullinertia="0.881856 0.881856 0.881856        0        0        0" />
                  <joint name="shoulder_elv" type="hinge" pos="0 0 0" axis="-0.998261   0.0023 0.058898" limited="true" range="       0  3.14159" ref="0" user="1" />
                  <joint name="shoulder1_r2" type="hinge" pos="0 0 0" axis="  0.0048 0.999089   0.0424" limited="false" range="-99999.9  99999.9" ref="0" />
                  <body name="humerus" pos="       0        0        0" quat="1.0 0.0 0.0 0.0">
                    <geom name="humerus" type="mesh" mesh="humerus" />
                    <inertial pos="0.0173226 -0.134389 -0.0122229" mass="1.91558403472617" fullinertia="0.0108271 0.00224991 0.0110928 -0.000306366 -0.000205031 0.00108407" />
                    <site name="DELT1-P1" pos="0.00859226 -0.113953 0.0056099" />
                    <site name="DELT1-P2" pos="0.0155639 -0.105802 0.0039509" />
                    <site name="DELT2-P1" pos="0.00442079 -0.130524 0.00537016" />
                    <site name="DELT3-P3" pos="0.00197545 -0.0728999 0.0100211" />
                    <site name="SUPSP-P1" pos="0.00245493 0.0101937 0.0248658" />
                    <site name="INFSP-P1" pos="-0.00850595 0.00464135 0.0234753" />
                    <site name="SUBSC-P1" pos="0.0134542 0.00805524 -0.0127637" />
                    <site name="TMIN-P1" pos="-0.00105485 -0.0121212 0.0206751" />
                    <site name="TMAJ-P1" pos="0.00957039 -0.0519659 -0.00544688" />
                    <site name="PECM1-P1" pos="0.0112102 -0.0401899 0.00747987" />
                    <site name="PECM1-P2" pos="  0.0191  -0.0301  0.00143" />
                    <site name="PECM2-P1" pos="0.0122171 -0.0411297 0.00752781" />
                    <site name="PECM2-P2" pos=" 0.01748 -0.03533  0.00033" />
                    <site name="PECM3-P1" pos="0.0121692 -0.0419544 0.00719218" />
                    <site name="PECM3-P2" pos="0.0159185 -0.045833 -0.00378312" />
                    <site name="LAT1-P1" pos="0.0100691 -0.0327484 -0.00626199" />
                    <site name="LAT2-P1" pos="0.00928271 -0.0390391 -0.00585923" />
                    <site name="LAT3-P1" pos="0.0115842 -0.0376103 -0.00398926" />
                    <site name="CORB-P3" pos="0.00712505 -0.144304 -0.00749904" />
                    <site name="TRIlong-P2" pos="-0.0260261 -0.109714 -0.00636748" />
                    <site name="TRIlong-P3" pos="-0.0305332 -0.217079 -0.0116705" />
                    <site name="TRIlong-P4" pos="-0.0167146 -0.256588 -0.0115842" />
                    <site name="TRIlat-P1" pos="-0.00574415 -0.12127 0.00410434" />
                    <site name="TRIlat-P2" pos="-0.022478 -0.139317 0.00889912" />
                    <site name="TRIlat-P3" pos="-0.0305332 -0.217079 -0.0116705" />
                    <site name="TRIlat-P4" pos="-0.0167146 -0.256588 -0.0115842" />
                    <site name="TRImed-P1" pos="-0.00803606 -0.131329 -0.00868815" />
                    <site name="TRImed-P2" pos="-0.0249425 -0.145177 -0.0103567" />
                    <site name="TRImed-P3" pos="-0.0305332 -0.217079 -0.0116705" />
                    <site name="TRImed-P4" pos="-0.0167146 -0.256588 -0.0115842" />
                    <site name="ANC-P1" pos="-0.00713464 -0.271951 0.00938819" />
                    <site name="BIClong-P3" pos="0.0204354 0.0171941 0.00985808" />
                    <site name="BIClong-P4" pos="0.022804 -0.00490027 0.0115171" />
                    <site name="BIClong-P5" pos="0.012898 -0.0271097 0.00130418" />
                    <site name="BIClong-P6" pos="0.0102417 -0.0741849 -0.00158228" />
                    <site name="BIClong-P7" pos="0.016331 -0.116274 0.00023015" />
                    <site name="BIClong-P8" pos="0.0218642 -0.168201 -0.00604143" />
                    <site name="BICshort-P3" pos="0.0107116 -0.0726506 -0.0105581" />
                    <site name="BICshort-P4" pos="0.016331 -0.116274 -0.0103471" />
                    <site name="BICshort-P5" pos="0.0218642 -0.168201 -0.00604143" />
                    <site name="BRA-P1" pos="0.00652091 -0.166763 -0.00345225" />
                    <site name="BRA-P2" pos="0.0181626 -0.273869 -0.0105965" />
                    <site name="BRD-P1" pos="-0.00939778 -0.191437 0.00213847" />
                    <site name="ECRL-P1" pos="-0.00700039 -0.250192 0.00872651" />
                    <site name="ECRB-P1" pos="0.0129363 -0.278558 0.0162831" />
                    <site name="ECU-P1" pos="0.000795934 -0.277666 0.0180284" />
                    <site name="FCR-P1" pos="0.0072689 -0.266648 -0.0355294" />
                    <site name="FCU-P1" pos="0.00210012 -0.266015 -0.0372075" />
                    <site name="PL-P1" pos="0.00438243 -0.263895 -0.0370637" />
                    <site name="PT-P1" pos="0.00345225 -0.264576 -0.0350019" />
                    <site name="FDSL-P1" pos="0.00403721 -0.264653 -0.0370541" />
                    <site name="FDSR-P1" pos="0.0045934 -0.267357 -0.0357787" />
                    <site name="EDCL-P1" pos="-0.000383583 -0.276477 0.0179325" />
                    <site name="EDCR-P1" pos="-0.00149597 -0.277484 0.0170886" />
                    <site name="EDCM-P1" pos="0.000489068 -0.277944 0.0186901" />
                    <site name="EDCI-P1" pos="0.000623322 -0.277119 0.0179229" />
                    <site name="EDM-P1" pos="0.000853472 -0.277321 0.0177119" />
                    <joint name="shoulder_rot" type="hinge" pos="0 0 0" axis="  0.0048 0.999089   0.0424" limited="true" range=" -1.5708 0.349066" ref="0" user="1" />
                    <body name="ulna" pos="0.00584964 -0.278481 -0.0117952" quat="1.0 0.0 0.0 0.0">
                      <geom name="ulna" type="mesh" mesh="ulna" />
                      <inertial pos="0.00931898 -0.0920128 0.0232892" mass="1.05993533822737" fullinertia="0.00477357 0.00101694 0.00435955 0.000279425 -6.71533e-05 0.000962713" />
                      <site name="TRIlong-P5" pos="-0.0210012 0.0100307 -0.000747987" />
                      <site name="TRIlat-P5" pos="-0.0210012 0.0100307 -0.000747987" />
                      <site name="TRImed-P5" pos="-0.0210012 0.0100307 -0.000747987" />
                      <site name="ANC-P2" pos="-0.0242808 -0.00118911 0.00575374" />
                      <site name="SUP-P3" pos="-0.0130418 -0.0324511 0.0193038" />
                      <site name="BRA-P4" pos="-0.00306866 -0.0229191 0.000863061" />
                      <site name="BRA-P3" pos="0.00477561 -0.0140295 0.00122747" />
                      <site name="ECU-P2" pos="-0.0133391 -0.0306962 0.0282605" />
                      <site name="ECU-P3" pos="-0.0163502 -0.0520522 0.0275029" />
                      <site name="ECU-P4" pos="-0.0171941 -0.091801 0.0314346" />
                      <site name="PT-P2" pos="0.00811278 -0.0323456 -0.0137323" />
                      <site name="PT-P3" pos=" 0.01219 -0.06516 -0.00219" />
                      <site name="PQ-P2" pos="0.00185079 -0.201112 0.0348293" />
                      <site name="FDSM-P1" pos="-0.00641542 -0.0260165 -0.00183161" />
                      <site name="FDSI-P1" pos="-0.00648255 -0.027033 -0.00131377" />
                      <site name="FDPL-P1" pos="-0.00602225 -0.0308209 0.00243575" />
                      <site name="FDPR-P1" pos="-0.00481396 -0.0323552 0.00261795" />
                      <site name="FDPM-P1" pos="-0.00500576 -0.0319045 0.00201381" />
                      <site name="FDPI-P1" pos="-0.00620445 -0.0304565 0.00268508" />
                      <site name="EDM-P2" pos="-0.00936901 -0.0374665 0.0295838" />
                      <site name="EDM-P3" pos="-0.00724013 -0.079277 0.0349636" />
                      <site name="EIP-P1" pos="-0.00377829 -0.159686 0.0353088" />
                      <site name="EIP-P2" pos="0.00163982 -0.16752 0.0388282" />
                      <site name="EPL-P1" pos="-0.0135405 -0.0930764 0.0283084" />
                      <joint name="elbow_flexion" type="hinge" pos="0 0 0" axis="  0.0494   0.0366 0.998108" limited="true" range="       0  4.26893" ref="0" user="1" />
                      <body name="radius" pos="0.000383583 -0.0110309 0.0191782" quat="1.0 0.0 0.0 0.0">
                        <geom name="radius" type="mesh" mesh="radius" />
                        <inertial pos="0.0322537 -0.174107 0.0149597" mass="0.224002800738741" fullinertia="0.000386738 7.81236e-05 0.000355018 2.65791e-05 -3.73907e-06 5.65975e-05" />
                        <site name="SUP-P1" pos="0.00955121 -0.058458 0.000719218" />
                        <site name="SUP-P2" pos="0.0115171 -0.0495781 -0.00102608" />
                        <site name="BIClong-P11" pos="-0.00191791 -0.0359609 -0.00191791" />
                        <site name="BIClong-P9" pos=" 0.00273 -0.0343493 -0.0119845" />
                        <site name="BICshort-P8" pos="-0.00191791 -0.0359609 -0.00191791" />
                        <site name="BICshort-P6" pos=" 0.00273 -0.0343493 -0.0119845" />
                        <site name="BRD-P2" pos="0.0343019 -0.12219 0.0221999" />
                        <site name="BRD-P3" pos="0.0401803 -0.21193 0.0214806" />
                        <site name="ECRL-P2" pos="0.0306387 -0.129104 0.0266494" />
                        <site name="ECRL-P3" pos="0.0406886 -0.227119 0.0347142" />
                        <site name="ECRB-P2" pos="0.0278577 -0.125489 0.0228711" />
                        <site name="ECRB-P3" pos="0.0340334 -0.21869 0.0377541" />
                        <site name="ECU-P5" pos="-0.0136268 -0.217645 0.0333813" />
                        <site name="FCR-P2" pos="0.020234 -0.210424 0.00121788" />
                        <site name="FCU-P3" pos="0.0103759 -0.214106 0.00929229" />
                        <site name="FCU-P2" pos="0.0101156 -0.183524 0.00202653" />
                        <site name="PL-P2" pos="0.0242712 -0.229335 -0.00264672" />
                        <site name="PT-P5" pos="0.0243575 -0.104335 0.0189874" />
                        <site name="PT-P4" pos="0.0226314 -0.0895666 0.0090142" />
                        <site name="PQ-P1" pos="0.0311182 -0.191772 0.0188147" />
                        <site name="FDSL-P2" pos="0.0132048 -0.179498 0.00196586" />
                        <site name="FDSR-P2" pos="0.0150652 -0.178999 0.00256042" />
                        <site name="FDSM-P2" pos="0.0182106 -0.179383 0.00406598" />
                        <site name="FDSI-P2" pos="0.0205696 -0.178587 0.00529344" />
                        <site name="FDPL-P2" pos="0.0135117 -0.177561 0.00825662" />
                        <site name="FDPR-P2" pos="0.0151515 -0.178644 0.00770043" />
                        <site name="FDPM-P2" pos="0.0182777 -0.178788 0.00752781" />
                        <site name="FDPI-P2" pos="0.0199463 -0.177982 0.00877446" />
                        <site name="EDCL-P3" pos="0.00952244 -0.213886 0.0346951" />
                        <site name="EDCL-P2" pos="  0.0013 -0.0382544 0.0129514" />
                        <site name="EDCR-P3" pos="0.008458 -0.21448 0.0410817" />
                        <site name="EDCR-P2" pos="  0.0026 -0.0392844 0.0144214" />
                        <site name="EDCM-P3" pos="0.013809 -0.214068 0.0404968" />
                        <site name="EDCM-P2" pos=" 0.00316 -0.0388544 0.0141814" />
                        <site name="EDCI-P3" pos="0.0147008 -0.213982 0.0402378" />
                        <site name="EDCI-P2" pos=" 0.00228 -0.0385544 0.0137314" />
                        <site name="EDM-P4" pos="0.00435367 -0.217117 0.0352704" />
                        <site name="EIP-P3" pos="0.0103184 -0.218479 0.0351362" />
                        <site name="EPL-P2" pos="0.00118911 -0.13107 0.0217683" />
                        <site name="EPL-P3" pos="0.025911 -0.209743 0.0367089" />
                        <site name="EPL-P4" pos="0.0324319 -0.218201 0.0441792" />
                        <site name="EPL-P5" pos="0.0406022 -0.227954 0.0400173" />
                        <site name="EPB-P1" pos="0.0184503 -0.140919 0.0202724" />
                        <site name="EPB-P2" pos="0.0218259 -0.152062 0.0255562" />
                        <site name="EPB-P3" pos="0.0367376 -0.189126 0.0367664" />
                        <site name="EPB-P4" pos="0.0502014 -0.226419 0.0258823" />
                        <site name="FPL-P1" pos="0.00931147 -0.0906982 0.016964" />
                        <site name="FPL-P2" pos="0.0158995 -0.129699 0.018364" />
                        <site name="FPL-P3" pos="0.0179229 -0.17196 0.0190641" />
                        <site name="FPL-P4" pos="0.0364404 -0.2222 0.0151515" />
                        <site name="APL-P1" pos="0.0110664 -0.0908804 0.0161201" />
                        <site name="APL-P2" pos="0.0290564 -0.133966 0.0336306" />
                        <site name="APL-P3" pos="0.0382912 -0.154124 0.0326045" />
                        <site name="APL-P4" pos="0.0421653 -0.171126 0.0300537" />
                        <site name="APL-P5" pos="0.0527906 -0.221366 0.0227081" />
                        <joint name="pro_sup" type="hinge" pos="0 0 0" axis="-0.017161 0.992666 -0.119668" limited="true" range=" -1.5708   1.5708" ref="0" user="1" />
                        <body name="proximal_row" pos="0.0172612 -0.232068 0.0239739" quat="1.0 0.0 0.0 0.0">
                          <geom name="lunate" type="mesh" mesh="lunate" />
                          <geom name="sdfastSCAPHOIDw" type="mesh" mesh="sdfastSCAPHOIDw" />
                          <geom name="sdfastPISIFORMw" type="mesh" mesh="sdfastPISIFORMw" />
                          <geom name="sdfastTRIQUETRALw" type="mesh" mesh="sdfastTRIQUETRALw" />
                          <inertial pos="       0        0        0" mass="9.58957150300702e-05" fullinertia="8.81856e-06 8.81856e-06 8.81856e-06        0        0        0" />
                          <body name="hand" pos="0.00382816 -0.0144361 0.00223149" quat="1.0 0.0 0.0 0.0">
                            <geom name="sdfast_1seg_hand_fr_c_5mc" type="mesh" mesh="sdfast_1seg_hand_fr_c_5mc" />
                            <geom name="sdfast_1seg_hand_fr_c_4mc" type="mesh" mesh="sdfast_1seg_hand_fr_c_4mc" />
                            <geom name="sdfast_1seg_hand_fr_c_3mc" type="mesh" mesh="sdfast_1seg_hand_fr_c_3mc" />
                            <geom name="sdfast_1seg_hand_fr_c_trapezium" type="mesh" mesh="sdfast_1seg_hand_fr_c_trapezium" />
                            <geom name="sdfast_1seg_hand_fr_c_trapezoid" type="mesh" mesh="sdfast_1seg_hand_fr_c_trapezoid" />
                            <geom name="sdfast_1seg_hand_fr_c_hamate" type="mesh" mesh="sdfast_1seg_hand_fr_c_hamate" />
                            <geom name="capitate" type="mesh" mesh="capitate" />
                            <geom name="hand_3proxph" type="mesh" mesh="hand_3proxph" />
                            <geom name="hand_3midph" type="mesh" mesh="hand_3midph" />
                            <geom name="hand_3distph" type="mesh" mesh="hand_3distph" />
                            <geom name="hand_4proxph" type="mesh" mesh="hand_4proxph" />
                            <geom name="hand_4midph" type="mesh" mesh="hand_4midph" />
                            <geom name="hand_4distph" type="mesh" mesh="hand_4distph" />
                            <geom name="hand_5proxph" type="mesh" mesh="hand_5proxph" />
                            <geom name="hand_5midph" type="mesh" mesh="hand_5midph" />
                            <geom name="hand_5distph" type="mesh" mesh="hand_5distph" />
                            <geom name="hand_thumbprox" type="mesh" mesh="hand_thumbprox" />
                            <geom name="hand_thumbdist" type="mesh" mesh="hand_thumbdist" />
                            <geom name="hand_1mc" type="mesh" mesh="hand_1mc" />
                            <inertial pos="-0.00288947 -0.040755 -0.001076" mass="0.558017165759978" fullinertia="9.70041e-05 5.29114e-05 0.000132278 7.9367e-07 -1.76371e-07 1.05823e-05" />
                            <site name="ECRL-P4" pos="0.0164653 -0.0203491 0.00559072" />
                            <site name="ECRB-P4" pos="0.00479479 -0.0108938 0.00815114" />
                            <site name="ECU-P6" pos="-0.0215861 -0.013435 -0.00122747" />
                            <site name="FCR-P3" pos="0.0107787 -0.0176832 -0.00400844" />
                            <site name="FCU-P4" pos="-0.0195244 -0.0169256 -0.00721136" />
                            <site name="PL-P3" pos="0.00879364 -0.018201 -0.0168201" />
                            <site name="PL-P4" pos="0.00217683 -0.0296893 0.00472766" />
                            <site name="FDSL-P3" pos="-0.00225355 -0.0133583 -0.0131953" />
                            <site name="FDSL-P4" pos="-0.0191312 -0.041053 -0.00711546" />
                            <site name="FDSL-P5" pos="-0.0196011 -0.0573552 -0.0180092" />
                            <site name="FDSL-P6" pos="-0.0164269 -0.0694764 -0.0264001" />
                            <site name="FDSL-P7" pos="-0.0110855 -0.0697258 -0.0350595" />
                            <site name="FDSL-P8" pos="-0.0101554 -0.0697258 -0.036402" />
                            <site name="FDSR-P3" pos="-0.000786345 -0.0128884 -0.0130322" />
                            <site name="FDSR-P4" pos="-0.00936901 -0.0496644 3.83583e-005" />
                            <site name="FDSR-P5" pos="-0.012687 -0.0639624 -0.00978136" />
                            <site name="FDSR-P6" pos="-0.00755658 -0.0769755 -0.0240027" />
                            <site name="FDSR-P7" pos="-0.00286728 -0.0779153 -0.0325566" />
                            <site name="FDSR-P8" pos="0.000594553 -0.0775988 -0.0373226" />
                            <site name="FDSM-P3" pos="0.00652091 -0.0132048 -0.0134158" />
                            <site name="FDSM-P4" pos="0.00451669 -0.0319525 -0.00126582" />
                            <site name="FDSM-P5" pos="0.00519755 -0.054277 0.000575374" />
                            <site name="FDSM-P6" pos="0.00532221 -0.0692751 -0.00324128" />
                            <site name="FDSM-P7" pos="0.011191 -0.0844841 -0.0160146" />
                            <site name="FDSM-P8" pos="0.012476 -0.0850595 -0.0285482" />
                            <site name="FDSM-P9" pos="0.0150364 -0.0822498 -0.0361047" />
                            <site name="FDSI-P3" pos="0.00852513 -0.0130994 -0.0133007" />
                            <site name="FDSI-P4" pos="0.0101745 -0.0363157 0.00023015" />
                            <site name="FDSI-P5" pos="0.0170886 -0.0489835 0.00400844" />
                            <site name="FDSI-P6" pos="0.0177311 -0.0699751 -0.00359609" />
                            <site name="FDSI-P7" pos="0.0256809 -0.0835635 -0.0172996" />
                            <site name="FDSI-P8" pos="0.0255754 -0.0838129 -0.0256809" />
                            <site name="FDSI-P9" pos="0.0255083 -0.0827868 -0.0278385" />
                            <site name="FDPL-P3" pos="-0.000843882 -0.00984849 -0.0113924" />
                            <site name="FDPL-P4" pos="-0.0177887 -0.0445531 -0.00702916" />
                            <site name="FDPL-P5" pos="-0.0173379 -0.0560127 -0.0149597" />
                            <site name="FDPL-P6" pos="-0.0136939 -0.0698984 -0.0257288" />
                            <site name="FDPL-P7" pos="-0.00882241 -0.0717588 -0.035328" />
                            <site name="FDPL-P8" pos="-0.00299195 -0.0710108 -0.0399406" />
                            <site name="FDPL-P9" pos="0.00427695 -0.0676928 -0.0446586" />
                            <site name="FDPR-P3" pos="0.00101649 -0.0112869 -0.0113541" />
                            <site name="FDPR-P4" pos="-0.00819908 -0.0531454 0.000843882" />
                            <site name="FDPR-P5" pos="-0.0103471 -0.0631761 -0.00783468" />
                            <site name="FDPR-P6" pos="-0.0052455 -0.0781934 -0.0216341" />
                            <site name="FDPR-P7" pos="-0.000537016 -0.0789222 -0.0322881" />
                            <site name="FDPR-P8" pos="0.00584005 -0.0751535 -0.0406406" />
                            <site name="FDPR-P9" pos="0.011613 -0.070771 -0.0465861" />
                            <site name="FDPM-P3" pos="0.00321251 -0.0122747 -0.0109705" />
                            <site name="FDPM-P4" pos="0.00289605 -0.0330553 -0.00585923" />
                            <site name="FDPM-P5" pos="0.00241657 -0.0562237 0.00116993" />
                            <site name="FDPM-P6" pos="0.00273303 -0.0669832 -0.00127541" />
                            <site name="FDPM-P7" pos="0.0082758 -0.0841868 -0.0174051" />
                            <site name="FDPM-P8" pos="0.00960875 -0.0840622 -0.0284235" />
                            <site name="FDPM-P9" pos="0.0156598 -0.0782221 -0.0425297" />
                            <site name="FDPM-P10" pos="0.0183065 -0.0734849 -0.0501439" />
                            <site name="FDPI-P3" pos="0.00859226 -0.0112006 -0.0116226" />
                            <site name="FDPI-P4" pos="0.0184312 -0.0531454 0.00420023" />
                            <site name="FDPI-P5" pos="0.0198792 -0.0673284 -0.00274262" />
                            <site name="FDPI-P6" pos="0.0278481 -0.0823552 -0.0170886" />
                            <site name="FDPI-P7" pos="0.0280399 -0.0831608 -0.0265535" />
                            <site name="FDPI-P8" pos="0.027944 -0.0789701 -0.0381569" />
                            <site name="FDPI-P9" pos="0.0273015 -0.0745206 -0.0457039" />
                            <site name="EDCL-P4" pos="-0.0236287 -0.0422133 0.00162064" />
                            <site name="EDCL-P5" pos="-0.0228328 -0.045397 0.000738397" />
                            <site name="EDCL-P6" pos="-0.022967 -0.0634158 -0.00959916" />
                            <site name="EDCL-P7" pos="-0.017242 -0.0752494 -0.0259973" />
                            <site name="EDCL-P8" pos="-0.0112965 -0.0755371 -0.036239" />
                            <site name="EDCL-P9" pos="-0.00143844 -0.0727465 -0.0439778" />
                            <site name="EDCL-P10" pos="0.0019275 -0.0717971 -0.0459724" />
                            <site name="EDCR-P4" pos="-0.0149981 -0.0532221 0.00895666" />
                            <site name="EDCR-P5" pos="-0.0136843 -0.0558017 0.0111335" />
                            <site name="EDCR-P6" pos="-0.0151515 -0.0691983 -0.00403721" />
                            <site name="EDCR-P7" pos="-0.0079114 -0.0837649 -0.0216724" />
                            <site name="EDCR-P8" pos="-0.00260836 -0.0844458 -0.0326908" />
                            <site name="EDCR-P9" pos="0.00731684 -0.0769659 -0.0446682" />
                            <site name="EDCR-P10" pos="0.0102513 -0.074885 -0.0473821" />
                            <site name="EDCM-P4" pos="0.000373993 -0.0505754 0.0142981" />
                            <site name="EDCM-P5" pos="-0.000834293 -0.0534523 0.0139241" />
                            <site name="EDCM-P6" pos="0.00178366 -0.0740123 0.00572497" />
                            <site name="EDCM-P7" pos="0.0096567 -0.0893077 -0.0170119" />
                            <site name="EDCM-P8" pos="0.0126678 -0.0916571 -0.0293057" />
                            <site name="EDCM-P9" pos="0.0178078 -0.0817511 -0.0456368" />
                            <site name="EDCM-P10" pos="0.0197162 -0.0766494 -0.0512179" />
                            <site name="EDCM-P11" pos="0.0210491 -0.0738493 -0.0543057" />
                            <site name="EDCI-P4" pos="0.0147967 -0.0448792 0.0157173" />
                            <site name="EDCI-P5" pos="0.0181914 -0.0542194 0.0137898" />
                            <site name="EDCI-P6" pos="0.0191216 -0.0736287 0.00569621" />
                            <site name="EDCI-P7" pos="0.0282413 -0.0878597 -0.011939" />
                            <site name="EDCI-P8" pos="0.0299291 -0.0896529 -0.0278577" />
                            <site name="EDCI-P9" pos="0.0288934 -0.0813867 -0.0409283" />
                            <site name="EDCI-P10" pos="0.0280879 -0.0777043 -0.0476218" />
                            <site name="EDM-P5" pos="-0.0197449 -0.00989644 0.00356732" />
                            <site name="EDM-P6" pos="-0.0245781 -0.045282 0.00022056" />
                            <site name="EDM-P7" pos="-0.0244438 -0.0624377 -0.0105293" />
                            <site name="EDM-P8" pos="-0.0185366 -0.0748946 -0.0260645" />
                            <site name="EDM-P9" pos="-0.0129076 -0.0756809 -0.0373418" />
                            <site name="EDM-P10" pos="-0.00207135 -0.0721232 -0.0440065" />
                            <site name="EDM-P11" pos="0.00126582 -0.0704354 -0.0460587" />
                            <site name="EIP-P4" pos="0.00372075 -0.0214231 0.0113541" />
                            <site name="EIP-P5" pos="0.0162351 -0.0540852 0.0132048" />
                            <site name="EIP-P6" pos="0.0166379 -0.073763 0.00557154" />
                            <site name="EIP-P7" pos="0.0265152 -0.0893173 -0.0144898" />
                            <site name="EIP-P8" pos="0.0276084 -0.0904968 -0.0270714" />
                            <site name="EIP-P9" pos="0.0275221 -0.0817415 -0.0411872" />
                            <site name="EIP-P10" pos="0.0271768 -0.0746548 -0.0527522" />
                            <site name="EPL-P6" pos="0.0232835 0.000134254 0.00583046" />
                            <site name="EPL-P7" pos="0.0224204 -0.00879364 -0.000373993" />
                            <site name="EPL-P8" pos="0.0278577 -0.0136843 -0.0046893" />
                            <site name="EPL-P9" pos="0.0423284 -0.0327676 -0.0173955" />
                            <site name="EPL-P10" pos="0.0466724 -0.0445531 -0.0238493" />
                            <site name="EPL-P11" pos="0.0455601 -0.0672229 -0.036191" />
                            <site name="EPL-P12" pos="0.0384638 -0.0725451 -0.0410721" />
                            <site name="EPB-P5" pos="0.0299482 0.00245493 -0.00313579" />
                            <site name="EPB-P6" pos="0.0285002 -0.00761412 -0.0137706" />
                            <site name="EPB-P7" pos="0.0424051 -0.0316456 -0.0232259" />
                            <site name="EPB-P8" pos="0.0434216 -0.0458861 -0.0305524" />
                            <site name="FPL-P6" pos="0.0119294 -0.0211642 -0.0200326" />
                            <site name="FPL-P7" pos="0.0157365 -0.0251343 -0.0212984" />
                            <site name="FPL-P8" pos="0.0235616 -0.031588 -0.0214519" />
                            <site name="FPL-P9" pos="0.0271097 -0.05257 -0.0292961" />
                            <site name="FPL-P10" pos="0.033669 -0.0625144 -0.0359513" />
                            <site name="FPL-P11" pos="0.03388 -0.0734178 -0.0394899" />
                            <site name="FPL-P5" pos="0.0178892 0.0064176 -0.0168214" />
                            <site name="APL-P7" pos="0.0248082 0.00196586 -0.0158228" />
                            <site name="APL-P8" pos="0.0275988 -0.00646337 -0.0179325" />
                            <site name="APL-P9" pos="0.0294975 -0.0151803 -0.0180763" />
                            <site name="APL-P6" pos="0.0332244 0.00608975 -0.00870125" />
                            <body name="index0" pos="0 0 0">
                              <inertial pos="0 0 0" mass="0.001" diaginertia="0.001 0.001 0.001" />
                              <geom name="sdfast_1seg_hand_fr_c_2mc" type="mesh" mesh="sdfast_1seg_hand_fr_c_2mc" />
                              <body name="index1" pos="0 0 0">
                                <inertial pos="0 0 0" mass="0.001" diaginertia="0.001 0.001 0.001" />
                                <geom name="hand_2proxph" type="mesh" mesh="hand_2proxph" />
                                <body name="index2" pos="0 0 0">
                                  <inertial pos="0 0 0" mass="0.001" diaginertia="0.001 0.001 0.001" />
                                  <geom name="hand_2midph" type="mesh" mesh="hand_2midph" />
                                  <body name="index3" pos="0 0 0">
                                    <inertial pos="0 0 0" mass="0.001" diaginertia="0.001 0.001 0.001" />
                                    <geom name="hand_2distph" type="mesh" mesh="hand_2distph" />
                                    <site name="fingertip" pos="0.024 -0.149 -0.0065" type="sphere" rgba="0.1 0.8 0.1 0.0" size="0.004" />
                                  </body>
                                </body>
                              </body>
                            </body>
                          </body>
                        </body>
                      </body>
                    </body>
                  </body>
                </body>
              </body>
            </body>
          </body>
        </body>
      </body>
    </body>

</mujocoinclude>