<mujocoinclude model="MoBL Arms Index Model">

    <body name="thorax" pos="0 0 0" quat="0.7071067811865475 0.7071067811865475 0.0 0.0">
      <light mode="trackcom" directional="false" pos="0 0 4.0" dir="0 0 -1" />
      <geom name="thorax" type="mesh" mesh="thorax" />
      <site name="PECM1-P3" pos="  -7e-05  0.00821  0.10454" />
      <site name="PECM2-P4" pos="0.0336308 -0.0426723 0.105593" />
      <site name="PECM2-P5" pos="0.0301273 -0.0489393 0.024709" />
      <site name="PECM2-P3" pos=" 0.02083 -0.02005  0.11555" />
      <site name="PECM3-P4" pos="0.0571212 -0.0915789 0.0972148" />
      <site name="PECM3-P5" pos="0.0622784 -0.126798 0.0412034" />
      <site name="PECM3-P3" pos=" 0.02984 -0.0544459   0.1151" />
      <site name="LAT1-P4" pos="-0.128691 -0.110086 0.0360788" />
      <site name="LAT1-P5" pos="-0.104211 -0.12756 0.00959636" />
      <site name="LAT2-P4" pos="-0.119595 -0.183963 0.0313133" />
      <site name="LAT2-P5" pos="-0.0781853 -0.204744 0.00886739" />
      <site name="LAT3-P4" pos="-0.121391 -0.210935 0.0601894" />
      <site name="LAT3-P5" pos="-0.0774346 -0.270461 0.00986837" />
      <joint name="r_z" type="hinge" pos="0 0 0" axis="       0        0        1" limited="true" range="-6.28319  6.28319" ref="0" armature="0" damping="0" stiffness="0" />
      <body name="clavicle" pos="0.00688174  0.00754 0.0277065" quat="1.0 0.0 0.0 0.0">
        <geom name="clavicle" type="mesh" mesh="clavicle" />
        <inertial pos="-0.0120727 0.00693321 0.058936" mass="0.169731543608673" fullinertia="0.000312454 0.000328773 5.72127e-05 -2.44461e-05 -9.00823e-05 6.91782e-05" />
        <site name="DELT1-P4" pos="-0.0152323 0.0120335 0.0872703" />
        <site name="DELT2-P2" pos="0.0191703 0.0244002 0.162891" />
        <site name="PECM1-P4" pos="0.00349255 -0.000141443 0.0556306" />
        <joint name="sternoclavicular_r2" type="hinge" pos="0 0 0" axis="  0.0153 0.989299  -0.1451" limited="false" range="-99999.9  99999.9" ref="0" />
        <joint name="sternoclavicular_r3" type="hinge" pos="0 0 0" axis="-0.994473        0 -0.104997" limited="false" range="-99999.9  99999.9" ref="0" />
        <body name="clavphant" pos="-0.0155914 0.0218366 0.147465" quat="1.0 0.0 0.0 0.0">
          <inertial pos="       0        0        0" mass="0.000108802271544021" fullinertia=" 1.28799  1.28799  1.28799        0        0        0" />
          <joint name="unrotscap_r3" type="hinge" pos="0 0 0" axis="-0.994473        0 -0.104997" limited="false" range="-99999.9  99999.9" ref="0" />
          <joint name="unrotscap_r2" type="hinge" pos="0 0 0" axis="  0.0153 0.989299  -0.1451" limited="false" range="-99999.9  99999.9" ref="0" />
          <body name="scapula" pos="       0        0        0" quat="1.0 0.0 0.0 0.0">
            <geom name="scapula" type="mesh" mesh="scapula" />
            <inertial pos="-0.0595083 -0.0381156 -0.0475836" mass="0.765924470761292" fullinertia="0.00160085 0.00148171 0.00175824 0.000578825 0.000527073 0.000310535" />
            <site name="DELT1-P3" pos="0.0472963 -0.0353825 0.00107714" />
            <site name="DELT2-P3" pos="5.44011e-005 0.00319879 0.0242955" />
            <site name="DELT2-P4" pos="-0.0117289 -0.000369928 0.00674574" />
            <site name="DELT3-P1" pos="-0.0606355 0.00132739 -0.0273311" />
            <site name="DELT3-P2" pos="-0.078849 -0.0357415 0.0134153" />
            <site name="SUPSP-P2" pos="-0.0208683 0.00138179 -0.0138288" />
            <site name="SUPSP-P3" pos="-0.047873 -0.0164509 -0.0637037" />
            <site name="INFSP-P2" pos="-0.0803178 -0.0595801 -0.0520184" />
            <site name="SUBSC-P2" pos="-0.0199217 -0.0568274 -0.0267327" />
            <site name="SUBSC-P3" pos="-0.0788381 -0.0429007 -0.0704495" />
            <site name="TMIN-P2" pos="-0.103068 -0.0869439 -0.0515396" />
            <site name="TMIN-P3" pos="-0.104918 -0.0883583 -0.0576434" />
            <site name="TMAJ-P2" pos="-0.111675 -0.112273 -0.0634208" />
            <site name="TMAJ-P3" pos="-0.114123 -0.11854 -0.0774346" />
            <site name="LAT1-P2" pos="-0.08052 -0.06821 -0.02908" />
            <site name="LAT1-P3" pos="-0.10925 -0.07239 -0.07422" />
            <site name="LAT2-P2" pos="-0.08345 -0.08695 -0.02453" />
            <site name="LAT2-P3" pos="-0.11524 -0.10749 -0.08863" />
            <site name="LAT3-P2" pos="-0.08438 -0.11598 -0.02995" />
            <site name="LAT3-P3" pos="-0.11279 -0.13833 -0.08911" />
            <site name="CORB-P1" pos="0.0136003 -0.0449027 -0.0288544" />
            <site name="CORB-P2" pos="0.00525515 -0.0757046 -0.0170058" />
            <site name="TRIlong-P1" pos="-0.0496682 -0.0443152 -0.0149821" />
            <site name="BIClong-P1" pos="-0.0339789 -0.0256012 -0.0141987" />
            <site name="BIClong-P2" pos="-0.0227832 -0.0142422 -0.00501578" />
            <site name="BICshort-P1" pos="0.0137961 -0.0427702 -0.0285606" />
            <site name="BICshort-P2" pos="0.00101186 -0.072941 -0.0173322" />
            <joint name="acromioclavicular_r2" type="hinge" pos="0 0 0" axis="0.157095 0.947269 -0.279291" limited="false" range="-99999.9  99999.9" ref="0" />
            <joint name="acromioclavicular_r3" type="hinge" pos="0 0 0" axis="-0.754084 0.297594 0.585487" limited="false" range="-99999.9  99999.9" ref="0" />
            <joint name="acromioclavicular_r1" type="hinge" pos="0 0 0" axis="  0.6377   0.1186   0.7611" limited="false" range="-99999.9  99999.9" ref="0" />
            <body name="scapphant" pos="-0.0103906 -0.0369928 0.0097922" quat="1.0 0.0 0.0 0.0">
              <inertial pos="       0        0        0" mass="0.000108802271544021" fullinertia=" 1.28799  1.28799  1.28799        0        0        0" />
              <joint name="unrothum_r1" type="hinge" pos="0 0 0" axis="  0.6377   0.1186   0.7611" limited="false" range="-99999.9  99999.9" ref="0" />
              <joint name="unrothum_r3" type="hinge" pos="0 0 0" axis="-0.754084 0.297594 0.585487" limited="false" range="-99999.9  99999.9" ref="0" />
              <joint name="unrothum_r2" type="hinge" pos="0 0 0" axis="0.157095 0.947269 -0.279291" limited="false" range="-99999.9  99999.9" ref="0" />
              <body name="humphant" pos="       0        0        0" quat="1.0 0.0 0.0 0.0">
                <inertial pos="       0        0        0" mass="0.000108802271544021" fullinertia=" 1.28799  1.28799  1.28799        0        0        0" />
                <joint name="elv_angle" type="hinge" pos="0 0 0" axis="  0.0048 0.999089   0.0424" limited="true" range=" -1.5708  2.26893" ref="0" user="1" />
                <body name="humphant1" pos="       0        0        0" quat="1.0 0.0 0.0 0.0">
                  <inertial pos="       0        0        0" mass="0.000108802271544021" fullinertia=" 1.28799  1.28799  1.28799        0        0        0" />
                  <joint name="shoulder_elv" type="hinge" pos="0 0 0" axis="-0.998261   0.0023 0.058898" limited="true" range="       0  3.14159" ref="0" user="1" />
                  <joint name="shoulder1_r2" type="hinge" pos="0 0 0" axis="  0.0048 0.999089   0.0424" limited="false" range="-99999.9  99999.9" ref="0" />
                  <body name="humerus" pos="       0        0        0" quat="1.0 0.0 0.0 0.0">
                    <geom name="humerus" type="mesh" mesh="humerus" />
                    <inertial pos="0.019654 -0.152477 -0.0138679" mass="2.17340153568191" fullinertia="0.0158135 0.0032861 0.0162015 -0.000447462 -0.000299459 0.00158333" />
                    <site name="DELT1-P1" pos="0.00974868 -0.12929 0.00636493" />
                    <site name="DELT1-P2" pos="0.0176586 -0.120042 0.00448265" />
                    <site name="DELT2-P1" pos="0.00501578 -0.148091 0.00609293" />
                    <site name="DELT3-P3" pos="0.00224133 -0.0827115 0.0113698" />
                    <site name="SUPSP-P1" pos="0.00278534 0.0115657 0.0282124" />
                    <site name="INFSP-P1" pos="-0.00965076 0.00526603 0.0266348" />
                    <site name="SUBSC-P1" pos="0.015265 0.00913939 -0.0144816" />
                    <site name="TMIN-P1" pos="-0.00119682 -0.0137526 0.0234578" />
                    <site name="TMAJ-P1" pos="0.0108585 -0.05896 -0.00617997" />
                    <site name="PECM1-P1" pos="0.012719 -0.045599 0.00848658" />
                    <site name="PECM1-P2" pos="  0.0191  -0.0301  0.00143" />
                    <site name="PECM2-P1" pos="0.0138614 -0.0466653 0.00854098" />
                    <site name="PECM2-P2" pos=" 0.01748 -0.03533  0.00033" />
                    <site name="PECM3-P1" pos="0.013807 -0.047601 0.00816017" />
                    <site name="PECM3-P2" pos="0.0159185 -0.045833 -0.00378312" />
                    <site name="LAT1-P1" pos="0.0114242 -0.037156 -0.00710479" />
                    <site name="LAT2-P1" pos="0.0105321 -0.0442934 -0.00664782" />
                    <site name="LAT3-P1" pos="0.0131433 -0.0426723 -0.00452617" />
                    <site name="CORB-P3" pos="0.00808401 -0.163726 -0.00850834" />
                    <site name="TRIlong-P2" pos="-0.0295289 -0.124481 -0.00722447" />
                    <site name="TRIlong-P3" pos="-0.0346426 -0.246296 -0.0132412" />
                    <site name="TRIlong-P4" pos="-0.0189642 -0.291122 -0.0131433" />
                    <site name="TRIlat-P1" pos="-0.00651726 -0.137591 0.00465674" />
                    <site name="TRIlat-P2" pos="-0.0255033 -0.158068 0.0100969" />
                    <site name="TRIlat-P3" pos="-0.0346426 -0.246296 -0.0132412" />
                    <site name="TRIlat-P4" pos="-0.0189642 -0.291122 -0.0131433" />
                    <site name="TRImed-P1" pos="-0.00911763 -0.149005 -0.00985749" />
                    <site name="TRImed-P2" pos="-0.0282995 -0.164716 -0.0117506" />
                    <site name="TRImed-P3" pos="-0.0346426 -0.246296 -0.0132412" />
                    <site name="TRImed-P4" pos="-0.0189642 -0.291122 -0.0131433" />
                    <site name="ANC-P1" pos="-0.00809489 -0.308552 0.0106517" />
                    <site name="BIClong-P3" pos="0.0231858 0.0195082 0.0111849" />
                    <site name="BIClong-P4" pos="0.0258732 -0.0055598 0.0130672" />
                    <site name="BIClong-P5" pos="0.0146339 -0.0307584 0.00147971" />
                    <site name="BIClong-P6" pos="0.0116201 -0.0841694 -0.00179524" />
                    <site name="BIClong-P7" pos="0.018529 -0.131923 0.000261125" />
                    <site name="BIClong-P8" pos="0.0248069 -0.190839 -0.00685454" />
                    <site name="BICshort-P3" pos="0.0121532 -0.0824286 -0.0119791" />
                    <site name="BICshort-P4" pos="0.018529 -0.131923 -0.0117398" />
                    <site name="BICshort-P5" pos="0.0248069 -0.190839 -0.00685454" />
                    <site name="BRA-P1" pos="0.00739855 -0.189207 -0.00391688" />
                    <site name="BRA-P2" pos="0.0206072 -0.310728 -0.0120227" />
                    <site name="BRD-P1" pos="-0.0106626 -0.217202 0.00242629" />
                    <site name="ECRL-P1" pos="-0.00794257 -0.283865 0.00990101" />
                    <site name="ECRB-P1" pos="0.0146774 -0.316049 0.0184746" />
                    <site name="ECU-P1" pos="0.000903059 -0.315037 0.0204548" />
                    <site name="FCR-P1" pos="0.00824721 -0.302536 -0.0403112" />
                    <site name="FCU-P1" pos="0.00238277 -0.301818 -0.0422153" />
                    <site name="PL-P1" pos="0.00497226 -0.299413 -0.0420521" />
                    <site name="PT-P1" pos="0.00391688 -0.300185 -0.0397128" />
                    <site name="FDSL-P1" pos="0.00458058 -0.300273 -0.0420412" />
                    <site name="FDSR-P1" pos="0.00521163 -0.303341 -0.0405941" />
                    <site name="EDCL-P1" pos="-0.000435209 -0.313688 0.020346" />
                    <site name="EDCR-P1" pos="-0.00169732 -0.31483 0.0193886" />
                    <site name="EDCM-P1" pos="0.000554892 -0.315353 0.0212056" />
                    <site name="EDCI-P1" pos="0.000707215 -0.314417 0.0203351" />
                    <site name="EDM-P1" pos="0.00096834 -0.314645 0.0200958" />
                    <joint name="shoulder_rot" type="hinge" pos="0 0 0" axis="  0.0048 0.999089   0.0424" limited="true" range=" -1.5708 0.349066" ref="0" user="1" />
                    <body name="ulna" pos="0.00663694 -0.315962 -0.0133827" quat="1.0 0.0 0.0 0.0">
                      <geom name="ulna" type="mesh" mesh="ulna" />
                      <inertial pos="0.0105732 -0.104397 0.0264237" mass="1.20259150737607" fullinertia="0.00697203 0.00148529 0.00636734 0.000408114 -9.80808e-05 0.00140609" />
                      <site name="TRIlong-P5" pos="-0.0238277 0.0113807 -0.000848658" />
                      <site name="TRIlat-P5" pos="-0.0238277 0.0113807 -0.000848658" />
                      <site name="TRImed-P5" pos="-0.0238277 0.0113807 -0.000848658" />
                      <site name="ANC-P2" pos="-0.0275487 -0.00134915 0.00652814" />
                      <site name="SUP-P3" pos="-0.0147971 -0.0368187 0.0219019" />
                      <site name="BRA-P4" pos="-0.00348167 -0.0260037 0.00097922" />
                      <site name="BRA-P3" pos="0.00541835 -0.0159178 0.00139267" />
                      <site name="ECU-P2" pos="-0.0151344 -0.0348276 0.032064" />
                      <site name="ECU-P3" pos="-0.0185508 -0.0590579 0.0312045" />
                      <site name="ECU-P4" pos="-0.0195082 -0.104156 0.0356654" />
                      <site name="PT-P2" pos="0.00920467 -0.036699 -0.0155805" />
                      <site name="PT-P3" pos=" 0.01219 -0.06516 -0.00219" />
                      <site name="PQ-P2" pos="0.00209988 -0.22818 0.039517" />
                      <site name="FDSM-P1" pos="-0.00727887 -0.0295181 -0.00207812" />
                      <site name="FDSI-P1" pos="-0.00735503 -0.0306714 -0.00149059" />
                      <site name="FDPL-P1" pos="-0.00683278 -0.0349691 0.00276358" />
                      <site name="FDPR-P1" pos="-0.00546187 -0.0367099 0.0029703" />
                      <site name="FDPM-P1" pos="-0.00567948 -0.0361985 0.00228485" />
                      <site name="FDPI-P1" pos="-0.00703951 -0.0345556 0.00304646" />
                      <site name="EDM-P2" pos="-0.01063 -0.042509 0.0335655" />
                      <site name="EDM-P3" pos="-0.00821457 -0.0899468 0.0396693" />
                      <site name="EIP-P1" pos="-0.00428681 -0.181178 0.040061" />
                      <site name="EIP-P2" pos="0.00186052 -0.190067 0.044054" />
                      <site name="EPL-P1" pos="-0.0153629 -0.105603 0.0321184" />
                      <joint name="elbow_flexion" type="hinge" pos="0 0 0" axis="  0.0494   0.0366 0.998108" limited="true" range="       0  4.26893" ref="0" user="1" />
                      <body name="radius" pos="0.000435209 -0.0125155 0.0217594" quat="1.0 0.0 0.0 0.0">
                        <geom name="radius" type="mesh" mesh="radius" />
                        <inertial pos="0.0365947 -0.19754 0.0169732" mass="0.254151226099679" fullinertia="0.00056485 0.000114103 0.000518521 3.88201e-05 -5.4611e-06 8.26635e-05" />
                        <site name="SUP-P1" pos="0.0108367 -0.0663259 0.000816017" />
                        <site name="SUP-P2" pos="0.0130672 -0.0562508 -0.00116418" />
                        <site name="BIClong-P11" pos="-0.00217605 -0.0408009 -0.00217605" />
                        <site name="BIClong-P9" pos=" 0.00273 -0.0343493 -0.0119845" />
                        <site name="BICshort-P8" pos="-0.00217605 -0.0408009 -0.00217605" />
                        <site name="BICshort-P6" pos=" 0.00273 -0.0343493 -0.0119845" />
                        <site name="BRD-P2" pos="0.0389186 -0.138636 0.0251877" />
                        <site name="BRD-P3" pos="0.0455882 -0.240453 0.0243717" />
                        <site name="ECRL-P2" pos="0.0347623 -0.14648 0.0302362" />
                        <site name="ECRL-P3" pos="0.0461648 -0.257687 0.0393864" />
                        <site name="ECRB-P2" pos="0.0316071 -0.142379 0.0259493" />
                        <site name="ECRB-P3" pos="0.0386139 -0.248124 0.0428355" />
                        <site name="ECU-P5" pos="-0.0154608 -0.246938 0.0378741" />
                        <site name="FCR-P2" pos="0.0229573 -0.238745 0.00138179" />
                        <site name="FCU-P3" pos="0.0117724 -0.242923 0.0105429" />
                        <site name="FCU-P2" pos="0.0101156 -0.183524 0.00202653" />
                        <site name="PL-P2" pos="0.0275379 -0.260201 -0.00300294" />
                        <site name="PT-P5" pos="0.0276358 -0.118377 0.0215428" />
                        <site name="PT-P4" pos="0.0256773 -0.101621 0.0102274" />
                        <site name="PQ-P1" pos="0.0353063 -0.217583 0.021347" />
                        <site name="FDSL-P2" pos="0.0149821 -0.203656 0.00223045" />
                        <site name="FDSR-P2" pos="0.0170928 -0.20309 0.00290502" />
                        <site name="FDSM-P2" pos="0.0206616 -0.203526 0.00461322" />
                        <site name="FDSI-P2" pos="0.0233381 -0.202622 0.00600589" />
                        <site name="FDPL-P2" pos="0.0153302 -0.201458 0.00936788" />
                        <site name="FDPR-P2" pos="0.0171908 -0.202688 0.00873682" />
                        <site name="FDPM-P2" pos="0.0207377 -0.202851 0.00854098" />
                        <site name="FDPI-P2" pos="0.0226309 -0.201937 0.00995541" />
                        <site name="EDCL-P3" pos="0.0108041 -0.242673 0.0393647" />
                        <site name="EDCL-P2" pos="  0.0013 -0.0382544 0.0129514" />
                        <site name="EDCR-P3" pos="0.00959636 -0.243347 0.0466109" />
                        <site name="EDCR-P2" pos="  0.0026 -0.0392844 0.0144214" />
                        <site name="EDCM-P3" pos="0.0156675 -0.242879 0.0459472" />
                        <site name="EDCM-P2" pos=" 0.00316 -0.0388544 0.0141814" />
                        <site name="EDCI-P3" pos="0.0166794 -0.242781 0.0456534" />
                        <site name="EDCI-P2" pos=" 0.00228 -0.0385544 0.0137314" />
                        <site name="EDM-P4" pos="0.00493962 -0.246339 0.0400175" />
                        <site name="EIP-P3" pos="0.0117071 -0.247884 0.0398652" />
                        <site name="EPL-P2" pos="0.00134915 -0.148711 0.0246981" />
                        <site name="EPL-P3" pos="0.0293984 -0.237972 0.0416495" />
                        <site name="EPL-P4" pos="0.0367969 -0.247569 0.0501252" />
                        <site name="EPL-P5" pos="0.0460669 -0.258634 0.0454032" />
                        <site name="EPB-P1" pos="0.0209336 -0.159885 0.0230008" />
                        <site name="EPB-P2" pos="0.0247634 -0.172528 0.0289958" />
                        <site name="EPB-P3" pos="0.0416822 -0.21458 0.0417148" />
                        <site name="EPB-P4" pos="0.056958 -0.256893 0.0293657" />
                        <site name="FPL-P1" pos="0.0105647 -0.102905 0.0192471" />
                        <site name="FPL-P2" pos="0.0180394 -0.147155 0.0208356" />
                        <site name="FPL-P3" pos="0.0203351 -0.195104 0.0216299" />
                        <site name="FPL-P4" pos="0.0413449 -0.252106 0.0171908" />
                        <site name="APL-P1" pos="0.0125558 -0.103112 0.0182897" />
                        <site name="APL-P2" pos="0.0329671 -0.151997 0.038157" />
                        <site name="APL-P3" pos="0.0434447 -0.174867 0.0369928" />
                        <site name="APL-P4" pos="0.0478404 -0.194158 0.0340986" />
                        <site name="APL-P5" pos="0.0598957 -0.251159 0.0257644" />
                        <joint name="pro_sup" type="hinge" pos="0 0 0" axis="-0.017161 0.992666 -0.119668" limited="true" range=" -1.5708   1.5708" ref="0" user="1" />
                        <body name="proximal_row" pos="0.0195844 -0.263301 0.0272006" quat="1.0 0.0 0.0 0.0">
                          <geom name="lunate" type="mesh" mesh="lunate" />
                          <geom name="sdfastSCAPHOIDw" type="mesh" mesh="sdfastSCAPHOIDw" />
                          <geom name="sdfastPISIFORMw" type="mesh" mesh="sdfastPISIFORMw" />
                          <geom name="sdfastTRIQUETRALw" type="mesh" mesh="sdfastTRIQUETRALw" />
                          <inertial pos="       0        0        0" mass="0.000108802271544021" fullinertia="1.28799e-05 1.28799e-05 1.28799e-05        0        0        0" />
                          <body name="hand" pos="0.00434339 -0.0163791 0.00253183" quat="1.0 0.0 0.0 0.0">
                            <geom name="sdfast_1seg_hand_fr_c_5mc" type="mesh" mesh="sdfast_1seg_hand_fr_c_5mc" />
                            <geom name="sdfast_1seg_hand_fr_c_4mc" type="mesh" mesh="sdfast_1seg_hand_fr_c_4mc" />
                            <geom name="sdfast_1seg_hand_fr_c_3mc" type="mesh" mesh="sdfast_1seg_hand_fr_c_3mc" />
                            <geom name="sdfast_1seg_hand_fr_c_trapezium" type="mesh" mesh="sdfast_1seg_hand_fr_c_trapezium" />
                            <geom name="sdfast_1seg_hand_fr_c_trapezoid" type="mesh" mesh="sdfast_1seg_hand_fr_c_trapezoid" />
                            <geom name="sdfast_1seg_hand_fr_c_hamate" type="mesh" mesh="sdfast_1seg_hand_fr_c_hamate" />
                            <geom name="capitate" type="mesh" mesh="capitate" />
                            <geom name="hand_3proxph" type="mesh" mesh="hand_3proxph" />
                            <geom name="hand_3midph" type="mesh" mesh="hand_3midph" />
                            <geom name="hand_3distph" type="mesh" mesh="hand_3distph" />
                            <geom name="hand_4proxph" type="mesh" mesh="hand_4proxph" />
                            <geom name="hand_4midph" type="mesh" mesh="hand_4midph" />
                            <geom name="hand_4distph" type="mesh" mesh="hand_4distph" />
                            <geom name="hand_5proxph" type="mesh" mesh="hand_5proxph" />
                            <geom name="hand_5midph" type="mesh" mesh="hand_5midph" />
                            <geom name="hand_5distph" type="mesh" mesh="hand_5distph" />
                            <geom name="hand_thumbprox" type="mesh" mesh="hand_thumbprox" />
                            <geom name="hand_thumbdist" type="mesh" mesh="hand_thumbdist" />
                            <geom name="hand_1mc" type="mesh" mesh="hand_1mc" />
                            <inertial pos="-0.00327836 -0.0462402 -0.00122082" mass="0.63312041811466" fullinertia="0.000141679 7.72796e-05 0.000193199 1.15919e-06 -2.57599e-07 1.54559e-05" />
                            <site name="ECRL-P4" pos="0.0186814 -0.0230878 0.00634317" />
                            <site name="ECRB-P4" pos="0.00544011 -0.0123599 0.00924819" />
                            <site name="ECU-P6" pos="-0.0244914 -0.0152432 -0.00139267" />
                            <site name="FCR-P3" pos="0.0122294 -0.0200631 -0.00454793" />
                            <site name="FCU-P4" pos="-0.0221521 -0.0192036 -0.00818193" />
                            <site name="PL-P3" pos="0.00997717 -0.0206507 -0.0190839" />
                            <site name="PL-P4" pos="0.00246981 -0.0336852 0.00536395" />
                            <site name="FDSL-P3" pos="-0.00255685 -0.0151562 -0.0149712" />
                            <site name="FDSL-P4" pos="-0.0217061 -0.0465783 -0.00807313" />
                            <site name="FDSL-P5" pos="-0.0222392 -0.0650746 -0.0204331" />
                            <site name="FDSL-P6" pos="-0.0186378 -0.0788272 -0.0299533" />
                            <site name="FDSL-P7" pos="-0.0125775 -0.0791101 -0.0397781" />
                            <site name="FDSL-P8" pos="-0.0115222 -0.0791101 -0.0413013" />
                            <site name="FDSR-P3" pos="-0.000892179 -0.014623 -0.0147862" />
                            <site name="FDSR-P4" pos="-0.01063 -0.0563487 4.35209e-005" />
                            <site name="FDSR-P5" pos="-0.0143945 -0.0725711 -0.0110978" />
                            <site name="FDSR-P6" pos="-0.00857362 -0.0873356 -0.0272332" />
                            <site name="FDSR-P7" pos="-0.00325319 -0.0884018 -0.0369384" />
                            <site name="FDSR-P8" pos="0.000674574 -0.0880428 -0.0423458" />
                            <site name="FDSM-P3" pos="0.00739855 -0.0149821 -0.0152214" />
                            <site name="FDSM-P4" pos="0.00512459 -0.0362529 -0.00143619" />
                            <site name="FDSM-P5" pos="0.00589708 -0.0615821 0.000652814" />
                            <site name="FDSM-P6" pos="0.00603853 -0.0785988 -0.00367752" />
                            <site name="FDSM-P7" pos="0.0126972 -0.0958548 -0.01817" />
                            <site name="FDSM-P8" pos="0.0141552 -0.0965076 -0.0323904" />
                            <site name="FDSM-P9" pos="0.0170602 -0.0933197 -0.0409641" />
                            <site name="FDSI-P3" pos="0.00967252 -0.0148624 -0.0150909" />
                            <site name="FDSI-P4" pos="0.0115439 -0.0412034 0.000261125" />
                            <site name="FDSI-P5" pos="0.0193886 -0.0555762 0.00454793" />
                            <site name="FDSI-P6" pos="0.0201175 -0.079393 -0.00408009" />
                            <site name="FDSI-P7" pos="0.0291372 -0.0948103 -0.0196279" />
                            <site name="FDSI-P8" pos="0.0290176 -0.0950932 -0.0291372" />
                            <site name="FDSI-P9" pos="0.0289414 -0.093929 -0.0315853" />
                            <site name="FDPL-P3" pos="-0.00095746 -0.011174 -0.0129257" />
                            <site name="FDPL-P4" pos="-0.0201828 -0.0505495 -0.00797521" />
                            <site name="FDPL-P5" pos="-0.0196715 -0.0635514 -0.0169732" />
                            <site name="FDPL-P6" pos="-0.015537 -0.079306 -0.0291916" />
                            <site name="FDPL-P7" pos="-0.0100098 -0.0814167 -0.0400828" />
                            <site name="FDPL-P8" pos="-0.00339463 -0.0805681 -0.0453161" />
                            <site name="FDPL-P9" pos="0.00485258 -0.0768035 -0.0506692" />
                            <site name="FDPR-P3" pos="0.0011533 -0.012806 -0.0128822" />
                            <site name="FDPR-P4" pos="-0.00930259 -0.0602982 0.00095746" />
                            <site name="FDPR-P5" pos="-0.0117398 -0.0716789 -0.00888915" />
                            <site name="FDPR-P6" pos="-0.00595148 -0.0887174 -0.0245458" />
                            <site name="FDPR-P7" pos="-0.000609293 -0.0895443 -0.0366337" />
                            <site name="FDPR-P8" pos="0.00662606 -0.0852683 -0.0461104" />
                            <site name="FDPR-P9" pos="0.013176 -0.0802961 -0.0528561" />
                            <site name="FDPM-P3" pos="0.00364488 -0.0139267 -0.012447" />
                            <site name="FDPM-P4" pos="0.00328583 -0.0375041 -0.00664782" />
                            <site name="FDPM-P5" pos="0.00274182 -0.0637908 0.00132739" />
                            <site name="FDPM-P6" pos="0.00310086 -0.0759984 -0.00144707" />
                            <site name="FDPM-P7" pos="0.00938964 -0.0955175 -0.0197476" />
                            <site name="FDPM-P8" pos="0.010902 -0.0953761 -0.032249" />
                            <site name="FDPM-P9" pos="0.0177674 -0.08875 -0.0482538" />
                            <site name="FDPM-P10" pos="0.0207704 -0.0833752 -0.0568927" />
                            <site name="FDPI-P3" pos="0.00974868 -0.0127081 -0.0131868" />
                            <site name="FDPI-P4" pos="0.0209118 -0.0602982 0.00476554" />
                            <site name="FDPI-P5" pos="0.0225547 -0.0763901 -0.00311174" />
                            <site name="FDPI-P6" pos="0.0315962 -0.0934394 -0.0193886" />
                            <site name="FDPI-P7" pos="0.0318138 -0.0943533 -0.0301273" />
                            <site name="FDPI-P8" pos="0.031705 -0.0895987 -0.0432924" />
                            <site name="FDPI-P9" pos="0.030976 -0.0845502 -0.0518552" />
                            <site name="EDCL-P4" pos="-0.0268089 -0.0478948 0.00183876" />
                            <site name="EDCL-P5" pos="-0.0259058 -0.051507 0.000837777" />
                            <site name="EDCL-P6" pos="-0.0260581 -0.0719509 -0.0108911" />
                            <site name="EDCL-P7" pos="-0.0195626 -0.0853771 -0.0294963" />
                            <site name="EDCL-P8" pos="-0.0128169 -0.0857035 -0.0411164" />
                            <site name="EDCL-P9" pos="-0.00163203 -0.0825374 -0.0498967" />
                            <site name="EDCL-P10" pos="0.00218693 -0.0814603 -0.0521598" />
                            <site name="EDCR-P4" pos="-0.0170167 -0.0603853 0.0101621" />
                            <site name="EDCR-P5" pos="-0.0155261 -0.063312 0.0126319" />
                            <site name="EDCR-P6" pos="-0.0171908 -0.0785117 -0.00458058" />
                            <site name="EDCR-P7" pos="-0.00897619 -0.0950388 -0.0245893" />
                            <site name="EDCR-P8" pos="-0.00295942 -0.0958113 -0.0370907" />
                            <site name="EDCR-P9" pos="0.00830161 -0.0873247 -0.0506801" />
                            <site name="EDCR-P10" pos="0.011631 -0.0849637 -0.0537592" />
                            <site name="EDCM-P4" pos="0.000424329 -0.0573823 0.0162224" />
                            <site name="EDCM-P5" pos="-0.00094658 -0.0606464 0.0157981" />
                            <site name="EDCM-P6" pos="0.00202372 -0.0839736 0.0064955" />
                            <site name="EDCM-P7" pos="0.0109564 -0.101328 -0.0193015" />
                            <site name="EDCM-P8" pos="0.0143728 -0.103993 -0.03325" />
                            <site name="EDCM-P9" pos="0.0202046 -0.0927539 -0.051779" />
                            <site name="EDCM-P10" pos="0.0223697 -0.0869657 -0.0581113" />
                            <site name="EDCM-P11" pos="0.0238821 -0.0837886 -0.0616147" />
                            <site name="EDCI-P4" pos="0.0167882 -0.0509195 0.0178327" />
                            <site name="EDCI-P5" pos="0.0206398 -0.0615168 0.0156458" />
                            <site name="EDCI-P6" pos="0.0216952 -0.0835384 0.00646285" />
                            <site name="EDCI-P7" pos="0.0320423 -0.0996846 -0.0135459" />
                            <site name="EDCI-P8" pos="0.0339572 -0.101719 -0.0316071" />
                            <site name="EDCI-P9" pos="0.0327821 -0.0923405 -0.0464368" />
                            <site name="EDCI-P10" pos="0.0318682 -0.0881625 -0.0540312" />
                            <site name="EDM-P5" pos="-0.0224024 -0.0112284 0.00404744" />
                            <site name="EDM-P6" pos="-0.027886 -0.0513764 0.000250245" />
                            <site name="EDM-P7" pos="-0.0277337 -0.0708412 -0.0119465" />
                            <site name="EDM-P8" pos="-0.0210315 -0.0849746 -0.0295725" />
                            <site name="EDM-P9" pos="-0.0146448 -0.0858668 -0.0423676" />
                            <site name="EDM-P10" pos="-0.00235013 -0.0818302 -0.0499294" />
                            <site name="EDM-P11" pos="0.00143619 -0.0799153 -0.0522577" />
                            <site name="EIP-P4" pos="0.00422153 -0.0243064 0.0128822" />
                            <site name="EIP-P5" pos="0.0184202 -0.0613645 0.0149821" />
                            <site name="EIP-P6" pos="0.0188772 -0.0836907 0.00632141" />
                            <site name="EIP-P7" pos="0.0300838 -0.101338 -0.01644" />
                            <site name="EIP-P8" pos="0.0313242 -0.102677 -0.0307149" />
                            <site name="EIP-P9" pos="0.0312263 -0.0927431 -0.0467306" />
                            <site name="EIP-P10" pos="0.0308346 -0.0847026 -0.0598521" />
                            <site name="EPL-P6" pos="0.0264172 0.000152323 0.00661518" />
                            <site name="EPL-P7" pos="0.025438 -0.00997717 -0.000424329" />
                            <site name="EPL-P8" pos="0.0316071 -0.0155261 -0.00532043" />
                            <site name="EPL-P9" pos="0.0480253 -0.0371777 -0.0197367" />
                            <site name="EPL-P10" pos="0.0529541 -0.0505495 -0.0270591" />
                            <site name="EPL-P11" pos="0.051692 -0.0762704 -0.041062" />
                            <site name="EPL-P12" pos="0.0436406 -0.0823089 -0.0466" />
                            <site name="EPB-P5" pos="0.0339789 0.00278534 -0.00355783" />
                            <site name="EPB-P6" pos="0.032336 -0.0086389 -0.015624" />
                            <site name="EPB-P7" pos="0.0481124 -0.0359047 -0.0263519" />
                            <site name="EPB-P8" pos="0.0492657 -0.0520619 -0.0346644" />
                            <site name="FPL-P6" pos="0.013535 -0.0240127 -0.0227288" />
                            <site name="FPL-P7" pos="0.0178545 -0.0285171 -0.024165" />
                            <site name="FPL-P8" pos="0.0267327 -0.0358395 -0.0243391" />
                            <site name="FPL-P9" pos="0.0307584 -0.0596454 -0.0332391" />
                            <site name="FPL-P10" pos="0.0382005 -0.0709282 -0.04079" />
                            <site name="FPL-P11" pos="0.0384398 -0.083299 -0.0448048" />
                            <site name="FPL-P5" pos="0.0178892 0.0064176 -0.0168214" />
                            <site name="APL-P7" pos="0.0281471 0.00223045 -0.0179524" />
                            <site name="APL-P8" pos="0.0313133 -0.00733327 -0.020346" />
                            <site name="APL-P9" pos="0.0334676 -0.0172234 -0.0205092" />
                            <site name="APL-P6" pos="0.0332244 0.00608975 -0.00870125" />
                            <body name="index0" pos="0 0 0">
                              <inertial pos="0 0 0" mass="0.001" diaginertia="0.001 0.001 0.001" />
                              <geom name="sdfast_1seg_hand_fr_c_2mc" type="mesh" mesh="sdfast_1seg_hand_fr_c_2mc" />
                              <body name="index1" pos="0 0 0">
                                <inertial pos="0 0 0" mass="0.001" diaginertia="0.001 0.001 0.001" />
                                <geom name="hand_2proxph" type="mesh" mesh="hand_2proxph" />
                                <body name="index2" pos="0 0 0">
                                  <inertial pos="0 0 0" mass="0.001" diaginertia="0.001 0.001 0.001" />
                                  <geom name="hand_2midph" type="mesh" mesh="hand_2midph" />
                                  <body name="index3" pos="0 0 0">
                                    <inertial pos="0 0 0" mass="0.001" diaginertia="0.001 0.001 0.001" />
                                    <geom name="hand_2distph" type="mesh" mesh="hand_2distph" />
                                    <site name="fingertip" pos="0.024 -0.149 -0.0065" type="sphere" rgba="0.1 0.8 0.1 0.0" size="0.004" />
                                  </body>
                                </body>
                              </body>
                            </body>
                          </body>
                        </body>
                      </body>
                    </body>
                  </body>
                </body>
              </body>
            </body>
          </body>
        </body>
      </body>
    </body>

</mujocoinclude>